Workbook

Sheet Instructions
A1: Global Wholesale Machinery Inc.
A2: OEM Compareson Spreadsheet Instructions
A4: NET MARKUP% for each quote must be over 100% otherwise need approval from Quinten.
A5: NET MARGIN% for each quote must be over 50% otherwise need approval from Quinten.
A7: Customer Information Section
B8: Must be fully completed in OEM COMPARISON TAB.
B9: Information entered will be automatically transferred to QUOTE, and SERVICE QUOTE tab.
B10: Customer Information will not be transferred to RFQ tab as we do not give out customer information to vendors.
A12: Machine Information Section
B13: Optional - depends on customer request.
B14: Information entered will be automatically transferred to RFQ, QUOTE, and SERVICE QUOTE tab.
A16: Machine Service Interval Section
B17: Optional - depends on customer request.
B18: For internal use only. Information entered will not be transferred to RFQ, QUOTE, and SERVICE QUOTE tab.
A20: Parts Pricing and Cost Section
B21: Part Number - OEM Part Number (with exception to UC and Tires)
B22: Description - Description of Part
B23: Vendor - Name of the Vendor where we acquire parts from
B24: OEM Name - Name of OEM Manufacturer used for MSRP comparison
B25: Freight Cost - Vendor shipping cost.
A27: Customizable Features
A28: 1) Show or Hide OEM Comparison in Quote or Service Quote to cusomter.
B29: Select from drop down option at cell J13
A34: 2) Enter OEM pricing in USD or CAD.
B35: Select from drop down option at cell G17
A41: 3) Provide customer quotes in USD or CAD.
B42: Select from drop down option at cell L17
A51: 4) Enter Vendor pricing in USD or CAD.
B52: Select from drop down option at cell Q17

Sheet CAT 325 EXCAVATOR
B1: CUSTOMER INFORMATION | D1: MACHINE INFORMATION | H1: MACHINE SERVICE HR INTERVALS | L1: SUMMARY | O1: =K17 -> CAD $ | R1: COMPLETED DEAL INFORMATION
B2: DATE: | D2: UNIT # | H2: ENGINE AIR | L2: OEM MSRP | O2: =H129 -> 210310.33 | R2: SALES REP
B3: COMPANY: | D3: YEAR | H3: ENGINE OIL | L3: GQP LIST | O3: =L129 -> 105158.1 | R3: ORDER PO #
B4: CUSTOMER: | D4: MAKE | H4: FUEL FILTERS | L4: $ SAVINGS | O4: =O2-O3 -> 105152.23 | R4: PROJECT #
B5: PHONE: | D5: MODEL | H5: HYDRAULIC FILTERS | L5: % SAVINGS | O5: =IFERROR((O2-O3)/O2,"") -> 0.49998604 | R5: CUST INVOICE #
B6: EMAIL: | D6: SERIAL NUMBER | H6: TRANSMISSION FILTERS | L6: TOTAL ORDER MARGIN | O6: =S129 -> 105158.1 | R6: PAYMENT TYPE
B7: SALES REP: | D7: ENGINE SER NUMBER | H7: CAB FILTERS | L7: TOTAL ITEM COST | O7: =Q129 -> 0 | R7: DATE DELIVERED
D8: CURRENT HOURS | H8: UNDERCARRIAGE / TIRES | L8: TOTAL ORDER FREIGHT | O8: =IF(O1=P14,Q14,IF(P14="CAD $",Q14*D15,IF(P14="USD $",Q14*E15,0))) -> 0 | R8: TOTAL COST | S8: NET MARGIN | T8: NET MARKUP % | U8: NET MARGIN %
D9: USAGE/MONTH | L9: TOTAL CUSTOMS/BROKERAGE | O9: =U14 -> 0 | R9: =O7+O8+O9 -> 0 | S9: =O3-R9 -> 105158.1 | T9: =IFERROR(((O3-R9)/R9),0) -> 0 | U9: =IFERROR(((O3-R9)/O3),0) -> 1
L10: TOTAL NUMBER PIECES | O10: =E129 -> 1061
D11: ENTER EXCHANGE RATES $ | F11: OEM MSRP | J11: CUSTOMER SELL PRICE | O11: COST ANALYSIS | X11: CAD $
X12: USD $
F13: SHOW OEM MSRP ON QUOTE: | H13: YES | X13: YES
D14: CAD-USD | E14: USD-CAD | F14: OEM NAME | J14: CUSTOMER PRICE % OF OEM LIST | L14: 0.5 | O14: FREIGHT TOTAL ORDER | P14: USD $ | R14: CUSTOMS AND BROKERAGE % | S14: 0.025 | T14: BROKERAGE FEES | U14: =ROUND(Q129*S14,2) -> 0 | X14: NO
D15: =1/E15 -> 0.72463768 | E15: 1.38 | M15: ADDITIONAL +/- DISC % PER ITEM | O15: MARKUP LESS THAN 100% REQUIRES MANAGER APPROVAL
B16: PART NUMBER | C16: DESCRIPTION | D16: SERVICE INTERVAL | E16: QTY | F16: UNIT PRICE | H16: EXT AMOUNT | J16: QTY | K16: UNIT PRICE | L16: EXTENDED AMOUNT | O16: VENDOR | P16: COST EACH | Q16: EXTENDED COST | R16: MARGIN EACH | S16: EXTENDED MARGIN | T16: MARKUP % | U16: MARGIN %
F17: USD $ | G17: =IF(F17="USD $", "CAD $", "USD $") -> CAD $ | H17: =K17 -> CAD $ | K17: CAD $ | P17: USD $ | Q17: =K17 -> CAD $
B18: 1R-1807 | C18: OIL FILTER | E18: 1 | F18: 44.09 | G18: =ROUND(IF($F$17="USD $", F18*$E$15,F18*$D$15),2) -> 60.84 | H18: =ROUND(IF($H$17=$G$17,E18*G18,E18*F18),2) -> 60.84 | J18: =E18 -> 1 | K18: =ROUND(IF($K$17=$F$17,F18*($L$14-M18),G18*($L$14-M18)),2) -> 30.42 | L18: =ROUND((J18*K18),2) -> 30.42 | Q18: =ROUND(IF($Q$17=$P$17,P18,IF($Q$17="USD $",P18*$D$15,P18*$E$15))*E18,2) -> 0 | R18: =IFERROR(ROUND(S18/E18,2),0) -> 30.42 | S18: =ROUND(L18-Q18,2) -> 30.42 | T18: =IFERROR(((K18-(Q18/J18))/(Q18/J18)),0) -> 0 | U18: =IFERROR(((K18-(Q18/J18))/K18),0) -> 1 | Y18: 250
B19: 179-9806 | C19: Hydraulic Filter | E19: 1 | F19: 229 | G19: =ROUND(IF($F$17="USD $", F19*$E$15,F19*$D$15),2) -> 316.02 | H19: =ROUND(IF($H$17=$G$17,E19*G19,E19*F19),2) -> 316.02 | J19: =E19 -> 1 | K19: =ROUND(IF($K$17=$F$17,F19*($L$14-M19),G19*($L$14-M19)),2) -> 158.01 | L19: =ROUND((J19*K19),2) -> 158.01 | Q19: =ROUND(IF($Q$17=$P$17,P19,IF($Q$17="USD $",P19*$D$15,P19*$E$15))*E19,2) -> 0 | R19: =IFERROR(ROUND(S19/E19,2),0) -> 158.01 | S19: =ROUND(L19-Q19,2) -> 158.01 | T19: =IFERROR(((K19-(Q19/J19))/(Q19/J19)),0) -> 0 | U19: =IFERROR(((K19-(Q19/J19))/K19),0) -> 1 | X19: GQP | Y19: 500
B20: 126-1813 | C20: HYDRAULIC/TRANSMISSION OIL FILTER | E20: 1 | F20: 170.36 | G20: =ROUND(IF($F$17="USD $", F20*$E$15,F20*$D$15),2) -> 235.1 | H20: =ROUND(IF($H$17=$G$17,E20*G20,E20*F20),2) -> 235.1 | J20: =E20 -> 1 | K20: =ROUND(IF($K$17=$F$17,F20*($L$14-M20),G20*($L$14-M20)),2) -> 117.55 | L20: =ROUND((J20*K20),2) -> 117.55 | Q20: =ROUND(IF($Q$17=$P$17,P20,IF($Q$17="USD $",P20*$D$15,P20*$E$15))*E20,2) -> 0 | R20: =IFERROR(ROUND(S20/E20,2),0) -> 117.55 | S20: =ROUND(L20-Q20,2) -> 117.55 | T20: =IFERROR(((K20-(Q20/J20))/(Q20/J20)),0) -> 0 | U20: =IFERROR(((K20-(Q20/J20))/K20),0) -> 1 | X20: CTP | Y20: 750
B21: 1R7062 | C21: FUEL FILTER | E21: 1 | F21: 67.44 | G21: =ROUND(IF($F$17="USD $", F21*$E$15,F21*$D$15),2) -> 93.07 | H21: =ROUND(IF($H$17=$G$17,E21*G21,E21*F21),2) -> 93.07 | J21: =E21 -> 1 | K21: =ROUND(IF($K$17=$F$17,F21*($L$14-M21),G21*($L$14-M21)),2) -> 46.54 | L21: =ROUND((J21*K21),2) -> 46.54 | Q21: =ROUND(IF($Q$17=$P$17,P21,IF($Q$17="USD $",P21*$D$15,P21*$E$15))*E21,2) -> 0 | R21: =IFERROR(ROUND(S21/E21,2),0) -> 46.54 | S21: =ROUND(L21-Q21,2) -> 46.54 | T21: =IFERROR(((K21-(Q21/J21))/(Q21/J21)),0) -> 0 | U21: =IFERROR(((K21-(Q21/J21))/K21),0) -> 1 | X21: BLMQ | Y21: 1000
B22: 6I-2504 | C22: SECONDARY AIR FILTER | E22: 1 | F22: 117.3 | G22: =ROUND(IF($F$17="USD $", F22*$E$15,F22*$D$15),2) -> 161.87 | H22: =ROUND(IF($H$17=$G$17,E22*G22,E22*F22),2) -> 161.87 | J22: =E22 -> 1 | K22: =ROUND(IF($K$17=$F$17,F22*($L$14-M22),G22*($L$14-M22)),2) -> 80.94 | L22: =ROUND((J22*K22),2) -> 80.94 | Q22: =ROUND(IF($Q$17=$P$17,P22,IF($Q$17="USD $",P22*$D$15,P22*$E$15))*E22,2) -> 0 | R22: =IFERROR(ROUND(S22/E22,2),0) -> 80.94 | S22: =ROUND(L22-Q22,2) -> 80.94 | T22: =IFERROR(((K22-(Q22/J22))/(Q22/J22)),0) -> 0 | U22: =IFERROR(((K22-(Q22/J22))/K22),0) -> 1 | X22: CAT | Y22: 1200
B23: 6I-2503 | C23: PRIMARY AIR FILTER | E23: 1 | F23: 165.83 | G23: =ROUND(IF($F$17="USD $", F23*$E$15,F23*$D$15),2) -> 228.85 | H23: =ROUND(IF($H$17=$G$17,E23*G23,E23*F23),2) -> 228.85 | J23: =E23 -> 1 | K23: =ROUND(IF($K$17=$F$17,F23*($L$14-M23),G23*($L$14-M23)),2) -> 114.43 | L23: =ROUND((J23*K23),2) -> 114.43 | Q23: =ROUND(IF($Q$17=$P$17,P23,IF($Q$17="USD $",P23*$D$15,P23*$E$15))*E23,2) -> 0 | R23: =IFERROR(ROUND(S23/E23,2),0) -> 114.43 | S23: =ROUND(L23-Q23,2) -> 114.43 | T23: =IFERROR(((K23-(Q23/J23))/(Q23/J23)),0) -> 0 | U23: =IFERROR(((K23-(Q23/J23))/K23),0) -> 1 | X23: FINNING | Y23: 2000
B24: 326-1644 | C24: WATER/FUEL SEPARATOR | E24: 1 | F24: 85.6 | G24: =ROUND(IF($F$17="USD $", F24*$E$15,F24*$D$15),2) -> 118.13 | H24: =ROUND(IF($H$17=$G$17,E24*G24,E24*F24),2) -> 118.13 | J24: =E24 -> 1 | K24: =ROUND(IF($K$17=$F$17,F24*($L$14-M24),G24*($L$14-M24)),2) -> 59.07 | L24: =ROUND((J24*K24),2) -> 59.07 | Q24: =ROUND(IF($Q$17=$P$17,P24,IF($Q$17="USD $",P24*$D$15,P24*$E$15))*E24,2) -> 0 | R24: =IFERROR(ROUND(S24/E24,2),0) -> 59.07 | S24: =ROUND(L24-Q24,2) -> 59.07 | T24: =IFERROR(((K24-(Q24/J24))/(Q24/J24)),0) -> 0 | U24: =IFERROR(((K24-(Q24/J24))/K24),0) -> 1 | X24: JD | Y24: 4000
B25: 177-4754 | C25: INJECTOR | E25: 6 | F25: 1834.86 | G25: =ROUND(IF($F$17="USD $", F25*$E$15,F25*$D$15),2) -> 2532.11 | H25: =ROUND(IF($H$17=$G$17,E25*G25,E25*F25),2) -> 15192.66 | J25: =E25 -> 6 | K25: =ROUND(IF($K$17=$F$17,F25*($L$14-M25),G25*($L$14-M25)),2) -> 1266.06 | L25: =ROUND((J25*K25),2) -> 7596.36 | Q25: =ROUND(IF($Q$17=$P$17,P25,IF($Q$17="USD $",P25*$D$15,P25*$E$15))*E25,2) -> 0 | R25: =IFERROR(ROUND(S25/E25,2),0) -> 1266.06 | S25: =ROUND(L25-Q25,2) -> 7596.36 | T25: =IFERROR(((K25-(Q25/J25))/(Q25/J25)),0) -> 0 | U25: =IFERROR(((K25-(Q25/J25))/K25),0) -> 1 | X25: BRANDT | Y25: 6000
B26: 3T-5760 | C26: BATTERY | E26: 1 | F26: 451.85 | G26: =ROUND(IF($F$17="USD $", F26*$E$15,F26*$D$15),2) -> 623.55 | H26: =ROUND(IF($H$17=$G$17,E26*G26,E26*F26),2) -> 623.55 | J26: =E26 -> 1 | K26: =ROUND(IF($K$17=$F$17,F26*($L$14-M26),G26*($L$14-M26)),2) -> 311.78 | L26: =ROUND((J26*K26),2) -> 311.78 | Q26: =ROUND(IF($Q$17=$P$17,P26,IF($Q$17="USD $",P26*$D$15,P26*$E$15))*E26,2) -> 0 | R26: =IFERROR(ROUND(S26/E26,2),0) -> 311.78 | S26: =ROUND(L26-Q26,2) -> 311.78 | T26: =IFERROR(((K26-(Q26/J26))/(Q26/J26)),0) -> 0 | U26: =IFERROR(((K26-(Q26/J26))/K26),0) -> 1 | X26: PTI | Y26: 8000
G27: =ROUND(IF($F$17="USD $", F27*$E$15,F27*$D$15),2) -> 0 | H27: =ROUND(IF($H$17=$G$17,E27*G27,E27*F27),2) -> 0 | J27: =E27 -> 0 | K27: =ROUND(IF($K$17=$F$17,F27*($L$14-M27),G27*($L$14-M27)),2) -> 0 | L27: =ROUND((J27*K27),2) -> 0 | Q27: =ROUND(IF($Q$17=$P$17,P27,IF($Q$17="USD $",P27*$D$15,P27*$E$15))*E27,2) -> 0 | R27: =IFERROR(ROUND(S27/E27,2),0) -> 0 | S27: =ROUND(L27-Q27,2) -> 0 | T27: =IFERROR(((K27-(Q27/J27))/(Q27/J27)),0) -> 0 | U27: =IFERROR(((K27-(Q27/J27))/K27),0) -> 0 | X27: CONEQUIP | Y27: 10000
B28: 177-0440 | C28: TURBOCHARGER | E28: 1 | F28: 6839.06 | G28: =ROUND(IF($F$17="USD $", F28*$E$15,F28*$D$15),2) -> 9437.9 | H28: =ROUND(IF($H$17=$G$17,E28*G28,E28*F28),2) -> 9437.9 | J28: =E28 -> 1 | K28: =ROUND(IF($K$17=$F$17,F28*($L$14-M28),G28*($L$14-M28)),2) -> 4718.95 | L28: =ROUND((J28*K28),2) -> 4718.95 | Q28: =ROUND(IF($Q$17=$P$17,P28,IF($Q$17="USD $",P28*$D$15,P28*$E$15))*E28,2) -> 0 | R28: =IFERROR(ROUND(S28/E28,2),0) -> 4718.95 | S28: =ROUND(L28-Q28,2) -> 4718.95 | T28: =IFERROR(((K28-(Q28/J28))/(Q28/J28)),0) -> 0 | U28: =IFERROR(((K28-(Q28/J28))/K28),0) -> 1 | X28: CANDY | Y28: AS REQ'D
B29: 205-1259 | C29: CAMSHAFT | E29: 1 | F29: 4419.09 | G29: =ROUND(IF($F$17="USD $", F29*$E$15,F29*$D$15),2) -> 6098.34 | H29: =ROUND(IF($H$17=$G$17,E29*G29,E29*F29),2) -> 6098.34 | J29: =E29 -> 1 | K29: =ROUND(IF($K$17=$F$17,F29*($L$14-M29),G29*($L$14-M29)),2) -> 3049.17 | L29: =ROUND((J29*K29),2) -> 3049.17 | Q29: =ROUND(IF($Q$17=$P$17,P29,IF($Q$17="USD $",P29*$D$15,P29*$E$15))*E29,2) -> 0 | R29: =IFERROR(ROUND(S29/E29,2),0) -> 3049.17 | S29: =ROUND(L29-Q29,2) -> 3049.17 | T29: =IFERROR(((K29-(Q29/J29))/(Q29/J29)),0) -> 0 | U29: =IFERROR(((K29-(Q29/J29))/K29),0) -> 1 | X29: U/C
B30: 4892731 | C30: CRANKSHAFT | E30: 1 | F30: 14944.09 | G30: =ROUND(IF($F$17="USD $", F30*$E$15,F30*$D$15),2) -> 20622.84 | H30: =ROUND(IF($H$17=$G$17,E30*G30,E30*F30),2) -> 20622.84 | J30: =E30 -> 1 | K30: =ROUND(IF($K$17=$F$17,F30*($L$14-M30),G30*($L$14-M30)),2) -> 10311.42 | L30: =ROUND((J30*K30),2) -> 10311.42 | Q30: =ROUND(IF($Q$17=$P$17,P30,IF($Q$17="USD $",P30*$D$15,P30*$E$15))*E30,2) -> 0 | R30: =IFERROR(ROUND(S30/E30,2),0) -> 10311.42 | S30: =ROUND(L30-Q30,2) -> 10311.42 | T30: =IFERROR(((K30-(Q30/J30))/(Q30/J30)),0) -> 0 | U30: =IFERROR(((K30-(Q30/J30))/K30),0) -> 1
B31: CUSTOM | C31: ENGINE REBUILD KIT | G31: =ROUND(IF($F$17="USD $", F31*$E$15,F31*$D$15),2) -> 0 | H31: =ROUND(IF($H$17=$G$17,E31*G31,E31*F31),2) -> 0 | J31: =E31 -> 0 | K31: =ROUND(IF($K$17=$F$17,F31*($L$14-M31),G31*($L$14-M31)),2) -> 0 | L31: =ROUND((J31*K31),2) -> 0 | Q31: =ROUND(IF($Q$17=$P$17,P31,IF($Q$17="USD $",P31*$D$15,P31*$E$15))*E31,2) -> 0 | R31: =IFERROR(ROUND(S31/E31,2),0) -> 0 | S31: =ROUND(L31-Q31,2) -> 0 | T31: =IFERROR(((K31-(Q31/J31))/(Q31/J31)),0) -> 0 | U31: =IFERROR(((K31-(Q31/J31))/K31),0) -> 0
G32: =ROUND(IF($F$17="USD $", F32*$E$15,F32*$D$15),2) -> 0 | H32: =ROUND(IF($H$17=$G$17,E32*G32,E32*F32),2) -> 0 | J32: =E32 -> 0 | K32: =ROUND(IF($K$17=$F$17,F32*($L$14-M32),G32*($L$14-M32)),2) -> 0 | L32: =ROUND((J32*K32),2) -> 0 | Q32: =ROUND(IF($Q$17=$P$17,P32,IF($Q$17="USD $",P32*$D$15,P32*$E$15))*E32,2) -> 0 | R32: =IFERROR(ROUND(S32/E32,2),0) -> 0 | S32: =ROUND(L32-Q32,2) -> 0 | T32: =IFERROR(((K32-(Q32/J32))/(Q32/J32)),0) -> 0 | U32: =IFERROR(((K32-(Q32/J32))/K32),0) -> 0
B33: CUSTOM | C33: UNDERCARRIAGE TRACK GROUP ASSY | E33: 2 | F33: =SUM(F34:F37) -> 10726.82 | G33: =ROUND(IF($F$17="USD $", F33*$E$15,F33*$D$15),2) -> 14803.01 | H33: =ROUND(IF($H$17=$G$17,E33*G33,E33*F33),2) -> 29606.02 | J33: =E33 -> 2 | K33: =ROUND(IF($K$17=$F$17,F33*($L$14-M33),G33*($L$14-M33)),2) -> 7401.51 | L33: =ROUND((J33*K33),2) -> 14803.02 | Q33: =ROUND(IF($Q$17=$P$17,P33,IF($Q$17="USD $",P33*$D$15,P33*$E$15))*E33,2) -> 0 | R33: =IFERROR(ROUND(S33/E33,2),0) -> 7401.51 | S33: =ROUND(L33-Q33,2) -> 14803.02 | T33: =IFERROR(((K33-(Q33/J33))/(Q33/J33)),0) -> 0 | U33: =IFERROR(((K33-(Q33/J33))/K33),0) -> 1
B34: 213-1932 | C34: LINK AS- TRACK | E34: 2 | F34: 10460.7 | G34: =ROUND(IF($F$17="USD $", F34*$E$15,F34*$D$15),2) -> 14435.77 | H34: =ROUND(IF($H$17=$G$17,E34*G34,E34*F34),2) -> 28871.54 | J34: =E34 -> 2 | K34: =ROUND(IF($K$17=$F$17,F34*($L$14-M34),G34*($L$14-M34)),2) -> 7217.89 | L34: =ROUND((J34*K34),2) -> 14435.78 | Q34: =ROUND(IF($Q$17=$P$17,P34,IF($Q$17="USD $",P34*$D$15,P34*$E$15))*E34,2) -> 0 | R34: =IFERROR(ROUND(S34/E34,2),0) -> 7217.89 | S34: =ROUND(L34-Q34,2) -> 14435.78 | T34: =IFERROR(((K34-(Q34/J34))/(Q34/J34)),0) -> 0 | U34: =IFERROR(((K34-(Q34/J34))/K34),0) -> 1
B35: 6I-8651 | C35: TRACK SHOE 36INCH | E35: 96 | F35: 256.66 | G35: =ROUND(IF($F$17="USD $", F35*$E$15,F35*$D$15),2) -> 354.19 | H35: =ROUND(IF($H$17=$G$17,E35*G35,E35*F35),2) -> 34002.24 | J35: =E35 -> 96 | K35: =ROUND(IF($K$17=$F$17,F35*($L$14-M35),G35*($L$14-M35)),2) -> 177.1 | L35: =ROUND((J35*K35),2) -> 17001.6 | Q35: =ROUND(IF($Q$17=$P$17,P35,IF($Q$17="USD $",P35*$D$15,P35*$E$15))*E35,2) -> 0 | R35: =IFERROR(ROUND(S35/E35,2),0) -> 177.1 | S35: =ROUND(L35-Q35,2) -> 17001.6 | T35: =IFERROR(((K35-(Q35/J35))/(Q35/J35)),0) -> 0 | U35: =IFERROR(((K35-(Q35/J35))/K35),0) -> 1
B36: 6Y-0846 | C36: TRACK BOLT | E36: 384 | F36: 6.32 | G36: =ROUND(IF($F$17="USD $", F36*$E$15,F36*$D$15),2) -> 8.72 | H36: =ROUND(IF($H$17=$G$17,E36*G36,E36*F36),2) -> 3348.48 | J36: =E36 -> 384 | K36: =ROUND(IF($K$17=$F$17,F36*($L$14-M36),G36*($L$14-M36)),2) -> 4.36 | L36: =ROUND((J36*K36),2) -> 1674.24 | Q36: =ROUND(IF($Q$17=$P$17,P36,IF($Q$17="USD $",P36*$D$15,P36*$E$15))*E36,2) -> 0 | R36: =IFERROR(ROUND(S36/E36,2),0) -> 4.36 | S36: =ROUND(L36-Q36,2) -> 1674.24 | T36: =IFERROR(((K36-(Q36/J36))/(Q36/J36)),0) -> 0 | U36: =IFERROR(((K36-(Q36/J36))/K36),0) -> 1
B37: 9W-3361 | C37: TRACK NUT | E37: 384 | F37: 3.14 | G37: =ROUND(IF($F$17="USD $", F37*$E$15,F37*$D$15),2) -> 4.33 | H37: =ROUND(IF($H$17=$G$17,E37*G37,E37*F37),2) -> 1662.72 | J37: =E37 -> 384 | K37: =ROUND(IF($K$17=$F$17,F37*($L$14-M37),G37*($L$14-M37)),2) -> 2.17 | L37: =ROUND((J37*K37),2) -> 833.28 | Q37: =ROUND(IF($Q$17=$P$17,P37,IF($Q$17="USD $",P37*$D$15,P37*$E$15))*E37,2) -> 0 | R37: =IFERROR(ROUND(S37/E37,2),0) -> 2.17 | S37: =ROUND(L37-Q37,2) -> 833.28 | T37: =IFERROR(((K37-(Q37/J37))/(Q37/J37)),0) -> 0 | U37: =IFERROR(((K37-(Q37/J37))/K37),0) -> 1
G38: =ROUND(IF($F$17="USD $", F38*$E$15,F38*$D$15),2) -> 0 | H38: =ROUND(IF($H$17=$G$17,E38*G38,E38*F38),2) -> 0 | J38: =E38 -> 0 | K38: =ROUND(IF($K$17=$F$17,F38*($L$14-M38),G38*($L$14-M38)),2) -> 0 | L38: =ROUND((J38*K38),2) -> 0 | Q38: =ROUND(IF($Q$17=$P$17,P38,IF($Q$17="USD $",P38*$D$15,P38*$E$15))*E38,2) -> 0 | R38: =IFERROR(ROUND(S38/E38,2),0) -> 0 | S38: =ROUND(L38-Q38,2) -> 0 | T38: =IFERROR(((K38-(Q38/J38))/(Q38/J38)),0) -> 0 | U38: =IFERROR(((K38-(Q38/J38))/K38),0) -> 0
B39: 602-9393 | C39: FRONT WHEEL IDLER ASSY | E39: 2 | F39: 3159.07 | G39: =ROUND(IF($F$17="USD $", F39*$E$15,F39*$D$15),2) -> 4359.52 | H39: =ROUND(IF($H$17=$G$17,E39*G39,E39*F39),2) -> 8719.04 | J39: =E39 -> 2 | K39: =ROUND(IF($K$17=$F$17,F39*($L$14-M39),G39*($L$14-M39)),2) -> 2179.76 | L39: =ROUND((J39*K39),2) -> 4359.52 | Q39: =ROUND(IF($Q$17=$P$17,P39,IF($Q$17="USD $",P39*$D$15,P39*$E$15))*E39,2) -> 0 | R39: =IFERROR(ROUND(S39/E39,2),0) -> 2179.76 | S39: =ROUND(L39-Q39,2) -> 4359.52 | T39: =IFERROR(((K39-(Q39/J39))/(Q39/J39)),0) -> 0 | U39: =IFERROR(((K39-(Q39/J39))/K39),0) -> 1
B40: 300-4545 | C40: CARRIER ROLLER | E40: 4 | F40: 635.42 | G40: =ROUND(IF($F$17="USD $", F40*$E$15,F40*$D$15),2) -> 876.88 | H40: =ROUND(IF($H$17=$G$17,E40*G40,E40*F40),2) -> 3507.52 | J40: =E40 -> 4 | K40: =ROUND(IF($K$17=$F$17,F40*($L$14-M40),G40*($L$14-M40)),2) -> 438.44 | L40: =ROUND((J40*K40),2) -> 1753.76 | Q40: =ROUND(IF($Q$17=$P$17,P40,IF($Q$17="USD $",P40*$D$15,P40*$E$15))*E40,2) -> 0 | R40: =IFERROR(ROUND(S40/E40,2),0) -> 438.44 | S40: =ROUND(L40-Q40,2) -> 1753.76 | T40: =IFERROR(((K40-(Q40/J40))/(Q40/J40)),0) -> 0 | U40: =IFERROR(((K40-(Q40/J40))/K40),0) -> 1
...

Sheet CAT D7R
B1: CUSTOMER INFORMATION | D1: MACHINE INFORMATION | H1: MACHINE SERVICE HR INTERVALS | L1: SUMMARY | O1: =K17 -> CAD $ | R1: COMPLETED DEAL INFORMATION
B2: DATE: | D2: UNIT # | H2: ENGINE AIR | L2: OEM MSRP | O2: =H129 -> 315127.21 | R2: SALES REP
B3: COMPANY: | D3: YEAR | H3: ENGINE OIL | L3: GQP LIST | O3: =L129 -> 157565.35 | R3: ORDER PO #
B4: CUSTOMER: | D4: MAKE | H4: FUEL FILTERS | L4: $ SAVINGS | O4: =O2-O3 -> 157561.86 | R4: PROJECT #
B5: PHONE: | D5: MODEL | H5: HYDRAULIC FILTERS | L5: % SAVINGS | O5: =IFERROR((O2-O3)/O2,"") -> 0.49999446 | R5: CUST INVOICE #
B6: EMAIL: | D6: SERIAL NUMBER | H6: TRANSMISSION FILTERS | L6: TOTAL ORDER MARGIN | O6: =S129 -> 157565.35 | R6: PAYMENT TYPE
B7: SALES REP: | D7: ENGINE SER NUMBER | H7: CAB FILTERS | L7: TOTAL ITEM COST | O7: =Q129 -> 0 | R7: DATE DELIVERED
D8: CURRENT HOURS | H8: UNDERCARRIAGE / TIRES | L8: TOTAL ORDER FREIGHT | O8: =IF(O1=P14,Q14,IF(P14="CAD $",Q14*D15,IF(P14="USD $",Q14*E15,0))) -> 0 | R8: TOTAL COST | S8: NET MARGIN | T8: NET MARKUP % | U8: NET MARGIN %
D9: USAGE/MONTH | L9: TOTAL CUSTOMS/BROKERAGE | O9: =U14 -> 0 | R9: =O7+O8+O9 -> 0 | S9: =O3-R9 -> 157565.35 | T9: =IFERROR(((O3-R9)/R9),0) -> 0 | U9: =IFERROR(((O3-R9)/O3),0) -> 1
L10: TOTAL NUMBER PIECES | O10: =E129 -> 487
D11: ENTER EXCHANGE RATES $ | F11: OEM MSRP | J11: CUSTOMER SELL PRICE | O11: COST ANALYSIS | X11: CAD $
X12: USD $
F13: SHOW OEM MSRP ON QUOTE: | H13: YES | X13: YES
D14: CAD-USD | E14: USD-CAD | F14: OEM NAME | J14: CUSTOMER PRICE % OF OEM LIST | L14: 0.5 | O14: FREIGHT TOTAL ORDER | P14: USD $ | R14: CUSTOMS AND BROKERAGE % | S14: 0.025 | T14: BROKERAGE FEES | U14: =ROUND(Q129*S14,2) -> 0 | X14: NO
D15: =1/E15 -> 0.72463768 | E15: 1.38 | M15: ADDITIONAL +/- DISC % PER ITEM | O15: MARKUP LESS THAN 100% REQUIRES MANAGER APPROVAL
B16: PART NUMBER | C16: DESCRIPTION | D16: SERVICE INTERVAL | E16: QTY | F16: UNIT PRICE | H16: EXT AMOUNT | J16: QTY | K16: UNIT PRICE | L16: EXTENDED AMOUNT | O16: VENDOR | P16: COST EACH | Q16: EXTENDED COST | R16: MARGIN EACH | S16: EXTENDED MARGIN | T16: MARKUP % | U16: MARGIN %
F17: CAD $ | G17: =IF(F17="USD $", "CAD $", "USD $") -> USD $ | H17: =K17 -> CAD $ | K17: CAD $ | P17: USD $ | Q17: =K17 -> CAD $
B18: 1R-0716 | C18: ENGINE OIL FILTER | E18: 1 | F18: 61.62 | G18: =ROUND(IF($F$17="USD $", F18*$E$15,F18*$D$15),2) -> 44.65 | H18: =ROUND(IF($H$17=$G$17,E18*G18,E18*F18),2) -> 61.62 | J18: =E18 -> 1 | K18: =ROUND(IF($K$17=$F$17,F18*($L$14-M18),G18*($L$14-M18)),2) -> 30.81 | L18: =ROUND((J18*K18),2) -> 30.81 | Q18: =ROUND(IF($Q$17=$P$17,P18,IF($Q$17="USD $",P18*$D$15,P18*$E$15))*E18,2) -> 0 | R18: =IFERROR(ROUND(S18/E18,2),0) -> 30.81 | S18: =ROUND(L18-Q18,2) -> 30.81 | T18: =IFERROR(((K18-(Q18/J18))/(Q18/J18)),0) -> 0 | U18: =IFERROR(((K18-(Q18/J18))/K18),0) -> 1 | Y18: 250
B19: 326-1643 | C19: fuel filter | E19: 1 | F19: 104.86 | G19: =ROUND(IF($F$17="USD $", F19*$E$15,F19*$D$15),2) -> 75.99 | H19: =ROUND(IF($H$17=$G$17,E19*G19,E19*F19),2) -> 104.86 | J19: =E19 -> 1 | K19: =ROUND(IF($K$17=$F$17,F19*($L$14-M19),G19*($L$14-M19)),2) -> 52.43 | L19: =ROUND((J19*K19),2) -> 52.43 | Q19: =ROUND(IF($Q$17=$P$17,P19,IF($Q$17="USD $",P19*$D$15,P19*$E$15))*E19,2) -> 0 | R19: =IFERROR(ROUND(S19/E19,2),0) -> 52.43 | S19: =ROUND(L19-Q19,2) -> 52.43 | T19: =IFERROR(((K19-(Q19/J19))/(Q19/J19)),0) -> 0 | U19: =IFERROR(((K19-(Q19/J19))/K19),0) -> 1 | X19: GQP | Y19: 500
B20: 1R-0749 | C20: SECONDARY FUEL FILTER | E20: 1 | F20: 51.52 | G20: =ROUND(IF($F$17="USD $", F20*$E$15,F20*$D$15),2) -> 37.33 | H20: =ROUND(IF($H$17=$G$17,E20*G20,E20*F20),2) -> 51.52 | J20: =E20 -> 1 | K20: =ROUND(IF($K$17=$F$17,F20*($L$14-M20),G20*($L$14-M20)),2) -> 25.76 | L20: =ROUND((J20*K20),2) -> 25.76 | Q20: =ROUND(IF($Q$17=$P$17,P20,IF($Q$17="USD $",P20*$D$15,P20*$E$15))*E20,2) -> 0 | R20: =IFERROR(ROUND(S20/E20,2),0) -> 25.76 | S20: =ROUND(L20-Q20,2) -> 25.76 | T20: =IFERROR(((K20-(Q20/J20))/(Q20/J20)),0) -> 0 | U20: =IFERROR(((K20-(Q20/J20))/K20),0) -> 1 | X20: CTP | Y20: 750
B21: 326-1642 | C21: FUEL WATER SEPARATOR FILTER | E21: 1 | F21: 79.42 | G21: =ROUND(IF($F$17="USD $", F21*$E$15,F21*$D$15),2) -> 57.55 | H21: =ROUND(IF($H$17=$G$17,E21*G21,E21*F21),2) -> 79.42 | J21: =E21 -> 1 | K21: =ROUND(IF($K$17=$F$17,F21*($L$14-M21),G21*($L$14-M21)),2) -> 39.71 | L21: =ROUND((J21*K21),2) -> 39.71 | Q21: =ROUND(IF($Q$17=$P$17,P21,IF($Q$17="USD $",P21*$D$15,P21*$E$15))*E21,2) -> 0 | R21: =IFERROR(ROUND(S21/E21,2),0) -> 39.71 | S21: =ROUND(L21-Q21,2) -> 39.71 | T21: =IFERROR(((K21-(Q21/J21))/(Q21/J21)),0) -> 0 | U21: =IFERROR(((K21-(Q21/J21))/K21),0) -> 1 | X21: BLMQ | Y21: 1000
B22: 1R-0735 | C22: HYDRAULIC FILTER | E22: 1 | F22: 86.67 | G22: =ROUND(IF($F$17="USD $", F22*$E$15,F22*$D$15),2) -> 62.8 | H22: =ROUND(IF($H$17=$G$17,E22*G22,E22*F22),2) -> 86.67 | J22: =E22 -> 1 | K22: =ROUND(IF($K$17=$F$17,F22*($L$14-M22),G22*($L$14-M22)),2) -> 43.34 | L22: =ROUND((J22*K22),2) -> 43.34 | Q22: =ROUND(IF($Q$17=$P$17,P22,IF($Q$17="USD $",P22*$D$15,P22*$E$15))*E22,2) -> 0 | R22: =IFERROR(ROUND(S22/E22,2),0) -> 43.34 | S22: =ROUND(L22-Q22,2) -> 43.34 | T22: =IFERROR(((K22-(Q22/J22))/(Q22/J22)),0) -> 0 | U22: =IFERROR(((K22-(Q22/J22))/K22),0) -> 1 | X22: CAT | Y22: 1200
B23: 1R-0719 | C23: HYDRAULIC TRANSMISSION OIL FILTER | E23: 1 | F23: 30.32 | G23: =ROUND(IF($F$17="USD $", F23*$E$15,F23*$D$15),2) -> 21.97 | H23: =ROUND(IF($H$17=$G$17,E23*G23,E23*F23),2) -> 30.32 | J23: =E23 -> 1 | K23: =ROUND(IF($K$17=$F$17,F23*($L$14-M23),G23*($L$14-M23)),2) -> 15.16 | L23: =ROUND((J23*K23),2) -> 15.16 | Q23: =ROUND(IF($Q$17=$P$17,P23,IF($Q$17="USD $",P23*$D$15,P23*$E$15))*E23,2) -> 0 | R23: =IFERROR(ROUND(S23/E23,2),0) -> 15.16 | S23: =ROUND(L23-Q23,2) -> 15.16 | T23: =IFERROR(((K23-(Q23/J23))/(Q23/J23)),0) -> 0 | U23: =IFERROR(((K23-(Q23/J23))/K23),0) -> 1 | X23: FINNING | Y23: 2000
B24: 6I-0273 | C24: PRIMARY AIR FILTER | E24: 1 | F24: 155.46 | G24: =ROUND(IF($F$17="USD $", F24*$E$15,F24*$D$15),2) -> 112.65 | H24: =ROUND(IF($H$17=$G$17,E24*G24,E24*F24),2) -> 155.46 | J24: =E24 -> 1 | K24: =ROUND(IF($K$17=$F$17,F24*($L$14-M24),G24*($L$14-M24)),2) -> 77.73 | L24: =ROUND((J24*K24),2) -> 77.73 | Q24: =ROUND(IF($Q$17=$P$17,P24,IF($Q$17="USD $",P24*$D$15,P24*$E$15))*E24,2) -> 0 | R24: =IFERROR(ROUND(S24/E24,2),0) -> 77.73 | S24: =ROUND(L24-Q24,2) -> 77.73 | T24: =IFERROR(((K24-(Q24/J24))/(Q24/J24)),0) -> 0 | U24: =IFERROR(((K24-(Q24/J24))/K24),0) -> 1 | X24: JD | Y24: 4000
B25: 6I-0274 | C25: SECONDARY AIR FILTER ELEMENT | E25: 1 | F25: 118.89 | G25: =ROUND(IF($F$17="USD $", F25*$E$15,F25*$D$15),2) -> 86.15 | H25: =ROUND(IF($H$17=$G$17,E25*G25,E25*F25),2) -> 118.89 | J25: =E25 -> 1 | K25: =ROUND(IF($K$17=$F$17,F25*($L$14-M25),G25*($L$14-M25)),2) -> 59.45 | L25: =ROUND((J25*K25),2) -> 59.45 | Q25: =ROUND(IF($Q$17=$P$17,P25,IF($Q$17="USD $",P25*$D$15,P25*$E$15))*E25,2) -> 0 | R25: =IFERROR(ROUND(S25/E25,2),0) -> 59.45 | S25: =ROUND(L25-Q25,2) -> 59.45 | T25: =IFERROR(((K25-(Q25/J25))/(Q25/J25)),0) -> 0 | U25: =IFERROR(((K25-(Q25/J25))/K25),0) -> 1 | X25: BRANDT | Y25: 6000
B26: 6T-0988 | C26: CABIN AIR FILTER ELEMENT | E26: 1 | F26: 102.6 | G26: =ROUND(IF($F$17="USD $", F26*$E$15,F26*$D$15),2) -> 74.35 | H26: =ROUND(IF($H$17=$G$17,E26*G26,E26*F26),2) -> 102.6 | J26: =E26 -> 1 | K26: =ROUND(IF($K$17=$F$17,F26*($L$14-M26),G26*($L$14-M26)),2) -> 51.3 | L26: =ROUND((J26*K26),2) -> 51.3 | Q26: =ROUND(IF($Q$17=$P$17,P26,IF($Q$17="USD $",P26*$D$15,P26*$E$15))*E26,2) -> 0 | R26: =IFERROR(ROUND(S26/E26,2),0) -> 51.3 | S26: =ROUND(L26-Q26,2) -> 51.3 | T26: =IFERROR(((K26-(Q26/J26))/(Q26/J26)),0) -> 0 | U26: =IFERROR(((K26-(Q26/J26))/K26),0) -> 1 | X26: PTI | Y26: 8000
B27: 153-5710 | C27: 12V 4D BCI BATTERY (19.3" X 8.6" X 9.9") | E27: 2 | F27: 811.6 | G27: =ROUND(IF($F$17="USD $", F27*$E$15,F27*$D$15),2) -> 588.12 | H27: =ROUND(IF($H$17=$G$17,E27*G27,E27*F27),2) -> 1623.2 | J27: =E27 -> 2 | K27: =ROUND(IF($K$17=$F$17,F27*($L$14-M27),G27*($L$14-M27)),2) -> 405.8 | L27: =ROUND((J27*K27),2) -> 811.6 | Q27: =ROUND(IF($Q$17=$P$17,P27,IF($Q$17="USD $",P27*$D$15,P27*$E$15))*E27,2) -> 0 | R27: =IFERROR(ROUND(S27/E27,2),0) -> 405.8 | S27: =ROUND(L27-Q27,2) -> 811.6 | T27: =IFERROR(((K27-(Q27/J27))/(Q27/J27)),0) -> 0 | U27: =IFERROR(((K27-(Q27/J27))/K27),0) -> 1 | X27: CONEQUIP | Y27: 10000
G28: =ROUND(IF($F$17="USD $", F28*$E$15,F28*$D$15),2) -> 0 | H28: =ROUND(IF($H$17=$G$17,E28*G28,E28*F28),2) -> 0 | J28: =E28 -> 0 | K28: =ROUND(IF($K$17=$F$17,F28*($L$14-M28),G28*($L$14-M28)),2) -> 0 | L28: =ROUND((J28*K28),2) -> 0 | Q28: =ROUND(IF($Q$17=$P$17,P28,IF($Q$17="USD $",P28*$D$15,P28*$E$15))*E28,2) -> 0 | R28: =IFERROR(ROUND(S28/E28,2),0) -> 0 | S28: =ROUND(L28-Q28,2) -> 0 | T28: =IFERROR(((K28-(Q28/J28))/(Q28/J28)),0) -> 0 | U28: =IFERROR(((K28-(Q28/J28))/K28),0) -> 0 | X28: CANDY | Y28: AS REQ'D
B29: 317-5278 | C29: FUEL INJECTOR | E29: 6 | F29: 1949.47 | G29: =ROUND(IF($F$17="USD $", F29*$E$15,F29*$D$15),2) -> 1412.66 | H29: =ROUND(IF($H$17=$G$17,E29*G29,E29*F29),2) -> 11696.82 | J29: =E29 -> 6 | K29: =ROUND(IF($K$17=$F$17,F29*($L$14-M29),G29*($L$14-M29)),2) -> 974.74 | L29: =ROUND((J29*K29),2) -> 5848.44 | Q29: =ROUND(IF($Q$17=$P$17,P29,IF($Q$17="USD $",P29*$D$15,P29*$E$15))*E29,2) -> 0 | R29: =IFERROR(ROUND(S29/E29,2),0) -> 974.74 | S29: =ROUND(L29-Q29,2) -> 5848.44 | T29: =IFERROR(((K29-(Q29/J29))/(Q29/J29)),0) -> 0 | U29: =IFERROR(((K29-(Q29/J29))/K29),0) -> 1 | X29: U/C
B30: 4P-8730 | C30: TURBOCHARGER ASSEMBLY | E30: 1 | F30: 7023.145 | G30: =ROUND(IF($F$17="USD $", F30*$E$15,F30*$D$15),2) -> 5089.24 | H30: =ROUND(IF($H$17=$G$17,E30*G30,E30*F30),2) -> 7023.15 | J30: =E30 -> 1 | K30: =ROUND(IF($K$17=$F$17,F30*($L$14-M30),G30*($L$14-M30)),2) -> 3511.57 | L30: =ROUND((J30*K30),2) -> 3511.57 | Q30: =ROUND(IF($Q$17=$P$17,P30,IF($Q$17="USD $",P30*$D$15,P30*$E$15))*E30,2) -> 0 | R30: =IFERROR(ROUND(S30/E30,2),0) -> 3511.57 | S30: =ROUND(L30-Q30,2) -> 3511.57 | T30: =IFERROR(((K30-(Q30/J30))/(Q30/J30)),0) -> 0 | U30: =IFERROR(((K30-(Q30/J30))/K30),0) -> 1
G31: =ROUND(IF($F$17="USD $", F31*$E$15,F31*$D$15),2) -> 0 | H31: =ROUND(IF($H$17=$G$17,E31*G31,E31*F31),2) -> 0 | J31: =E31 -> 0 | K31: =ROUND(IF($K$17=$F$17,F31*($L$14-M31),G31*($L$14-M31)),2) -> 0 | L31: =ROUND((J31*K31),2) -> 0 | Q31: =ROUND(IF($Q$17=$P$17,P31,IF($Q$17="USD $",P31*$D$15,P31*$E$15))*E31,2) -> 0 | R31: =IFERROR(ROUND(S31/E31,2),0) -> 0 | S31: =ROUND(L31-Q31,2) -> 0 | T31: =IFERROR(((K31-(Q31/J31))/(Q31/J31)),0) -> 0 | U31: =IFERROR(((K31-(Q31/J31))/K31),0) -> 0
B32: 278-2363 | C32: TRACK SPROCKET SEGMENT | E32: 10 | F32: 395.87 | G32: =ROUND(IF($F$17="USD $", F32*$E$15,F32*$D$15),2) -> 286.86 | H32: =ROUND(IF($H$17=$G$17,E32*G32,E32*F32),2) -> 3958.7 | J32: =E32 -> 10 | K32: =ROUND(IF($K$17=$F$17,F32*($L$14-M32),G32*($L$14-M32)),2) -> 197.94 | L32: =ROUND((J32*K32),2) -> 1979.4 | Q32: =ROUND(IF($Q$17=$P$17,P32,IF($Q$17="USD $",P32*$D$15,P32*$E$15))*E32,2) -> 0 | R32: =IFERROR(ROUND(S32/E32,2),0) -> 197.94 | S32: =ROUND(L32-Q32,2) -> 1979.4 | T32: =IFERROR(((K32-(Q32/J32))/(Q32/J32)),0) -> 0 | U32: =IFERROR(((K32-(Q32/J32))/K32),0) -> 1
B33: 5P-7665 | C33: SPROCKET BOLT | E33: 50 | F33: 5.51 | G33: =ROUND(IF($F$17="USD $", F33*$E$15,F33*$D$15),2) -> 3.99 | H33: =ROUND(IF($H$17=$G$17,E33*G33,E33*F33),2) -> 275.5 | J33: =E33 -> 50 | K33: =ROUND(IF($K$17=$F$17,F33*($L$14-M33),G33*($L$14-M33)),2) -> 2.76 | L33: =ROUND((J33*K33),2) -> 138 | Q33: =ROUND(IF($Q$17=$P$17,P33,IF($Q$17="USD $",P33*$D$15,P33*$E$15))*E33,2) -> 0 | R33: =IFERROR(ROUND(S33/E33,2),0) -> 2.76 | S33: =ROUND(L33-Q33,2) -> 138 | T33: =IFERROR(((K33-(Q33/J33))/(Q33/J33)),0) -> 0 | U33: =IFERROR(((K33-(Q33/J33))/K33),0) -> 1
B34: 6V-5841 | C34: FLAT WASHER | E34: 50 | F34: 4.01 | G34: =ROUND(IF($F$17="USD $", F34*$E$15,F34*$D$15),2) -> 2.91 | H34: =ROUND(IF($H$17=$G$17,E34*G34,E34*F34),2) -> 200.5 | J34: =E34 -> 50 | K34: =ROUND(IF($K$17=$F$17,F34*($L$14-M34),G34*($L$14-M34)),2) -> 2.01 | L34: =ROUND((J34*K34),2) -> 100.5 | Q34: =ROUND(IF($Q$17=$P$17,P34,IF($Q$17="USD $",P34*$D$15,P34*$E$15))*E34,2) -> 0 | R34: =IFERROR(ROUND(S34/E34,2),0) -> 2.01 | S34: =ROUND(L34-Q34,2) -> 100.5 | T34: =IFERROR(((K34-(Q34/J34))/(Q34/J34)),0) -> 0 | U34: =IFERROR(((K34-(Q34/J34))/K34),0) -> 1
B35: 7H-3608 | C35: SPROCKET NUT | E35: 50 | F35: 5.35 | G35: =ROUND(IF($F$17="USD $", F35*$E$15,F35*$D$15),2) -> 3.88 | H35: =ROUND(IF($H$17=$G$17,E35*G35,E35*F35),2) -> 267.5 | J35: =E35 -> 50 | K35: =ROUND(IF($K$17=$F$17,F35*($L$14-M35),G35*($L$14-M35)),2) -> 2.68 | L35: =ROUND((J35*K35),2) -> 134 | Q35: =ROUND(IF($Q$17=$P$17,P35,IF($Q$17="USD $",P35*$D$15,P35*$E$15))*E35,2) -> 0 | R35: =IFERROR(ROUND(S35/E35,2),0) -> 2.68 | S35: =ROUND(L35-Q35,2) -> 134 | T35: =IFERROR(((K35-(Q35/J35))/(Q35/J35)),0) -> 0 | U35: =IFERROR(((K35-(Q35/J35))/K35),0) -> 1
B36: 420-9357 | C36: FRONT IDLER | E36: 2 | F36: 3842.24 | G36: =ROUND(IF($F$17="USD $", F36*$E$15,F36*$D$15),2) -> 2784.23 | H36: =ROUND(IF($H$17=$G$17,E36*G36,E36*F36),2) -> 7684.48 | J36: =E36 -> 2 | K36: =ROUND(IF($K$17=$F$17,F36*($L$14-M36),G36*($L$14-M36)),2) -> 1921.12 | L36: =ROUND((J36*K36),2) -> 3842.24 | Q36: =ROUND(IF($Q$17=$P$17,P36,IF($Q$17="USD $",P36*$D$15,P36*$E$15))*E36,2) -> 0 | R36: =IFERROR(ROUND(S36/E36,2),0) -> 1921.12 | S36: =ROUND(L36-Q36,2) -> 3842.24 | T36: =IFERROR(((K36-(Q36/J36))/(Q36/J36)),0) -> 0 | U36: =IFERROR(((K36-(Q36/J36))/K36),0) -> 1
B37: 428-0056 | C37: CARRIER ROLLER | E37: 4 | F37: 722.36 | G37: =ROUND(IF($F$17="USD $", F37*$E$15,F37*$D$15),2) -> 523.45 | H37: =ROUND(IF($H$17=$G$17,E37*G37,E37*F37),2) -> 2889.44 | J37: =E37 -> 4 | K37: =ROUND(IF($K$17=$F$17,F37*($L$14-M37),G37*($L$14-M37)),2) -> 361.18 | L37: =ROUND((J37*K37),2) -> 1444.72 | Q37: =ROUND(IF($Q$17=$P$17,P37,IF($Q$17="USD $",P37*$D$15,P37*$E$15))*E37,2) -> 0 | R37: =IFERROR(ROUND(S37/E37,2),0) -> 361.18 | S37: =ROUND(L37-Q37,2) -> 1444.72 | T37: =IFERROR(((K37-(Q37/J37))/(Q37/J37)),0) -> 0 | U37: =IFERROR(((K37-(Q37/J37))/K37),0) -> 1
B38: 114-6099 | C38: CARRIER BOLT | E38: 4 | F38: 31.9 | G38: =ROUND(IF($F$17="USD $", F38*$E$15,F38*$D$15),2) -> 23.12 | H38: =ROUND(IF($H$17=$G$17,E38*G38,E38*F38),2) -> 127.6 | J38: =E38 -> 4 | K38: =ROUND(IF($K$17=$F$17,F38*($L$14-M38),G38*($L$14-M38)),2) -> 15.95 | L38: =ROUND((J38*K38),2) -> 63.8 | Q38: =ROUND(IF($Q$17=$P$17,P38,IF($Q$17="USD $",P38*$D$15,P38*$E$15))*E38,2) -> 0 | R38: =IFERROR(ROUND(S38/E38,2),0) -> 15.95 | S38: =ROUND(L38-Q38,2) -> 63.8 | T38: =IFERROR(((K38-(Q38/J38))/(Q38/J38)),0) -> 0 | U38: =IFERROR(((K38-(Q38/J38))/K38),0) -> 1
B39: 422-1054 | C39: SINGLE FLANGE TRACK ROLLER | E39: 8 | F39: 860.3 | G39: =ROUND(IF($F$17="USD $", F39*$E$15,F39*$D$15),2) -> 623.41 | H39: =ROUND(IF($H$17=$G$17,E39*G39,E39*F39),2) -> 6882.4 | J39: =E39 -> 8 | K39: =ROUND(IF($K$17=$F$17,F39*($L$14-M39),G39*($L$14-M39)),2) -> 430.15 | L39: =ROUND((J39*K39),2) -> 3441.2 | Q39: =ROUND(IF($Q$17=$P$17,P39,IF($Q$17="USD $",P39*$D$15,P39*$E$15))*E39,2) -> 0 | R39: =IFERROR(ROUND(S39/E39,2),0) -> 430.15 | S39: =ROUND(L39-Q39,2) -> 3441.2 | T39: =IFERROR(((K39-(Q39/J39))/(Q39/J39)),0) -> 0 | U39: =IFERROR(((K39-(Q39/J39))/K39),0) -> 1
B40: 1D-4630 | C40: ROLLER BOLT | E40: 64 | F40: 24.13 | G40: =ROUND(IF($F$17="USD $", F40*$E$15,F40*$D$15),2) -> 17.49 | H40: =ROUND(IF($H$17=$G$17,E40*G40,E40*F40),2) -> 1544.32 | J40: =E40 -> 64 | K40: =ROUND(IF($K$17=$F$17,F40*($L$14-M40),G40*($L$14-M40)),2) -> 12.07 | L40: =ROUND((J40*K40),2) -> 772.48 | Q40: =ROUND(IF($Q$17=$P$17,P40,IF($Q$17="USD $",P40*$D$15,P40*$E$15))*E40,2) -> 0 | R40: =IFERROR(ROUND(S40/E40,2),0) -> 12.07 | S40: =ROUND(L40-Q40,2) -> 772.48 | T40: =IFERROR(((K40-(Q40/J40))/(Q40/J40)),0) -> 0 | U40: =IFERROR(((K40-(Q40/J40))/K40),0) -> 1
...

Sheet CAT 160M GRADER
B1: CUSTOMER INFORMATION | D1: MACHINE INFORMATION | H1: MACHINE SERVICE HR INTERVALS | L1: SUMMARY | O1: =K17 -> CAD $ | R1: COMPLETED DEAL INFORMATION
B2: DATE: | D2: UNIT # | H2: ENGINE AIR | L2: OEM MSRP | O2: =H129 -> 127177.97 | R2: SALES REP
B3: COMPANY: | D3: YEAR | H3: ENGINE OIL | L3: GQP LIST | O3: =L129 -> 63589.41 | R3: ORDER PO #
B4: CUSTOMER: | D4: MAKE | H4: FUEL FILTERS | L4: $ SAVINGS | O4: =O2-O3 -> 63588.56 | R4: PROJECT #
B5: PHONE: | D5: MODEL | H5: HYDRAULIC FILTERS | L5: % SAVINGS | O5: =IFERROR((O2-O3)/O2,"") -> 0.49999666 | R5: CUST INVOICE #
B6: EMAIL: | D6: SERIAL NUMBER | H6: TRANSMISSION FILTERS | L6: TOTAL ORDER MARGIN | O6: =S129 -> 63589.41 | R6: PAYMENT TYPE
B7: SALES REP: | D7: ENGINE SER NUMBER | H7: CAB FILTERS | L7: TOTAL ITEM COST | O7: =Q129 -> 0 | R7: DATE DELIVERED
D8: CURRENT HOURS | H8: UNDERCARRIAGE / TIRES | L8: TOTAL ORDER FREIGHT | O8: =IF(O1=P14,Q14,IF(P14="CAD $",Q14*D15,IF(P14="USD $",Q14*E15,0))) -> 0 | R8: TOTAL COST | S8: NET MARGIN | T8: NET MARKUP % | U8: NET MARGIN %
D9: USAGE/MONTH | L9: TOTAL CUSTOMS/BROKERAGE | O9: =U14 -> 0 | R9: =O7+O8+O9 -> 0 | S9: =O3-R9 -> 63589.41 | T9: =IFERROR(((O3-R9)/R9),0) -> 0 | U9: =IFERROR(((O3-R9)/O3),0) -> 1
L10: TOTAL NUMBER PIECES | O10: =E129 -> 132
D11: ENTER EXCHANGE RATES $ | F11: OEM MSRP | J11: CUSTOMER SELL PRICE | O11: COST ANALYSIS | X11: CAD $
X12: USD $
F13: SHOW OEM MSRP ON QUOTE: | H13: YES | X13: YES
D14: CAD-USD | E14: USD-CAD | F14: OEM NAME | J14: CUSTOMER PRICE % OF OEM LIST | L14: 0.5 | O14: FREIGHT TOTAL ORDER | P14: USD $ | R14: CUSTOMS AND BROKERAGE % | S14: 0.025 | T14: BROKERAGE FEES | U14: =ROUND(Q129*S14,2) -> 0 | X14: NO
D15: =1/E15 -> 0.72463768 | E15: 1.38 | M15: ADDITIONAL +/- DISC % PER ITEM | O15: MARKUP LESS THAN 100% REQUIRES MANAGER APPROVAL
B16: PART NUMBER | C16: DESCRIPTION | D16: SERVICE INTERVAL | E16: QTY | F16: UNIT PRICE | H16: EXT AMOUNT | J16: QTY | K16: UNIT PRICE | L16: EXTENDED AMOUNT | O16: VENDOR | P16: COST EACH | Q16: EXTENDED COST | R16: MARGIN EACH | S16: EXTENDED MARGIN | T16: MARKUP % | U16: MARGIN %
F17: CAD $ | G17: =IF(F17="USD $", "CAD $", "USD $") -> USD $ | H17: =K17 -> CAD $ | K17: CAD $ | P17: USD $ | Q17: =K17 -> CAD $
B18: 1R-1809 | C18: ENGINE OIL FILTER | E18: 1 | F18: 95.68 | G18: =ROUND(IF($F$17="USD $", F18*$E$15,F18*$D$15),2) -> 69.33 | H18: =ROUND(IF($H$17=$G$17,E18*G18,E18*F18),2) -> 95.68 | J18: =E18 -> 1 | K18: =ROUND(IF($K$17=$F$17,F18*($L$14-M18),G18*($L$14-M18)),2) -> 47.84 | L18: =ROUND((J18*K18),2) -> 47.84 | Q18: =ROUND(IF($Q$17=$P$17,P18,IF($Q$17="USD $",P18*$D$15,P18*$E$15))*E18,2) -> 0 | R18: =IFERROR(ROUND(S18/E18,2),0) -> 47.84 | S18: =ROUND(L18-Q18,2) -> 47.84 | T18: =IFERROR(((K18-(Q18/J18))/(Q18/J18)),0) -> 0 | U18: =IFERROR(((K18-(Q18/J18))/K18),0) -> 1 | Y18: 250
B19: 1R-0749 | C19: FUEL FILTER | E19: 1 | F19: 51.52 | G19: =ROUND(IF($F$17="USD $", F19*$E$15,F19*$D$15),2) -> 37.33 | H19: =ROUND(IF($H$17=$G$17,E19*G19,E19*F19),2) -> 51.52 | J19: =E19 -> 1 | K19: =ROUND(IF($K$17=$F$17,F19*($L$14-M19),G19*($L$14-M19)),2) -> 25.76 | L19: =ROUND((J19*K19),2) -> 25.76 | Q19: =ROUND(IF($Q$17=$P$17,P19,IF($Q$17="USD $",P19*$D$15,P19*$E$15))*E19,2) -> 0 | R19: =IFERROR(ROUND(S19/E19,2),0) -> 25.76 | S19: =ROUND(L19-Q19,2) -> 25.76 | T19: =IFERROR(((K19-(Q19/J19))/(Q19/J19)),0) -> 0 | U19: =IFERROR(((K19-(Q19/J19))/K19),0) -> 1 | X19: GQP | Y19: 500
B20: 326-1644 | C20: FUEL WATER SEPARATOR FILTER | E20: 1 | F20: 85.6 | G20: =ROUND(IF($F$17="USD $", F20*$E$15,F20*$D$15),2) -> 62.03 | H20: =ROUND(IF($H$17=$G$17,E20*G20,E20*F20),2) -> 85.6 | J20: =E20 -> 1 | K20: =ROUND(IF($K$17=$F$17,F20*($L$14-M20),G20*($L$14-M20)),2) -> 42.8 | L20: =ROUND((J20*K20),2) -> 42.8 | Q20: =ROUND(IF($Q$17=$P$17,P20,IF($Q$17="USD $",P20*$D$15,P20*$E$15))*E20,2) -> 0 | R20: =IFERROR(ROUND(S20/E20,2),0) -> 42.8 | S20: =ROUND(L20-Q20,2) -> 42.8 | T20: =IFERROR(((K20-(Q20/J20))/(Q20/J20)),0) -> 0 | U20: =IFERROR(((K20-(Q20/J20))/K20),0) -> 1 | X20: CTP | Y20: 750
B21: 338-3540 | C21: HYDRAULIC FILTER | E21: 1 | F21: 255.48 | G21: =ROUND(IF($F$17="USD $", F21*$E$15,F21*$D$15),2) -> 185.13 | H21: =ROUND(IF($H$17=$G$17,E21*G21,E21*F21),2) -> 255.48 | J21: =E21 -> 1 | K21: =ROUND(IF($K$17=$F$17,F21*($L$14-M21),G21*($L$14-M21)),2) -> 127.74 | L21: =ROUND((J21*K21),2) -> 127.74 | Q21: =ROUND(IF($Q$17=$P$17,P21,IF($Q$17="USD $",P21*$D$15,P21*$E$15))*E21,2) -> 0 | R21: =IFERROR(ROUND(S21/E21,2),0) -> 127.74 | S21: =ROUND(L21-Q21,2) -> 127.74 | T21: =IFERROR(((K21-(Q21/J21))/(Q21/J21)),0) -> 0 | U21: =IFERROR(((K21-(Q21/J21))/K21),0) -> 1 | X21: BLMQ | Y21: 1000
B22: 571-5253 | C22: HYDRAULIC TRANSMISSION OIL FILTER | E22: 1 | F22: 171.55 | G22: =ROUND(IF($F$17="USD $", F22*$E$15,F22*$D$15),2) -> 124.31 | H22: =ROUND(IF($H$17=$G$17,E22*G22,E22*F22),2) -> 171.55 | J22: =E22 -> 1 | K22: =ROUND(IF($K$17=$F$17,F22*($L$14-M22),G22*($L$14-M22)),2) -> 85.78 | L22: =ROUND((J22*K22),2) -> 85.78 | Q22: =ROUND(IF($Q$17=$P$17,P22,IF($Q$17="USD $",P22*$D$15,P22*$E$15))*E22,2) -> 0 | R22: =IFERROR(ROUND(S22/E22,2),0) -> 85.78 | S22: =ROUND(L22-Q22,2) -> 85.78 | T22: =IFERROR(((K22-(Q22/J22))/(Q22/J22)),0) -> 0 | U22: =IFERROR(((K22-(Q22/J22))/K22),0) -> 1 | X22: CAT | Y22: 1200
B23: 245-6375 | C23: PRIMARY AIR FILTER | E23: 1 | F23: 167.02 | G23: =ROUND(IF($F$17="USD $", F23*$E$15,F23*$D$15),2) -> 121.03 | H23: =ROUND(IF($H$17=$G$17,E23*G23,E23*F23),2) -> 167.02 | J23: =E23 -> 1 | K23: =ROUND(IF($K$17=$F$17,F23*($L$14-M23),G23*($L$14-M23)),2) -> 83.51 | L23: =ROUND((J23*K23),2) -> 83.51 | Q23: =ROUND(IF($Q$17=$P$17,P23,IF($Q$17="USD $",P23*$D$15,P23*$E$15))*E23,2) -> 0 | R23: =IFERROR(ROUND(S23/E23,2),0) -> 83.51 | S23: =ROUND(L23-Q23,2) -> 83.51 | T23: =IFERROR(((K23-(Q23/J23))/(Q23/J23)),0) -> 0 | U23: =IFERROR(((K23-(Q23/J23))/K23),0) -> 1 | X23: FINNING | Y23: 2000
B24: 245-6376 | C24: SECONDARY AIR FILTER ELEMENT | E24: 1 | F24: 109.74 | G24: =ROUND(IF($F$17="USD $", F24*$E$15,F24*$D$15),2) -> 79.52 | H24: =ROUND(IF($H$17=$G$17,E24*G24,E24*F24),2) -> 109.74 | J24: =E24 -> 1 | K24: =ROUND(IF($K$17=$F$17,F24*($L$14-M24),G24*($L$14-M24)),2) -> 54.87 | L24: =ROUND((J24*K24),2) -> 54.87 | Q24: =ROUND(IF($Q$17=$P$17,P24,IF($Q$17="USD $",P24*$D$15,P24*$E$15))*E24,2) -> 0 | R24: =IFERROR(ROUND(S24/E24,2),0) -> 54.87 | S24: =ROUND(L24-Q24,2) -> 54.87 | T24: =IFERROR(((K24-(Q24/J24))/(Q24/J24)),0) -> 0 | U24: =IFERROR(((K24-(Q24/J24))/K24),0) -> 1 | X24: JD | Y24: 4000
B25: 211-2660 | C25: CABIN AIR FILTER ELEMENT | E25: 1 | F25: 77.4 | G25: =ROUND(IF($F$17="USD $", F25*$E$15,F25*$D$15),2) -> 56.09 | H25: =ROUND(IF($H$17=$G$17,E25*G25,E25*F25),2) -> 77.4 | J25: =E25 -> 1 | K25: =ROUND(IF($K$17=$F$17,F25*($L$14-M25),G25*($L$14-M25)),2) -> 38.7 | L25: =ROUND((J25*K25),2) -> 38.7 | Q25: =ROUND(IF($Q$17=$P$17,P25,IF($Q$17="USD $",P25*$D$15,P25*$E$15))*E25,2) -> 0 | R25: =IFERROR(ROUND(S25/E25,2),0) -> 38.7 | S25: =ROUND(L25-Q25,2) -> 38.7 | T25: =IFERROR(((K25-(Q25/J25))/(Q25/J25)),0) -> 0 | U25: =IFERROR(((K25-(Q25/J25))/K25),0) -> 1 | X25: BRANDT | Y25: 6000
B26: 153-5700 | C26: 12V 4D BCI BATTERY (20" X 8.6" X 8.7") | E26: 2 | F26: 726.37 | G26: =ROUND(IF($F$17="USD $", F26*$E$15,F26*$D$15),2) -> 526.36 | H26: =ROUND(IF($H$17=$G$17,E26*G26,E26*F26),2) -> 1452.74 | J26: =E26 -> 2 | K26: =ROUND(IF($K$17=$F$17,F26*($L$14-M26),G26*($L$14-M26)),2) -> 363.19 | L26: =ROUND((J26*K26),2) -> 726.38 | Q26: =ROUND(IF($Q$17=$P$17,P26,IF($Q$17="USD $",P26*$D$15,P26*$E$15))*E26,2) -> 0 | R26: =IFERROR(ROUND(S26/E26,2),0) -> 363.19 | S26: =ROUND(L26-Q26,2) -> 726.38 | T26: =IFERROR(((K26-(Q26/J26))/(Q26/J26)),0) -> 0 | U26: =IFERROR(((K26-(Q26/J26))/K26),0) -> 1 | X26: PTI | Y26: 8000
G27: =ROUND(IF($F$17="USD $", F27*$E$15,F27*$D$15),2) -> 0 | H27: =ROUND(IF($H$17=$G$17,E27*G27,E27*F27),2) -> 0 | J27: =E27 -> 0 | K27: =ROUND(IF($K$17=$F$17,F27*($L$14-M27),G27*($L$14-M27)),2) -> 0 | L27: =ROUND((J27*K27),2) -> 0 | Q27: =ROUND(IF($Q$17=$P$17,P27,IF($Q$17="USD $",P27*$D$15,P27*$E$15))*E27,2) -> 0 | R27: =IFERROR(ROUND(S27/E27,2),0) -> 0 | S27: =ROUND(L27-Q27,2) -> 0 | T27: =IFERROR(((K27-(Q27/J27))/(Q27/J27)),0) -> 0 | U27: =IFERROR(((K27-(Q27/J27))/K27),0) -> 0 | X27: CONEQUIP | Y27: 10000
B28: 658-0254 | C28: ENGINE OVERHAUL KIT | E28: 1 | F28: 10386.33 | G28: =ROUND(IF($F$17="USD $", F28*$E$15,F28*$D$15),2) -> 7526.33 | H28: =ROUND(IF($H$17=$G$17,E28*G28,E28*F28),2) -> 10386.33 | J28: =E28 -> 1 | K28: =ROUND(IF($K$17=$F$17,F28*($L$14-M28),G28*($L$14-M28)),2) -> 5193.17 | L28: =ROUND((J28*K28),2) -> 5193.17 | Q28: =ROUND(IF($Q$17=$P$17,P28,IF($Q$17="USD $",P28*$D$15,P28*$E$15))*E28,2) -> 0 | R28: =IFERROR(ROUND(S28/E28,2),0) -> 5193.17 | S28: =ROUND(L28-Q28,2) -> 5193.17 | T28: =IFERROR(((K28-(Q28/J28))/(Q28/J28)),0) -> 0 | U28: =IFERROR(((K28-(Q28/J28))/K28),0) -> 1 | X28: CANDY | Y28: AS REQ'D
B29: 242-0673 | C29: CAMSHAFT | E29: 1 | F29: 4483.87 | G29: =ROUND(IF($F$17="USD $", F29*$E$15,F29*$D$15),2) -> 3249.18 | H29: =ROUND(IF($H$17=$G$17,E29*G29,E29*F29),2) -> 4483.87 | J29: =E29 -> 1 | K29: =ROUND(IF($K$17=$F$17,F29*($L$14-M29),G29*($L$14-M29)),2) -> 2241.94 | L29: =ROUND((J29*K29),2) -> 2241.94 | Q29: =ROUND(IF($Q$17=$P$17,P29,IF($Q$17="USD $",P29*$D$15,P29*$E$15))*E29,2) -> 0 | R29: =IFERROR(ROUND(S29/E29,2),0) -> 2241.94 | S29: =ROUND(L29-Q29,2) -> 2241.94 | T29: =IFERROR(((K29-(Q29/J29))/(Q29/J29)),0) -> 0 | U29: =IFERROR(((K29-(Q29/J29))/K29),0) -> 1 | X29: U/C
B30: 261-1544 | C30: CRANKSHAFT | E30: 1 | F30: 16109.08 | G30: =ROUND(IF($F$17="USD $", F30*$E$15,F30*$D$15),2) -> 11673.25 | H30: =ROUND(IF($H$17=$G$17,E30*G30,E30*F30),2) -> 16109.08 | J30: =E30 -> 1 | K30: =ROUND(IF($K$17=$F$17,F30*($L$14-M30),G30*($L$14-M30)),2) -> 8054.54 | L30: =ROUND((J30*K30),2) -> 8054.54 | Q30: =ROUND(IF($Q$17=$P$17,P30,IF($Q$17="USD $",P30*$D$15,P30*$E$15))*E30,2) -> 0 | R30: =IFERROR(ROUND(S30/E30,2),0) -> 8054.54 | S30: =ROUND(L30-Q30,2) -> 8054.54 | T30: =IFERROR(((K30-(Q30/J30))/(Q30/J30)),0) -> 0 | U30: =IFERROR(((K30-(Q30/J30))/K30),0) -> 1
B31: 344-2149 | C31: CYLINDER HEAD | E31: 1 | F31: 13237.86 | G31: =ROUND(IF($F$17="USD $", F31*$E$15,F31*$D$15),2) -> 9592.65 | H31: =ROUND(IF($H$17=$G$17,E31*G31,E31*F31),2) -> 13237.86 | J31: =E31 -> 1 | K31: =ROUND(IF($K$17=$F$17,F31*($L$14-M31),G31*($L$14-M31)),2) -> 6618.93 | L31: =ROUND((J31*K31),2) -> 6618.93 | Q31: =ROUND(IF($Q$17=$P$17,P31,IF($Q$17="USD $",P31*$D$15,P31*$E$15))*E31,2) -> 0 | R31: =IFERROR(ROUND(S31/E31,2),0) -> 6618.93 | S31: =ROUND(L31-Q31,2) -> 6618.93 | T31: =IFERROR(((K31-(Q31/J31))/(Q31/J31)),0) -> 0 | U31: =IFERROR(((K31-(Q31/J31))/K31),0) -> 1
B32: 352-2395 | C32: TURBOCHARGER | E32: 1 | F32: 6920.52 | G32: =ROUND(IF($F$17="USD $", F32*$E$15,F32*$D$15),2) -> 5014.87 | H32: =ROUND(IF($H$17=$G$17,E32*G32,E32*F32),2) -> 6920.52 | J32: =E32 -> 1 | K32: =ROUND(IF($K$17=$F$17,F32*($L$14-M32),G32*($L$14-M32)),2) -> 3460.26 | L32: =ROUND((J32*K32),2) -> 3460.26 | Q32: =ROUND(IF($Q$17=$P$17,P32,IF($Q$17="USD $",P32*$D$15,P32*$E$15))*E32,2) -> 0 | R32: =IFERROR(ROUND(S32/E32,2),0) -> 3460.26 | S32: =ROUND(L32-Q32,2) -> 3460.26 | T32: =IFERROR(((K32-(Q32/J32))/(Q32/J32)),0) -> 0 | U32: =IFERROR(((K32-(Q32/J32))/K32),0) -> 1
C33: INJECTOR | G33: =ROUND(IF($F$17="USD $", F33*$E$15,F33*$D$15),2) -> 0 | H33: =ROUND(IF($H$17=$G$17,E33*G33,E33*F33),2) -> 0 | J33: =E33 -> 0 | K33: =ROUND(IF($K$17=$F$17,F33*($L$14-M33),G33*($L$14-M33)),2) -> 0 | L33: =ROUND((J33*K33),2) -> 0 | Q33: =ROUND(IF($Q$17=$P$17,P33,IF($Q$17="USD $",P33*$D$15,P33*$E$15))*E33,2) -> 0 | R33: =IFERROR(ROUND(S33/E33,2),0) -> 0 | S33: =ROUND(L33-Q33,2) -> 0 | T33: =IFERROR(((K33-(Q33/J33))/(Q33/J33)),0) -> 0 | U33: =IFERROR(((K33-(Q33/J33))/K33),0) -> 0
B34: 282-4577 | C34: STRAIGHT BLADE AS | E34: 1 | F34: 19075.97 | G34: =ROUND(IF($F$17="USD $", F34*$E$15,F34*$D$15),2) -> 13823.17 | H34: =ROUND(IF($H$17=$G$17,E34*G34,E34*F34),2) -> 19075.97 | J34: =E34 -> 1 | K34: =ROUND(IF($K$17=$F$17,F34*($L$14-M34),G34*($L$14-M34)),2) -> 9537.99 | L34: =ROUND((J34*K34),2) -> 9537.99 | Q34: =ROUND(IF($Q$17=$P$17,P34,IF($Q$17="USD $",P34*$D$15,P34*$E$15))*E34,2) -> 0 | R34: =IFERROR(ROUND(S34/E34,2),0) -> 9537.99 | S34: =ROUND(L34-Q34,2) -> 9537.99 | T34: =IFERROR(((K34-(Q34/J34))/(Q34/J34)),0) -> 0 | U34: =IFERROR(((K34-(Q34/J34))/K34),0) -> 1
B35: 519-2885 | C35: CYLINDER | E35: 2 | F35: 15107.68 | G35: =ROUND(IF($F$17="USD $", F35*$E$15,F35*$D$15),2) -> 10947.59 | H35: =ROUND(IF($H$17=$G$17,E35*G35,E35*F35),2) -> 30215.36 | J35: =E35 -> 2 | K35: =ROUND(IF($K$17=$F$17,F35*($L$14-M35),G35*($L$14-M35)),2) -> 7553.84 | L35: =ROUND((J35*K35),2) -> 15107.68 | Q35: =ROUND(IF($Q$17=$P$17,P35,IF($Q$17="USD $",P35*$D$15,P35*$E$15))*E35,2) -> 0 | R35: =IFERROR(ROUND(S35/E35,2),0) -> 7553.84 | S35: =ROUND(L35-Q35,2) -> 15107.68 | T35: =IFERROR(((K35-(Q35/J35))/(Q35/J35)),0) -> 0 | U35: =IFERROR(((K35-(Q35/J35))/K35),0) -> 1
B36: 1J-6762 | C36: PLOW BOLT | E36: 34 | F36: 5.66 | G36: =ROUND(IF($F$17="USD $", F36*$E$15,F36*$D$15),2) -> 4.1 | H36: =ROUND(IF($H$17=$G$17,E36*G36,E36*F36),2) -> 192.44 | J36: =E36 -> 34 | K36: =ROUND(IF($K$17=$F$17,F36*($L$14-M36),G36*($L$14-M36)),2) -> 2.83 | L36: =ROUND((J36*K36),2) -> 96.22 | Q36: =ROUND(IF($Q$17=$P$17,P36,IF($Q$17="USD $",P36*$D$15,P36*$E$15))*E36,2) -> 0 | R36: =IFERROR(ROUND(S36/E36,2),0) -> 2.83 | S36: =ROUND(L36-Q36,2) -> 96.22 | T36: =IFERROR(((K36-(Q36/J36))/(Q36/J36)),0) -> 0 | U36: =IFERROR(((K36-(Q36/J36))/K36),0) -> 1
B37: 2J-3506 | C37: NUT | E37: 34 | F37: 3.65 | G37: =ROUND(IF($F$17="USD $", F37*$E$15,F37*$D$15),2) -> 2.64 | H37: =ROUND(IF($H$17=$G$17,E37*G37,E37*F37),2) -> 124.1 | J37: =E37 -> 34 | K37: =ROUND(IF($K$17=$F$17,F37*($L$14-M37),G37*($L$14-M37)),2) -> 1.83 | L37: =ROUND((J37*K37),2) -> 62.22 | Q37: =ROUND(IF($Q$17=$P$17,P37,IF($Q$17="USD $",P37*$D$15,P37*$E$15))*E37,2) -> 0 | R37: =IFERROR(ROUND(S37/E37,2),0) -> 1.83 | S37: =ROUND(L37-Q37,2) -> 62.22 | T37: =IFERROR(((K37-(Q37/J37))/(Q37/J37)),0) -> 0 | U37: =IFERROR(((K37-(Q37/J37))/K37),0) -> 1
B38: 8E-5529 | C38: END BIT | E38: 2 | F38: 220.93 | G38: =ROUND(IF($F$17="USD $", F38*$E$15,F38*$D$15),2) -> 160.09 | H38: =ROUND(IF($H$17=$G$17,E38*G38,E38*F38),2) -> 441.86 | J38: =E38 -> 2 | K38: =ROUND(IF($K$17=$F$17,F38*($L$14-M38),G38*($L$14-M38)),2) -> 110.47 | L38: =ROUND((J38*K38),2) -> 220.94 | Q38: =ROUND(IF($Q$17=$P$17,P38,IF($Q$17="USD $",P38*$D$15,P38*$E$15))*E38,2) -> 0 | R38: =IFERROR(ROUND(S38/E38,2),0) -> 110.47 | S38: =ROUND(L38-Q38,2) -> 220.94 | T38: =IFERROR(((K38-(Q38/J38))/(Q38/J38)),0) -> 0 | U38: =IFERROR(((K38-(Q38/J38))/K38),0) -> 1
B39: 5J-4773 | C39: END BIT BOLT | E39: 10 | F39: 4.51 | G39: =ROUND(IF($F$17="USD $", F39*$E$15,F39*$D$15),2) -> 3.27 | H39: =ROUND(IF($H$17=$G$17,E39*G39,E39*F39),2) -> 45.1 | J39: =E39 -> 10 | K39: =ROUND(IF($K$17=$F$17,F39*($L$14-M39),G39*($L$14-M39)),2) -> 2.26 | L39: =ROUND((J39*K39),2) -> 22.6 | Q39: =ROUND(IF($Q$17=$P$17,P39,IF($Q$17="USD $",P39*$D$15,P39*$E$15))*E39,2) -> 0 | R39: =IFERROR(ROUND(S39/E39,2),0) -> 2.26 | S39: =ROUND(L39-Q39,2) -> 22.6 | T39: =IFERROR(((K39-(Q39/J39))/(Q39/J39)),0) -> 0 | U39: =IFERROR(((K39-(Q39/J39))/K39),0) -> 1
B40: 2J-3506 | C40: END BIT NUT | E40: 10 | F40: 3.65 | G40: =ROUND(IF($F$17="USD $", F40*$E$15,F40*$D$15),2) -> 2.64 | H40: =ROUND(IF($H$17=$G$17,E40*G40,E40*F40),2) -> 36.5 | J40: =E40 -> 10 | K40: =ROUND(IF($K$17=$F$17,F40*($L$14-M40),G40*($L$14-M40)),2) -> 1.83 | L40: =ROUND((J40*K40),2) -> 18.3 | Q40: =ROUND(IF($Q$17=$P$17,P40,IF($Q$17="USD $",P40*$D$15,P40*$E$15))*E40,2) -> 0 | R40: =IFERROR(ROUND(S40/E40,2),0) -> 1.83 | S40: =ROUND(L40-Q40,2) -> 18.3 | T40: =IFERROR(((K40-(Q40/J40))/(Q40/J40)),0) -> 0 | U40: =IFERROR(((K40-(Q40/J40))/K40),0) -> 1
...

Sheet CAT 950H LOADER
B1: CUSTOMER INFORMATION | D1: MACHINE INFORMATION | H1: MACHINE SERVICE HR INTERVALS | L1: SUMMARY | O1: =K17 -> CAD $ | R1: COMPLETED DEAL INFORMATION
B2: DATE: | D2: UNIT # | H2: ENGINE AIR | L2: OEM MSRP | O2: =H129 -> 114313.26 | R2: SALES REP
B3: COMPANY: | D3: YEAR | H3: ENGINE OIL | L3: GQP LIST | O3: =L129 -> 57156.78 | R3: ORDER PO #
B4: CUSTOMER: | D4: MAKE | H4: FUEL FILTERS | L4: $ SAVINGS | O4: =O2-O3 -> 57156.48 | R4: PROJECT #
B5: PHONE: | D5: MODEL | H5: HYDRAULIC FILTERS | L5: % SAVINGS | O5: =IFERROR((O2-O3)/O2,"") -> 0.49999869 | R5: CUST INVOICE #
B6: EMAIL: | D6: SERIAL NUMBER | H6: TRANSMISSION FILTERS | L6: TOTAL ORDER MARGIN | O6: =S129 -> 57156.78 | R6: PAYMENT TYPE
B7: SALES REP: | D7: ENGINE SER NUMBER | H7: CAB FILTERS | L7: TOTAL ITEM COST | O7: =Q129 -> 0 | R7: DATE DELIVERED
D8: CURRENT HOURS | H8: UNDERCARRIAGE / TIRES | L8: TOTAL ORDER FREIGHT | O8: =IF(O1=P14,Q14,IF(P14="CAD $",Q14*D15,IF(P14="USD $",Q14*E15,0))) -> 0 | R8: TOTAL COST | S8: NET MARGIN | T8: NET MARKUP % | U8: NET MARGIN %
D9: USAGE/MONTH | L9: TOTAL CUSTOMS/BROKERAGE | O9: =U14 -> 0 | R9: =O7+O8+O9 -> 0 | S9: =O3-R9 -> 57156.78 | T9: =IFERROR(((O3-R9)/R9),0) -> 0 | U9: =IFERROR(((O3-R9)/O3),0) -> 1
L10: TOTAL NUMBER PIECES | O10: =E129 -> 49
D11: ENTER EXCHANGE RATES $ | F11: OEM MSRP | J11: CUSTOMER SELL PRICE | O11: COST ANALYSIS | X11: CAD $
X12: USD $
F13: SHOW OEM MSRP ON QUOTE: | H13: YES | X13: YES
D14: CAD-USD | E14: USD-CAD | F14: OEM NAME | J14: CUSTOMER PRICE % OF OEM LIST | L14: 0.5 | O14: FREIGHT TOTAL ORDER | P14: USD $ | R14: CUSTOMS AND BROKERAGE % | S14: 0.025 | T14: BROKERAGE FEES | U14: =ROUND(Q129*S14,2) -> 0 | X14: NO
D15: =1/E15 -> 0.72463768 | E15: 1.38 | M15: ADDITIONAL +/- DISC % PER ITEM | O15: MARKUP LESS THAN 100% REQUIRES MANAGER APPROVAL
B16: PART NUMBER | C16: DESCRIPTION | D16: SERVICE INTERVAL | E16: QTY | F16: UNIT PRICE | H16: EXT AMOUNT | J16: QTY | K16: UNIT PRICE | L16: EXTENDED AMOUNT | O16: VENDOR | P16: COST EACH | Q16: EXTENDED COST | R16: MARGIN EACH | S16: EXTENDED MARGIN | T16: MARKUP % | U16: MARGIN %
F17: USD $ | G17: =IF(F17="USD $", "CAD $", "USD $") -> CAD $ | H17: =K17 -> CAD $ | K17: CAD $ | P17: USD $ | Q17: =K17 -> CAD $
B18: 1R-1807 | C18: Oil Filter | E18: 1 | F18: 44.09 | G18: =ROUND(IF($F$17="USD $", F18*$E$15,F18*$D$15),2) -> 60.84 | H18: =ROUND(IF($H$17=$G$17,E18*G18,E18*F18),2) -> 60.84 | J18: =E18 -> 1 | K18: =ROUND(IF($K$17=$F$17,F18*($L$14-M18),G18*($L$14-M18)),2) -> 30.42 | L18: =ROUND((J18*K18),2) -> 30.42 | Q18: =ROUND(IF($Q$17=$P$17,P18,IF($Q$17="USD $",P18*$D$15,P18*$E$15))*E18,2) -> 0 | R18: =IFERROR(ROUND(S18/E18,2),0) -> 30.42 | S18: =ROUND(L18-Q18,2) -> 30.42 | T18: =IFERROR(((K18-(Q18/J18))/(Q18/J18)),0) -> 0 | U18: =IFERROR(((K18-(Q18/J18))/K18),0) -> 1 | Y18: 250
B19: 330-9358 | C19: Hydarulic Oil Filter | E19: 1 | F19: 1227.31 | G19: =ROUND(IF($F$17="USD $", F19*$E$15,F19*$D$15),2) -> 1693.69 | H19: =ROUND(IF($H$17=$G$17,E19*G19,E19*F19),2) -> 1693.69 | J19: =E19 -> 1 | K19: =ROUND(IF($K$17=$F$17,F19*($L$14-M19),G19*($L$14-M19)),2) -> 846.85 | L19: =ROUND((J19*K19),2) -> 846.85 | Q19: =ROUND(IF($Q$17=$P$17,P19,IF($Q$17="USD $",P19*$D$15,P19*$E$15))*E19,2) -> 0 | R19: =IFERROR(ROUND(S19/E19,2),0) -> 846.85 | S19: =ROUND(L19-Q19,2) -> 846.85 | T19: =IFERROR(((K19-(Q19/J19))/(Q19/J19)),0) -> 0 | U19: =IFERROR(((K19-(Q19/J19))/K19),0) -> 1 | X19: GQP | Y19: 500
B20: 326-1644 | C20: Fuel/Water Separator Filter (Primary) | E20: 1 | F20: 85.6 | G20: =ROUND(IF($F$17="USD $", F20*$E$15,F20*$D$15),2) -> 118.13 | H20: =ROUND(IF($H$17=$G$17,E20*G20,E20*F20),2) -> 118.13 | J20: =E20 -> 1 | K20: =ROUND(IF($K$17=$F$17,F20*($L$14-M20),G20*($L$14-M20)),2) -> 59.07 | L20: =ROUND((J20*K20),2) -> 59.07 | Q20: =ROUND(IF($Q$17=$P$17,P20,IF($Q$17="USD $",P20*$D$15,P20*$E$15))*E20,2) -> 0 | R20: =IFERROR(ROUND(S20/E20,2),0) -> 59.07 | S20: =ROUND(L20-Q20,2) -> 59.07 | T20: =IFERROR(((K20-(Q20/J20))/(Q20/J20)),0) -> 0 | U20: =IFERROR(((K20-(Q20/J20))/K20),0) -> 1 | X20: CTP | Y20: 750
B21: 245-6375 | C21: PRIMAERY AIR FILTER | E21: 1 | F21: 167.02 | G21: =ROUND(IF($F$17="USD $", F21*$E$15,F21*$D$15),2) -> 230.49 | H21: =ROUND(IF($H$17=$G$17,E21*G21,E21*F21),2) -> 230.49 | J21: =E21 -> 1 | K21: =ROUND(IF($K$17=$F$17,F21*($L$14-M21),G21*($L$14-M21)),2) -> 115.25 | L21: =ROUND((J21*K21),2) -> 115.25 | Q21: =ROUND(IF($Q$17=$P$17,P21,IF($Q$17="USD $",P21*$D$15,P21*$E$15))*E21,2) -> 0 | R21: =IFERROR(ROUND(S21/E21,2),0) -> 115.25 | S21: =ROUND(L21-Q21,2) -> 115.25 | T21: =IFERROR(((K21-(Q21/J21))/(Q21/J21)),0) -> 0 | U21: =IFERROR(((K21-(Q21/J21))/K21),0) -> 1 | X21: BLMQ | Y21: 1000
B22: 245-6376 | C22: SECONDARY AIR FILTER | E22: 1 | F22: 109.74 | G22: =ROUND(IF($F$17="USD $", F22*$E$15,F22*$D$15),2) -> 151.44 | H22: =ROUND(IF($H$17=$G$17,E22*G22,E22*F22),2) -> 151.44 | J22: =E22 -> 1 | K22: =ROUND(IF($K$17=$F$17,F22*($L$14-M22),G22*($L$14-M22)),2) -> 75.72 | L22: =ROUND((J22*K22),2) -> 75.72 | Q22: =ROUND(IF($Q$17=$P$17,P22,IF($Q$17="USD $",P22*$D$15,P22*$E$15))*E22,2) -> 0 | R22: =IFERROR(ROUND(S22/E22,2),0) -> 75.72 | S22: =ROUND(L22-Q22,2) -> 75.72 | T22: =IFERROR(((K22-(Q22/J22))/(Q22/J22)),0) -> 0 | U22: =IFERROR(((K22-(Q22/J22))/K22),0) -> 1 | X22: CAT | Y22: 1200
B23: 7X-6041 | C23: CABIN AIR FILTER | E23: 1 | F23: 92 | G23: =ROUND(IF($F$17="USD $", F23*$E$15,F23*$D$15),2) -> 126.96 | H23: =ROUND(IF($H$17=$G$17,E23*G23,E23*F23),2) -> 126.96 | J23: =E23 -> 1 | K23: =ROUND(IF($K$17=$F$17,F23*($L$14-M23),G23*($L$14-M23)),2) -> 63.48 | L23: =ROUND((J23*K23),2) -> 63.48 | Q23: =ROUND(IF($Q$17=$P$17,P23,IF($Q$17="USD $",P23*$D$15,P23*$E$15))*E23,2) -> 0 | R23: =IFERROR(ROUND(S23/E23,2),0) -> 63.48 | S23: =ROUND(L23-Q23,2) -> 63.48 | T23: =IFERROR(((K23-(Q23/J23))/(Q23/J23)),0) -> 0 | U23: =IFERROR(((K23-(Q23/J23))/K23),0) -> 1 | X23: FINNING | Y23: 2000
B24: 1G-8878 | C24: TRANSMISSION FILTER | E24: 1 | F24: 150.47 | G24: =ROUND(IF($F$17="USD $", F24*$E$15,F24*$D$15),2) -> 207.65 | H24: =ROUND(IF($H$17=$G$17,E24*G24,E24*F24),2) -> 207.65 | J24: =E24 -> 1 | K24: =ROUND(IF($K$17=$F$17,F24*($L$14-M24),G24*($L$14-M24)),2) -> 103.83 | L24: =ROUND((J24*K24),2) -> 103.83 | Q24: =ROUND(IF($Q$17=$P$17,P24,IF($Q$17="USD $",P24*$D$15,P24*$E$15))*E24,2) -> 0 | R24: =IFERROR(ROUND(S24/E24,2),0) -> 103.83 | S24: =ROUND(L24-Q24,2) -> 103.83 | T24: =IFERROR(((K24-(Q24/J24))/(Q24/J24)),0) -> 0 | U24: =IFERROR(((K24-(Q24/J24))/K24),0) -> 1 | X24: JD | Y24: 4000
B25: 1R-0762 | C25: SECONDARY FUEL FILTER | E25: 1 | F25: 67.44 | G25: =ROUND(IF($F$17="USD $", F25*$E$15,F25*$D$15),2) -> 93.07 | H25: =ROUND(IF($H$17=$G$17,E25*G25,E25*F25),2) -> 93.07 | J25: =E25 -> 1 | K25: =ROUND(IF($K$17=$F$17,F25*($L$14-M25),G25*($L$14-M25)),2) -> 46.54 | L25: =ROUND((J25*K25),2) -> 46.54 | Q25: =ROUND(IF($Q$17=$P$17,P25,IF($Q$17="USD $",P25*$D$15,P25*$E$15))*E25,2) -> 0 | R25: =IFERROR(ROUND(S25/E25,2),0) -> 46.54 | S25: =ROUND(L25-Q25,2) -> 46.54 | T25: =IFERROR(((K25-(Q25/J25))/(Q25/J25)),0) -> 0 | U25: =IFERROR(((K25-(Q25/J25))/K25),0) -> 1 | X25: BRANDT | Y25: 6000
G26: =ROUND(IF($F$17="USD $", F26*$E$15,F26*$D$15),2) -> 0 | H26: =ROUND(IF($H$17=$G$17,E26*G26,E26*F26),2) -> 0 | J26: =E26 -> 0 | K26: =ROUND(IF($K$17=$F$17,F26*($L$14-M26),G26*($L$14-M26)),2) -> 0 | L26: =ROUND((J26*K26),2) -> 0 | Q26: =ROUND(IF($Q$17=$P$17,P26,IF($Q$17="USD $",P26*$D$15,P26*$E$15))*E26,2) -> 0 | R26: =IFERROR(ROUND(S26/E26,2),0) -> 0 | S26: =ROUND(L26-Q26,2) -> 0 | T26: =IFERROR(((K26-(Q26/J26))/(Q26/J26)),0) -> 0 | U26: =IFERROR(((K26-(Q26/J26))/K26),0) -> 0 | X26: PTI | Y26: 8000
B27: 134-4483 | C27: MAJOR ENGINE OVERHAUL KIT | E27: 1 | F27: 11907.74 | G27: =ROUND(IF($F$17="USD $", F27*$E$15,F27*$D$15),2) -> 16432.68 | H27: =ROUND(IF($H$17=$G$17,E27*G27,E27*F27),2) -> 16432.68 | J27: =E27 -> 1 | K27: =ROUND(IF($K$17=$F$17,F27*($L$14-M27),G27*($L$14-M27)),2) -> 8216.34 | L27: =ROUND((J27*K27),2) -> 8216.34 | Q27: =ROUND(IF($Q$17=$P$17,P27,IF($Q$17="USD $",P27*$D$15,P27*$E$15))*E27,2) -> 0 | R27: =IFERROR(ROUND(S27/E27,2),0) -> 8216.34 | S27: =ROUND(L27-Q27,2) -> 8216.34 | T27: =IFERROR(((K27-(Q27/J27))/(Q27/J27)),0) -> 0 | U27: =IFERROR(((K27-(Q27/J27))/K27),0) -> 1 | X27: CONEQUIP | Y27: 10000
B28: 212-4288 | C28: Camshaft Assembly | E28: 1 | F28: 3804.56 | G28: =ROUND(IF($F$17="USD $", F28*$E$15,F28*$D$15),2) -> 5250.29 | H28: =ROUND(IF($H$17=$G$17,E28*G28,E28*F28),2) -> 5250.29 | J28: =E28 -> 1 | K28: =ROUND(IF($K$17=$F$17,F28*($L$14-M28),G28*($L$14-M28)),2) -> 2625.15 | L28: =ROUND((J28*K28),2) -> 2625.15 | Q28: =ROUND(IF($Q$17=$P$17,P28,IF($Q$17="USD $",P28*$D$15,P28*$E$15))*E28,2) -> 0 | R28: =IFERROR(ROUND(S28/E28,2),0) -> 2625.15 | S28: =ROUND(L28-Q28,2) -> 2625.15 | T28: =IFERROR(((K28-(Q28/J28))/(Q28/J28)),0) -> 0 | U28: =IFERROR(((K28-(Q28/J28))/K28),0) -> 1 | X28: CANDY | Y28: AS REQ'D
B29: 134-0734 | C29: Crankshaft Group | E29: 1 | F29: 5410.74 | G29: =ROUND(IF($F$17="USD $", F29*$E$15,F29*$D$15),2) -> 7466.82 | H29: =ROUND(IF($H$17=$G$17,E29*G29,E29*F29),2) -> 7466.82 | J29: =E29 -> 1 | K29: =ROUND(IF($K$17=$F$17,F29*($L$14-M29),G29*($L$14-M29)),2) -> 3733.41 | L29: =ROUND((J29*K29),2) -> 3733.41 | Q29: =ROUND(IF($Q$17=$P$17,P29,IF($Q$17="USD $",P29*$D$15,P29*$E$15))*E29,2) -> 0 | R29: =IFERROR(ROUND(S29/E29,2),0) -> 3733.41 | S29: =ROUND(L29-Q29,2) -> 3733.41 | T29: =IFERROR(((K29-(Q29/J29))/(Q29/J29)),0) -> 0 | U29: =IFERROR(((K29-(Q29/J29))/K29),0) -> 1 | X29: U/C
B30: 3058141 | C30: Cylinder Block | E30: 1 | F30: 18371.68 | G30: =ROUND(IF($F$17="USD $", F30*$E$15,F30*$D$15),2) -> 25352.92 | H30: =ROUND(IF($H$17=$G$17,E30*G30,E30*F30),2) -> 25352.92 | J30: =E30 -> 1 | K30: =ROUND(IF($K$17=$F$17,F30*($L$14-M30),G30*($L$14-M30)),2) -> 12676.46 | L30: =ROUND((J30*K30),2) -> 12676.46 | Q30: =ROUND(IF($Q$17=$P$17,P30,IF($Q$17="USD $",P30*$D$15,P30*$E$15))*E30,2) -> 0 | R30: =IFERROR(ROUND(S30/E30,2),0) -> 12676.46 | S30: =ROUND(L30-Q30,2) -> 12676.46 | T30: =IFERROR(((K30-(Q30/J30))/(Q30/J30)),0) -> 0 | U30: =IFERROR(((K30-(Q30/J30))/K30),0) -> 1
B31: 4872807 | C31: Cylinder Head GP | E31: 1 | F31: 10196.18 | G31: =ROUND(IF($F$17="USD $", F31*$E$15,F31*$D$15),2) -> 14070.73 | H31: =ROUND(IF($H$17=$G$17,E31*G31,E31*F31),2) -> 14070.73 | J31: =E31 -> 1 | K31: =ROUND(IF($K$17=$F$17,F31*($L$14-M31),G31*($L$14-M31)),2) -> 7035.37 | L31: =ROUND((J31*K31),2) -> 7035.37 | Q31: =ROUND(IF($Q$17=$P$17,P31,IF($Q$17="USD $",P31*$D$15,P31*$E$15))*E31,2) -> 0 | R31: =IFERROR(ROUND(S31/E31,2),0) -> 7035.37 | S31: =ROUND(L31-Q31,2) -> 7035.37 | T31: =IFERROR(((K31-(Q31/J31))/(Q31/J31)),0) -> 0 | U31: =IFERROR(((K31-(Q31/J31))/K31),0) -> 1
B32: 557-7627 | C32: Fuel Injector | E32: 4 | F32: 1906.27 | G32: =ROUND(IF($F$17="USD $", F32*$E$15,F32*$D$15),2) -> 2630.65 | H32: =ROUND(IF($H$17=$G$17,E32*G32,E32*F32),2) -> 10522.6 | J32: =E32 -> 4 | K32: =ROUND(IF($K$17=$F$17,F32*($L$14-M32),G32*($L$14-M32)),2) -> 1315.33 | L32: =ROUND((J32*K32),2) -> 5261.32 | Q32: =ROUND(IF($Q$17=$P$17,P32,IF($Q$17="USD $",P32*$D$15,P32*$E$15))*E32,2) -> 0 | R32: =IFERROR(ROUND(S32/E32,2),0) -> 1315.33 | S32: =ROUND(L32-Q32,2) -> 5261.32 | T32: =IFERROR(((K32-(Q32/J32))/(Q32/J32)),0) -> 0 | U32: =IFERROR(((K32-(Q32/J32))/K32),0) -> 1
