Workbook

Sheet MOQ Batteries
E1: MOQ QUOTE | H1: Batteries
B7: COMPANY: | C7: ='MOQ Grand Total'!C7 -> LINCOLN COUNTY OILFIELD SERVICES | E7: DATE: | F7: 45748 | H7: PO NUMBER: | I7: ='MOQ Grand Total'!I7
B8: CONTACT NAME: | C8: ='MOQ Grand Total'!C8 -> DUSTIN MINNS | E8: PHONE NUMBER: | H8: 780-609-0758
B9: BILLING ADDRESS: | C9: ='MOQ Grand Total'!C9 -> 0 | E9: EMAIL ADDRESS: | H9: D.MINNS@LCOS.CA
C10: ='MOQ Grand Total'!C10 -> 0 | E10: SHIPPING ADDRESS:
C11: ='MOQ Grand Total'!C11 -> 0
C12: ='MOQ Grand Total'!C12 -> 0
F13: CAD $
B14: PART NUMBER | C14: Make & Model | D14: DESCRIPTION | E14: QTY | F14: OEM MSRP | H14: GQP PRICE | I14: TOTAL
B15: 115-2422 | C15: =VLOOKUP(B15,'[1]Product by Part Number'!$A:$K,2,0) -> CAT 320E L (WBK) CAT 320 (HEX) CAT 320 (MYK) CAT 329E L (ZCD) CAT 329F L (ERL) CAT 330F L (MBX) CAT 330F L (HCK) | D15: =VLOOKUP(B15,'[1]Product by Part Number'!$A:$K,3,0) -> 12V BATTERY 1000CCA | E15: =VLOOKUP(B15,'[1]Product by Part Number'!$A:$K,11,0) -> 26 | F15: =VLOOKUP(B15,'[1]Product by Part Number'!$A:$K,4,0) -> 523.07 | G15: =E15*F15 -> 13599.82 | H15: =VLOOKUP(B15,'[1]Product by Part Number'!$A:$K,5,0) -> 132.13 | I15: =ROUND(E15*H15,2) -> 3435.38
B16: 153-5656 | C16: =VLOOKUP(B16,'[1]Product by Part Number'!$A:$K,2,0) -> CAT 303.5E | D16: =VLOOKUP(B16,'[1]Product by Part Number'!$A:$K,3,0) -> 12V BATTERY - 650CCA | E16: =VLOOKUP(B16,'[1]Product by Part Number'!$A:$K,11,0) -> 1 | F16: =VLOOKUP(B16,'[1]Product by Part Number'!$A:$K,4,0) -> 356.29 | G16: =E16*F16 -> 356.29 | H16: =VLOOKUP(B16,'[1]Product by Part Number'!$A:$K,5,0) -> 160.67 | I16: =ROUND(E16*H16,2) -> 160.67
B17: 153-5700 | C17: =VLOOKUP(B17,'[1]Product by Part Number'!$A:$K,2,0) -> CAT D3 (1PJ) CAT D7G (92V) | D17: =VLOOKUP(B17,'[1]Product by Part Number'!$A:$K,3,0) -> 12V BATTERY - 1125CCA | E17: =VLOOKUP(B17,'[1]Product by Part Number'!$A:$K,11,0) -> 2 | F17: =VLOOKUP(B17,'[1]Product by Part Number'!$A:$K,4,0) -> 726.37 | H17: =VLOOKUP(B17,'[1]Product by Part Number'!$A:$K,5,0) -> 292.44 | I17: =ROUND(E17*H17,2) -> 584.88
B18: 9X-3404 | C18: =VLOOKUP(B18,'[1]Product by Part Number'!$A:$K,2,0) -> CAT 320F L (YBM) CAT 330 (LHW) CAT 330 (WCH) CAT 561N (CPH) | D18: =VLOOKUP(B18,'[1]Product by Part Number'!$A:$K,3,0) -> 12V BATTERY - 900CCA | E18: =VLOOKUP(B18,'[1]Product by Part Number'!$A:$K,11,0) -> 52 | F18: =VLOOKUP(B18,'[1]Product by Part Number'!$A:$K,4,0) -> 503.86 | H18: =VLOOKUP(B18,'[1]Product by Part Number'!$A:$K,5,0) -> 120.88 | I18: =ROUND(E18*H18,2) -> 6285.76
G19: =E19*F19 -> 0 | I19: =ROUND(E19*H19,2) -> 0
I20: =ROUND(E20*H20,2) -> 0
I21: =ROUND(E21*H21,2) -> 0
I22: =ROUND(E22*H22,2) -> 0
I23: =ROUND(E23*H23,2) -> 0
I24: =ROUND(E24*H24,2) -> 0
I25: =ROUND(E25*H25,2) -> 0
I26: =ROUND(E26*H26,2) -> 0
I27: =ROUND(E27*H27,2) -> 0
I28: =ROUND(E28*H28,2) -> 0
I29: =ROUND(E29*H29,2) -> 0
I30: =ROUND(E30*H30,2) -> 0
I31: =ROUND(E31*H31,2) -> 0
... I57: =ROUND(E57*H57,2) -> 0
H58: Subtotal | I58: =SUM(I15:I57) -> 10466.69
D59: OEM MSRP : | E59: =SUM(G15:G57) -> 13956.11 | H59: Shipping | I59: 0
D60: GQP : | E60: =SUM(I15:I57) -> 10466.69 | H60: Customs/Broker Fee | I60: 0
D61: GQP SAVINGS : | E61: =E59-E60 -> 3489.42 | H61: Total | I61: =SUM(I58:I60) -> 10466.69
H62: GST | I62: =I61*0.05 -> 523.3345
H63: PST / QST
B64: Quote valid for 14 days, shipping subject to delays in supply chain. | H64: GRAND TOTAL | I64: =SUM(I61:I63) -> 10990.025

Sheet MOQ GET Parts
E1: MOQ QUOTE | H1: G.E.T.
B7: COMPANY: | C7: ='MOQ Grand Total'!C7 -> LINCOLN COUNTY OILFIELD SERVICES | E7: DATE: | F7: 45748 | H7: PO NUMBER: | I7: ='MOQ Grand Total'!I7
B8: CONTACT NAME: | C8: ='MOQ Grand Total'!C8 -> DUSTIN MINNS | E8: PHONE NUMBER: | H8: 780-609-0758
B9: BILLING ADDRESS: | C9: ='MOQ Grand Total'!C9 -> 0 | E9: EMAIL ADDRESS: | H9: D.MINNS@LCOS.CA
C10: ='MOQ Grand Total'!C10 -> 0 | E10: SHIPPING ADDRESS:
C11: ='MOQ Grand Total'!C11 -> 0
C12: ='MOQ Grand Total'!C12 -> 0
F13: CAD $
B14: PART NUMBER | C14: Make & Model | D14: DESCRIPTION | E14: QTY | F14: OEM MSRP | H14: GQP PRICE | I14: TOTAL
B15: 114-0358 | C15: =VLOOKUP(B15,'[1]Product by Part Number'!$A:$K,2,0) -> CAT D6N LGP (PBA) CAT D6N LGP (SGG) CAT D6T (MH7) CAT D7G (92V) | D15: =VLOOKUP(B15,'[1]Product by Part Number'!$A:$K,3,0) -> GROOVED PIN | E15: =VLOOKUP(B15,'[1]Product by Part Number'!$A:$K,11,0) -> 16 | F15: =VLOOKUP(B15,'[1]Product by Part Number'!$A:$K,4,0) -> 12.96 | G15: =E15*F15 -> 207.36 | H15: =VLOOKUP(B15,'[1]Product by Part Number'!$A:$K,5,0) -> 4.92 | I15: =ROUND(E15*H15,2) -> 78.72
B16: 114-0359 | C16: =VLOOKUP(B16,'[1]Product by Part Number'!$A:$K,2,0) -> CAT D5 (3CR) CAT D6N LGP (PBA) CAT D6N LGP (SGG) CAT D6T (MH7) CAT D7G (92V) | D16: =VLOOKUP(B16,'[1]Product by Part Number'!$A:$K,3,0) -> RETAINER | E16: =VLOOKUP(B16,'[1]Product by Part Number'!$A:$K,11,0) -> 18 | F16: =VLOOKUP(B16,'[1]Product by Part Number'!$A:$K,4,0) -> 22.39 | G16: =E16*F16 -> 403.02 | H16: =VLOOKUP(B16,'[1]Product by Part Number'!$A:$K,5,0) -> 8.51 | I16: =ROUND(E16*H16,2) -> 153.18
B17: 136-8308 | C17: =VLOOKUP(B17,'[1]Product by Part Number'!$A:$K,2,0) -> CAT D5 (3CR) | D17: =VLOOKUP(B17,'[1]Product by Part Number'!$A:$K,3,0) -> RIPPER PIN | E17: =VLOOKUP(B17,'[1]Product by Part Number'!$A:$K,11,0) -> 2 | F17: =VLOOKUP(B17,'[1]Product by Part Number'!$A:$K,4,0) -> 10.35 | G17: =E17*F17 -> 20.7 | H17: =VLOOKUP(B17,'[1]Product by Part Number'!$A:$K,5,0) -> 3.93 | I17: =ROUND(E17*H17,2) -> 7.86
B18: 1U-3202 | C18: =VLOOKUP(B18,'[1]Product by Part Number'!$A:$K,2,0) -> CAT D3 (1PJ) | D18: =VLOOKUP(B18,'[1]Product by Part Number'!$A:$K,3,0) -> TIP SHORT | E18: =VLOOKUP(B18,'[1]Product by Part Number'!$A:$K,11,0) -> 1 | F18: =VLOOKUP(B18,'[1]Product by Part Number'!$A:$K,4,0) -> 37.42 | G18: =E18*F18 -> 37.42 | H18: =VLOOKUP(B18,'[1]Product by Part Number'!$A:$K,5,0) -> 14.22 | I18: =ROUND(E18*H18,2) -> 14.22
B19: 229-6958 | C19: =VLOOKUP(B19,'[1]Product by Part Number'!$A:$K,2,0) -> CAT D6T (MH7) | D19: =VLOOKUP(B19,'[1]Product by Part Number'!$A:$K,3,0) -> CUTTING EDGE | E19: =VLOOKUP(B19,'[1]Product by Part Number'!$A:$K,11,0) -> 2 | F19: =VLOOKUP(B19,'[1]Product by Part Number'!$A:$K,4,0) -> 559.01 | G19: =E19*F19 -> 1118.02 | H19: =VLOOKUP(B19,'[1]Product by Part Number'!$A:$K,5,0) -> 212.42 | I19: =ROUND(E19*H19,2) -> 424.84
B20: 288-3462 | C20: =VLOOKUP(B20,'[1]Product by Part Number'!$A:$K,2,0) -> CAT 303.5E | D20: =VLOOKUP(B20,'[1]Product by Part Number'!$A:$K,3,0) -> FINAL DRIVE | E20: =VLOOKUP(B20,'[1]Product by Part Number'!$A:$K,11,0) -> 2 | F20: =VLOOKUP(B20,'[1]Product by Part Number'!$A:$K,4,0) -> 10089.31 | G20: =E20*F20 -> 20178.62 | H20: =VLOOKUP(B20,'[1]Product by Part Number'!$A:$K,5,0) -> 5044.66 | I20: =ROUND(E20*H20,2) -> 10089.32
B21: 2J-3506 | C21: =VLOOKUP(B21,'[1]Product by Part Number'!$A:$K,2,0) -> CAT D5 (3CR) CAT D6N LGP (GHS) CAT D6N LGP (PBA) CAT D6N LGP (SGG) CAT D6T (MH7) | D21: =VLOOKUP(B21,'[1]Product by Part Number'!$A:$K,3,0) -> HEX NUT | E21: =VLOOKUP(B21,'[1]Product by Part Number'!$A:$K,11,0) -> 222 | F21: =VLOOKUP(B21,'[1]Product by Part Number'!$A:$K,4,0) -> 3.65 | G21: =E21*F21 -> 810.3 | H21: =VLOOKUP(B21,'[1]Product by Part Number'!$A:$K,5,0) -> 1.39 | I21: =ROUND(E21*H21,2) -> 308.58
B22: 341-2814 | C22: =VLOOKUP(B22,'[1]Product by Part Number'!$A:$K,2,0) -> CAT 320F L (YBM) CAT 320 (HEX) CAT 320 (MYK) | D22: =VLOOKUP(B22,'[1]Product by Part Number'!$A:$K,3,0) -> BUCKET CYLINDER | E22: =VLOOKUP(B22,'[1]Product by Part Number'!$A:$K,11,0) -> 4 | F22: =VLOOKUP(B22,'[1]Product by Part Number'!$A:$K,4,0) -> 22869.96 | G22: =E22*F22 -> 91479.84 | H22: =VLOOKUP(B22,'[1]Product by Part Number'!$A:$K,5,0) -> 8690.58 | I22: =ROUND(E22*H22,2) -> 34762.32
B23: 376-2025 | C23: =VLOOKUP(B23,'[1]Product by Part Number'!$A:$K,2,0) -> CAT 303.5E | D23: =VLOOKUP(B23,'[1]Product by Part Number'!$A:$K,3,0) -> HYDRAULIC PUMP | E23: =VLOOKUP(B23,'[1]Product by Part Number'!$A:$K,11,0) -> 1 | F23: =VLOOKUP(B23,'[1]Product by Part Number'!$A:$K,4,0) -> 7622.73 | G23: =E23*F23 -> 7622.73 | H23: =VLOOKUP(B23,'[1]Product by Part Number'!$A:$K,5,0) -> 3811.37 | I23: =ROUND(E23*H23,2) -> 3811.37
B24: 383-0293 | C24: =VLOOKUP(B24,'[1]Product by Part Number'!$A:$K,2,0) -> CAT 303.5E | D24: =VLOOKUP(B24,'[1]Product by Part Number'!$A:$K,3,0) -> OIL PUMP ENGINE | E24: =VLOOKUP(B24,'[1]Product by Part Number'!$A:$K,11,0) -> 1 | F24: =VLOOKUP(B24,'[1]Product by Part Number'!$A:$K,4,0) -> 831.44 | G24: =E24*F24 -> 831.44 | H24: =VLOOKUP(B24,'[1]Product by Part Number'!$A:$K,5,0) -> 415.72 | I24: =ROUND(E24*H24,2) -> 415.72
B25: 383-0433 | C25: =VLOOKUP(B25,'[1]Product by Part Number'!$A:$K,2,0) -> CAT 303.5E | D25: =VLOOKUP(B25,'[1]Product by Part Number'!$A:$K,3,0) -> WATER PUMP | E25: =VLOOKUP(B25,'[1]Product by Part Number'!$A:$K,11,0) -> 1 | F25: =VLOOKUP(B25,'[1]Product by Part Number'!$A:$K,4,0) -> 512.79 | G25: =E25*F25 -> 512.79 | H25: =VLOOKUP(B25,'[1]Product by Part Number'!$A:$K,5,0) -> 256.4 | I25: =ROUND(E25*H25,2) -> 256.4
B26: 3B-4632 | C26: =VLOOKUP(B26,'[1]Product by Part Number'!$A:$K,2,0) -> CAT D3 (1PJ) | D26: =VLOOKUP(B26,'[1]Product by Part Number'!$A:$K,3,0) -> COTTER PIN | E26: =VLOOKUP(B26,'[1]Product by Part Number'!$A:$K,11,0) -> 1 | F26: =VLOOKUP(B26,'[1]Product by Part Number'!$A:$K,4,0) -> 1.18 | G26: =E26*F26 -> 1.18 | H26: =VLOOKUP(B26,'[1]Product by Part Number'!$A:$K,5,0) -> 0.45 | I26: =ROUND(E26*H26,2) -> 0.45
... B58: CUSTOM-GQPD5ABA | C58: =VLOOKUP(B58,'[1]Product by Part Number'!$A:$K,2,0) -> CAT D5 (3CR) | D58: =VLOOKUP(B58,'[1]Product by Part Number'!$A:$K,3,0) -> ANGLING BLADE ASSY | E58: =VLOOKUP(B58,'[1]Product by Part Number'!$A:$K,11,0) -> 2 | F58: =VLOOKUP(B58,'[1]Product by Part Number'!$A:$K,4,0) -> 16888.9 | G58: =E58*F58 -> 33777.8 | H58: =VLOOKUP(B58,'[1]Product by Part Number'!$A:$K,5,0) -> 6417.78 | I58: =ROUND(E58*H58,2) -> 12835.56
I59: =ROUND(E59*H59,2) -> 0
I60: =ROUND(E60*H60,2) -> 0
I61: =ROUND(E61*H61,2) -> 0
I62: =ROUND(E62*H62,2) -> 0
I63: =ROUND(E63*H63,2) -> 0
I64: =ROUND(E64*H64,2) -> 0
I65: =ROUND(E65*H65,2) -> 0
I66: =ROUND(E66*H66,2) -> 0
I67: =ROUND(E67*H67,2) -> 0
I68: =ROUND(E68*H68,2) -> 0
I69: =ROUND(E69*H69,2) -> 0
I70: =ROUND(E70*H70,2) -> 0
... I90: =ROUND(E90*H90,2) -> 0
H91: Subtotal | I91: =SUM(I15:I90) -> 100228.45
D92: OEM MSRP : | E92: =SUM(G15:G90) -> 254240.57 | H92: Shipping | I92: 0
D93: GQP : | E93: =SUM(I15:I90) -> 100228.45 | H93: Customs/Broker Fee | I93: 0
D94: GQP SAVINGS : | E94: =E92-E93 -> 154012.12 | H94: Total | I94: =SUM(I91:I93) -> 100228.45
H95: GST | I95: =I94*0.05 -> 5011.4225
...

Sheet MOQ SEAT
E1: MOQ QUOTE | H1: Injectors
B7: COMPANY: | C7: ='MOQ Grand Total'!C7 -> LINCOLN COUNTY OILFIELD SERVICES | E7: DATE: | F7: 45748 | H7: PO NUMBER: | I7: ='MOQ Grand Total'!I7
B8: CONTACT NAME: | C8: ='MOQ Grand Total'!C8 -> DUSTIN MINNS | E8: PHONE NUMBER: | H8: 780-609-0758
B9: BILLING ADDRESS: | C9: ='MOQ Grand Total'!C9 -> 0 | E9: EMAIL ADDRESS: | H9: D.MINNS@LCOS.CA
C10: ='MOQ Grand Total'!C10 -> 0 | E10: SHIPPING ADDRESS:
C11: ='MOQ Grand Total'!C11 -> 0
C12: ='MOQ Grand Total'!C12 -> 0
F13: CAD $
B14: PART NUMBER | C14: Make & Model | D14: DESCRIPTION | E14: QTY | F14: OEM MSRP | H14: GQP PRICE | I14: TOTAL
B15: 191-2933 | C15: =VLOOKUP(B15,'[1]Product by Part Number'!$A:$K,2,0) -> CAT D6N LGP (GHS) | D15: =VLOOKUP(B15,'[1]Product by Part Number'!$A:$K,3,0) -> SEAT SUSPENSION ASSEMBLY | E15: =VLOOKUP(B15,'[1]Product by Part Number'!$A:$K,11,0) -> 1 | F15: =VLOOKUP(B15,'[1]Product by Part Number'!$A:$K,4,0) -> 3100.37 | G15: =E15*F15 -> 3100.37 | H15: =VLOOKUP(B15,'[1]Product by Part Number'!$A:$K,5,0) -> 1550.19 | I15: =ROUND(E15*H15,2) -> 1550.19
B16: 316-8889 | C16: =VLOOKUP(B16,'[1]Product by Part Number'!$A:$K,2,0) -> CAT 329F L (ERL) | D16: =VLOOKUP(B16,'[1]Product by Part Number'!$A:$K,3,0) -> SEAT ASSEMBLY | E16: =VLOOKUP(B16,'[1]Product by Part Number'!$A:$K,11,0) -> 2 | F16: =VLOOKUP(B16,'[1]Product by Part Number'!$A:$K,4,0) -> 3384.84 | G16: =E16*F16 -> 6769.68 | H16: =VLOOKUP(B16,'[1]Product by Part Number'!$A:$K,5,0) -> 1692.42 | I16: =ROUND(E16*H16,2) -> 3384.84
B17: 316-8894 | C17: =VLOOKUP(B17,'[1]Product by Part Number'!$A:$K,2,0) -> CAT 329F L (ERL) | D17: =VLOOKUP(B17,'[1]Product by Part Number'!$A:$K,3,0) -> SEAT SUSPENSION ASSEMBLY | E17: =VLOOKUP(B17,'[1]Product by Part Number'!$A:$K,11,0) -> 2 | F17: =VLOOKUP(B17,'[1]Product by Part Number'!$A:$K,4,0) -> 3739.65 | G17: =E17*F17 -> 7479.3 | H17: =VLOOKUP(B17,'[1]Product by Part Number'!$A:$K,5,0) -> 1869.83 | I17: =ROUND(E17*H17,2) -> 3739.66
B18: 316-8895 | C18: =VLOOKUP(B18,'[1]Product by Part Number'!$A:$K,2,0) -> CAT 320F L (YBM) CAT 329E L (ZCD) CAT 330F L (MBX) CAT 330F L (HCK) CAT 336F L (RKB) | D18: =VLOOKUP(B18,'[1]Product by Part Number'!$A:$K,3,0) -> SEAT SUSPENSION ASSEMBLY | E18: =VLOOKUP(B18,'[1]Product by Part Number'!$A:$K,11,0) -> 6 | F18: =VLOOKUP(B18,'[1]Product by Part Number'!$A:$K,4,0) -> 4369.08 | G18: =E18*F18 -> 26214.48 | H18: =VLOOKUP(B18,'[1]Product by Part Number'!$A:$K,5,0) -> 2184.54 | I18: =ROUND(E18*H18,2) -> 13107.24
B19: 384-5674 | C19: =VLOOKUP(B19,'[1]Product by Part Number'!$A:$K,2,0) -> CAT 303.5E | D19: =VLOOKUP(B19,'[1]Product by Part Number'!$A:$K,3,0) -> SUSPENSION SEAT ASSEMBLY | E19: =VLOOKUP(B19,'[1]Product by Part Number'!$A:$K,11,0) -> 1 | F19: =VLOOKUP(B19,'[1]Product by Part Number'!$A:$K,4,0) -> 3786.04 | G19: =E19*F19 -> 3786.04 | H19: =VLOOKUP(B19,'[1]Product by Part Number'!$A:$K,5,0) -> 1893.02 | I19: =ROUND(E19*H19,2) -> 1893.02
B20: 488-6511 | C20: =VLOOKUP(B20,'[1]Product by Part Number'!$A:$K,2,0) -> CAT 320 (HEX) CAT 320 (MYK) CAT 330 (LHW) CAT 330 (WCH) | D20: =VLOOKUP(B20,'[1]Product by Part Number'!$A:$K,3,0) -> SUSPENSION SEAT ASSEMBLY | E20: =VLOOKUP(B20,'[1]Product by Part Number'!$A:$K,11,0) -> 13 | F20: =VLOOKUP(B20,'[1]Product by Part Number'!$A:$K,4,0) -> 8493.36 | G20: =E20*F20 -> 110413.68 | H20: =VLOOKUP(B20,'[1]Product by Part Number'!$A:$K,5,0) -> 4246.68 | I20: =ROUND(E20*H20,2) -> 55206.84
B21: 489-6483 | C21: =VLOOKUP(B21,'[1]Product by Part Number'!$A:$K,2,0) -> CAT D6N LGP (GHS) | D21: =VLOOKUP(B21,'[1]Product by Part Number'!$A:$K,3,0) -> SEAT ASSEMBLY | E21: =VLOOKUP(B21,'[1]Product by Part Number'!$A:$K,11,0) -> 1 | F21: =VLOOKUP(B21,'[1]Product by Part Number'!$A:$K,4,0) -> 3921.14 | G21: =E21*F21 -> 3921.14 | H21: =VLOOKUP(B21,'[1]Product by Part Number'!$A:$K,5,0) -> 1960.57 | I21: =ROUND(E21*H21,2) -> 1960.57
B22: 494-0057 | C22: =VLOOKUP(B22,'[1]Product by Part Number'!$A:$K,2,0) -> CAT 320F L (YBM) CAT 329E L (ZCD) CAT 330F L (MBX) CAT 330F L (HCK) CAT 336F L (RKB) | D22: =VLOOKUP(B22,'[1]Product by Part Number'!$A:$K,3,0) -> OPERATOR SEAT ASSEMBLY | E22: =VLOOKUP(B22,'[1]Product by Part Number'!$A:$K,11,0) -> 6 | F22: =VLOOKUP(B22,'[1]Product by Part Number'!$A:$K,4,0) -> 4161.44 | G22: =E22*F22 -> 24968.64 | H22: =VLOOKUP(B22,'[1]Product by Part Number'!$A:$K,5,0) -> 2080.72 | I22: =ROUND(E22*H22,2) -> 12484.32
B23: 526-7416 | C23: =VLOOKUP(B23,'[1]Product by Part Number'!$A:$K,2,0) -> CAT 561N (CPH) | D23: =VLOOKUP(B23,'[1]Product by Part Number'!$A:$K,3,0) -> SEAT ASSY | E23: =VLOOKUP(B23,'[1]Product by Part Number'!$A:$K,11,0) -> 5 | F23: =VLOOKUP(B23,'[1]Product by Part Number'!$A:$K,4,0) -> 2482.65 | G23: =E23*F23 -> 12413.25 | H23: =VLOOKUP(B23,'[1]Product by Part Number'!$A:$K,5,0) -> 1241.33 | I23: =ROUND(E23*H23,2) -> 6206.65
B24: 8Y-6179 | C24: =VLOOKUP(B24,'[1]Product by Part Number'!$A:$K,2,0) -> CAT D5 (3CR) | D24: =VLOOKUP(B24,'[1]Product by Part Number'!$A:$K,3,0) -> SEAT/SUSPENSION ASSEMBLY | E24: =VLOOKUP(B24,'[1]Product by Part Number'!$A:$K,11,0) -> 2 | F24: =VLOOKUP(B24,'[1]Product by Part Number'!$A:$K,4,0) -> 9424.19 | G24: =E24*F24 -> 18848.38 | H24: =VLOOKUP(B24,'[1]Product by Part Number'!$A:$K,5,0) -> 4712.1 | I24: =ROUND(E24*H24,2) -> 9424.2
B25: 9C-3696 | C25: =VLOOKUP(B25,'[1]Product by Part Number'!$A:$K,2,0) -> CAT D3 (1PJ) | D25: =VLOOKUP(B25,'[1]Product by Part Number'!$A:$K,3,0) -> SEAT ASSEMBLY | E25: =VLOOKUP(B25,'[1]Product by Part Number'!$A:$K,11,0) -> 1 | F25: =VLOOKUP(B25,'[1]Product by Part Number'!$A:$K,4,0) -> 5796.13 | G25: =E25*F25 -> 5796.13 | H25: =VLOOKUP(B25,'[1]Product by Part Number'!$A:$K,5,0) -> 2898.07 | I25: =ROUND(E25*H25,2) -> 2898.07
B26: CUSTOM-GQPD4SSA | C26: =VLOOKUP(B26,'[1]Product by Part Number'!$A:$K,2,0) -> CAT D4 (66J) | D26: =VLOOKUP(B26,'[1]Product by Part Number'!$A:$K,3,0) -> SEAT SUSPENSION ASSEMBLY | E26: =VLOOKUP(B26,'[1]Product by Part Number'!$A:$K,11,0) -> 1 | F26: =VLOOKUP(B26,'[1]Product by Part Number'!$A:$K,4,0) -> 1021.54 | G26: =E26*F26 -> 1021.54 | H26: =VLOOKUP(B26,'[1]Product by Part Number'!$A:$K,5,0) -> 510.77 | I26: =ROUND(E26*H26,2) -> 510.77
I27: =ROUND(E27*H27,2) -> 0
I28: =ROUND(E28*H28,2) -> 0
I29: =ROUND(E29*H29,2) -> 0
I30: =ROUND(E30*H30,2) -> 0
I31: =ROUND(E31*H31,2) -> 0
I32: =ROUND(E32*H32,2) -> 0
I33: =ROUND(E33*H33,2) -> 0
I34: =ROUND(E34*H34,2) -> 0
I35: =ROUND(E35*H35,2) -> 0
I36: =ROUND(E36*H36,2) -> 0
I37: =ROUND(E37*H37,2) -> 0
I38: =ROUND(E38*H38,2) -> 0
... I57: =ROUND(E57*H57,2) -> 0
H58: Subtotal | I58: =SUM(I15:I57) -> 112366.37
D59: OEM MSRP : | E59: =SUM(G15:G57) -> 224732.63 | H59: Shipping | I59: 0
D60: GQP : | E60: =SUM(I15:I57) -> 112366.37 | H60: Customs/Broker Fee | I60: 0
D61: GQP SAVINGS : | E61: =E59-E60 -> 112366.26 | H61: Total | I61: =SUM(I58:I60) -> 112366.37
H62: GST | I62: =I61*0.05 -> 5618.3185
H63: PST / QST
...

Sheet MOQ Seats
E1: MOQ QUOTE | H1: Seats
B7: COMPANY: | C7: Enoch | E7: DATE: | F7: 45444 | H7: PO NUMBER:
B8: CONTACT NAME: | C8: 0 | E8: PHONE NUMBER:
B9: BILLING ADDRESS: | C9: 0 | E9: EMAIL ADDRESS:
C10: 0 | E10: SHIPPING ADDRESS:
C11: 0
C12: 0
F13: CAD $
B14: PART NUMBER | C14: Make & Model | D14: DESCRIPTION | E14: QTY | F14: OEM MSRP | H14: GQP PRICE | I14: TOTAL
B15: 577-8381 | C15: CAT D7 | D15: Seat Group | E15: 1 | F15: 4801.95 | G15: =E15*F15 -> 4801.95 | H15: 2400.98 | I15: =ROUND(E15*H15,2) -> 2400.98
B16: 6W-9744 | C16: CAT D7 | D16: Seat Group | E16: 1 | F16: 3996.4 | G16: =E16*F16 -> 3996.4 | H16: 1998.2 | I16: =ROUND(E16*H16,2) -> 1998.2
B17: AT527707 | C17: JD 624K, JD 624KXDW | D17: Seat | E17: 3 | F17: 4614.62 | G17: =E17*F17 -> 13843.86 | H17: 2307.31 | I17: =ROUND(E17*H17,2) -> 6921.93
B18: AT522591 | C18: JD 650K | D18: Seat Group | E18: 1 | F18: 5739.32 | G18: =E18*F18 -> 5739.32 | H18: 2869.66 | I18: =ROUND(E18*H18,2) -> 2869.66
B19: AT522601 | C19: JD 770G, JD 772G | D19: Seat Group | E19: 2 | F19: 12791.1 | G19: =E19*F19 -> 25582.2 | H19: 6395.55 | I19: =ROUND(E19*H19,2) -> 12791.1
G20: =E20*F20 -> 0 | I20: =ROUND(E20*H20,2) -> 0
G21: =E21*F21 -> 0 | I21: =ROUND(E21*H21,2) -> 0
G22: =E22*F22 -> 0 | I22: =ROUND(E22*H22,2) -> 0
I23: =ROUND(E23*H23,2) -> 0
I24: =ROUND(E24*H24,2) -> 0
I25: =ROUND(E25*H25,2) -> 0
I26: =ROUND(E26*H26,2) -> 0
I27: =ROUND(E27*H27,2) -> 0
I28: =ROUND(E28*H28,2) -> 0
I29: =ROUND(E29*H29,2) -> 0
I30: =ROUND(E30*H30,2) -> 0
I31: =ROUND(E31*H31,2) -> 0
I32: =ROUND(E32*H32,2) -> 0
I33: =ROUND(E33*H33,2) -> 0
I34: =ROUND(E34*H34,2) -> 0
... I56: =ROUND(E56*H56,2) -> 0
H57: Subtotal | I57: =SUM(I15:I56) -> 26981.87
D58: OEM MSRP : | E58: =SUM(G15:G56) -> 53963.73 | H58: Shipping | I58: 0
D59: GQP : | E59: =SUM(I15:I56) -> 26981.87 | H59: Customs/Broker Fee | I59: 0
D60: GQP SAVINGS : | E60: =E58-E59 -> 26981.86 | H60: Total | I60: =SUM(I57:I59) -> 26981.87
H61: GST | I61: =I60*0.05 -> 1349.0935
H62: PST / QST
B63: Quote valid for 14 days, shipping subject to delays in supply chain. | H63: GRAND TOTAL | I63: =SUM(I60:I62) -> 28330.964

Sheet MOQ Undercarriage
E1: MOQ QUOTE | H1: Undercarriages
B7: COMPANY: | C7: ='MOQ Grand Total'!C7 -> LINCOLN COUNTY OILFIELD SERVICES | E7: DATE: | F7: 45748 | H7: PO NUMBER: | I7: ='MOQ Grand Total'!I7
B8: CONTACT NAME: | C8: ='MOQ Grand Total'!C8 -> DUSTIN MINNS | E8: PHONE NUMBER: | H8: 780-609-0758
B9: BILLING ADDRESS: | C9: ='MOQ Grand Total'!C9 -> 0 | E9: EMAIL ADDRESS: | H9: D.MINNS@LCOS.CA
C10: ='MOQ Grand Total'!C10 -> 0 | E10: SHIPPING ADDRESS:
C11: ='MOQ Grand Total'!C11 -> 0
C12: ='MOQ Grand Total'!C12 -> 0
F13: CAD $
B14: PART NUMBER | C14: Make & Model | D14: DESCRIPTION | E14: QTY | F14: OEM MSRP | H14: GQP PRICE | I14: TOTAL
B15: 0S-1585 | C15: =VLOOKUP(B15,'[1]Product by Part Number'!$A:$K,2,0) -> CAT D3 (1PJ) | D15: =VLOOKUP(B15,'[1]Product by Part Number'!$A:$K,3,0) -> HEX HEAD BOLT SF | E15: =VLOOKUP(B15,'[1]Product by Part Number'!$A:$K,11,0) -> 16 | F15: =VLOOKUP(B15,'[1]Product by Part Number'!$A:$K,4,0) -> 2.78 | G15: =E15*F15 -> 44.48 | H15: =VLOOKUP(B15,'[1]Product by Part Number'!$A:$K,5,0) -> 1.39 | I15: =ROUND(E15*H15,2) -> 22.24
B16: 0S-1594 | C16: =VLOOKUP(B16,'[1]Product by Part Number'!$A:$K,2,0) -> CAT D7G (92V) | D16: =VLOOKUP(B16,'[1]Product by Part Number'!$A:$K,3,0) -> CARRIER BOLT | E16: =VLOOKUP(B16,'[1]Product by Part Number'!$A:$K,11,0) -> 6 | F16: =VLOOKUP(B16,'[1]Product by Part Number'!$A:$K,4,0) -> 1.16 | G16: =E16*F16 -> 6.96 | H16: =VLOOKUP(B16,'[1]Product by Part Number'!$A:$K,5,0) -> 0.58 | I16: =ROUND(E16*H16,2) -> 3.48
B17: 106-1642 | C17: =VLOOKUP(B17,'[1]Product by Part Number'!$A:$K,2,0) -> CAT D4 (66J) CAT D6N LGP (GHS) CAT D6N LGP (SGG) CAT PL61 (WGS) | D17: =VLOOKUP(B17,'[1]Product by Part Number'!$A:$K,3,0) -> TRACK BOLT MASTER | E17: =VLOOKUP(B17,'[1]Product by Part Number'!$A:$K,11,0) -> 28 | F17: =VLOOKUP(B17,'[1]Product by Part Number'!$A:$K,4,0) -> 6.66 | G17: =E17*F17 -> 186.48 | H17: =VLOOKUP(B17,'[1]Product by Part Number'!$A:$K,5,0) -> 3.33 | I17: =ROUND(E17*H17,2) -> 93.24
B18: 107-0719 | C18: =VLOOKUP(B18,'[1]Product by Part Number'!$A:$K,2,0) -> CAT D4 (66J) CAT D6N LGP (GHS) CAT D6N LGP (SGG) CAT PL61 (WGS) | D18: =VLOOKUP(B18,'[1]Product by Part Number'!$A:$K,3,0) -> TRACK BOLT MASTER | E18: =VLOOKUP(B18,'[1]Product by Part Number'!$A:$K,11,0) -> 28 | F18: =VLOOKUP(B18,'[1]Product by Part Number'!$A:$K,4,0) -> 9.23 | G18: =E18*F18 -> 258.44 | H18: =VLOOKUP(B18,'[1]Product by Part Number'!$A:$K,5,0) -> 4.62 | I18: =ROUND(E18*H18,2) -> 129.36
B19: 108-0946 | C19: =VLOOKUP(B19,'[1]Product by Part Number'!$A:$K,2,0) -> CAT D5 (3CR) CAT 561N (CPH) | D19: =VLOOKUP(B19,'[1]Product by Part Number'!$A:$K,3,0) -> SPROCKET SEGMENT | E19: =VLOOKUP(B19,'[1]Product by Part Number'!$A:$K,11,0) -> 70 | F19: =VLOOKUP(B19,'[1]Product by Part Number'!$A:$K,4,0) -> 177.98 | G19: =E19*F19 -> 12458.6 | H19: =VLOOKUP(B19,'[1]Product by Part Number'!$A:$K,5,0) -> 88.99 | I19: =ROUND(E19*H19,2) -> 6229.3
B20: 108-0954 | C20: =VLOOKUP(B20,'[1]Product by Part Number'!$A:$K,2,0) -> CAT D5 (3CR) CAT 561N (CPH) | D20: =VLOOKUP(B20,'[1]Product by Part Number'!$A:$K,3,0) -> TRACK LINK ASSEMBLY | E20: =VLOOKUP(B20,'[1]Product by Part Number'!$A:$K,11,0) -> 14 | F20: =VLOOKUP(B20,'[1]Product by Part Number'!$A:$K,4,0) -> 11935.92 | G20: =E20*F20 -> 167102.88 | H20: =VLOOKUP(B20,'[1]Product by Part Number'!$A:$K,5,0) -> 5967.96 | I20: =ROUND(E20*H20,2) -> 83551.44
B21: 110-2976 | C21: =VLOOKUP(B21,'[1]Product by Part Number'!$A:$K,2,0) -> CAT PL61 (WGS) | D21: =VLOOKUP(B21,'[1]Product by Part Number'!$A:$K,3,0) -> TRACK LINK 39 JOINT | E21: =VLOOKUP(B21,'[1]Product by Part Number'!$A:$K,11,0) -> 6 | F21: =VLOOKUP(B21,'[1]Product by Part Number'!$A:$K,4,0) -> 8654.55 | G21: =E21*F21 -> 51927.3 | H21: =VLOOKUP(B21,'[1]Product by Part Number'!$A:$K,5,0) -> 4327.28 | I21: =ROUND(E21*H21,2) -> 25963.68
B22: 114-6099 | C22: =VLOOKUP(B22,'[1]Product by Part Number'!$A:$K,2,0) -> CAT 329E L (ZCD) | D22: =VLOOKUP(B22,'[1]Product by Part Number'!$A:$K,3,0) -> CARRIER BOLT | E22: =VLOOKUP(B22,'[1]Product by Part Number'!$A:$K,11,0) -> 4 | F22: =VLOOKUP(B22,'[1]Product by Part Number'!$A:$K,4,0) -> 31.9 | G22: =E22*F22 -> 127.6 | H22: =VLOOKUP(B22,'[1]Product by Part Number'!$A:$K,5,0) -> 15.95 | I22: =ROUND(E22*H22,2) -> 63.8
B23: 115-3696 | C23: =VLOOKUP(B23,'[1]Product by Part Number'!$A:$K,2,0) -> CAT 329E L (ZCD) CAT 329F L (ERL) CAT 330F L (MBX) CAT 330F L (HCK) CAT 330 (LHW) CAT 330 (WCH) | D23: =VLOOKUP(B23,'[1]Product by Part Number'!$A:$K,3,0) -> FRONT IDLER | E23: =VLOOKUP(B23,'[1]Product by Part Number'!$A:$K,11,0) -> 32 | F23: =VLOOKUP(B23,'[1]Product by Part Number'!$A:$K,4,0) -> 3159.07 | G23: =E23*F23 -> 101090.24 | H23: =VLOOKUP(B23,'[1]Product by Part Number'!$A:$K,5,0) -> 1579.54 | I23: =ROUND(E23*H23,2) -> 50545.28
B24: 118-1608 | C24: =VLOOKUP(B24,'[1]Product by Part Number'!$A:$K,2,0) -> CAT D4 (66J) | D24: =VLOOKUP(B24,'[1]Product by Part Number'!$A:$K,3,0) -> SINGLE FLANGE TRACK ROLLER | E24: =VLOOKUP(B24,'[1]Product by Part Number'!$A:$K,11,0) -> 4 | F24: =VLOOKUP(B24,'[1]Product by Part Number'!$A:$K,4,0) -> 1023.71 | G24: =E24*F24 -> 4094.84 | H24: =VLOOKUP(B24,'[1]Product by Part Number'!$A:$K,5,0) -> 511.86 | I24: =ROUND(E24*H24,2) -> 2047.44
B25: 118-1609 | C25: =VLOOKUP(B25,'[1]Product by Part Number'!$A:$K,2,0) -> CAT D4 (66J) | D25: =VLOOKUP(B25,'[1]Product by Part Number'!$A:$K,3,0) -> DOUBLE FLANGE TRACK ROLLER (GUIDE AR)* | E25: =VLOOKUP(B25,'[1]Product by Part Number'!$A:$K,11,0) -> 6 | F25: =VLOOKUP(B25,'[1]Product by Part Number'!$A:$K,4,0) -> 1246.45 | G25: =E25*F25 -> 7478.7 | H25: =VLOOKUP(B25,'[1]Product by Part Number'!$A:$K,5,0) -> 623.23 | I25: =ROUND(E25*H25,2) -> 3739.38
B26: 124-8237 | C26: =VLOOKUP(B26,'[1]Product by Part Number'!$A:$K,2,0) -> CAT D5 (3CR) CAT 561N (CPH) | D26: =VLOOKUP(B26,'[1]Product by Part Number'!$A:$K,3,0) -> SINGLE FLANGE TRACK ROLLER | E26: =VLOOKUP(B26,'[1]Product by Part Number'!$A:$K,11,0) -> 102 | F26: =VLOOKUP(B26,'[1]Product by Part Number'!$A:$K,4,0) -> 785.53 | G26: =E26*F26 -> 80124.06 | H26: =VLOOKUP(B26,'[1]Product by Part Number'!$A:$K,5,0) -> 392.77 | I26: =ROUND(E26*H26,2) -> 40062.54
... B189: CUSTOM-GQPPL6130"TG | C189: =VLOOKUP(B189,'[1]Product by Part Number'!$A:$K,2,0) -> CAT PL61 (WGS) | D189: =VLOOKUP(B189,'[1]Product by Part Number'!$A:$K,3,0) -> 30" GQP TRACK GROUP | E189: =VLOOKUP(B189,'[1]Product by Part Number'!$A:$K,11,0) -> 6 | F189: =VLOOKUP(B189,'[1]Product by Part Number'!$A:$K,4,0) -> 8945.71 | G189: =E189*F189 -> 53674.26 | H189: =VLOOKUP(B189,'[1]Product by Part Number'!$A:$K,5,0) -> 4472.86 | I189: =ROUND(E189*H189,2) -> 26837.16
I199: =ROUND(E199*H199,2) -> 0
H200: Subtotal | I200: =SUM(I15:I199) -> 1805217.6
D201: OEM MSRP : | E201: =SUM(G15:G199) -> 3610253.4 | H201: Shipping | I201: 0
D202: GQP : | E202: =SUM(I15:I199) -> 1805217.6 | H202: Customs/Broker Fee | I202: 0
D203: GQP SAVINGS : | E203: =E201-E202 -> 1805035.8 | H203: Total | I203: =SUM(I200:I202) -> 1805217.6
H204: GST | I204: =I203*0.05 -> 90260.879
H205: PST / QST
B206: Quote valid for 14 days, shipping subject to delays in supply chain. | H206: GRAND TOTAL | I206: =SUM(I203:I205) -> 1895478.5

Sheet MOQ Grand Total
E1: MOQ QUOTE | H1: Grand Total
B7: COMPANY: | C7: LINCOLN COUNTY OILFIELD SERVICES | E7: DATE: | F7: 45748 | H7: PO NUMBER:
B8: CONTACT NAME: | C8: DUSTIN MINNS | E8: PHONE NUMBER: | H8: 780-609-0758
B9: BILLING ADDRESS: | C9: 0 | E9: EMAIL ADDRESS: | H9: D.MINNS@LCOS.CA
C10: 0 | E10: SHIPPING ADDRESS:
C11: 0
C12: 0
F13: CAD $
B14: PART NUMBER | C14: Make & Model | D14: DESCRIPTION | E14: QTY | F14: OEM MSRP | H14: GQP PRICE | I14: TOTAL
B15: 093-7521 | C15: =VLOOKUP(B15,'[1]Product by Part Number'!$A:$K,2,0) -> CAT 320F L (YBM) CAT 336F L (RKB) | D15: =VLOOKUP(B15,'[1]Product by Part Number'!$A:$K,3,0) -> HYDRAULIC OIL FILTER | E15: =VLOOKUP(B15,'[1]Product by Part Number'!$A:$K,11,0) -> 10 | F15: =VLOOKUP(B15,'[1]Product by Part Number'!$A:$K,4,0) -> 102.09 | G15: =E15*F15 -> 1020.9 | H15: =VLOOKUP(B15,'[1]Product by Part Number'!$A:$K,5,0) -> 38.79 | I15: =ROUND(E15*H15,2) -> 387.9
B16: 0S-1585 | C16: =VLOOKUP(B16,'[1]Product by Part Number'!$A:$K,2,0) -> CAT D3 (1PJ) | D16: =VLOOKUP(B16,'[1]Product by Part Number'!$A:$K,3,0) -> HEX HEAD BOLT SF | E16: =VLOOKUP(B16,'[1]Product by Part Number'!$A:$K,11,0) -> 16 | F16: =VLOOKUP(B16,'[1]Product by Part Number'!$A:$K,4,0) -> 2.78 | G16: =E16*F16 -> 44.48 | H16: =VLOOKUP(B16,'[1]Product by Part Number'!$A:$K,5,0) -> 1.39 | I16: =ROUND(E16*H16,2) -> 22.24
B17: 0S-1594 | C17: =VLOOKUP(B17,'[1]Product by Part Number'!$A:$K,2,0) -> CAT D7G (92V) | D17: =VLOOKUP(B17,'[1]Product by Part Number'!$A:$K,3,0) -> CARRIER BOLT | E17: =VLOOKUP(B17,'[1]Product by Part Number'!$A:$K,11,0) -> 6 | F17: =VLOOKUP(B17,'[1]Product by Part Number'!$A:$K,4,0) -> 1.16 | G17: =E17*F17 -> 6.96 | H17: =VLOOKUP(B17,'[1]Product by Part Number'!$A:$K,5,0) -> 0.58 | I17: =ROUND(E17*H17,2) -> 3.48
B18: 104-5857 | C18: =VLOOKUP(B18,'[1]Product by Part Number'!$A:$K,2,0) -> CAT D5 (3CR) | D18: =VLOOKUP(B18,'[1]Product by Part Number'!$A:$K,3,0) -> TURBOCHARGER ASSEMBLY | E18: =VLOOKUP(B18,'[1]Product by Part Number'!$A:$K,11,0) -> 2 | F18: =VLOOKUP(B18,'[1]Product by Part Number'!$A:$K,4,0) -> 4677.47 | G18: =E18*F18 -> 9354.94 | H18: =VLOOKUP(B18,'[1]Product by Part Number'!$A:$K,5,0) -> 2338.74 | I18: =ROUND(E18*H18,2) -> 4677.48
B19: 106-1642 | C19: =VLOOKUP(B19,'[1]Product by Part Number'!$A:$K,2,0) -> CAT D4 (66J) CAT D6N LGP (GHS) CAT D6N LGP (SGG) CAT PL61 (WGS) | D19: =VLOOKUP(B19,'[1]Product by Part Number'!$A:$K,3,0) -> TRACK BOLT MASTER | E19: =VLOOKUP(B19,'[1]Product by Part Number'!$A:$K,11,0) -> 28 | F19: =VLOOKUP(B19,'[1]Product by Part Number'!$A:$K,4,0) -> 6.66 | G19: =E19*F19 -> 186.48 | H19: =VLOOKUP(B19,'[1]Product by Part Number'!$A:$K,5,0) -> 3.33 | I19: =ROUND(E19*H19,2) -> 93.24
B20: 107-0719 | C20: =VLOOKUP(B20,'[1]Product by Part Number'!$A:$K,2,0) -> CAT D4 (66J) CAT D6N LGP (GHS) CAT D6N LGP (SGG) CAT PL61 (WGS) | D20: =VLOOKUP(B20,'[1]Product by Part Number'!$A:$K,3,0) -> TRACK BOLT MASTER | E20: =VLOOKUP(B20,'[1]Product by Part Number'!$A:$K,11,0) -> 28 | F20: =VLOOKUP(B20,'[1]Product by Part Number'!$A:$K,4,0) -> 9.23 | G20: =E20*F20 -> 258.44 | H20: =VLOOKUP(B20,'[1]Product by Part Number'!$A:$K,5,0) -> 4.62 | I20: =ROUND(E20*H20,2) -> 129.36
B21: 108-0946 | C21: =VLOOKUP(B21,'[1]Product by Part Number'!$A:$K,2,0) -> CAT D5 (3CR) CAT 561N (CPH) | D21: =VLOOKUP(B21,'[1]Product by Part Number'!$A:$K,3,0) -> SPROCKET SEGMENT | E21: =VLOOKUP(B21,'[1]Product by Part Number'!$A:$K,11,0) -> 70 | F21: =VLOOKUP(B21,'[1]Product by Part Number'!$A:$K,4,0) -> 177.98 | G21: =E21*F21 -> 12458.6 | H21: =VLOOKUP(B21,'[1]Product by Part Number'!$A:$K,5,0) -> 88.99 | I21: =ROUND(E21*H21,2) -> 6229.3
B22: 108-0954 | C22: =VLOOKUP(B22,'[1]Product by Part Number'!$A:$K,2,0) -> CAT D5 (3CR) CAT 561N (CPH) | D22: =VLOOKUP(B22,'[1]Product by Part Number'!$A:$K,3,0) -> TRACK LINK ASSEMBLY | E22: =VLOOKUP(B22,'[1]Product by Part Number'!$A:$K,11,0) -> 14 | F22: =VLOOKUP(B22,'[1]Product by Part Number'!$A:$K,4,0) -> 11935.92 | G22: =E22*F22 -> 167102.88 | H22: =VLOOKUP(B22,'[1]Product by Part Number'!$A:$K,5,0) -> 5967.96 | I22: =ROUND(E22*H22,2) -> 83551.44
B23: 110-2976 | C23: =VLOOKUP(B23,'[1]Product by Part Number'!$A:$K,2,0) -> CAT PL61 (WGS) | D23: =VLOOKUP(B23,'[1]Product by Part Number'!$A:$K,3,0) -> TRACK LINK 39 JOINT | E23: =VLOOKUP(B23,'[1]Product by Part Number'!$A:$K,11,0) -> 6 | F23: =VLOOKUP(B23,'[1]Product by Part Number'!$A:$K,4,0) -> 8654.55 | G23: =E23*F23 -> 51927.3 | H23: =VLOOKUP(B23,'[1]Product by Part Number'!$A:$K,5,0) -> 4327.28 | I23: =ROUND(E23*H23,2) -> 25963.68
B24: 112-7448 | C24: =VLOOKUP(B24,'[1]Product by Part Number'!$A:$K,2,0) -> CAT D6T (MH7) | D24: =VLOOKUP(B24,'[1]Product by Part Number'!$A:$K,3,0) -> CABIN AIR FILTER ELEMENT | E24: =VLOOKUP(B24,'[1]Product by Part Number'!$A:$K,11,0) -> 3 | F24: =VLOOKUP(B24,'[1]Product by Part Number'!$A:$K,4,0) -> 43.37 | G24: =E24*F24 -> 130.11 | H24: =VLOOKUP(B24,'[1]Product by Part Number'!$A:$K,5,0) -> 16.48 | I24: =ROUND(E24*H24,2) -> 49.44
B25: 114-0358 | C25: =VLOOKUP(B25,'[1]Product by Part Number'!$A:$K,2,0) -> CAT D6N LGP (PBA) CAT D6N LGP (SGG) CAT D6T (MH7) CAT D7G (92V) | D25: =VLOOKUP(B25,'[1]Product by Part Number'!$A:$K,3,0) -> GROOVED PIN | E25: =VLOOKUP(B25,'[1]Product by Part Number'!$A:$K,11,0) -> 16 | F25: =VLOOKUP(B25,'[1]Product by Part Number'!$A:$K,4,0) -> 12.96 | G25: =E25*F25 -> 207.36 | H25: =VLOOKUP(B25,'[1]Product by Part Number'!$A:$K,5,0) -> 4.92 | I25: =ROUND(E25*H25,2) -> 78.72
B26: 114-0359 | C26: =VLOOKUP(B26,'[1]Product by Part Number'!$A:$K,2,0) -> CAT D5 (3CR) CAT D6N LGP (PBA) CAT D6N LGP (SGG) CAT D6T (MH7) CAT D7G (92V) | D26: =VLOOKUP(B26,'[1]Product by Part Number'!$A:$K,3,0) -> RETAINER | E26: =VLOOKUP(B26,'[1]Product by Part Number'!$A:$K,11,0) -> 18 | F26: =VLOOKUP(B26,'[1]Product by Part Number'!$A:$K,4,0) -> 22.39 | G26: =E26*F26 -> 403.02 | H26: =VLOOKUP(B26,'[1]Product by Part Number'!$A:$K,5,0) -> 8.51 | I26: =ROUND(E26*H26,2) -> 153.18
... B386: CUSTOM-GQPPL6130"TG | C386: =VLOOKUP(B386,'[1]Product by Part Number'!$A:$K,2,0) -> CAT PL61 (WGS) | D386: =VLOOKUP(B386,'[1]Product by Part Number'!$A:$K,3,0) -> 30" GQP TRACK GROUP | E386: =VLOOKUP(B386,'[1]Product by Part Number'!$A:$K,11,0) -> 6 | F386: =VLOOKUP(B386,'[1]Product by Part Number'!$A:$K,4,0) -> 8945.71 | G386: =E386*F386 -> 53674.26 | H386: =VLOOKUP(B386,'[1]Product by Part Number'!$A:$K,5,0) -> 4472.86 | I386: =ROUND(E386*H386,2) -> 26837.16
H387: Subtotal | I387: =SUM(I15:I386) -> 2670325.1
D388: OEM MSRP : | E388: =SUM(G15:G386) -> 5461186.1 | H388: Shipping | I388: 0
D389: GQP : | E389: =SUM(I15:I386) -> 2670325.1 | H389: Customs/Broker Fee | I389: 0
D390: GQP SAVINGS : | E390: =E388-E389 -> 2790861 | H390: Total | I390: =SUM(I387:I389) -> 2670325.1
H391: GST | I391: =I390*0.05 -> 133516.25
H392: PST / QST
B393: Quote valid for 14 days, shipping subject to delays in supply chain. | H393: GRAND TOTAL | I393: =SUM(I390:I392) -> 2803841.3
