Workbook

Sheet MOQ GET Parts
E1: MOQ QUOTE | H1: G.E.T.
B7: COMPANY: | C7: ='MOQ Grand Total'!C7 -> LINCOLN COUNTY OILFIELD SERVICES | E7: DATE: | F7: 45748 | H7: PO NUMBER: | I7: ='MOQ Grand Total'!I7
B8: CONTACT NAME: | C8: ='MOQ Grand Total'!C8 -> DUSTIN MINNS | E8: PHONE NUMBER: | H8: 780-609-0758
B9: BILLING ADDRESS: | C9: ='MOQ Grand Total'!C9 -> 0 | E9: EMAIL ADDRESS: | H9: D.MINNS@LCOS.CA
C10: ='MOQ Grand Total'!C10 -> 0 | E10: SHIPPING ADDRESS:
C11: ='MOQ Grand Total'!C11 -> 0
C12: ='MOQ Grand Total'!C12 -> 0
F13: CAD $
B14: PART NUMBER | C14: Make & Model | D14: DESCRIPTION | E14: QTY | F14: OEM MSRP | H14: GQP PRICE | I14: TOTAL
B15: 114-0358 | C15: =VLOOKUP(B15,'[1]Product by Part Number'!$A:$K,2,0) -> CAT D6N LGP (PBA) CAT D6N LGP (PBA) (2) CAT D6N LGP (SGG) CAT D6N LGP (SGG) (2) CAT D6T (MH7) CAT D7G (92V) CAT D7G (3ZD) CAT D7G (3ZD) (2) | D15: =VLOOKUP(B15,'[1]Product by Part Number'!$A:$K,3,0) -> GROOVED PIN | E15: =VLOOKUP(B15,'[1]Product by Part Number'!$A:$K,11,0) -> 18 | F15: =VLOOKUP(B15,'[1]Product by Part Number'!$A:$K,4,0) -> 12.96 | G15: =E15*F15 -> 233.28 | H15: =VLOOKUP(B15,'[1]Product by Part Number'!$A:$K,5,0) -> 4.92 | I15: =ROUND(E15*H15,2) -> 88.56
B16: 114-0359 | C16: =VLOOKUP(B16,'[1]Product by Part Number'!$A:$K,2,0) -> CAT D5 (3CR) CAT D5 (3CR) (2) CAT D6N LGP (PBA) CAT D6N LGP (PBA) (2) CAT D6N LGP (SGG) CAT D6N LGP (SGG) (2) CAT D6T (MH7) CAT D7G (92V) CAT D7G (3ZD) CAT D7G (3ZD) (2) | D16: =VLOOKUP(B16,'[1]Product by Part Number'!$A:$K,3,0) -> RETAINER | E16: =VLOOKUP(B16,'[1]Product by Part Number'!$A:$K,11,0) -> 20 | F16: =VLOOKUP(B16,'[1]Product by Part Number'!$A:$K,4,0) -> 22.39 | G16: =E16*F16 -> 447.8 | H16: =VLOOKUP(B16,'[1]Product by Part Number'!$A:$K,5,0) -> 8.51 | I16: =ROUND(E16*H16,2) -> 170.2
B17: 136-8308 | C17: =VLOOKUP(B17,'[1]Product by Part Number'!$A:$K,2,0) -> CAT D5 (3CR) CAT D5 (3CR) (2) | D17: =VLOOKUP(B17,'[1]Product by Part Number'!$A:$K,3,0) -> RIPPER PIN | E17: =VLOOKUP(B17,'[1]Product by Part Number'!$A:$K,11,0) -> 2 | F17: =VLOOKUP(B17,'[1]Product by Part Number'!$A:$K,4,0) -> 10.35 | G17: =E17*F17 -> 20.7 | H17: =VLOOKUP(B17,'[1]Product by Part Number'!$A:$K,5,0) -> 3.93 | I17: =ROUND(E17*H17,2) -> 7.86
B18: 1U-3202 | C18: =VLOOKUP(B18,'[1]Product by Part Number'!$A:$K,2,0) -> CAT D3 (1PJ) | D18: =VLOOKUP(B18,'[1]Product by Part Number'!$A:$K,3,0) -> TIP SHORT | E18: =VLOOKUP(B18,'[1]Product by Part Number'!$A:$K,11,0) -> 1 | F18: =VLOOKUP(B18,'[1]Product by Part Number'!$A:$K,4,0) -> 37.42 | G18: =E18*F18 -> 37.42 | H18: =VLOOKUP(B18,'[1]Product by Part Number'!$A:$K,5,0) -> 14.22 | I18: =ROUND(E18*H18,2) -> 14.22
B19: 229-6958 | C19: =VLOOKUP(B19,'[1]Product by Part Number'!$A:$K,2,0) -> CAT D6T (MH7) | D19: =VLOOKUP(B19,'[1]Product by Part Number'!$A:$K,3,0) -> CUTTING EDGE | E19: =VLOOKUP(B19,'[1]Product by Part Number'!$A:$K,11,0) -> 2 | F19: =VLOOKUP(B19,'[1]Product by Part Number'!$A:$K,4,0) -> 559.01 | G19: =E19*F19 -> 1118.02 | H19: =VLOOKUP(B19,'[1]Product by Part Number'!$A:$K,5,0) -> 212.42 | I19: =ROUND(E19*H19,2) -> 424.84
B20: 288-3462 | C20: =VLOOKUP(B20,'[1]Product by Part Number'!$A:$K,2,0) -> CAT 303.5E | D20: =VLOOKUP(B20,'[1]Product by Part Number'!$A:$K,3,0) -> FINAL DRIVE | E20: =VLOOKUP(B20,'[1]Product by Part Number'!$A:$K,11,0) -> 2 | F20: =VLOOKUP(B20,'[1]Product by Part Number'!$A:$K,4,0) -> 10089.31 | G20: =E20*F20 -> 20178.62 | H20: =VLOOKUP(B20,'[1]Product by Part Number'!$A:$K,5,0) -> 5044.66 | I20: =ROUND(E20*H20,2) -> 10089.32
B21: 2J-3506 | C21: =VLOOKUP(B21,'[1]Product by Part Number'!$A:$K,2,0) -> CAT D5 (3CR) CAT D5 (3CR) (2) CAT D6N LGP (GHS) CAT D6N LGP (PBA) CAT D6N LGP (PBA) (2) CAT D6N LGP (SGG) CAT D6N LGP (SGG) (2) CAT D6T (MH7) | D21: =VLOOKUP(B21,'[1]Product by Part Number'!$A:$K,3,0) -> HEX NUT | E21: =VLOOKUP(B21,'[1]Product by Part Number'!$A:$K,11,0) -> 222 | F21: =VLOOKUP(B21,'[1]Product by Part Number'!$A:$K,4,0) -> 3.65 | G21: =E21*F21 -> 810.3 | H21: =VLOOKUP(B21,'[1]Product by Part Number'!$A:$K,5,0) -> 1.39 | I21: =ROUND(E21*H21,2) -> 308.58
B22: 341-2814 | C22: =VLOOKUP(B22,'[1]Product by Part Number'!$A:$K,2,0) -> CAT 320F L (YBM) CAT 320 (HEX) CAT 320 (MYK) CAT 320 (MYK) (2) | D22: =VLOOKUP(B22,'[1]Product by Part Number'!$A:$K,3,0) -> BUCKET CYLINDER | E22: =VLOOKUP(B22,'[1]Product by Part Number'!$A:$K,11,0) -> 4 | F22: =VLOOKUP(B22,'[1]Product by Part Number'!$A:$K,4,0) -> 22869.96 | G22: =E22*F22 -> 91479.84 | H22: =VLOOKUP(B22,'[1]Product by Part Number'!$A:$K,5,0) -> 8690.58 | I22: =ROUND(E22*H22,2) -> 34762.32
B23: 376-2025 | C23: =VLOOKUP(B23,'[1]Product by Part Number'!$A:$K,2,0) -> CAT 303.5E | D23: =VLOOKUP(B23,'[1]Product by Part Number'!$A:$K,3,0) -> HYDRAULIC PUMP | E23: =VLOOKUP(B23,'[1]Product by Part Number'!$A:$K,11,0) -> 1 | F23: =VLOOKUP(B23,'[1]Product by Part Number'!$A:$K,4,0) -> 7622.73 | G23: =E23*F23 -> 7622.73 | H23: =VLOOKUP(B23,'[1]Product by Part Number'!$A:$K,5,0) -> 3811.37 | I23: =ROUND(E23*H23,2) -> 3811.37
B24: 383-0293 | C24: =VLOOKUP(B24,'[1]Product by Part Number'!$A:$K,2,0) -> CAT 303.5E | D24: =VLOOKUP(B24,'[1]Product by Part Number'!$A:$K,3,0) -> OIL PUMP ENGINE | E24: =VLOOKUP(B24,'[1]Product by Part Number'!$A:$K,11,0) -> 1 | F24: =VLOOKUP(B24,'[1]Product by Part Number'!$A:$K,4,0) -> 831.44 | G24: =E24*F24 -> 831.44 | H24: =VLOOKUP(B24,'[1]Product by Part Number'!$A:$K,5,0) -> 415.72 | I24: =ROUND(E24*H24,2) -> 415.72
B25: 383-0433 | C25: =VLOOKUP(B25,'[1]Product by Part Number'!$A:$K,2,0) -> CAT 303.5E | D25: =VLOOKUP(B25,'[1]Product by Part Number'!$A:$K,3,0) -> WATER PUMP | E25: =VLOOKUP(B25,'[1]Product by Part Number'!$A:$K,11,0) -> 1 | F25: =VLOOKUP(B25,'[1]Product by Part Number'!$A:$K,4,0) -> 512.79 | G25: =E25*F25 -> 512.79 | H25: =VLOOKUP(B25,'[1]Product by Part Number'!$A:$K,5,0) -> 256.4 | I25: =ROUND(E25*H25,2) -> 256.4
B26: 3B-4632 | C26: =VLOOKUP(B26,'[1]Product by Part Number'!$A:$K,2,0) -> CAT D3 (1PJ) | D26: =VLOOKUP(B26,'[1]Product by Part Number'!$A:$K,3,0) -> COTTER PIN | E26: =VLOOKUP(B26,'[1]Product by Part Number'!$A:$K,11,0) -> 1 | F26: =VLOOKUP(B26,'[1]Product by Part Number'!$A:$K,4,0) -> 1.18 | G26: =E26*F26 -> 1.18 | H26: =VLOOKUP(B26,'[1]Product by Part Number'!$A:$K,5,0) -> 0.45 | I26: =ROUND(E26*H26,2) -> 0.45
... B58: CUSTOM-GQPD5ABA | C58: =VLOOKUP(B58,'[1]Product by Part Number'!$A:$K,2,0) -> CAT D5 (3CR) CAT D5 (3CR) (2) | D58: =VLOOKUP(B58,'[1]Product by Part Number'!$A:$K,3,0) -> ANGLING BLADE ASSY | E58: =VLOOKUP(B58,'[1]Product by Part Number'!$A:$K,11,0) -> 2 | F58: =VLOOKUP(B58,'[1]Product by Part Number'!$A:$K,4,0) -> 16888.9 | G58: =E58*F58 -> 33777.8 | H58: =VLOOKUP(B58,'[1]Product by Part Number'!$A:$K,5,0) -> 6417.78 | I58: =ROUND(E58*H58,2) -> 12835.56
H59: Subtotal | I59: =SUM(I15:I58) -> 126025.23
D60: OEM MSRP : | E60: =SUM(G15:G58) -> 322061.51 | H60: Shipping | I60: 0
D61: GQP : | E61: =SUM(I15:I58) -> 126025.23 | H61: Customs/Broker Fee | I61: 0
D62: GQP SAVINGS : | E62: =E60-E61 -> 196036.28 | H62: Total | I62: =SUM(I59:I61) -> 126025.23
H63: GST | I63: =I62*0.05 -> 6301.2615
H64: PST / QST
B65: Quote valid for 14 days, shipping subject to delays in supply chain. | H65: GRAND TOTAL | I65: =SUM(I62:I64) -> 132326.49

Sheet MOQ Operator Seats
E1: MOQ QUOTE | H1: Injectors
B7: COMPANY: | C7: ='MOQ Grand Total'!C7 -> LINCOLN COUNTY OILFIELD SERVICES | E7: DATE: | F7: 45748 | H7: PO NUMBER: | I7: ='MOQ Grand Total'!I7
B8: CONTACT NAME: | C8: ='MOQ Grand Total'!C8 -> DUSTIN MINNS | E8: PHONE NUMBER: | H8: 780-609-0758
B9: BILLING ADDRESS: | C9: ='MOQ Grand Total'!C9 -> 0 | E9: EMAIL ADDRESS: | H9: D.MINNS@LCOS.CA
C10: ='MOQ Grand Total'!C10 -> 0 | E10: SHIPPING ADDRESS:
C11: ='MOQ Grand Total'!C11 -> 0
C12: ='MOQ Grand Total'!C12 -> 0
F13: CAD $
B14: PART NUMBER | C14: Make & Model | D14: DESCRIPTION | E14: QTY | F14: OEM MSRP | H14: GQP PRICE | I14: TOTAL
B15: 191-2933 | C15: =VLOOKUP(B15,'[1]Product by Part Number'!$A:$K,2,0) -> CAT D6N LGP (GHS) | D15: =VLOOKUP(B15,'[1]Product by Part Number'!$A:$K,3,0) -> SEAT SUSPENSION ASSEMBLY | E15: =VLOOKUP(B15,'[1]Product by Part Number'!$A:$K,11,0) -> 1 | F15: =VLOOKUP(B15,'[1]Product by Part Number'!$A:$K,4,0) -> 3100.37 | G15: =E15*F15 -> 3100.37 | H15: =VLOOKUP(B15,'[1]Product by Part Number'!$A:$K,5,0) -> 1550.19 | I15: =ROUND(E15*H15,2) -> 1550.19
B16: 316-8889 | C16: =VLOOKUP(B16,'[1]Product by Part Number'!$A:$K,2,0) -> CAT 329F L (ERL) CAT 329F L (ERL) (2) | D16: =VLOOKUP(B16,'[1]Product by Part Number'!$A:$K,3,0) -> SEAT ASSEMBLY | E16: =VLOOKUP(B16,'[1]Product by Part Number'!$A:$K,11,0) -> 2 | F16: =VLOOKUP(B16,'[1]Product by Part Number'!$A:$K,4,0) -> 3384.84 | G16: =E16*F16 -> 6769.68 | H16: =VLOOKUP(B16,'[1]Product by Part Number'!$A:$K,5,0) -> 1692.42 | I16: =ROUND(E16*H16,2) -> 3384.84
B17: 316-8894 | C17: =VLOOKUP(B17,'[1]Product by Part Number'!$A:$K,2,0) -> CAT 329F L (ERL) CAT 329F L (ERL) (2) | D17: =VLOOKUP(B17,'[1]Product by Part Number'!$A:$K,3,0) -> SEAT SUSPENSION ASSEMBLY | E17: =VLOOKUP(B17,'[1]Product by Part Number'!$A:$K,11,0) -> 2 | F17: =VLOOKUP(B17,'[1]Product by Part Number'!$A:$K,4,0) -> 3739.65 | G17: =E17*F17 -> 7479.3 | H17: =VLOOKUP(B17,'[1]Product by Part Number'!$A:$K,5,0) -> 1869.83 | I17: =ROUND(E17*H17,2) -> 3739.66
B18: 316-8895 | C18: =VLOOKUP(B18,'[1]Product by Part Number'!$A:$K,2,0) -> CAT 320F L (YBM) CAT 329E L (ZCD) CAT 330F L (MBX) CAT 330F L (HCK) CAT 330F L (HCK) (2) CAT 336F L (RKB) | D18: =VLOOKUP(B18,'[1]Product by Part Number'!$A:$K,3,0) -> SEAT SUSPENSION ASSEMBLY | E18: =VLOOKUP(B18,'[1]Product by Part Number'!$A:$K,11,0) -> 6 | F18: =VLOOKUP(B18,'[1]Product by Part Number'!$A:$K,4,0) -> 4369.08 | G18: =E18*F18 -> 26214.48 | H18: =VLOOKUP(B18,'[1]Product by Part Number'!$A:$K,5,0) -> 2184.54 | I18: =ROUND(E18*H18,2) -> 13107.24
B19: 384-5674 | C19: =VLOOKUP(B19,'[1]Product by Part Number'!$A:$K,2,0) -> CAT 303.5E | D19: =VLOOKUP(B19,'[1]Product by Part Number'!$A:$K,3,0) -> SUSPENSION SEAT ASSEMBLY | E19: =VLOOKUP(B19,'[1]Product by Part Number'!$A:$K,11,0) -> 1 | F19: =VLOOKUP(B19,'[1]Product by Part Number'!$A:$K,4,0) -> 3786.04 | G19: =E19*F19 -> 3786.04 | H19: =VLOOKUP(B19,'[1]Product by Part Number'!$A:$K,5,0) -> 1893.02 | I19: =ROUND(E19*H19,2) -> 1893.02
B20: 488-6511 | C20: =VLOOKUP(B20,'[1]Product by Part Number'!$A:$K,2,0) -> CAT 320 (HEX) CAT 320 (MYK) CAT 320 (MYK) (2) CAT 330 (LHW) CAT 330 (LHW) (2) CAT 330 (LHW) (3) CAT 330 (LHW) (4) CAT 330 (WCH) CAT 330 (WCH) (2) CAT 330 (WCH) (3) CAT 330 (WCH) (4) CAT 330 (WCH) (5) CAT 330 (WCH) (6) | D20: =VLOOKUP(B20,'[1]Product by Part Number'!$A:$K,3,0) -> SUSPENSION SEAT ASSEMBLY | E20: =VLOOKUP(B20,'[1]Product by Part Number'!$A:$K,11,0) -> 13 | F20: =VLOOKUP(B20,'[1]Product by Part Number'!$A:$K,4,0) -> 8493.36 | G20: =E20*F20 -> 110413.68 | H20: =VLOOKUP(B20,'[1]Product by Part Number'!$A:$K,5,0) -> 4246.68 | I20: =ROUND(E20*H20,2) -> 55206.84
B21: 489-6483 | C21: =VLOOKUP(B21,'[1]Product by Part Number'!$A:$K,2,0) -> CAT D6N LGP (GHS) | D21: =VLOOKUP(B21,'[1]Product by Part Number'!$A:$K,3,0) -> SEAT ASSEMBLY | E21: =VLOOKUP(B21,'[1]Product by Part Number'!$A:$K,11,0) -> 1 | F21: =VLOOKUP(B21,'[1]Product by Part Number'!$A:$K,4,0) -> 3921.14 | G21: =E21*F21 -> 3921.14 | H21: =VLOOKUP(B21,'[1]Product by Part Number'!$A:$K,5,0) -> 1960.57 | I21: =ROUND(E21*H21,2) -> 1960.57
B22: 494-0057 | C22: =VLOOKUP(B22,'[1]Product by Part Number'!$A:$K,2,0) -> CAT 320F L (YBM) CAT 329E L (ZCD) CAT 330F L (MBX) CAT 330F L (HCK) CAT 330F L (HCK) (2) CAT 336F L (RKB) | D22: =VLOOKUP(B22,'[1]Product by Part Number'!$A:$K,3,0) -> OPERATOR SEAT ASSEMBLY | E22: =VLOOKUP(B22,'[1]Product by Part Number'!$A:$K,11,0) -> 6 | F22: =VLOOKUP(B22,'[1]Product by Part Number'!$A:$K,4,0) -> 4161.44 | G22: =E22*F22 -> 24968.64 | H22: =VLOOKUP(B22,'[1]Product by Part Number'!$A:$K,5,0) -> 2080.72 | I22: =ROUND(E22*H22,2) -> 12484.32
B23: 526-7416 | C23: =VLOOKUP(B23,'[1]Product by Part Number'!$A:$K,2,0) -> CAT 561N (CPH) CAT 561N (CPH) (2) CAT 561N (CPH) (3) CAT 561N (CPH) (4) CAT 561N (CPH) (5) | D23: =VLOOKUP(B23,'[1]Product by Part Number'!$A:$K,3,0) -> SEAT ASSY | E23: =VLOOKUP(B23,'[1]Product by Part Number'!$A:$K,11,0) -> 5 | F23: =VLOOKUP(B23,'[1]Product by Part Number'!$A:$K,4,0) -> 2482.65 | G23: =E23*F23 -> 12413.25 | H23: =VLOOKUP(B23,'[1]Product by Part Number'!$A:$K,5,0) -> 1241.33 | I23: =ROUND(E23*H23,2) -> 6206.65
B24: 8Y-6179 | C24: =VLOOKUP(B24,'[1]Product by Part Number'!$A:$K,2,0) -> CAT D5 (3CR) CAT D5 (3CR) (2) | D24: =VLOOKUP(B24,'[1]Product by Part Number'!$A:$K,3,0) -> SEAT/SUSPENSION ASSEMBLY | E24: =VLOOKUP(B24,'[1]Product by Part Number'!$A:$K,11,0) -> 2 | F24: =VLOOKUP(B24,'[1]Product by Part Number'!$A:$K,4,0) -> 9424.19 | G24: =E24*F24 -> 18848.38 | H24: =VLOOKUP(B24,'[1]Product by Part Number'!$A:$K,5,0) -> 4712.1 | I24: =ROUND(E24*H24,2) -> 9424.2
B25: 9C-3696 | C25: =VLOOKUP(B25,'[1]Product by Part Number'!$A:$K,2,0) -> CAT D3 (1PJ) | D25: =VLOOKUP(B25,'[1]Product by Part Number'!$A:$K,3,0) -> SEAT ASSEMBLY | E25: =VLOOKUP(B25,'[1]Product by Part Number'!$A:$K,11,0) -> 1 | F25: =VLOOKUP(B25,'[1]Product by Part Number'!$A:$K,4,0) -> 5796.13 | G25: =E25*F25 -> 5796.13 | H25: =VLOOKUP(B25,'[1]Product by Part Number'!$A:$K,5,0) -> 2898.07 | I25: =ROUND(E25*H25,2) -> 2898.07
B26: CUSTOM-GQPD4SSA | C26: =VLOOKUP(B26,'[1]Product by Part Number'!$A:$K,2,0) -> CAT D4 (66J) | D26: =VLOOKUP(B26,'[1]Product by Part Number'!$A:$K,3,0) -> SEAT SUSPENSION ASSEMBLY | E26: =VLOOKUP(B26,'[1]Product by Part Number'!$A:$K,11,0) -> 1 | F26: =VLOOKUP(B26,'[1]Product by Part Number'!$A:$K,4,0) -> 1021.54 | G26: =E26*F26 -> 1021.54 | H26: =VLOOKUP(B26,'[1]Product by Part Number'!$A:$K,5,0) -> 510.77 | I26: =ROUND(E26*H26,2) -> 510.77
I27: =ROUND(E27*H27,2) -> 0
I28: =ROUND(E28*H28,2) -> 0
I29: =ROUND(E29*H29,2) -> 0
I30: =ROUND(E30*H30,2) -> 0
I31: =ROUND(E31*H31,2) -> 0
I32: =ROUND(E32*H32,2) -> 0
I33: =ROUND(E33*H33,2) -> 0
I34: =ROUND(E34*H34,2) -> 0
I35: =ROUND(E35*H35,2) -> 0
I36: =ROUND(E36*H36,2) -> 0
I37: =ROUND(E37*H37,2) -> 0
I38: =ROUND(E38*H38,2) -> 0
... I57: =ROUND(E57*H57,2) -> 0
H58: Subtotal | I58: =SUM(I15:I57) -> 112366.37
D59: OEM MSRP : | E59: =SUM(G15:G57) -> 224732.63 | H59: Shipping | I59: 0
D60: GQP : | E60: =SUM(I15:I57) -> 112366.37 | H60: Customs/Broker Fee | I60: 0
D61: GQP SAVINGS : | E61: =E59-E60 -> 112366.26 | H61: Total | I61: =SUM(I58:I60) -> 112366.37
H62: GST | I62: =I61*0.05 -> 5618.3185
H63: PST / QST
...

Sheet MOQ Seats
E1: MOQ QUOTE | H1: Seats
B7: COMPANY: | C7: Enoch | E7: DATE: | F7: 45444 | H7: PO NUMBER:
B8: CONTACT NAME: | C8: 0 | E8: PHONE NUMBER:
B9: BILLING ADDRESS: | C9: 0 | E9: EMAIL ADDRESS:
C10: 0 | E10: SHIPPING ADDRESS:
C11: 0
C12: 0
F13: CAD $
B14: PART NUMBER | C14: Make & Model | D14: DESCRIPTION | E14: QTY | F14: OEM MSRP | H14: GQP PRICE | I14: TOTAL
B15: 577-8381 | C15: CAT D7 | D15: Seat Group | E15: 1 | F15: 4801.95 | G15: =E15*F15 -> 4801.95 | H15: 2400.98 | I15: =ROUND(E15*H15,2) -> 2400.98
B16: 6W-9744 | C16: CAT D7 | D16: Seat Group | E16: 1 | F16: 3996.4 | G16: =E16*F16 -> 3996.4 | H16: 1998.2 | I16: =ROUND(E16*H16,2) -> 1998.2
B17: AT527707 | C17: JD 624K, JD 624KXDW | D17: Seat | E17: 3 | F17: 4614.62 | G17: =E17*F17 -> 13843.86 | H17: 2307.31 | I17: =ROUND(E17*H17,2) -> 6921.93
B18: AT522591 | C18: JD 650K | D18: Seat Group | E18: 1 | F18: 5739.32 | G18: =E18*F18 -> 5739.32 | H18: 2869.66 | I18: =ROUND(E18*H18,2) -> 2869.66
B19: AT522601 | C19: JD 770G, JD 772G | D19: Seat Group | E19: 2 | F19: 12791.1 | G19: =E19*F19 -> 25582.2 | H19: 6395.55 | I19: =ROUND(E19*H19,2) -> 12791.1
G20: =E20*F20 -> 0 | I20: =ROUND(E20*H20,2) -> 0
G21: =E21*F21 -> 0 | I21: =ROUND(E21*H21,2) -> 0
G22: =E22*F22 -> 0 | I22: =ROUND(E22*H22,2) -> 0
I23: =ROUND(E23*H23,2) -> 0
I24: =ROUND(E24*H24,2) -> 0
I25: =ROUND(E25*H25,2) -> 0
I26: =ROUND(E26*H26,2) -> 0
I27: =ROUND(E27*H27,2) -> 0
I28: =ROUND(E28*H28,2) -> 0
I29: =ROUND(E29*H29,2) -> 0
I30: =ROUND(E30*H30,2) -> 0
I31: =ROUND(E31*H31,2) -> 0
I32: =ROUND(E32*H32,2) -> 0
I33: =ROUND(E33*H33,2) -> 0
I34: =ROUND(E34*H34,2) -> 0
... I56: =ROUND(E56*H56,2) -> 0
H57: Subtotal | I57: =SUM(I15:I56) -> 26981.87
D58: OEM MSRP : | E58: =SUM(G15:G56) -> 53963.73 | H58: Shipping | I58: 0
D59: GQP : | E59: =SUM(I15:I56) -> 26981.87 | H59: Customs/Broker Fee | I59: 0
D60: GQP SAVINGS : | E60: =E58-E59 -> 26981.86 | H60: Total | I60: =SUM(I57:I59) -> 26981.87
H61: GST | I61: =I60*0.05 -> 1349.0935
H62: PST / QST
B63: Quote valid for 14 days, shipping subject to delays in supply chain. | H63: GRAND TOTAL | I63: =SUM(I60:I62) -> 28330.964

Sheet MOQ Undercarriages
E1: MOQ QUOTE | H1: Undercarriages
B7: COMPANY: | C7: ='MOQ Grand Total'!C7 -> LINCOLN COUNTY OILFIELD SERVICES | E7: DATE: | F7: 45748 | H7: PO NUMBER: | I7: ='MOQ Grand Total'!I7
B8: CONTACT NAME: | C8: ='MOQ Grand Total'!C8 -> DUSTIN MINNS | E8: PHONE NUMBER: | H8: 780-609-0758
B9: BILLING ADDRESS: | C9: ='MOQ Grand Total'!C9 -> 0 | E9: EMAIL ADDRESS: | H9: D.MINNS@LCOS.CA
C10: ='MOQ Grand Total'!C10 -> 0 | E10: SHIPPING ADDRESS:
C11: ='MOQ Grand Total'!C11 -> 0
C12: ='MOQ Grand Total'!C12 -> 0
F13: CAD $
B14: PART NUMBER | C14: Make & Model | D14: DESCRIPTION | E14: QTY | F14: OEM MSRP | H14: GQP PRICE | I14: TOTAL
B15: 0S-1585 | C15: =VLOOKUP(B15,'[1]Product by Part Number'!$A:$K,2,0) -> CAT D3 (1PJ) | D15: =VLOOKUP(B15,'[1]Product by Part Number'!$A:$K,3,0) -> HEX HEAD BOLT SF | E15: =VLOOKUP(B15,'[1]Product by Part Number'!$A:$K,11,0) -> 16 | F15: =VLOOKUP(B15,'[1]Product by Part Number'!$A:$K,4,0) -> 2.78 | G15: =E15*F15 -> 44.48 | H15: =VLOOKUP(B15,'[1]Product by Part Number'!$A:$K,5,0) -> 1.39 | I15: =ROUND(E15*H15,2) -> 22.24
B16: 0S-1594 | C16: =VLOOKUP(B16,'[1]Product by Part Number'!$A:$K,2,0) -> CAT D7G (92V) CAT D7G (3ZD) CAT D7G (3ZD) (2) | D16: =VLOOKUP(B16,'[1]Product by Part Number'!$A:$K,3,0) -> CARRIER BOLT | E16: =VLOOKUP(B16,'[1]Product by Part Number'!$A:$K,11,0) -> 18 | F16: =VLOOKUP(B16,'[1]Product by Part Number'!$A:$K,4,0) -> 1.16 | G16: =E16*F16 -> 20.88 | H16: =VLOOKUP(B16,'[1]Product by Part Number'!$A:$K,5,0) -> 0.58 | I16: =ROUND(E16*H16,2) -> 10.44
B17: 0S-1601 | C17: =VLOOKUP(B17,'[1]Product by Part Number'!$A:$K,2,0) -> CAT 561 (85H) CAT 561 (92J) CAT 561 (92J) (2) | D17: =VLOOKUP(B17,'[1]Product by Part Number'!$A:$K,3,0) -> BOLT ROLLER | E17: =VLOOKUP(B17,'[1]Product by Part Number'!$A:$K,11,0) -> 144 | F17: =VLOOKUP(B17,'[1]Product by Part Number'!$A:$K,4,0) -> 8.05 | G17: =E17*F17 -> 1159.2 | H17: =VLOOKUP(B17,'[1]Product by Part Number'!$A:$K,5,0) -> 4.03 | I17: =ROUND(E17*H17,2) -> 580.32
B18: 106-1642 | C18: =VLOOKUP(B18,'[1]Product by Part Number'!$A:$K,2,0) -> CAT D4 (66J) CAT D6N LGP (GHS) CAT D6N LGP (SGG) CAT D6N LGP (SGG) (2) CAT PL61 (WGS) CAT PL61 (WGS) (2) CAT PL61 (WGS) (3) | D18: =VLOOKUP(B18,'[1]Product by Part Number'!$A:$K,3,0) -> TRACK BOLT MASTER | E18: =VLOOKUP(B18,'[1]Product by Part Number'!$A:$K,11,0) -> 28 | F18: =VLOOKUP(B18,'[1]Product by Part Number'!$A:$K,4,0) -> 6.66 | G18: =E18*F18 -> 186.48 | H18: =VLOOKUP(B18,'[1]Product by Part Number'!$A:$K,5,0) -> 3.33 | I18: =ROUND(E18*H18,2) -> 93.24
B19: 107-0719 | C19: =VLOOKUP(B19,'[1]Product by Part Number'!$A:$K,2,0) -> CAT D4 (66J) CAT D6N LGP (GHS) CAT D6N LGP (SGG) CAT D6N LGP (SGG) (2) CAT PL61 (WGS) CAT PL61 (WGS) (2) CAT PL61 (WGS) (3) | D19: =VLOOKUP(B19,'[1]Product by Part Number'!$A:$K,3,0) -> TRACK BOLT MASTER | E19: =VLOOKUP(B19,'[1]Product by Part Number'!$A:$K,11,0) -> 28 | F19: =VLOOKUP(B19,'[1]Product by Part Number'!$A:$K,4,0) -> 9.23 | G19: =E19*F19 -> 258.44 | H19: =VLOOKUP(B19,'[1]Product by Part Number'!$A:$K,5,0) -> 4.62 | I19: =ROUND(E19*H19,2) -> 129.36
B20: 108-0946 | C20: =VLOOKUP(B20,'[1]Product by Part Number'!$A:$K,2,0) -> CAT D5 (3CR) CAT D5 (3CR) (2) CAT 561M (1KW) CAT 561N (CPH) CAT 561N (CPH) (2) CAT 561N (CPH) (3) CAT 561N (CPH) (4) CAT 561N (CPH) (5) | D20: =VLOOKUP(B20,'[1]Product by Part Number'!$A:$K,3,0) -> SPROCKET SEGMENT | E20: =VLOOKUP(B20,'[1]Product by Part Number'!$A:$K,11,0) -> 80 | F20: =VLOOKUP(B20,'[1]Product by Part Number'!$A:$K,4,0) -> 177.98 | G20: =E20*F20 -> 14238.4 | H20: =VLOOKUP(B20,'[1]Product by Part Number'!$A:$K,5,0) -> 88.99 | I20: =ROUND(E20*H20,2) -> 7119.2
B21: 108-0954 | C21: =VLOOKUP(B21,'[1]Product by Part Number'!$A:$K,2,0) -> CAT D5 (3CR) CAT D5 (3CR) (2) CAT 561M (1KW) CAT 561N (CPH) CAT 561N (CPH) (2) CAT 561N (CPH) (3) CAT 561N (CPH) (4) CAT 561N (CPH) (5) | D21: =VLOOKUP(B21,'[1]Product by Part Number'!$A:$K,3,0) -> TRACK LINK ASSEMBLY | E21: =VLOOKUP(B21,'[1]Product by Part Number'!$A:$K,11,0) -> 16 | F21: =VLOOKUP(B21,'[1]Product by Part Number'!$A:$K,4,0) -> 11935.92 | G21: =E21*F21 -> 190974.72 | H21: =VLOOKUP(B21,'[1]Product by Part Number'!$A:$K,5,0) -> 5967.96 | I21: =ROUND(E21*H21,2) -> 95487.36
B22: 108-1136 | C22: =VLOOKUP(B22,'[1]Product by Part Number'!$A:$K,2,0) -> CAT 561M (1KW) | D22: =VLOOKUP(B22,'[1]Product by Part Number'!$A:$K,3,0) -> BLOCK IDLER | E22: =VLOOKUP(B22,'[1]Product by Part Number'!$A:$K,11,0) -> 8 | F22: =VLOOKUP(B22,'[1]Product by Part Number'!$A:$K,4,0) -> 229.89 | G22: =E22*F22 -> 1839.12 | H22: =VLOOKUP(B22,'[1]Product by Part Number'!$A:$K,5,0) -> 114.95 | I22: =ROUND(E22*H22,2) -> 919.6
B23: 108-1138 | C23: =VLOOKUP(B23,'[1]Product by Part Number'!$A:$K,2,0) -> CAT 561M (1KW) | D23: =VLOOKUP(B23,'[1]Product by Part Number'!$A:$K,3,0) -> CAP IDLER | E23: =VLOOKUP(B23,'[1]Product by Part Number'!$A:$K,11,0) -> 8 | F23: =VLOOKUP(B23,'[1]Product by Part Number'!$A:$K,4,0) -> 166.52 | G23: =E23*F23 -> 1332.16 | H23: =VLOOKUP(B23,'[1]Product by Part Number'!$A:$K,5,0) -> 83.26 | I23: =ROUND(E23*H23,2) -> 666.08
B24: 110-2976 | C24: =VLOOKUP(B24,'[1]Product by Part Number'!$A:$K,2,0) -> CAT PL61 (WGS) CAT PL61 (WGS) (2) CAT PL61 (WGS) (3) | D24: =VLOOKUP(B24,'[1]Product by Part Number'!$A:$K,3,0) -> TRACK LINK 39 JOINT | E24: =VLOOKUP(B24,'[1]Product by Part Number'!$A:$K,11,0) -> 6 | F24: =VLOOKUP(B24,'[1]Product by Part Number'!$A:$K,4,0) -> 8654.55 | G24: =E24*F24 -> 51927.3 | H24: =VLOOKUP(B24,'[1]Product by Part Number'!$A:$K,5,0) -> 4327.28 | I24: =ROUND(E24*H24,2) -> 25963.68
B25: 114-6099 | C25: =VLOOKUP(B25,'[1]Product by Part Number'!$A:$K,2,0) -> CAT 329E L (ZCD) | D25: =VLOOKUP(B25,'[1]Product by Part Number'!$A:$K,3,0) -> CARRIER BOLT | E25: =VLOOKUP(B25,'[1]Product by Part Number'!$A:$K,11,0) -> 4 | F25: =VLOOKUP(B25,'[1]Product by Part Number'!$A:$K,4,0) -> 31.9 | G25: =E25*F25 -> 127.6 | H25: =VLOOKUP(B25,'[1]Product by Part Number'!$A:$K,5,0) -> 15.95 | I25: =ROUND(E25*H25,2) -> 63.8
B26: 115-3696 | C26: =VLOOKUP(B26,'[1]Product by Part Number'!$A:$K,2,0) -> CAT 329E L (ZCD) CAT 329F L (ERL) CAT 329F L (ERL) (2) CAT 330F L (MBX) CAT 330F L (HCK) CAT 330F L (HCK) (2) CAT 330 (LHW) CAT 330 (LHW) (2) CAT 330 (LHW) (3) CAT 330 (LHW) (4) CAT 330 (WCH) CAT 330 (WCH) (2) CAT 330 (WCH) (3) CAT 330 (WCH) (4) CAT 330 (WCH) (5) CAT 330 (WCH) (6) | D26: =VLOOKUP(B26,'[1]Product by Part Number'!$A:$K,3,0) -> FRONT IDLER | E26: =VLOOKUP(B26,'[1]Product by Part Number'!$A:$K,11,0) -> 32 | F26: =VLOOKUP(B26,'[1]Product by Part Number'!$A:$K,4,0) -> 3159.07 | G26: =E26*F26 -> 101090.24 | H26: =VLOOKUP(B26,'[1]Product by Part Number'!$A:$K,5,0) -> 1579.54 | I26: =ROUND(E26*H26,2) -> 50545.28
... B205: CUSTOM-GQPPL6130"TG | C205: =VLOOKUP(B205,'[1]Product by Part Number'!$A:$K,2,0) -> CAT PL61 (WGS) CAT PL61 (WGS) (2) CAT PL61 (WGS) (3) | D205: =VLOOKUP(B205,'[1]Product by Part Number'!$A:$K,3,0) -> 30" GQP TRACK GROUP | E205: =VLOOKUP(B205,'[1]Product by Part Number'!$A:$K,11,0) -> 6 | F205: =VLOOKUP(B205,'[1]Product by Part Number'!$A:$K,4,0) -> 8945.71 | G205: =E205*F205 -> 53674.26 | H205: =VLOOKUP(B205,'[1]Product by Part Number'!$A:$K,5,0) -> 4472.86 | I205: =ROUND(E205*H205,2) -> 26837.16
H206: Subtotal | I206: =SUM(I15:I205) -> 2029492
D207: OEM MSRP : | E207: =SUM(G15:G205) -> 4058774 | H207: Shipping | I207: 0
D208: GQP : | E208: =SUM(I15:I205) -> 2029492 | H208: Customs/Broker Fee | I208: 0
D209: GQP SAVINGS : | E209: =E207-E208 -> 2029282 | H209: Total | I209: =SUM(I206:I208) -> 2029492
H210: GST | I210: =I209*0.05 -> 101474.6
H211: PST / QST
B212: Quote valid for 14 days, shipping subject to delays in supply chain. | H212: GRAND TOTAL | I212: =SUM(I209:I211) -> 2130966.6

Sheet MOQ Grand Total
E1: MOQ QUOTE | H1: Grand Total
B7: COMPANY: | C7: LINCOLN COUNTY OILFIELD SERVICES | E7: DATE: | F7: 45748 | H7: PO NUMBER:
B8: CONTACT NAME: | C8: DUSTIN MINNS | E8: PHONE NUMBER: | H8: 780-609-0758
B9: BILLING ADDRESS: | C9: 0 | E9: EMAIL ADDRESS: | H9: D.MINNS@LCOS.CA
C10: 0 | E10: SHIPPING ADDRESS:
C11: 0
C12: 0
F13: CAD $
B14: PART NUMBER | C14: Make & Model | D14: DESCRIPTION | E14: QTY | F14: OEM MSRP | H14: GQP PRICE | I14: TOTAL
B15: 093-7521 | C15: =VLOOKUP(B15,'[1]Product by Part Number'!$A:$K,2,0) -> CAT 320F L (YBM) CAT 336F L (RKB) | D15: =VLOOKUP(B15,'[1]Product by Part Number'!$A:$K,3,0) -> HYDRAULIC OIL FILTER | E15: =VLOOKUP(B15,'[1]Product by Part Number'!$A:$K,11,0) -> 10 | F15: =VLOOKUP(B15,'[1]Product by Part Number'!$A:$K,4,0) -> 102.09 | G15: =E15*F15 -> 1020.9 | H15: =VLOOKUP(B15,'[1]Product by Part Number'!$A:$K,5,0) -> 38.79 | I15: =ROUND(E15*H15,2) -> 387.9
B16: 0S-1585 | C16: =VLOOKUP(B16,'[1]Product by Part Number'!$A:$K,2,0) -> CAT D3 (1PJ) | D16: =VLOOKUP(B16,'[1]Product by Part Number'!$A:$K,3,0) -> HEX HEAD BOLT SF | E16: =VLOOKUP(B16,'[1]Product by Part Number'!$A:$K,11,0) -> 16 | F16: =VLOOKUP(B16,'[1]Product by Part Number'!$A:$K,4,0) -> 2.78 | G16: =E16*F16 -> 44.48 | H16: =VLOOKUP(B16,'[1]Product by Part Number'!$A:$K,5,0) -> 1.39 | I16: =ROUND(E16*H16,2) -> 22.24
B17: 0S-1594 | C17: =VLOOKUP(B17,'[1]Product by Part Number'!$A:$K,2,0) -> CAT D7G (92V) CAT D7G (3ZD) CAT D7G (3ZD) (2) | D17: =VLOOKUP(B17,'[1]Product by Part Number'!$A:$K,3,0) -> CARRIER BOLT | E17: =VLOOKUP(B17,'[1]Product by Part Number'!$A:$K,11,0) -> 18 | F17: =VLOOKUP(B17,'[1]Product by Part Number'!$A:$K,4,0) -> 1.16 | G17: =E17*F17 -> 20.88 | H17: =VLOOKUP(B17,'[1]Product by Part Number'!$A:$K,5,0) -> 0.58 | I17: =ROUND(E17*H17,2) -> 10.44
B18: 0S-1601 | C18: =VLOOKUP(B18,'[1]Product by Part Number'!$A:$K,2,0) -> CAT 561 (85H) CAT 561 (92J) CAT 561 (92J) (2) | D18: =VLOOKUP(B18,'[1]Product by Part Number'!$A:$K,3,0) -> BOLT ROLLER | E18: =VLOOKUP(B18,'[1]Product by Part Number'!$A:$K,11,0) -> 144 | F18: =VLOOKUP(B18,'[1]Product by Part Number'!$A:$K,4,0) -> 8.05 | G18: =E18*F18 -> 1159.2 | H18: =VLOOKUP(B18,'[1]Product by Part Number'!$A:$K,5,0) -> 4.03 | I18: =ROUND(E18*H18,2) -> 580.32
B19: 104-5857 | C19: =VLOOKUP(B19,'[1]Product by Part Number'!$A:$K,2,0) -> CAT D5 (3CR) CAT D5 (3CR) (2) CAT 561M (1KW) | D19: =VLOOKUP(B19,'[1]Product by Part Number'!$A:$K,3,0) -> TURBOCHARGER ASSEMBLY | E19: =VLOOKUP(B19,'[1]Product by Part Number'!$A:$K,11,0) -> 3 | F19: =VLOOKUP(B19,'[1]Product by Part Number'!$A:$K,4,0) -> 4677.47 | G19: =E19*F19 -> 14032.41 | H19: =VLOOKUP(B19,'[1]Product by Part Number'!$A:$K,5,0) -> 2338.74 | I19: =ROUND(E19*H19,2) -> 7016.22
B20: 106-1642 | C20: =VLOOKUP(B20,'[1]Product by Part Number'!$A:$K,2,0) -> CAT D4 (66J) CAT D6N LGP (GHS) CAT D6N LGP (SGG) CAT D6N LGP (SGG) (2) CAT PL61 (WGS) CAT PL61 (WGS) (2) CAT PL61 (WGS) (3) | D20: =VLOOKUP(B20,'[1]Product by Part Number'!$A:$K,3,0) -> TRACK BOLT MASTER | E20: =VLOOKUP(B20,'[1]Product by Part Number'!$A:$K,11,0) -> 28 | F20: =VLOOKUP(B20,'[1]Product by Part Number'!$A:$K,4,0) -> 6.66 | G20: =E20*F20 -> 186.48 | H20: =VLOOKUP(B20,'[1]Product by Part Number'!$A:$K,5,0) -> 3.33 | I20: =ROUND(E20*H20,2) -> 93.24
B21: 107-0719 | C21: =VLOOKUP(B21,'[1]Product by Part Number'!$A:$K,2,0) -> CAT D4 (66J) CAT D6N LGP (GHS) CAT D6N LGP (SGG) CAT D6N LGP (SGG) (2) CAT PL61 (WGS) CAT PL61 (WGS) (2) CAT PL61 (WGS) (3) | D21: =VLOOKUP(B21,'[1]Product by Part Number'!$A:$K,3,0) -> TRACK BOLT MASTER | E21: =VLOOKUP(B21,'[1]Product by Part Number'!$A:$K,11,0) -> 28 | F21: =VLOOKUP(B21,'[1]Product by Part Number'!$A:$K,4,0) -> 9.23 | G21: =E21*F21 -> 258.44 | H21: =VLOOKUP(B21,'[1]Product by Part Number'!$A:$K,5,0) -> 4.62 | I21: =ROUND(E21*H21,2) -> 129.36
B22: 108-0946 | C22: =VLOOKUP(B22,'[1]Product by Part Number'!$A:$K,2,0) -> CAT D5 (3CR) CAT D5 (3CR) (2) CAT 561M (1KW) CAT 561N (CPH) CAT 561N (CPH) (2) CAT 561N (CPH) (3) CAT 561N (CPH) (4) CAT 561N (CPH) (5) | D22: =VLOOKUP(B22,'[1]Product by Part Number'!$A:$K,3,0) -> SPROCKET SEGMENT | E22: =VLOOKUP(B22,'[1]Product by Part Number'!$A:$K,11,0) -> 80 | F22: =VLOOKUP(B22,'[1]Product by Part Number'!$A:$K,4,0) -> 177.98 | G22: =E22*F22 -> 14238.4 | H22: =VLOOKUP(B22,'[1]Product by Part Number'!$A:$K,5,0) -> 88.99 | I22: =ROUND(E22*H22,2) -> 7119.2
B23: 108-0954 | C23: =VLOOKUP(B23,'[1]Product by Part Number'!$A:$K,2,0) -> CAT D5 (3CR) CAT D5 (3CR) (2) CAT 561M (1KW) CAT 561N (CPH) CAT 561N (CPH) (2) CAT 561N (CPH) (3) CAT 561N (CPH) (4) CAT 561N (CPH) (5) | D23: =VLOOKUP(B23,'[1]Product by Part Number'!$A:$K,3,0) -> TRACK LINK ASSEMBLY | E23: =VLOOKUP(B23,'[1]Product by Part Number'!$A:$K,11,0) -> 16 | F23: =VLOOKUP(B23,'[1]Product by Part Number'!$A:$K,4,0) -> 11935.92 | G23: =E23*F23 -> 190974.72 | H23: =VLOOKUP(B23,'[1]Product by Part Number'!$A:$K,5,0) -> 5967.96 | I23: =ROUND(E23*H23,2) -> 95487.36
B24: 108-1136 | C24: =VLOOKUP(B24,'[1]Product by Part Number'!$A:$K,2,0) -> CAT 561M (1KW) | D24: =VLOOKUP(B24,'[1]Product by Part Number'!$A:$K,3,0) -> BLOCK IDLER | E24: =VLOOKUP(B24,'[1]Product by Part Number'!$A:$K,11,0) -> 8 | F24: =VLOOKUP(B24,'[1]Product by Part Number'!$A:$K,4,0) -> 229.89 | G24: =E24*F24 -> 1839.12 | H24: =VLOOKUP(B24,'[1]Product by Part Number'!$A:$K,5,0) -> 114.95 | I24: =ROUND(E24*H24,2) -> 919.6
B25: 108-1138 | C25: =VLOOKUP(B25,'[1]Product by Part Number'!$A:$K,2,0) -> CAT 561M (1KW) | D25: =VLOOKUP(B25,'[1]Product by Part Number'!$A:$K,3,0) -> CAP IDLER | E25: =VLOOKUP(B25,'[1]Product by Part Number'!$A:$K,11,0) -> 8 | F25: =VLOOKUP(B25,'[1]Product by Part Number'!$A:$K,4,0) -> 166.52 | G25: =E25*F25 -> 1332.16 | H25: =VLOOKUP(B25,'[1]Product by Part Number'!$A:$K,5,0) -> 83.26 | I25: =ROUND(E25*H25,2) -> 666.08
B26: 110-2976 | C26: =VLOOKUP(B26,'[1]Product by Part Number'!$A:$K,2,0) -> CAT PL61 (WGS) CAT PL61 (WGS) (2) CAT PL61 (WGS) (3) | D26: =VLOOKUP(B26,'[1]Product by Part Number'!$A:$K,3,0) -> TRACK LINK 39 JOINT | E26: =VLOOKUP(B26,'[1]Product by Part Number'!$A:$K,11,0) -> 6 | F26: =VLOOKUP(B26,'[1]Product by Part Number'!$A:$K,4,0) -> 8654.55 | G26: =E26*F26 -> 51927.3 | H26: =VLOOKUP(B26,'[1]Product by Part Number'!$A:$K,5,0) -> 4327.28 | I26: =ROUND(E26*H26,2) -> 25963.68
... B408: CUSTOM-GQPPL6130"TG | C408: =VLOOKUP(B408,'[1]Product by Part Number'!$A:$K,2,0) -> CAT PL61 (WGS) CAT PL61 (WGS) (2) CAT PL61 (WGS) (3) | D408: =VLOOKUP(B408,'[1]Product by Part Number'!$A:$K,3,0) -> 30" GQP TRACK GROUP | E408: =VLOOKUP(B408,'[1]Product by Part Number'!$A:$K,11,0) -> 6 | F408: =VLOOKUP(B408,'[1]Product by Part Number'!$A:$K,4,0) -> 8945.71 | G408: =E408*F408 -> 53674.26 | H408: =VLOOKUP(B408,'[1]Product by Part Number'!$A:$K,5,0) -> 4472.86 | I408: =ROUND(E408*H408,2) -> 26837.16
H409: Subtotal | I409: =SUM(I15:I408) -> 3035670.6
D410: OEM MSRP : | E410: =SUM(G15:G408) -> 6212899.1 | H410: Shipping | I410: 0
D411: GQP : | E411: =SUM(I15:I408) -> 3035670.6 | H411: Customs/Broker Fee | I411: 0
D412: GQP SAVINGS : | E412: =E410-E411 -> 3177228.5 | H412: Total | I412: =SUM(I409:I411) -> 3035670.6
H413: GST | I413: =I412*0.05 -> 151783.53
H414: PST / QST
B415: Quote valid for 14 days, shipping subject to delays in supply chain. | H415: GRAND TOTAL | I415: =SUM(I412:I414) -> 3187454.1
