Workbook

Sheet MOQ Batteries
E1: MOQ QUOTE | H1: Batteries
B7: COMPANY: | C7: GRAHAM | E7: DATE: | F7: 45870 | H7: PO NUMBER:
B8: CONTACT NAME: | C8: 0 | E8: PHONE NUMBER:
B9: BILLING ADDRESS: | C9: 0 | E9: EMAIL ADDRESS:
C10: 0 | E10: SHIPPING ADDRESS:
C11: 0
C12: 0
F13: CAD $
B14: PART NUMBER | C14: Make & Model | D14: DESCRIPTION | E14: QTY | F14: OEM MSRP | H14: GQP PRICE | I14: TOTAL
B15: 08000-D2213 | C15: =VLOOKUP($B15,'[1]Products by Part Number'!$A:$L,2,0) -> KOM WA320-8 (867) KOM WA320PZ-6 (729) | D15: =VLOOKUP($B15,'[1]Products by Part Number'!$A:$L,3,0) -> BATTERY | E15: =VLOOKUP($B15,'[1]Products by Part Number'!$A:$L,12,0) -> 4 | F15: =VLOOKUP($B15,'[1]Products by Part Number'!$A:$L,4,0) -> 600.03 | G15: =E15*F15 -> 2400.12 | H15: =VLOOKUP(B15,'[1]Products by Part Number'!$A:$L,6,0) -> 300.02 | I15: =ROUND(E15*H15,2) -> 1200.08
B16: 08003-3190H | C16: =VLOOKUP($B16,'[1]Products by Part Number'!$A:$L,2,0) -> KOM HM400-5 (1) KOM HM400-5 (2) KOM HM400-5 (3) KOM HM400-5 (4) KOM HM400-5 (5) KOM HM400-5 (6) KOM HM400-5 (7) KOM HM400-5 (8) KOM HM400-5 (9) KOM HM400-5 (10) KOM HM400 (11) KOM HM400 (12) KOM HM400 (13) KOM HM400-5 (14) | D16: =VLOOKUP($B16,'[1]Products by Part Number'!$A:$L,3,0) -> BATTERY | E16: =VLOOKUP($B16,'[1]Products by Part Number'!$A:$L,12,0) -> 28 | F16: =VLOOKUP($B16,'[1]Products by Part Number'!$A:$L,4,0) -> 583.87 | G16: =E16*F16 -> 16348.36 | H16: =VLOOKUP(B16,'[1]Products by Part Number'!$A:$L,6,0) -> 291.94 | I16: =ROUND(E16*H16,2) -> 8174.32
B17: 08003-C145F | C17: =VLOOKUP($B17,'[1]Products by Part Number'!$A:$L,2,0) -> KOM PC238USLC-11 (2) | D17: =VLOOKUP($B17,'[1]Products by Part Number'!$A:$L,3,0) -> BATTERY | E17: =VLOOKUP($B17,'[1]Products by Part Number'!$A:$L,12,0) -> 2 | F17: =VLOOKUP($B17,'[1]Products by Part Number'!$A:$L,4,0) -> 444.7 | G17: =E17*F17 -> 889.4 | H17: =VLOOKUP(B17,'[1]Products by Part Number'!$A:$L,6,0) -> 222.35 | I17: =ROUND(E17*H17,2) -> 444.7
B18: 08003-C165G | C18: =VLOOKUP($B18,'[1]Products by Part Number'!$A:$L,2,0) -> KOM WA380-8 (1) KOM WA380-8 (2) KOM WA475-10 (120) KOM PC290LC-11 (K73) | D18: =VLOOKUP($B18,'[1]Products by Part Number'!$A:$L,3,0) -> BATTERY | E18: =VLOOKUP($B18,'[1]Products by Part Number'!$A:$L,12,0) -> 8 | F18: =VLOOKUP($B18,'[1]Products by Part Number'!$A:$L,4,0) -> 483.17 | G18: =E18*F18 -> 3865.36 | H18: =VLOOKUP(B18,'[1]Products by Part Number'!$A:$L,6,0) -> 241.59 | I18: =ROUND(E18*H18,2) -> 1932.72
B19: 115-2422 | C19: =VLOOKUP($B19,'[1]Products by Part Number'!$A:$L,2,0) -> CAT 255 CAT 255 (2) CAT 255 (FL7) | D19: =VLOOKUP($B19,'[1]Products by Part Number'!$A:$L,3,0) -> BATTERY 12 V 1000 CCA | E19: =VLOOKUP($B19,'[1]Products by Part Number'!$A:$L,12,0) -> 3 | F19: =VLOOKUP($B19,'[1]Products by Part Number'!$A:$L,4,0) -> 505.03 | G19: =E19*F19 -> 1515.09 | H19: =VLOOKUP(B19,'[1]Products by Part Number'!$A:$L,6,0) -> 252.52 | I19: =ROUND(E19*H19,2) -> 757.56
B20: 134-06-61540 | C20: =VLOOKUP($B20,'[1]Products by Part Number'!$A:$L,2,0) -> KOM D61PX-24 (B60) | D20: =VLOOKUP($B20,'[1]Products by Part Number'!$A:$L,3,0) -> BATTERY | E20: =VLOOKUP($B20,'[1]Products by Part Number'!$A:$L,12,0) -> 2 | F20: =VLOOKUP($B20,'[1]Products by Part Number'!$A:$L,4,0) -> 631.66 | G20: =E20*F20 -> 1263.32 | H20: =VLOOKUP(B20,'[1]Products by Part Number'!$A:$L,6,0) -> 315.83 | I20: =ROUND(E20*H20,2) -> 631.66
B21: 153-5710 | C21: =VLOOKUP($B21,'[1]Products by Part Number'!$A:$L,2,0) -> CAT 14 (EN4) | D21: =VLOOKUP($B21,'[1]Products by Part Number'!$A:$L,3,0) -> BATTERY 12V 1400 CCA | E21: =VLOOKUP($B21,'[1]Products by Part Number'!$A:$L,12,0) -> 2 | F21: =VLOOKUP($B21,'[1]Products by Part Number'!$A:$L,4,0) -> 783.62 | G21: =E21*F21 -> 1567.24 | H21: =VLOOKUP(B21,'[1]Products by Part Number'!$A:$L,6,0) -> 391.81 | I21: =ROUND(E21*H21,2) -> 783.62
B22: 175-4390 | C22: =VLOOKUP($B22,'[1]Products by Part Number'!$A:$L,2,0) -> CAT TL1055C (KDE) | D22: =VLOOKUP($B22,'[1]Products by Part Number'!$A:$L,3,0) -> BATTERY 12V 1000CCA | E22: =VLOOKUP($B22,'[1]Products by Part Number'!$A:$L,12,0) -> 1 | F22: =VLOOKUP($B22,'[1]Products by Part Number'!$A:$L,4,0) -> 372.62 | G22: =E22*F22 -> 372.62 | H22: =VLOOKUP(B22,'[1]Products by Part Number'!$A:$L,6,0) -> 186.31 | I22: =ROUND(E22*H22,2) -> 186.31
B23: 22B-06-22311 | C23: =VLOOKUP($B23,'[1]Products by Part Number'!$A:$L,2,0) -> KOM PC138USLC-11 KOM PC238USLC-11 (1) | D23: =VLOOKUP($B23,'[1]Products by Part Number'!$A:$L,3,0) -> BATTERY | E23: =VLOOKUP($B23,'[1]Products by Part Number'!$A:$L,12,0) -> 4 | F23: =VLOOKUP($B23,'[1]Products by Part Number'!$A:$L,4,0) -> 532.45 | G23: =E23*F23 -> 2129.8 | H23: =VLOOKUP(B23,'[1]Products by Part Number'!$A:$L,6,0) -> 266.23 | I23: =ROUND(E23*H23,2) -> 1064.92
B24: 2A5-06-A1010 | C24: =VLOOKUP($B24,'[1]Products by Part Number'!$A:$L,2,0) -> KOM PC490LC-11 (A42) KOM PC490LC-11 (A42) (2) KOM PC490LC-11 (A42) (3) KOM PC490LC-11 (A42) (4) KOM PC490LC-11 (A42) (5) KOM PC490LC-11 (A43) KOM PC490LC-11 (KMT) (1) KOM PC490LC-11 (KMT) (2) KOM PC490LC-11 (KMT) (3) KOM PC360LC-11 (A37) KOM PC360LC-11 (A39) KOM PC360LC-11 (A39) (2) | D24: =VLOOKUP($B24,'[1]Products by Part Number'!$A:$L,3,0) -> BATTERY | E24: =VLOOKUP($B24,'[1]Products by Part Number'!$A:$L,12,0) -> 24 | F24: =VLOOKUP($B24,'[1]Products by Part Number'!$A:$L,4,0) -> 632.66 | G24: =E24*F24 -> 15183.84 | H24: =VLOOKUP(B24,'[1]Products by Part Number'!$A:$L,6,0) -> 316.33 | I24: =ROUND(E24*H24,2) -> 7591.92
B25: 9X-3404 | C25: =VLOOKUP($B25,'[1]Products by Part Number'!$A:$L,2,0) -> CAT 329EL (ZCD) | D25: =VLOOKUP($B25,'[1]Products by Part Number'!$A:$L,3,0) -> BATTERY 12V 900 CCA | E25: =VLOOKUP($B25,'[1]Products by Part Number'!$A:$L,12,0) -> 2 | F25: =VLOOKUP($B25,'[1]Products by Part Number'!$A:$L,4,0) -> 486.48 | G25: =E25*F25 -> 972.96 | H25: =VLOOKUP(B25,'[1]Products by Part Number'!$A:$L,6,0) -> 243.24 | I25: =ROUND(E25*H25,2) -> 486.48
B26: TY23020B | C26: =VLOOKUP($B26,'[1]Products by Part Number'!$A:$L,2,0) -> JD 470P (1FF) | D26: =VLOOKUP($B26,'[1]Products by Part Number'!$A:$L,3,0) -> BATTERY | E26: =VLOOKUP($B26,'[1]Products by Part Number'!$A:$L,12,0) -> 2 | F26: =VLOOKUP($B26,'[1]Products by Part Number'!$A:$L,4,0) -> 575.4186 | G26: =E26*F26 -> 1150.8372 | H26: =VLOOKUP(B26,'[1]Products by Part Number'!$A:$L,6,0) -> 287.71 | I26: =ROUND(E26*H26,2) -> 575.42
... B28: TY25879B | C28: =VLOOKUP($B28,'[1]Products by Part Number'!$A:$L,2,0) -> JD 624K (DW6) JD 764 (100) | D28: =VLOOKUP($B28,'[1]Products by Part Number'!$A:$L,3,0) -> BATTERY 12V 950CCA | E28: =VLOOKUP($B28,'[1]Products by Part Number'!$A:$L,12,0) -> 4 | F28: =VLOOKUP($B28,'[1]Products by Part Number'!$A:$L,4,0) -> 318.2004 | G28: =E28*F28 -> 1272.8016 | H28: =VLOOKUP(B28,'[1]Products by Part Number'!$A:$L,6,0) -> 159.1 | I28: =ROUND(E28*H28,2) -> 636.4
G29: =E29*F29 -> 0 | I29: =ROUND(E29*H29,2) -> 0
B30: TY25879B | I30: =ROUND(E30*H30,2) -> 0
I31: =ROUND(E31*H31,2) -> 0
I32: =ROUND(E32*H32,2) -> 0
I33: =ROUND(E33*H33,2) -> 0
I34: =ROUND(E34*H34,2) -> 0
I35: =ROUND(E35*H35,2) -> 0
I36: =ROUND(E36*H36,2) -> 0
I37: =ROUND(E37*H37,2) -> 0
I38: =ROUND(E38*H38,2) -> 0
I39: =ROUND(E39*H39,2) -> 0
I40: =ROUND(E40*H40,2) -> 0
I41: =ROUND(E41*H41,2) -> 0
I42: =ROUND(E42*H42,2) -> 0
... I67: =ROUND(E67*H67,2) -> 0
H68: Subtotal | I68: =SUM(I15:I67) -> 24625.21
D69: OEM MSRP : | E69: =SUM(G15:G67) -> 49249.949 | H69: Shipping | I69: 0
D70: GQP : | E70: =SUM(I15:I67) -> 24625.21 | H70: Customs/Broker Fee | I70: 0
...

Sheet MOQ Engine
E1: MOQ QUOTE | H1: Engine
B7: COMPANY: | C7: GRAHAM | E7: DATE: | F7: 45870 | H7: PO NUMBER:
B8: CONTACT NAME: | C8: 0 | E8: PHONE NUMBER:
B9: BILLING ADDRESS: | C9: 0 | E9: EMAIL ADDRESS:
C10: 0 | E10: SHIPPING ADDRESS:
C11: 0
C12: 0
F13: CAD $
B14: PART NUMBER | C14: Make & Model | D14: DESCRIPTION | E14: QTY | F14: OEM MSRP | H14: GQP PRICE | I14: TOTAL
B15: 336-7516 | C15: =VLOOKUP($B15,'[1]Products by Part Number'!$A:$L,2,0) -> CAT 329EL (ZCD) | D15: =VLOOKUP($B15,'[1]Products by Part Number'!$A:$L,3,0) -> CAMSHAFT | E15: =VLOOKUP($B15,'[1]Products by Part Number'!$A:$L,12,0) -> 1 | F15: =VLOOKUP($B15,'[1]Products by Part Number'!$A:$L,4,0) -> 1834.21 | G15: =E15*F15 -> 1834.21 | H15: =VLOOKUP($B15,'[1]Products by Part Number'!$A:$L,6,0) -> 917.11 | I15: =E15*H15 -> 917.11
B16: 361-5594 | C16: =VLOOKUP($B16,'[1]Products by Part Number'!$A:$L,2,0) -> CAT 14 (EN4) | D16: =VLOOKUP($B16,'[1]Products by Part Number'!$A:$L,3,0) -> CRANKSHAFT | E16: =VLOOKUP($B16,'[1]Products by Part Number'!$A:$L,12,0) -> 1 | F16: =VLOOKUP($B16,'[1]Products by Part Number'!$A:$L,4,0) -> 18666.01 | G16: =E16*F16 -> 18666.01 | H16: =VLOOKUP($B16,'[1]Products by Part Number'!$A:$L,6,0) -> 9333.01 | I16: =E16*H16 -> 9333.01
B17: 363-3890 | C17: =VLOOKUP($B17,'[1]Products by Part Number'!$A:$L,2,0) -> CAT TL1055C (KDE) | D17: =VLOOKUP($B17,'[1]Products by Part Number'!$A:$L,3,0) -> CAMSHAFT | E17: =VLOOKUP($B17,'[1]Products by Part Number'!$A:$L,12,0) -> 1 | F17: =VLOOKUP($B17,'[1]Products by Part Number'!$A:$L,4,0) -> 1706.83 | G17: =E17*F17 -> 1706.83 | H17: =VLOOKUP($B17,'[1]Products by Part Number'!$A:$L,6,0) -> 853.42 | I17: =E17*H17 -> 853.42
B18: 375-2810 | C18: =VLOOKUP($B18,'[1]Products by Part Number'!$A:$L,2,0) -> CAT 14 (EN4) | D18: =VLOOKUP($B18,'[1]Products by Part Number'!$A:$L,3,0) -> CAMSHAFT | E18: =VLOOKUP($B18,'[1]Products by Part Number'!$A:$L,12,0) -> 1 | F18: =VLOOKUP($B18,'[1]Products by Part Number'!$A:$L,4,0) -> 6599.72 | G18: =E18*F18 -> 6599.72 | H18: =VLOOKUP($B18,'[1]Products by Part Number'!$A:$L,6,0) -> 3299.86 | I18: =E18*H18 -> 3299.86
B19: 376-4074 | C19: =VLOOKUP($B19,'[1]Products by Part Number'!$A:$L,2,0) -> CAT 329EL (ZCD) | D19: =VLOOKUP($B19,'[1]Products by Part Number'!$A:$L,3,0) -> CRANKSHAFT | E19: =VLOOKUP($B19,'[1]Products by Part Number'!$A:$L,12,0) -> 1 | F19: =VLOOKUP($B19,'[1]Products by Part Number'!$A:$L,4,0) -> 11151.43 | G19: =E19*F19 -> 11151.43 | H19: =VLOOKUP($B19,'[1]Products by Part Number'!$A:$L,6,0) -> 5575.72 | I19: =E19*H19 -> 5575.72
B20: 466-4921 | C20: =VLOOKUP($B20,'[1]Products by Part Number'!$A:$L,2,0) -> CAT TL1055C (KDE) | D20: =VLOOKUP($B20,'[1]Products by Part Number'!$A:$L,3,0) -> CRANKSHAFT | E20: =VLOOKUP($B20,'[1]Products by Part Number'!$A:$L,12,0) -> 1 | F20: =VLOOKUP($B20,'[1]Products by Part Number'!$A:$L,4,0) -> 4302.96 | G20: =E20*F20 -> 4302.96 | H20: =VLOOKUP($B20,'[1]Products by Part Number'!$A:$L,6,0) -> 2151.48 | I20: =E20*H20 -> 2151.48
B21: 546-1917 | C21: =VLOOKUP($B21,'[1]Products by Part Number'!$A:$L,2,0) -> CAT 255 CAT 255 (2) CAT 255 (FL7) | D21: =VLOOKUP($B21,'[1]Products by Part Number'!$A:$L,3,0) -> CAMSHAFT | E21: =VLOOKUP($B21,'[1]Products by Part Number'!$A:$L,12,0) -> 3 | F21: =VLOOKUP($B21,'[1]Products by Part Number'!$A:$L,4,0) -> 1708.74 | G21: =E21*F21 -> 5126.22 | H21: =VLOOKUP($B21,'[1]Products by Part Number'!$A:$L,6,0) -> 854.37 | I21: =E21*H21 -> 2563.11
B22: 6252-31-1010 | C22: =VLOOKUP($B22,'[1]Products by Part Number'!$A:$L,2,0) -> KOM PC490LC-11 (A42) KOM PC490LC-11 (A42) (2) KOM PC490LC-11 (A42) (3) KOM PC490LC-11 (A42) (4) KOM PC490LC-11 (A42) (5) KOM PC490LC-11 (A43) KOM PC490LC-11 (KMT) (1) KOM PC490LC-11 (KMT) (2) KOM PC490LC-11 (KMT) (3) KOM WA475-10 (120) | D22: =VLOOKUP($B22,'[1]Products by Part Number'!$A:$L,3,0) -> CRANKSHAFT | E22: =VLOOKUP($B22,'[1]Products by Part Number'!$A:$L,12,0) -> 10 | F22: =VLOOKUP($B22,'[1]Products by Part Number'!$A:$L,4,0) -> 11348.37 | G22: =E22*F22 -> 113483.7 | H22: =VLOOKUP($B22,'[1]Products by Part Number'!$A:$L,6,0) -> 5674.19 | I22: =E22*H22 -> 56741.9
B23: 6252-41-1010 | C23: =VLOOKUP($B23,'[1]Products by Part Number'!$A:$L,2,0) -> KOM PC490LC-11 (A42) KOM PC490LC-11 (A42) (2) KOM PC490LC-11 (A42) (3) KOM PC490LC-11 (A42) (4) KOM PC490LC-11 (A42) (5) KOM PC490LC-11 (A43) KOM PC490LC-11 (KMT) (1) KOM PC490LC-11 (KMT) (2) KOM PC490LC-11 (KMT) (3) KOM WA475-10 (120) | D23: =VLOOKUP($B23,'[1]Products by Part Number'!$A:$L,3,0) -> CAMSHAFT | E23: =VLOOKUP($B23,'[1]Products by Part Number'!$A:$L,12,0) -> 10 | F23: =VLOOKUP($B23,'[1]Products by Part Number'!$A:$L,4,0) -> 3603.77 | G23: =E23*F23 -> 36037.7 | H23: =VLOOKUP($B23,'[1]Products by Part Number'!$A:$L,6,0) -> 1801.89 | I23: =E23*H23 -> 18018.9
B24: 6261-31-1200 | C24: =VLOOKUP($B24,'[1]Products by Part Number'!$A:$L,2,0) -> KOM HM400-5 (1) KOM HM400-5 (2) KOM HM400-5 (3) KOM HM400-5 (4) KOM HM400-5 (5) KOM HM400-5 (6) KOM HM400-5 (7) KOM HM400-5 (8) KOM HM400-5 (9) KOM HM400-5 (10) KOM HM400 (11) KOM HM400 (12) KOM HM400 (13) KOM HM400-5 (14) | D24: =VLOOKUP($B24,'[1]Products by Part Number'!$A:$L,3,0) -> CRANKSHAFT | E24: =VLOOKUP($B24,'[1]Products by Part Number'!$A:$L,12,0) -> 14 | F24: =VLOOKUP($B24,'[1]Products by Part Number'!$A:$L,4,0) -> 16696.43 | G24: =E24*F24 -> 233750.02 | H24: =VLOOKUP($B24,'[1]Products by Part Number'!$A:$L,6,0) -> 8348.22 | I24: =E24*H24 -> 116875.08
B25: 6263-41-1010 | C25: =VLOOKUP($B25,'[1]Products by Part Number'!$A:$L,2,0) -> KOM HM400-5 (1) KOM HM400-5 (2) KOM HM400-5 (3) KOM HM400-5 (4) KOM HM400-5 (5) KOM HM400-5 (6) KOM HM400-5 (7) KOM HM400-5 (8) KOM HM400-5 (9) KOM HM400-5 (10) KOM HM400 (11) KOM HM400 (12) KOM HM400 (13) KOM HM400-5 (14) | D25: =VLOOKUP($B25,'[1]Products by Part Number'!$A:$L,3,0) -> CAMSHAFT | E25: =VLOOKUP($B25,'[1]Products by Part Number'!$A:$L,12,0) -> 14 | F25: =VLOOKUP($B25,'[1]Products by Part Number'!$A:$L,4,0) -> 6442.61 | G25: =E25*F25 -> 90196.54 | H25: =VLOOKUP($B25,'[1]Products by Part Number'!$A:$L,6,0) -> 3221.31 | I25: =E25*H25 -> 45098.34
B26: 6271-31-1110 | C26: =VLOOKUP($B26,'[1]Products by Part Number'!$A:$L,2,0) -> KOM PC138USLC-11 KOM PC238USLC-11 (1) | D26: =VLOOKUP($B26,'[1]Products by Part Number'!$A:$L,3,0) -> CRANKSHAFT | E26: =VLOOKUP($B26,'[1]Products by Part Number'!$A:$L,12,0) -> 2 | F26: =VLOOKUP($B26,'[1]Products by Part Number'!$A:$L,4,0) -> 3547.2 | G26: =E26*F26 -> 7094.4 | H26: =VLOOKUP($B26,'[1]Products by Part Number'!$A:$L,6,0) -> 1773.6 | I26: =E26*H26 -> 3547.2
... B38: RE539339 | C38: =VLOOKUP($B38,'[1]Products by Part Number'!$A:$L,2,0) -> JD 470P (1FF) | D38: =VLOOKUP($B38,'[1]Products by Part Number'!$A:$L,3,0) -> CRANKSHAFT | E38: =VLOOKUP($B38,'[1]Products by Part Number'!$A:$L,12,0) -> 1 | F38: =VLOOKUP($B38,'[1]Products by Part Number'!$A:$L,4,0) -> 12521.734 | G38: =E38*F38 -> 12521.734 | H38: =VLOOKUP($B38,'[1]Products by Part Number'!$A:$L,6,0) -> 6260.87 | I38: =E38*H38 -> 6260.87
I39: =ROUND(E39*H39,2) -> 0
I40: =ROUND(E40*H40,2) -> 0
I41: =ROUND(E41*H41,2) -> 0
I42: =ROUND(E42*H42,2) -> 0
I43: =ROUND(E43*H43,2) -> 0
I44: =ROUND(E44*H44,2) -> 0
I45: =ROUND(E45*H45,2) -> 0
I46: =ROUND(E46*H46,2) -> 0
I47: =ROUND(E47*H47,2) -> 0
I48: =ROUND(E48*H48,2) -> 0
I49: =ROUND(E49*H49,2) -> 0
I50: =ROUND(E50*H50,2) -> 0
... I83: =ROUND(E83*H83,2) -> 0
H84: Subtotal | I84: =SUM(I15:I83) -> 319196.89
D85: OEM MSRP : | E85: =SUM(G15:G83) -> 638393.26 | H85: Shipping | I85: 0
D86: GQP : | E86: =SUM(I15:I83) -> 319196.89 | H86: Customs/Broker Fee | I86: 0
D87: GQP SAVINGS : | E87: =E85-E86 -> 319196.37 | H87: Total | I87: =SUM(I84:I86) -> 319196.89
H88: GST | I88: =I87*0.05 -> 15959.845
...

Sheet MOQ Filters Q1
E1: MOQ QUOTE | H1: Filters Q1
B7: COMPANY: | C7: GRAHAM | E7: DATE: | F7: 45870 | H7: PO NUMBER:
B8: CONTACT NAME: | C8: 0 | E8: PHONE NUMBER:
B9: BILLING ADDRESS: | C9: 0 | E9: EMAIL ADDRESS:
C10: 0 | E10: SHIPPING ADDRESS:
C11: 0
C12: 0
F13: CAD $
B14: PART NUMBER | C14: Make & Model | D14: DESCRIPTION | E14: QTY | F14: OEM MSRP | H14: GQP PRICE | I14: TOTAL
B15: 12Y-979-1174 | C15: =VLOOKUP($B15,'[1]Products by Part Number'!$A:$L,2,0) -> KOM D71PX-24 (1) KOM D71PX-24 (2) KOM D71PX-24 (3) KOM D71PX-24 (4) KOM D71PX-24 (5) KOM D71PX-24 (6) KOM D71PX-24 (7) KOM D61PX-24 (B60) | D15: =VLOOKUP($B15,'[1]Products by Part Number'!$A:$L,3,0) -> CAB AIR FILTER | E15: =VLOOKUP($B15,'[1]Products by Part Number'!$A:$L,8,0) -> 9 | F15: =VLOOKUP($B15,'[1]Products by Part Number'!$A:$L,4,0) -> 188.7426 | G15: =E15*F15 -> 1698.6834 | H15: =VLOOKUP($B15,'[1]Products by Part Number'!$A:$L,6,0) -> 122.68 | I15: =ROUND(E15*H15,2) -> 1104.12
B16: 12Y-979-6180 | C16: =VLOOKUP($B16,'[1]Products by Part Number'!$A:$L,2,0) -> KOM D71PX-24 (1) KOM D71PX-24 (2) KOM D71PX-24 (3) KOM D71PX-24 (4) KOM D71PX-24 (5) KOM D71PX-24 (6) KOM D71PX-24 (7) KOM D61PX-24 (B60) | D16: =VLOOKUP($B16,'[1]Products by Part Number'!$A:$L,3,0) -> CAB AIR FILTER | E16: =VLOOKUP($B16,'[1]Products by Part Number'!$A:$L,8,0) -> 9 | F16: =VLOOKUP($B16,'[1]Products by Part Number'!$A:$L,4,0) -> 164.082 | G16: =E16*F16 -> 1476.738 | H16: =VLOOKUP($B16,'[1]Products by Part Number'!$A:$L,6,0) -> 106.65 | I16: =ROUND(E16*H16,2) -> 959.85
B17: 149-1912 | C17: =VLOOKUP($B17,'[1]Products by Part Number'!$A:$L,2,0) -> CAT 14 (EN4) | D17: =VLOOKUP($B17,'[1]Products by Part Number'!$A:$L,3,0) -> CAB AIR FILTER | E17: =VLOOKUP($B17,'[1]Products by Part Number'!$A:$L,8,0) -> 2 | F17: =VLOOKUP($B17,'[1]Products by Part Number'!$A:$L,4,0) -> 93.03 | G17: =E17*F17 -> 186.06 | H17: =VLOOKUP($B17,'[1]Products by Part Number'!$A:$L,6,0) -> 60.47 | I17: =ROUND(E17*H17,2) -> 120.94
B18: 17M-911-3530 | C18: =VLOOKUP($B18,'[1]Products by Part Number'!$A:$L,2,0) -> KOM PC138USLC-11 KOM PC238USLC-11 (1) KOM PC490LC-11 (A42) KOM PC490LC-11 (A42) (2) KOM PC490LC-11 (A42) (3) KOM PC490LC-11 (A42) (4) KOM PC490LC-11 (A42) (5) KOM PC490LC-11 (A43) KOM PC490LC-11 (KMT) (1) KOM PC490LC-11 (KMT) (2) KOM PC490LC-11 (KMT) (3) KOM PC360LC-11 (A37) KOM PC360LC-11 (A39) KOM PC360LC-11 (A39) (2) KOM PC290LC-11 (K73) | D18: =VLOOKUP($B18,'[1]Products by Part Number'!$A:$L,3,0) -> CAB AIR FILTER | E18: =VLOOKUP($B18,'[1]Products by Part Number'!$A:$L,8,0) -> 30 | F18: =VLOOKUP($B18,'[1]Products by Part Number'!$A:$L,4,0) -> 67.87 | G18: =E18*F18 -> 2036.1 | H18: =VLOOKUP($B18,'[1]Products by Part Number'!$A:$L,6,0) -> 44.12 | I18: =ROUND(E18*H18,2) -> 1323.6
B19: 211-2660 | C19: =VLOOKUP($B19,'[1]Products by Part Number'!$A:$L,2,0) -> CAT 14 (EN4) | D19: =VLOOKUP($B19,'[1]Products by Part Number'!$A:$L,3,0) -> CAB AIR FILTER | E19: =VLOOKUP($B19,'[1]Products by Part Number'!$A:$L,8,0) -> 2 | F19: =VLOOKUP($B19,'[1]Products by Part Number'!$A:$L,4,0) -> 74.81 | G19: =E19*F19 -> 149.62 | H19: =VLOOKUP($B19,'[1]Products by Part Number'!$A:$L,6,0) -> 48.63 | I19: =ROUND(E19*H19,2) -> 97.26
B20: 222-9020 | C20: =VLOOKUP($B20,'[1]Products by Part Number'!$A:$L,2,0) -> CAT TL1055C (KDE) | D20: =VLOOKUP($B20,'[1]Products by Part Number'!$A:$L,3,0) -> PRIMARY AIR FILTER | E20: =VLOOKUP($B20,'[1]Products by Part Number'!$A:$L,8,0) -> 1 | F20: =VLOOKUP($B20,'[1]Products by Part Number'!$A:$L,4,0) -> 100.67 | G20: =E20*F20 -> 100.67 | H20: =VLOOKUP($B20,'[1]Products by Part Number'!$A:$L,6,0) -> 65.44 | I20: =ROUND(E20*H20,2) -> 65.44
B21: 222-9021 | C21: =VLOOKUP($B21,'[1]Products by Part Number'!$A:$L,2,0) -> CAT TL1055C (KDE) | D21: =VLOOKUP($B21,'[1]Products by Part Number'!$A:$L,3,0) -> SECONDARY AIR FILTER | E21: =VLOOKUP($B21,'[1]Products by Part Number'!$A:$L,8,0) -> 1 | F21: =VLOOKUP($B21,'[1]Products by Part Number'!$A:$L,4,0) -> 80.09 | G21: =E21*F21 -> 80.09 | H21: =VLOOKUP($B21,'[1]Products by Part Number'!$A:$L,6,0) -> 52.06 | I21: =ROUND(E21*H21,2) -> 52.06
B22: 2A5-979-1551 | C22: =VLOOKUP($B22,'[1]Products by Part Number'!$A:$L,2,0) -> KOM PC490LC-11 (A42) KOM PC490LC-11 (A42) (2) KOM PC490LC-11 (A42) (3) KOM PC490LC-11 (A42) (4) KOM PC490LC-11 (A42) (5) KOM PC490LC-11 (A43) KOM PC490LC-11 (KMT) (1) KOM PC490LC-11 (KMT) (2) KOM PC490LC-11 (KMT) (3) KOM PC360LC-11 (A37) KOM PC360LC-11 (A39) KOM PC360LC-11 (A39) (2) KOM PC290LC-11 (K73) | D22: =VLOOKUP($B22,'[1]Products by Part Number'!$A:$L,3,0) -> CAB AIR FILTER | E22: =VLOOKUP($B22,'[1]Products by Part Number'!$A:$L,8,0) -> 26 | F22: =VLOOKUP($B22,'[1]Products by Part Number'!$A:$L,4,0) -> 68.78 | G22: =E22*F22 -> 1788.28 | H22: =VLOOKUP($B22,'[1]Products by Part Number'!$A:$L,6,0) -> 44.71 | I22: =ROUND(E22*H22,2) -> 1162.46
B23: 327-6618 | C23: =VLOOKUP($B23,'[1]Products by Part Number'!$A:$L,2,0) -> CAT 329EL (ZCD) | D23: =VLOOKUP($B23,'[1]Products by Part Number'!$A:$L,3,0) -> CAB AIR FILTER | E23: =VLOOKUP($B23,'[1]Products by Part Number'!$A:$L,8,0) -> 2 | F23: =VLOOKUP($B23,'[1]Products by Part Number'!$A:$L,4,0) -> 82.09 | G23: =E23*F23 -> 164.18 | H23: =VLOOKUP($B23,'[1]Products by Part Number'!$A:$L,6,0) -> 53.36 | I23: =ROUND(E23*H23,2) -> 106.72
B24: 331-8108 | C24: =VLOOKUP($B24,'[1]Products by Part Number'!$A:$L,2,0) -> CAT 14 (EN4) | D24: =VLOOKUP($B24,'[1]Products by Part Number'!$A:$L,3,0) -> SECONDARY AIR FILTER | E24: =VLOOKUP($B24,'[1]Products by Part Number'!$A:$L,8,0) -> 1 | F24: =VLOOKUP($B24,'[1]Products by Part Number'!$A:$L,4,0) -> 105.26 | G24: =E24*F24 -> 105.26 | H24: =VLOOKUP($B24,'[1]Products by Part Number'!$A:$L,6,0) -> 68.42 | I24: =ROUND(E24*H24,2) -> 68.42
B25: 421-07-72450 | C25: =VLOOKUP($B25,'[1]Products by Part Number'!$A:$L,2,0) -> KOM WA475-10 (120) | D25: =VLOOKUP($B25,'[1]Products by Part Number'!$A:$L,3,0) -> CAB AIR FILTER | E25: =VLOOKUP($B25,'[1]Products by Part Number'!$A:$L,8,0) -> 1 | F25: =VLOOKUP($B25,'[1]Products by Part Number'!$A:$L,4,0) -> 134.67 | G25: =E25*F25 -> 134.67 | H25: =VLOOKUP($B25,'[1]Products by Part Number'!$A:$L,6,0) -> 87.54 | I25: =ROUND(E25*H25,2) -> 87.54
B26: 423-07-52411 | C26: =VLOOKUP($B26,'[1]Products by Part Number'!$A:$L,2,0) -> KOM WA380-8 (1) KOM WA380-8 (2) KOM WA320-8 (867) KOM WA320PZ-6 (729) | D26: =VLOOKUP($B26,'[1]Products by Part Number'!$A:$L,3,0) -> CAB AIR FILTER | E26: =VLOOKUP($B26,'[1]Products by Part Number'!$A:$L,8,0) -> 6 | F26: =VLOOKUP($B26,'[1]Products by Part Number'!$A:$L,4,0) -> 152.87 | G26: =E26*F26 -> 917.22 | H26: =VLOOKUP($B26,'[1]Products by Part Number'!$A:$L,6,0) -> 99.37 | I26: =ROUND(E26*H26,2) -> 596.22
... B60: TT220747 | C60: =VLOOKUP($B60,'[1]Products by Part Number'!$A:$L,2,0) -> JD 470P (1FF) | D60: =VLOOKUP($B60,'[1]Products by Part Number'!$A:$L,3,0) -> SECONDARY AIR FILTER | E60: =VLOOKUP($B60,'[1]Products by Part Number'!$A:$L,8,0) -> 1 | F60: =VLOOKUP($B60,'[1]Products by Part Number'!$A:$L,4,0) -> 122.9028 | G60: =E60*F60 -> 122.9028 | H60: =VLOOKUP($B60,'[1]Products by Part Number'!$A:$L,6,0) -> 79.89 | I60: =ROUND(E60*H60,2) -> 79.89
B61: 4630525 | C61: =VLOOKUP($B61,'[1]Products by Part Number'!$A:$L,2,0) -> JD 470P (1FF) | D61: =VLOOKUP($B61,'[1]Products by Part Number'!$A:$L,3,0) -> HYDRAULIC FILTER PILOT | E61: =VLOOKUP($B61,'[1]Products by Part Number'!$A:$L,8,0) -> 1 | F61: =VLOOKUP($B61,'[1]Products by Part Number'!$A:$L,4,0) -> 40.641 | G61: =E61*F61 -> 40.641 | H61: =VLOOKUP($B61,'[1]Products by Part Number'!$A:$L,6,0) -> 20.32 | I61: =ROUND(E61*H61,2) -> 20.32
B62: 207-970-5121 | C62: =VLOOKUP($B62,'[1]Products by Part Number'!$A:$L,2,0) -> KOM PC360LC-11 (A37) KOM PC360LC-11 (A39) KOM PC360LC-11 (A39) (2) | D62: =VLOOKUP($B62,'[1]Products by Part Number'!$A:$L,3,0) -> HYDRAULIC FILTER | E62: =VLOOKUP($B62,'[1]Products by Part Number'!$A:$L,8,0) -> 3 | F62: =VLOOKUP($B62,'[1]Products by Part Number'!$A:$L,4,0) -> 198.35 | G62: =E62*F62 -> 595.05 | H62: =VLOOKUP($B62,'[1]Products by Part Number'!$A:$L,6,0) -> 99.18 | I62: =ROUND(E62*H62,2) -> 297.54
B63: 093-7521 | C63: =VLOOKUP($B63,'[1]Products by Part Number'!$A:$L,2,0) -> CAT 329EL (ZCD) | D63: =VLOOKUP($B63,'[1]Products by Part Number'!$A:$L,3,0) -> HYDRAULIC FILTER CASE DRAIN | E63: =VLOOKUP($B63,'[1]Products by Part Number'!$A:$L,8,0) -> 1 | F63: =VLOOKUP($B63,'[1]Products by Part Number'!$A:$L,4,0) -> 98.57 | G63: =E63*F63 -> 98.57 | H63: =VLOOKUP($B63,'[1]Products by Part Number'!$A:$L,6,0) -> 49.29 | I63: =ROUND(E63*H63,2) -> 49.29
B64: 11Y-60-28712 | C64: =VLOOKUP($B64,'[1]Products by Part Number'!$A:$L,2,0) -> KOM D61PX-24 (B60) | D64: =VLOOKUP($B64,'[1]Products by Part Number'!$A:$L,3,0) -> HYDRAULIC FILTER | E64: =VLOOKUP($B64,'[1]Products by Part Number'!$A:$L,8,0) -> 1 | F64: =VLOOKUP($B64,'[1]Products by Part Number'!$A:$L,4,0) -> 370.6 | G64: =E64*F64 -> 370.6 | H64: =VLOOKUP($B64,'[1]Products by Part Number'!$A:$L,6,0) -> 185.3 | I64: =ROUND(E64*H64,2) -> 185.3
B65: 179-9806 | C65: =VLOOKUP($B65,'[1]Products by Part Number'!$A:$L,2,0) -> CAT 329EL (ZCD) | D65: =VLOOKUP($B65,'[1]Products by Part Number'!$A:$L,3,0) -> HYDRAULIC FILTER RETURN | E65: =VLOOKUP($B65,'[1]Products by Part Number'!$A:$L,8,0) -> 1 | F65: =VLOOKUP($B65,'[1]Products by Part Number'!$A:$L,4,0) -> 221.11 | G65: =E65*F65 -> 221.11 | H65: =VLOOKUP($B65,'[1]Products by Part Number'!$A:$L,6,0) -> 110.56 | I65: =ROUND(E65*H65,2) -> 110.56
B66: 207-60-71183 | C66: =VLOOKUP($B66,'[1]Products by Part Number'!$A:$L,2,0) -> KOM HM400-5 (1) KOM HM400-5 (2) KOM HM400-5 (3) KOM HM400-5 (4) KOM HM400-5 (5) KOM HM400-5 (6) KOM HM400-5 (7) KOM HM400-5 (8) KOM HM400-5 (9) KOM HM400-5 (10) KOM HM400 (11) KOM HM400 (12) KOM HM400 (13) KOM HM400-5 (14) KOM PC238USLC-11 (2) KOM PC360LC-11 (A37) KOM PC360LC-11 (A39) KOM PC360LC-11 (A39) (2) KOM WA475-10 (120) KOM PC290LC-11 (K73) | D66: =VLOOKUP($B66,'[1]Products by Part Number'!$A:$L,3,0) -> HYDRAULIC FILTER TANK | E66: =VLOOKUP($B66,'[1]Products by Part Number'!$A:$L,8,0) -> 20 | F66: =VLOOKUP($B66,'[1]Products by Part Number'!$A:$L,4,0) -> 188.98 | G66: =E66*F66 -> 3779.6 | H66: =VLOOKUP($B66,'[1]Products by Part Number'!$A:$L,6,0) -> 94.49 | I66: =ROUND(E66*H66,2) -> 1889.8
B67: 208-60-71124 | C67: =VLOOKUP($B67,'[1]Products by Part Number'!$A:$L,2,0) -> KOM HM400-5 (1) KOM HM400-5 (2) KOM HM400-5 (3) KOM HM400-5 (4) KOM HM400-5 (5) KOM HM400-5 (6) KOM HM400-5 (7) KOM HM400-5 (8) KOM HM400-5 (9) KOM HM400-5 (10) KOM HM400 (11) KOM HM400 (12) KOM HM400 (13) KOM HM400-5 (14) KOM PC490LC-11 (A42) KOM PC490LC-11 (A42) (2) KOM PC490LC-11 (A42) (3) KOM PC490LC-11 (A42) (4) KOM PC490LC-11 (A42) (5) KOM PC490LC-11 (A43) KOM PC490LC-11 (KMT) (1) KOM PC490LC-11 (KMT) (2) KOM PC490LC-11 (KMT) (3) | D67: =VLOOKUP($B67,'[1]Products by Part Number'!$A:$L,3,0) -> HYDRAULIC FILTER ACCUMULATOR | E67: =VLOOKUP($B67,'[1]Products by Part Number'!$A:$L,8,0) -> 23 | F67: =VLOOKUP($B67,'[1]Products by Part Number'!$A:$L,4,0) -> 259.43 | G67: =E67*F67 -> 5966.89 | H67: =VLOOKUP($B67,'[1]Products by Part Number'!$A:$L,6,0) -> 129.72 | I67: =ROUND(E67*H67,2) -> 2983.56
B68: 22P-60-21161 | C68: =VLOOKUP($B68,'[1]Products by Part Number'!$A:$L,2,0) -> KOM D61PX-24 (B60) | D68: =VLOOKUP($B68,'[1]Products by Part Number'!$A:$L,3,0) -> HYDRAULIC FILTER | E68: =VLOOKUP($B68,'[1]Products by Part Number'!$A:$L,8,0) -> 1 | F68: =VLOOKUP($B68,'[1]Products by Part Number'!$A:$L,4,0) -> 220.88 | G68: =E68*F68 -> 220.88 | H68: =VLOOKUP($B68,'[1]Products by Part Number'!$A:$L,6,0) -> 110.44 | I68: =ROUND(E68*H68,2) -> 110.44
B69: 328-3655 | C69: =VLOOKUP($B69,'[1]Products by Part Number'!$A:$L,2,0) -> CAT 14 (EN4) | D69: =VLOOKUP($B69,'[1]Products by Part Number'!$A:$L,3,0) -> HYDRAULIC FILTER | E69: =VLOOKUP($B69,'[1]Products by Part Number'!$A:$L,8,0) -> 1 | F69: =VLOOKUP($B69,'[1]Products by Part Number'!$A:$L,4,0) -> 197.31 | G69: =E69*F69 -> 197.31 | H69: =VLOOKUP($B69,'[1]Products by Part Number'!$A:$L,6,0) -> 98.66 | I69: =ROUND(E69*H69,2) -> 98.66
B70: 389-1076 | C70: =VLOOKUP($B70,'[1]Products by Part Number'!$A:$L,2,0) -> CAT 14 (EN4) | D70: =VLOOKUP($B70,'[1]Products by Part Number'!$A:$L,3,0) -> HYDRAULIC FILTER | E70: =VLOOKUP($B70,'[1]Products by Part Number'!$A:$L,8,0) -> 1 | F70: =VLOOKUP($B70,'[1]Products by Part Number'!$A:$L,4,0) -> 103.37 | G70: =E70*F70 -> 103.37 | H70: =VLOOKUP($B70,'[1]Products by Part Number'!$A:$L,6,0) -> 51.69 | I70: =ROUND(E70*H70,2) -> 51.69
B71: 418-60-55151 | C71: =VLOOKUP($B71,'[1]Products by Part Number'!$A:$L,2,0) -> KOM WA320-8 (867) KOM WA320PZ-6 (729) | D71: =VLOOKUP($B71,'[1]Products by Part Number'!$A:$L,3,0) -> HYDRAULIC FILTER | E71: =VLOOKUP($B71,'[1]Products by Part Number'!$A:$L,8,0) -> 2 | F71: =VLOOKUP($B71,'[1]Products by Part Number'!$A:$L,4,0) -> 197.46 | G71: =E71*F71 -> 394.92 | H71: =VLOOKUP($B71,'[1]Products by Part Number'!$A:$L,6,0) -> 98.73 | I71: =ROUND(E71*H71,2) -> 197.46
B72: 421-5479 | C72: =VLOOKUP($B72,'[1]Products by Part Number'!$A:$L,2,0) -> CAT 255 CAT 255 (2) CAT 255 (FL7) | D72: =VLOOKUP($B72,'[1]Products by Part Number'!$A:$L,3,0) -> HYDRAULIC FILTER | E72: =VLOOKUP($B72,'[1]Products by Part Number'!$A:$L,8,0) -> 3 | F72: =VLOOKUP($B72,'[1]Products by Part Number'!$A:$L,4,0) -> 91.89 | G72: =E72*F72 -> 275.67 | H72: =VLOOKUP($B72,'[1]Products by Part Number'!$A:$L,6,0) -> 45.95 | I72: =ROUND(E72*H72,2) -> 137.85
B73: 423-60-45461 | C73: =VLOOKUP($B73,'[1]Products by Part Number'!$A:$L,2,0) -> KOM D71PX-24 (1) KOM D71PX-24 (2) KOM D71PX-24 (3) KOM D71PX-24 (4) KOM D71PX-24 (5) KOM D71PX-24 (6) KOM D71PX-24 (7) KOM WA380-8 (1) KOM WA380-8 (2) | D73: =VLOOKUP($B73,'[1]Products by Part Number'!$A:$L,3,0) -> HYDRAULIC FILTER TANK | E73: =VLOOKUP($B73,'[1]Products by Part Number'!$A:$L,8,0) -> 16 | F73: =VLOOKUP($B73,'[1]Products by Part Number'!$A:$L,4,0) -> 161.1564 | G73: =E73*F73 -> 2578.5024 | H73: =VLOOKUP($B73,'[1]Products by Part Number'!$A:$L,6,0) -> 80.58 | I73: =ROUND(E73*H73,2) -> 1289.28
... B122: RE572785 | C122: =VLOOKUP($B122,'[1]Products by Part Number'!$A:$L,2,0) -> JD 470P (1FF) | D122: =VLOOKUP($B122,'[1]Products by Part Number'!$A:$L,3,0) -> ENGINE OIL FILTER | E122: =VLOOKUP($B122,'[1]Products by Part Number'!$A:$L,8,0) -> 2 | F122: =VLOOKUP($B122,'[1]Products by Part Number'!$A:$L,4,0) -> 122.9166 | G122: =E122*F122 -> 245.8332 | H122: =VLOOKUP($B122,'[1]Products by Part Number'!$A:$L,6,0) -> 61.46 | I122: =ROUND(E122*H122,2) -> 122.92
I123: =ROUND(E123*H123,2) -> 0
I124: =ROUND(E124*H124,2) -> 0
I125: =ROUND(E125*H125,2) -> 0
I126: =ROUND(E126*H126,2) -> 0
...

Sheet MOQ Filters Q2
E1: MOQ QUOTE | H1: Filters Q2
B7: COMPANY: | C7: GRAHAM | E7: DATE: | F7: 45870 | H7: PO NUMBER:
B8: CONTACT NAME: | C8: 0 | E8: PHONE NUMBER:
B9: BILLING ADDRESS: | C9: 0 | E9: EMAIL ADDRESS:
C10: 0 | E10: SHIPPING ADDRESS:
C11: 0
C12: 0
F13: CAD $
B14: PART NUMBER | C14: Make & Model | D14: DESCRIPTION | E14: QTY | F14: OEM MSRP | H14: GQP PRICE | I14: TOTAL
B15: 12Y-979-1174 | C15: =VLOOKUP($B15,'[1]Products by Part Number'!$A:$L,2,0) -> KOM D71PX-24 (1) KOM D71PX-24 (2) KOM D71PX-24 (3) KOM D71PX-24 (4) KOM D71PX-24 (5) KOM D71PX-24 (6) KOM D71PX-24 (7) KOM D61PX-24 (B60) | D15: =VLOOKUP($B15,'[1]Products by Part Number'!$A:$L,3,0) -> CAB AIR FILTER | E15: =VLOOKUP($B15,'[1]Products by Part Number'!$A:$L,9,0) -> 8 | F15: =VLOOKUP($B15,'[1]Products by Part Number'!$A:$L,4,0) -> 188.7426 | G15: =E15*F15 -> 1509.9408 | H15: =VLOOKUP($B15,'[1]Products by Part Number'!$A:$L,6,0) -> 122.68 | I15: =ROUND(E15*H15,2) -> 981.44
B16: 12Y-979-6180 | C16: =VLOOKUP($B16,'[1]Products by Part Number'!$A:$L,2,0) -> KOM D71PX-24 (1) KOM D71PX-24 (2) KOM D71PX-24 (3) KOM D71PX-24 (4) KOM D71PX-24 (5) KOM D71PX-24 (6) KOM D71PX-24 (7) KOM D61PX-24 (B60) | D16: =VLOOKUP($B16,'[1]Products by Part Number'!$A:$L,3,0) -> CAB AIR FILTER | E16: =VLOOKUP($B16,'[1]Products by Part Number'!$A:$L,9,0) -> 8 | F16: =VLOOKUP($B16,'[1]Products by Part Number'!$A:$L,4,0) -> 164.082 | G16: =E16*F16 -> 1312.656 | H16: =VLOOKUP($B16,'[1]Products by Part Number'!$A:$L,6,0) -> 106.65 | I16: =ROUND(E16*H16,2) -> 853.2
B17: 149-1912 | C17: =VLOOKUP($B17,'[1]Products by Part Number'!$A:$L,2,0) -> CAT 14 (EN4) | D17: =VLOOKUP($B17,'[1]Products by Part Number'!$A:$L,3,0) -> CAB AIR FILTER | E17: =VLOOKUP($B17,'[1]Products by Part Number'!$A:$L,9,0) -> 1 | F17: =VLOOKUP($B17,'[1]Products by Part Number'!$A:$L,4,0) -> 93.03 | G17: =E17*F17 -> 93.03 | H17: =VLOOKUP(B17,'[1]Products by Part Number'!$A:$F,6,0) -> 60.47 | I17: =ROUND(E17*H17,2) -> 60.47
B18: 17M-911-3530 | C18: =VLOOKUP($B18,'[1]Products by Part Number'!$A:$L,2,0) -> KOM PC138USLC-11 KOM PC238USLC-11 (1) KOM PC490LC-11 (A42) KOM PC490LC-11 (A42) (2) KOM PC490LC-11 (A42) (3) KOM PC490LC-11 (A42) (4) KOM PC490LC-11 (A42) (5) KOM PC490LC-11 (A43) KOM PC490LC-11 (KMT) (1) KOM PC490LC-11 (KMT) (2) KOM PC490LC-11 (KMT) (3) KOM PC360LC-11 (A37) KOM PC360LC-11 (A39) KOM PC360LC-11 (A39) (2) KOM PC290LC-11 (K73) | D18: =VLOOKUP($B18,'[1]Products by Part Number'!$A:$L,3,0) -> CAB AIR FILTER | E18: =VLOOKUP($B18,'[1]Products by Part Number'!$A:$L,9,0) -> 15 | F18: =VLOOKUP($B18,'[1]Products by Part Number'!$A:$L,4,0) -> 67.87 | G18: =E18*F18 -> 1018.05 | H18: =VLOOKUP(B18,'[1]Products by Part Number'!$A:$F,6,0) -> 44.12 | I18: =ROUND(E18*H18,2) -> 661.8
B19: 211-2660 | C19: =VLOOKUP($B19,'[1]Products by Part Number'!$A:$L,2,0) -> CAT 14 (EN4) | D19: =VLOOKUP($B19,'[1]Products by Part Number'!$A:$L,3,0) -> CAB AIR FILTER | E19: =VLOOKUP($B19,'[1]Products by Part Number'!$A:$L,9,0) -> 1 | F19: =VLOOKUP($B19,'[1]Products by Part Number'!$A:$L,4,0) -> 74.81 | G19: =E19*F19 -> 74.81 | H19: =VLOOKUP(B19,'[1]Products by Part Number'!$A:$F,6,0) -> 48.63 | I19: =ROUND(E19*H19,2) -> 48.63
B20: 222-9020 | C20: =VLOOKUP($B20,'[1]Products by Part Number'!$A:$L,2,0) -> CAT TL1055C (KDE) | D20: =VLOOKUP($B20,'[1]Products by Part Number'!$A:$L,3,0) -> PRIMARY AIR FILTER | E20: =VLOOKUP($B20,'[1]Products by Part Number'!$A:$L,9,0) -> 1 | F20: =VLOOKUP($B20,'[1]Products by Part Number'!$A:$L,4,0) -> 100.67 | G20: =E20*F20 -> 100.67 | H20: =VLOOKUP(B20,'[1]Products by Part Number'!$A:$F,6,0) -> 65.44 | I20: =ROUND(E20*H20,2) -> 65.44
B21: 222-9021 | C21: =VLOOKUP($B21,'[1]Products by Part Number'!$A:$L,2,0) -> CAT TL1055C (KDE) | D21: =VLOOKUP($B21,'[1]Products by Part Number'!$A:$L,3,0) -> SECONDARY AIR FILTER | E21: =VLOOKUP($B21,'[1]Products by Part Number'!$A:$L,9,0) -> 1 | F21: =VLOOKUP($B21,'[1]Products by Part Number'!$A:$L,4,0) -> 80.09 | G21: =E21*F21 -> 80.09 | H21: =VLOOKUP(B21,'[1]Products by Part Number'!$A:$F,6,0) -> 52.06 | I21: =ROUND(E21*H21,2) -> 52.06
B22: 2A5-979-1551 | C22: =VLOOKUP($B22,'[1]Products by Part Number'!$A:$L,2,0) -> KOM PC490LC-11 (A42) KOM PC490LC-11 (A42) (2) KOM PC490LC-11 (A42) (3) KOM PC490LC-11 (A42) (4) KOM PC490LC-11 (A42) (5) KOM PC490LC-11 (A43) KOM PC490LC-11 (KMT) (1) KOM PC490LC-11 (KMT) (2) KOM PC490LC-11 (KMT) (3) KOM PC360LC-11 (A37) KOM PC360LC-11 (A39) KOM PC360LC-11 (A39) (2) KOM PC290LC-11 (K73) | D22: =VLOOKUP($B22,'[1]Products by Part Number'!$A:$L,3,0) -> CAB AIR FILTER | E22: =VLOOKUP($B22,'[1]Products by Part Number'!$A:$L,9,0) -> 13 | F22: =VLOOKUP($B22,'[1]Products by Part Number'!$A:$L,4,0) -> 68.78 | G22: =E22*F22 -> 894.14 | H22: =VLOOKUP(B22,'[1]Products by Part Number'!$A:$F,6,0) -> 44.71 | I22: =ROUND(E22*H22,2) -> 581.23
B23: 327-6618 | C23: =VLOOKUP($B23,'[1]Products by Part Number'!$A:$L,2,0) -> CAT 329EL (ZCD) | D23: =VLOOKUP($B23,'[1]Products by Part Number'!$A:$L,3,0) -> CAB AIR FILTER | E23: =VLOOKUP($B23,'[1]Products by Part Number'!$A:$L,9,0) -> 1 | F23: =VLOOKUP($B23,'[1]Products by Part Number'!$A:$L,4,0) -> 82.09 | G23: =E23*F23 -> 82.09 | H23: =VLOOKUP(B23,'[1]Products by Part Number'!$A:$F,6,0) -> 53.36 | I23: =ROUND(E23*H23,2) -> 53.36
B24: 331-8108 | C24: =VLOOKUP($B24,'[1]Products by Part Number'!$A:$L,2,0) -> CAT 14 (EN4) | D24: =VLOOKUP($B24,'[1]Products by Part Number'!$A:$L,3,0) -> SECONDARY AIR FILTER | E24: =VLOOKUP($B24,'[1]Products by Part Number'!$A:$L,9,0) -> 1 | F24: =VLOOKUP($B24,'[1]Products by Part Number'!$A:$L,4,0) -> 105.26 | G24: =E24*F24 -> 105.26 | H24: =VLOOKUP(B24,'[1]Products by Part Number'!$A:$F,6,0) -> 68.42 | I24: =ROUND(E24*H24,2) -> 68.42
B25: 421-07-72450 | C25: =VLOOKUP($B25,'[1]Products by Part Number'!$A:$L,2,0) -> KOM WA475-10 (120) | D25: =VLOOKUP($B25,'[1]Products by Part Number'!$A:$L,3,0) -> CAB AIR FILTER | E25: =VLOOKUP($B25,'[1]Products by Part Number'!$A:$L,9,0) -> 1 | F25: =VLOOKUP($B25,'[1]Products by Part Number'!$A:$L,4,0) -> 134.67 | G25: =E25*F25 -> 134.67 | H25: =VLOOKUP(B25,'[1]Products by Part Number'!$A:$F,6,0) -> 87.54 | I25: =ROUND(E25*H25,2) -> 87.54
B26: 423-07-52411 | C26: =VLOOKUP($B26,'[1]Products by Part Number'!$A:$L,2,0) -> KOM WA380-8 (1) KOM WA380-8 (2) KOM WA320-8 (867) KOM WA320PZ-6 (729) | D26: =VLOOKUP($B26,'[1]Products by Part Number'!$A:$L,3,0) -> CAB AIR FILTER | E26: =VLOOKUP($B26,'[1]Products by Part Number'!$A:$L,9,0) -> 6 | F26: =VLOOKUP($B26,'[1]Products by Part Number'!$A:$L,4,0) -> 152.87 | G26: =E26*F26 -> 917.22 | H26: =VLOOKUP(B26,'[1]Products by Part Number'!$A:$F,6,0) -> 99.37 | I26: =ROUND(E26*H26,2) -> 596.22
B27: 426-07-32441 | C27: =VLOOKUP($B27,'[1]Products by Part Number'!$A:$L,2,0) -> KOM HM400-5 (1) KOM HM400-5 (2) KOM HM400-5 (3) KOM HM400-5 (4) KOM HM400-5 (5) KOM HM400-5 (6) KOM HM400-5 (7) KOM HM400-5 (8) KOM HM400-5 (9) KOM HM400-5 (10) KOM HM400 (11) KOM HM400 (12) KOM HM400 (13) KOM HM400-5 (14) | D27: =VLOOKUP($B27,'[1]Products by Part Number'!$A:$L,3,0) -> CAB AIR FILTER | E27: =VLOOKUP($B27,'[1]Products by Part Number'!$A:$L,9,0) -> 14 | F27: =VLOOKUP($B27,'[1]Products by Part Number'!$A:$L,4,0) -> 131.29 | G27: =E27*F27 -> 1838.06 | H27: =VLOOKUP(B27,'[1]Products by Part Number'!$A:$F,6,0) -> 85.34 | I27: =ROUND(E27*H27,2) -> 1194.76
B28: 4S00686R | C28: =VLOOKUP($B28,'[1]Products by Part Number'!$A:$L,2,0) -> JD 470P (1FF) | D28: =VLOOKUP($B28,'[1]Products by Part Number'!$A:$L,3,0) -> CAB AIR FILTER | E28: =VLOOKUP($B28,'[1]Products by Part Number'!$A:$L,9,0) -> 0 | F28: =VLOOKUP($B28,'[1]Products by Part Number'!$A:$L,4,0) -> 103.0722 | G28: =E28*F28 -> 0 | H28: =VLOOKUP(B28,'[1]Products by Part Number'!$A:$F,6,0) -> 67 | I28: =ROUND(E28*H28,2) -> 0
... B60: TT220747 | C60: =VLOOKUP($B60,'[1]Products by Part Number'!$A:$L,2,0) -> JD 470P (1FF) | D60: =VLOOKUP($B60,'[1]Products by Part Number'!$A:$L,3,0) -> SECONDARY AIR FILTER | E60: =VLOOKUP($B60,'[1]Products by Part Number'!$A:$L,9,0) -> 1 | F60: =VLOOKUP($B60,'[1]Products by Part Number'!$A:$L,4,0) -> 122.9028 | G60: =E60*F60 -> 122.9028 | H60: =VLOOKUP(B60,'[1]Products by Part Number'!$A:$F,6,0) -> 79.89 | I60: =ROUND(E60*H60,2) -> 79.89
B61: 4630525 | C61: =VLOOKUP($B61,'[1]Products by Part Number'!$A:$L,2,0) -> JD 470P (1FF) | D61: =VLOOKUP($B61,'[1]Products by Part Number'!$A:$L,3,0) -> HYDRAULIC FILTER PILOT | E61: =VLOOKUP($B61,'[1]Products by Part Number'!$A:$L,9,0) -> 1 | F61: =VLOOKUP($B61,'[1]Products by Part Number'!$A:$L,4,0) -> 40.641 | G61: =E61*F61 -> 40.641 | H61: =VLOOKUP(B61,'[1]Products by Part Number'!$A:$F,6,0) -> 20.32 | I61: =ROUND(E61*H61,2) -> 20.32
B62: 207-970-5121 | C62: =VLOOKUP($B62,'[1]Products by Part Number'!$A:$L,2,0) -> KOM PC360LC-11 (A37) KOM PC360LC-11 (A39) KOM PC360LC-11 (A39) (2) | D62: =VLOOKUP($B62,'[1]Products by Part Number'!$A:$L,3,0) -> HYDRAULIC FILTER | E62: =VLOOKUP($B62,'[1]Products by Part Number'!$A:$L,9,0) -> 3 | F62: =VLOOKUP($B62,'[1]Products by Part Number'!$A:$L,4,0) -> 198.35 | G62: =E62*F62 -> 595.05 | H62: =VLOOKUP(B62,'[1]Products by Part Number'!$A:$F,6,0) -> 99.18 | I62: =ROUND(E62*H62,2) -> 297.54
B63: 093-7521 | C63: =VLOOKUP($B63,'[1]Products by Part Number'!$A:$L,2,0) -> CAT 329EL (ZCD) | D63: =VLOOKUP($B63,'[1]Products by Part Number'!$A:$L,3,0) -> HYDRAULIC FILTER CASE DRAIN | E63: =VLOOKUP($B63,'[1]Products by Part Number'!$A:$L,9,0) -> 1 | F63: =VLOOKUP($B63,'[1]Products by Part Number'!$A:$L,4,0) -> 98.57 | G63: =E63*F63 -> 98.57 | H63: =VLOOKUP(B63,'[1]Products by Part Number'!$A:$F,6,0) -> 49.29 | I63: =ROUND(E63*H63,2) -> 49.29
B64: 11Y-60-28712 | C64: =VLOOKUP($B64,'[1]Products by Part Number'!$A:$L,2,0) -> KOM D61PX-24 (B60) | D64: =VLOOKUP($B64,'[1]Products by Part Number'!$A:$L,3,0) -> HYDRAULIC FILTER | E64: =VLOOKUP($B64,'[1]Products by Part Number'!$A:$L,9,0) -> 0 | F64: =VLOOKUP($B64,'[1]Products by Part Number'!$A:$L,4,0) -> 370.6 | G64: =E64*F64 -> 0 | H64: =VLOOKUP(B64,'[1]Products by Part Number'!$A:$F,6,0) -> 185.3 | I64: =ROUND(E64*H64,2) -> 0
B65: 179-9806 | C65: =VLOOKUP($B65,'[1]Products by Part Number'!$A:$L,2,0) -> CAT 329EL (ZCD) | D65: =VLOOKUP($B65,'[1]Products by Part Number'!$A:$L,3,0) -> HYDRAULIC FILTER RETURN | E65: =VLOOKUP($B65,'[1]Products by Part Number'!$A:$L,9,0) -> 0 | F65: =VLOOKUP($B65,'[1]Products by Part Number'!$A:$L,4,0) -> 221.11 | G65: =E65*F65 -> 0 | H65: =VLOOKUP(B65,'[1]Products by Part Number'!$A:$F,6,0) -> 110.56 | I65: =ROUND(E65*H65,2) -> 0
B66: 207-60-71183 | C66: =VLOOKUP($B66,'[1]Products by Part Number'!$A:$L,2,0) -> KOM HM400-5 (1) KOM HM400-5 (2) KOM HM400-5 (3) KOM HM400-5 (4) KOM HM400-5 (5) KOM HM400-5 (6) KOM HM400-5 (7) KOM HM400-5 (8) KOM HM400-5 (9) KOM HM400-5 (10) KOM HM400 (11) KOM HM400 (12) KOM HM400 (13) KOM HM400-5 (14) KOM PC238USLC-11 (2) KOM PC360LC-11 (A37) KOM PC360LC-11 (A39) KOM PC360LC-11 (A39) (2) KOM WA475-10 (120) KOM PC290LC-11 (K73) | D66: =VLOOKUP($B66,'[1]Products by Part Number'!$A:$L,3,0) -> HYDRAULIC FILTER TANK | E66: =VLOOKUP($B66,'[1]Products by Part Number'!$A:$L,9,0) -> 20 | F66: =VLOOKUP($B66,'[1]Products by Part Number'!$A:$L,4,0) -> 188.98 | G66: =E66*F66 -> 3779.6 | H66: =VLOOKUP(B66,'[1]Products by Part Number'!$A:$F,6,0) -> 94.49 | I66: =ROUND(E66*H66,2) -> 1889.8
B67: 208-60-71124 | C67: =VLOOKUP($B67,'[1]Products by Part Number'!$A:$L,2,0) -> KOM HM400-5 (1) KOM HM400-5 (2) KOM HM400-5 (3) KOM HM400-5 (4) KOM HM400-5 (5) KOM HM400-5 (6) KOM HM400-5 (7) KOM HM400-5 (8) KOM HM400-5 (9) KOM HM400-5 (10) KOM HM400 (11) KOM HM400 (12) KOM HM400 (13) KOM HM400-5 (14) KOM PC490LC-11 (A42) KOM PC490LC-11 (A42) (2) KOM PC490LC-11 (A42) (3) KOM PC490LC-11 (A42) (4) KOM PC490LC-11 (A42) (5) KOM PC490LC-11 (A43) KOM PC490LC-11 (KMT) (1) KOM PC490LC-11 (KMT) (2) KOM PC490LC-11 (KMT) (3) | D67: =VLOOKUP($B67,'[1]Products by Part Number'!$A:$L,3,0) -> HYDRAULIC FILTER ACCUMULATOR | E67: =VLOOKUP($B67,'[1]Products by Part Number'!$A:$L,9,0) -> 23 | F67: =VLOOKUP($B67,'[1]Products by Part Number'!$A:$L,4,0) -> 259.43 | G67: =E67*F67 -> 5966.89 | H67: =VLOOKUP(B67,'[1]Products by Part Number'!$A:$F,6,0) -> 129.72 | I67: =ROUND(E67*H67,2) -> 2983.56
B68: 22P-60-21161 | C68: =VLOOKUP($B68,'[1]Products by Part Number'!$A:$L,2,0) -> KOM D61PX-24 (B60) | D68: =VLOOKUP($B68,'[1]Products by Part Number'!$A:$L,3,0) -> HYDRAULIC FILTER | E68: =VLOOKUP($B68,'[1]Products by Part Number'!$A:$L,9,0) -> 0 | F68: =VLOOKUP($B68,'[1]Products by Part Number'!$A:$L,4,0) -> 220.88 | G68: =E68*F68 -> 0 | H68: =VLOOKUP(B68,'[1]Products by Part Number'!$A:$F,6,0) -> 110.44 | I68: =ROUND(E68*H68,2) -> 0
B69: 328-3655 | C69: =VLOOKUP($B69,'[1]Products by Part Number'!$A:$L,2,0) -> CAT 14 (EN4) | D69: =VLOOKUP($B69,'[1]Products by Part Number'!$A:$L,3,0) -> HYDRAULIC FILTER | E69: =VLOOKUP($B69,'[1]Products by Part Number'!$A:$L,9,0) -> 1 | F69: =VLOOKUP($B69,'[1]Products by Part Number'!$A:$L,4,0) -> 197.31 | G69: =E69*F69 -> 197.31 | H69: =VLOOKUP(B69,'[1]Products by Part Number'!$A:$F,6,0) -> 98.66 | I69: =ROUND(E69*H69,2) -> 98.66
B70: 389-1076 | C70: =VLOOKUP($B70,'[1]Products by Part Number'!$A:$L,2,0) -> CAT 14 (EN4) | D70: =VLOOKUP($B70,'[1]Products by Part Number'!$A:$L,3,0) -> HYDRAULIC FILTER | E70: =VLOOKUP($B70,'[1]Products by Part Number'!$A:$L,9,0) -> 1 | F70: =VLOOKUP($B70,'[1]Products by Part Number'!$A:$L,4,0) -> 103.37 | G70: =E70*F70 -> 103.37 | H70: =VLOOKUP(B70,'[1]Products by Part Number'!$A:$F,6,0) -> 51.69 | I70: =ROUND(E70*H70,2) -> 51.69
B71: 418-60-55151 | C71: =VLOOKUP($B71,'[1]Products by Part Number'!$A:$L,2,0) -> KOM WA320-8 (867) KOM WA320PZ-6 (729) | D71: =VLOOKUP($B71,'[1]Products by Part Number'!$A:$L,3,0) -> HYDRAULIC FILTER | E71: =VLOOKUP($B71,'[1]Products by Part Number'!$A:$L,9,0) -> 2 | F71: =VLOOKUP($B71,'[1]Products by Part Number'!$A:$L,4,0) -> 197.46 | G71: =E71*F71 -> 394.92 | H71: =VLOOKUP(B71,'[1]Products by Part Number'!$A:$F,6,0) -> 98.73 | I71: =ROUND(E71*H71,2) -> 197.46
B72: 421-5479 | C72: =VLOOKUP($B72,'[1]Products by Part Number'!$A:$L,2,0) -> CAT 255 CAT 255 (2) CAT 255 (FL7) | D72: =VLOOKUP($B72,'[1]Products by Part Number'!$A:$L,3,0) -> HYDRAULIC FILTER | E72: =VLOOKUP($B72,'[1]Products by Part Number'!$A:$L,9,0) -> 3 | F72: =VLOOKUP($B72,'[1]Products by Part Number'!$A:$L,4,0) -> 91.89 | G72: =E72*F72 -> 275.67 | H72: =VLOOKUP(B72,'[1]Products by Part Number'!$A:$F,6,0) -> 45.95 | I72: =ROUND(E72*H72,2) -> 137.85
B73: 423-60-45461 | C73: =VLOOKUP($B73,'[1]Products by Part Number'!$A:$L,2,0) -> KOM D71PX-24 (1) KOM D71PX-24 (2) KOM D71PX-24 (3) KOM D71PX-24 (4) KOM D71PX-24 (5) KOM D71PX-24 (6) KOM D71PX-24 (7) KOM WA380-8 (1) KOM WA380-8 (2) | D73: =VLOOKUP($B73,'[1]Products by Part Number'!$A:$L,3,0) -> HYDRAULIC FILTER TANK | E73: =VLOOKUP($B73,'[1]Products by Part Number'!$A:$L,9,0) -> 9 | F73: =VLOOKUP($B73,'[1]Products by Part Number'!$A:$L,4,0) -> 161.1564 | G73: =E73*F73 -> 1450.4076 | H73: =VLOOKUP(B73,'[1]Products by Part Number'!$A:$F,6,0) -> 80.58 | I73: =ROUND(E73*H73,2) -> 725.22
... B122: RE572785 | C122: =VLOOKUP($B122,'[1]Products by Part Number'!$A:$L,2,0) -> JD 470P (1FF) | D122: =VLOOKUP($B122,'[1]Products by Part Number'!$A:$L,3,0) -> ENGINE OIL FILTER | E122: =VLOOKUP($B122,'[1]Products by Part Number'!$A:$L,9,0) -> 1 | F122: =VLOOKUP($B122,'[1]Products by Part Number'!$A:$L,4,0) -> 122.9166 | G122: =E122*F122 -> 122.9166 | H122: =VLOOKUP(B122,'[1]Products by Part Number'!$A:$F,6,0) -> 61.46 | I122: =ROUND(E122*H122,2) -> 61.46
I123: =ROUND(E123*H123,2) -> 0
I124: =ROUND(E124*H124,2) -> 0
...

Sheet MOQ Filters Q3
E1: MOQ QUOTE | H1: Filters Q3
B7: COMPANY: | C7: GRAHAM | E7: DATE: | F7: 45870 | H7: PO NUMBER:
B8: CONTACT NAME: | C8: 0 | E8: PHONE NUMBER:
B9: BILLING ADDRESS: | C9: 0 | E9: EMAIL ADDRESS:
C10: 0 | E10: SHIPPING ADDRESS:
C11: 0
C12: 0
F13: CAD $
B14: PART NUMBER | C14: Make & Model | D14: DESCRIPTION | E14: QTY | F14: OEM MSRP | H14: GQP PRICE | I14: TOTAL
B15: 12Y-979-1174 | C15: =VLOOKUP($B15,'[1]Products by Part Number'!$A:$L,2,0) -> KOM D71PX-24 (1) KOM D71PX-24 (2) KOM D71PX-24 (3) KOM D71PX-24 (4) KOM D71PX-24 (5) KOM D71PX-24 (6) KOM D71PX-24 (7) KOM D61PX-24 (B60) | D15: =VLOOKUP($B15,'[1]Products by Part Number'!$A:$L,3,0) -> CAB AIR FILTER | E15: =VLOOKUP($B15,'[1]Products by Part Number'!$A:$L,10,0) -> 9 | F15: =VLOOKUP($B15,'[1]Products by Part Number'!$A:$L,4,0) -> 188.7426 | G15: =E15*F15 -> 1698.6834 | H15: =VLOOKUP($B15,'[1]Products by Part Number'!$A:$L,6,0) -> 122.68 | I15: =ROUND(E15*H15,2) -> 1104.12
B16: 12Y-979-6180 | C16: =VLOOKUP($B16,'[1]Products by Part Number'!$A:$L,2,0) -> KOM D71PX-24 (1) KOM D71PX-24 (2) KOM D71PX-24 (3) KOM D71PX-24 (4) KOM D71PX-24 (5) KOM D71PX-24 (6) KOM D71PX-24 (7) KOM D61PX-24 (B60) | D16: =VLOOKUP($B16,'[1]Products by Part Number'!$A:$L,3,0) -> CAB AIR FILTER | E16: =VLOOKUP($B16,'[1]Products by Part Number'!$A:$L,10,0) -> 9 | F16: =VLOOKUP($B16,'[1]Products by Part Number'!$A:$L,4,0) -> 164.082 | G16: =E16*F16 -> 1476.738 | H16: =VLOOKUP($B16,'[1]Products by Part Number'!$A:$L,6,0) -> 106.65 | I16: =ROUND(E16*H16,2) -> 959.85
B17: 149-1912 | C17: =VLOOKUP(B17,'[1]Products by Part Number'!$A:$B,2,0) -> CAT 14 (EN4) | D17: =VLOOKUP(B17,'[1]Products by Part Number'!$A:$C,3,0) -> CAB AIR FILTER | E17: =VLOOKUP($B17,'[1]Products by Part Number'!$A:$L,10,0) -> 2 | F17: =VLOOKUP(B17,'[1]Products by Part Number'!$A:$D,4,0) -> 93.03 | G17: =E17*F17 -> 186.06 | H17: =VLOOKUP(B17,'[1]Products by Part Number'!$A:$F,6,0) -> 60.47 | I17: =ROUND(E17*H17,2) -> 120.94
B18: 17M-911-3530 | C18: =VLOOKUP(B18,'[1]Products by Part Number'!$A:$B,2,0) -> KOM PC138USLC-11 KOM PC238USLC-11 (1) KOM PC490LC-11 (A42) KOM PC490LC-11 (A42) (2) KOM PC490LC-11 (A42) (3) KOM PC490LC-11 (A42) (4) KOM PC490LC-11 (A42) (5) KOM PC490LC-11 (A43) KOM PC490LC-11 (KMT) (1) KOM PC490LC-11 (KMT) (2) KOM PC490LC-11 (KMT) (3) KOM PC360LC-11 (A37) KOM PC360LC-11 (A39) KOM PC360LC-11 (A39) (2) KOM PC290LC-11 (K73) | D18: =VLOOKUP(B18,'[1]Products by Part Number'!$A:$C,3,0) -> CAB AIR FILTER | E18: =VLOOKUP($B18,'[1]Products by Part Number'!$A:$L,10,0) -> 30 | F18: =VLOOKUP(B18,'[1]Products by Part Number'!$A:$D,4,0) -> 67.87 | G18: =E18*F18 -> 2036.1 | H18: =VLOOKUP(B18,'[1]Products by Part Number'!$A:$F,6,0) -> 44.12 | I18: =ROUND(E18*H18,2) -> 1323.6
B19: 211-2660 | C19: =VLOOKUP(B19,'[1]Products by Part Number'!$A:$B,2,0) -> CAT 14 (EN4) | D19: =VLOOKUP(B19,'[1]Products by Part Number'!$A:$C,3,0) -> CAB AIR FILTER | E19: =VLOOKUP($B19,'[1]Products by Part Number'!$A:$L,10,0) -> 2 | F19: =VLOOKUP(B19,'[1]Products by Part Number'!$A:$D,4,0) -> 74.81 | G19: =E19*F19 -> 149.62 | H19: =VLOOKUP(B19,'[1]Products by Part Number'!$A:$F,6,0) -> 48.63 | I19: =ROUND(E19*H19,2) -> 97.26
B20: 222-9020 | C20: =VLOOKUP(B20,'[1]Products by Part Number'!$A:$B,2,0) -> CAT TL1055C (KDE) | D20: =VLOOKUP(B20,'[1]Products by Part Number'!$A:$C,3,0) -> PRIMARY AIR FILTER | E20: =VLOOKUP($B20,'[1]Products by Part Number'!$A:$L,10,0) -> 1 | F20: =VLOOKUP(B20,'[1]Products by Part Number'!$A:$D,4,0) -> 100.67 | G20: =E20*F20 -> 100.67 | H20: =VLOOKUP(B20,'[1]Products by Part Number'!$A:$F,6,0) -> 65.44 | I20: =ROUND(E20*H20,2) -> 65.44
B21: 222-9021 | C21: =VLOOKUP(B21,'[1]Products by Part Number'!$A:$B,2,0) -> CAT TL1055C (KDE) | D21: =VLOOKUP(B21,'[1]Products by Part Number'!$A:$C,3,0) -> SECONDARY AIR FILTER | E21: =VLOOKUP($B21,'[1]Products by Part Number'!$A:$L,10,0) -> 1 | F21: =VLOOKUP(B21,'[1]Products by Part Number'!$A:$D,4,0) -> 80.09 | G21: =E21*F21 -> 80.09 | H21: =VLOOKUP(B21,'[1]Products by Part Number'!$A:$F,6,0) -> 52.06 | I21: =ROUND(E21*H21,2) -> 52.06
B22: 2A5-979-1551 | C22: =VLOOKUP(B22,'[1]Products by Part Number'!$A:$B,2,0) -> KOM PC490LC-11 (A42) KOM PC490LC-11 (A42) (2) KOM PC490LC-11 (A42) (3) KOM PC490LC-11 (A42) (4) KOM PC490LC-11 (A42) (5) KOM PC490LC-11 (A43) KOM PC490LC-11 (KMT) (1) KOM PC490LC-11 (KMT) (2) KOM PC490LC-11 (KMT) (3) KOM PC360LC-11 (A37) KOM PC360LC-11 (A39) KOM PC360LC-11 (A39) (2) KOM PC290LC-11 (K73) | D22: =VLOOKUP(B22,'[1]Products by Part Number'!$A:$C,3,0) -> CAB AIR FILTER | E22: =VLOOKUP($B22,'[1]Products by Part Number'!$A:$L,10,0) -> 26 | F22: =VLOOKUP(B22,'[1]Products by Part Number'!$A:$D,4,0) -> 68.78 | G22: =E22*F22 -> 1788.28 | H22: =VLOOKUP(B22,'[1]Products by Part Number'!$A:$F,6,0) -> 44.71 | I22: =ROUND(E22*H22,2) -> 1162.46
B23: 327-6618 | C23: =VLOOKUP(B23,'[1]Products by Part Number'!$A:$B,2,0) -> CAT 329EL (ZCD) | D23: =VLOOKUP(B23,'[1]Products by Part Number'!$A:$C,3,0) -> CAB AIR FILTER | E23: =VLOOKUP($B23,'[1]Products by Part Number'!$A:$L,10,0) -> 2 | F23: =VLOOKUP(B23,'[1]Products by Part Number'!$A:$D,4,0) -> 82.09 | G23: =E23*F23 -> 164.18 | H23: =VLOOKUP(B23,'[1]Products by Part Number'!$A:$F,6,0) -> 53.36 | I23: =ROUND(E23*H23,2) -> 106.72
B24: 331-8108 | C24: =VLOOKUP(B24,'[1]Products by Part Number'!$A:$B,2,0) -> CAT 14 (EN4) | D24: =VLOOKUP(B24,'[1]Products by Part Number'!$A:$C,3,0) -> SECONDARY AIR FILTER | E24: =VLOOKUP($B24,'[1]Products by Part Number'!$A:$L,10,0) -> 1 | F24: =VLOOKUP(B24,'[1]Products by Part Number'!$A:$D,4,0) -> 105.26 | G24: =E24*F24 -> 105.26 | H24: =VLOOKUP(B24,'[1]Products by Part Number'!$A:$F,6,0) -> 68.42 | I24: =ROUND(E24*H24,2) -> 68.42
B25: 421-07-72450 | C25: =VLOOKUP(B25,'[1]Products by Part Number'!$A:$B,2,0) -> KOM WA475-10 (120) | D25: =VLOOKUP(B25,'[1]Products by Part Number'!$A:$C,3,0) -> CAB AIR FILTER | E25: =VLOOKUP($B25,'[1]Products by Part Number'!$A:$L,10,0) -> 1 | F25: =VLOOKUP(B25,'[1]Products by Part Number'!$A:$D,4,0) -> 134.67 | G25: =E25*F25 -> 134.67 | H25: =VLOOKUP(B25,'[1]Products by Part Number'!$A:$F,6,0) -> 87.54 | I25: =ROUND(E25*H25,2) -> 87.54
B26: 423-07-52411 | C26: =VLOOKUP(B26,'[1]Products by Part Number'!$A:$B,2,0) -> KOM WA380-8 (1) KOM WA380-8 (2) KOM WA320-8 (867) KOM WA320PZ-6 (729) | D26: =VLOOKUP(B26,'[1]Products by Part Number'!$A:$C,3,0) -> CAB AIR FILTER | E26: =VLOOKUP($B26,'[1]Products by Part Number'!$A:$L,10,0) -> 6 | F26: =VLOOKUP(B26,'[1]Products by Part Number'!$A:$D,4,0) -> 152.87 | G26: =E26*F26 -> 917.22 | H26: =VLOOKUP(B26,'[1]Products by Part Number'!$A:$F,6,0) -> 99.37 | I26: =ROUND(E26*H26,2) -> 596.22
B27: 426-07-32441 | C27: =VLOOKUP(B27,'[1]Products by Part Number'!$A:$B,2,0) -> KOM HM400-5 (1) KOM HM400-5 (2) KOM HM400-5 (3) KOM HM400-5 (4) KOM HM400-5 (5) KOM HM400-5 (6) KOM HM400-5 (7) KOM HM400-5 (8) KOM HM400-5 (9) KOM HM400-5 (10) KOM HM400 (11) KOM HM400 (12) KOM HM400 (13) KOM HM400-5 (14) | D27: =VLOOKUP(B27,'[1]Products by Part Number'!$A:$C,3,0) -> CAB AIR FILTER | E27: =VLOOKUP($B27,'[1]Products by Part Number'!$A:$L,10,0) -> 14 | F27: =VLOOKUP(B27,'[1]Products by Part Number'!$A:$D,4,0) -> 131.29 | G27: =E27*F27 -> 1838.06 | H27: =VLOOKUP(B27,'[1]Products by Part Number'!$A:$F,6,0) -> 85.34 | I27: =ROUND(E27*H27,2) -> 1194.76
B28: 4S00686R | C28: =VLOOKUP(B28,'[1]Products by Part Number'!$A:$B,2,0) -> JD 470P (1FF) | D28: =VLOOKUP(B28,'[1]Products by Part Number'!$A:$C,3,0) -> CAB AIR FILTER | E28: =VLOOKUP($B28,'[1]Products by Part Number'!$A:$L,10,0) -> 0 | F28: =VLOOKUP(B28,'[1]Products by Part Number'!$A:$D,4,0) -> 103.0722 | G28: =E28*F28 -> 0 | H28: =VLOOKUP(B28,'[1]Products by Part Number'!$A:$F,6,0) -> 67 | I28: =ROUND(E28*H28,2) -> 0
... B60: TT220747 | C60: =VLOOKUP(B60,'[1]Products by Part Number'!$A:$B,2,0) -> JD 470P (1FF) | D60: =VLOOKUP(B60,'[1]Products by Part Number'!$A:$C,3,0) -> SECONDARY AIR FILTER | E60: =VLOOKUP($B60,'[1]Products by Part Number'!$A:$L,10,0) -> 1 | F60: =VLOOKUP(B60,'[1]Products by Part Number'!$A:$D,4,0) -> 122.9028 | G60: =E60*F60 -> 122.9028 | H60: =VLOOKUP(B60,'[1]Products by Part Number'!$A:$F,6,0) -> 79.89 | I60: =ROUND(E60*H60,2) -> 79.89
B61: 4630525 | C61: =VLOOKUP(B61,'[1]Products by Part Number'!$A:$B,2,0) -> JD 470P (1FF) | D61: =VLOOKUP(B61,'[1]Products by Part Number'!$A:$C,3,0) -> HYDRAULIC FILTER PILOT | E61: =VLOOKUP($B61,'[1]Products by Part Number'!$A:$L,10,0) -> 1 | F61: =VLOOKUP(B61,'[1]Products by Part Number'!$A:$D,4,0) -> 40.641 | G61: =E61*F61 -> 40.641 | H61: =VLOOKUP(B61,'[1]Products by Part Number'!$A:$F,6,0) -> 20.32 | I61: =ROUND(E61*H61,2) -> 20.32
B62: 207-970-5121 | C62: =VLOOKUP(B62,'[1]Products by Part Number'!$A:$B,2,0) -> KOM PC360LC-11 (A37) KOM PC360LC-11 (A39) KOM PC360LC-11 (A39) (2) | D62: =VLOOKUP(B62,'[1]Products by Part Number'!$A:$C,3,0) -> HYDRAULIC FILTER | E62: =VLOOKUP($B62,'[1]Products by Part Number'!$A:$L,10,0) -> 3 | F62: =VLOOKUP(B62,'[1]Products by Part Number'!$A:$D,4,0) -> 198.35 | G62: =E62*F62 -> 595.05 | H62: =VLOOKUP(B62,'[1]Products by Part Number'!$A:$F,6,0) -> 99.18 | I62: =ROUND(E62*H62,2) -> 297.54
B63: 093-7521 | C63: =VLOOKUP(B63,'[1]Products by Part Number'!$A:$B,2,0) -> CAT 329EL (ZCD) | D63: =VLOOKUP(B63,'[1]Products by Part Number'!$A:$C,3,0) -> HYDRAULIC FILTER CASE DRAIN | E63: =VLOOKUP($B63,'[1]Products by Part Number'!$A:$L,10,0) -> 1 | F63: =VLOOKUP(B63,'[1]Products by Part Number'!$A:$D,4,0) -> 98.57 | G63: =E63*F63 -> 98.57 | H63: =VLOOKUP(B63,'[1]Products by Part Number'!$A:$F,6,0) -> 49.29 | I63: =ROUND(E63*H63,2) -> 49.29
B64: 11Y-60-28712 | C64: =VLOOKUP(B64,'[1]Products by Part Number'!$A:$B,2,0) -> KOM D61PX-24 (B60) | D64: =VLOOKUP(B64,'[1]Products by Part Number'!$A:$C,3,0) -> HYDRAULIC FILTER | E64: =VLOOKUP($B64,'[1]Products by Part Number'!$A:$L,10,0) -> 1 | F64: =VLOOKUP(B64,'[1]Products by Part Number'!$A:$D,4,0) -> 370.6 | G64: =E64*F64 -> 370.6 | H64: =VLOOKUP(B64,'[1]Products by Part Number'!$A:$F,6,0) -> 185.3 | I64: =ROUND(E64*H64,2) -> 185.3
B65: 179-9806 | C65: =VLOOKUP(B65,'[1]Products by Part Number'!$A:$B,2,0) -> CAT 329EL (ZCD) | D65: =VLOOKUP(B65,'[1]Products by Part Number'!$A:$C,3,0) -> HYDRAULIC FILTER RETURN | E65: =VLOOKUP($B65,'[1]Products by Part Number'!$A:$L,10,0) -> 1 | F65: =VLOOKUP(B65,'[1]Products by Part Number'!$A:$D,4,0) -> 221.11 | G65: =E65*F65 -> 221.11 | H65: =VLOOKUP(B65,'[1]Products by Part Number'!$A:$F,6,0) -> 110.56 | I65: =ROUND(E65*H65,2) -> 110.56
B66: 207-60-71183 | C66: =VLOOKUP(B66,'[1]Products by Part Number'!$A:$B,2,0) -> KOM HM400-5 (1) KOM HM400-5 (2) KOM HM400-5 (3) KOM HM400-5 (4) KOM HM400-5 (5) KOM HM400-5 (6) KOM HM400-5 (7) KOM HM400-5 (8) KOM HM400-5 (9) KOM HM400-5 (10) KOM HM400 (11) KOM HM400 (12) KOM HM400 (13) KOM HM400-5 (14) KOM PC238USLC-11 (2) KOM PC360LC-11 (A37) KOM PC360LC-11 (A39) KOM PC360LC-11 (A39) (2) KOM WA475-10 (120) KOM PC290LC-11 (K73) | D66: =VLOOKUP(B66,'[1]Products by Part Number'!$A:$C,3,0) -> HYDRAULIC FILTER TANK | E66: =VLOOKUP($B66,'[1]Products by Part Number'!$A:$L,10,0) -> 20 | F66: =VLOOKUP(B66,'[1]Products by Part Number'!$A:$D,4,0) -> 188.98 | G66: =E66*F66 -> 3779.6 | H66: =VLOOKUP(B66,'[1]Products by Part Number'!$A:$F,6,0) -> 94.49 | I66: =ROUND(E66*H66,2) -> 1889.8
B67: 208-60-71124 | C67: =VLOOKUP(B67,'[1]Products by Part Number'!$A:$B,2,0) -> KOM HM400-5 (1) KOM HM400-5 (2) KOM HM400-5 (3) KOM HM400-5 (4) KOM HM400-5 (5) KOM HM400-5 (6) KOM HM400-5 (7) KOM HM400-5 (8) KOM HM400-5 (9) KOM HM400-5 (10) KOM HM400 (11) KOM HM400 (12) KOM HM400 (13) KOM HM400-5 (14) KOM PC490LC-11 (A42) KOM PC490LC-11 (A42) (2) KOM PC490LC-11 (A42) (3) KOM PC490LC-11 (A42) (4) KOM PC490LC-11 (A42) (5) KOM PC490LC-11 (A43) KOM PC490LC-11 (KMT) (1) KOM PC490LC-11 (KMT) (2) KOM PC490LC-11 (KMT) (3) | D67: =VLOOKUP(B67,'[1]Products by Part Number'!$A:$C,3,0) -> HYDRAULIC FILTER ACCUMULATOR | E67: =VLOOKUP($B67,'[1]Products by Part Number'!$A:$L,10,0) -> 23 | F67: =VLOOKUP(B67,'[1]Products by Part Number'!$A:$D,4,0) -> 259.43 | G67: =E67*F67 -> 5966.89 | H67: =VLOOKUP(B67,'[1]Products by Part Number'!$A:$F,6,0) -> 129.72 | I67: =ROUND(E67*H67,2) -> 2983.56
B68: 22P-60-21161 | C68: =VLOOKUP(B68,'[1]Products by Part Number'!$A:$B,2,0) -> KOM D61PX-24 (B60) | D68: =VLOOKUP(B68,'[1]Products by Part Number'!$A:$C,3,0) -> HYDRAULIC FILTER | E68: =VLOOKUP($B68,'[1]Products by Part Number'!$A:$L,10,0) -> 1 | F68: =VLOOKUP(B68,'[1]Products by Part Number'!$A:$D,4,0) -> 220.88 | G68: =E68*F68 -> 220.88 | H68: =VLOOKUP(B68,'[1]Products by Part Number'!$A:$F,6,0) -> 110.44 | I68: =ROUND(E68*H68,2) -> 110.44
B69: 328-3655 | C69: =VLOOKUP(B69,'[1]Products by Part Number'!$A:$B,2,0) -> CAT 14 (EN4) | D69: =VLOOKUP(B69,'[1]Products by Part Number'!$A:$C,3,0) -> HYDRAULIC FILTER | E69: =VLOOKUP($B69,'[1]Products by Part Number'!$A:$L,10,0) -> 1 | F69: =VLOOKUP(B69,'[1]Products by Part Number'!$A:$D,4,0) -> 197.31 | G69: =E69*F69 -> 197.31 | H69: =VLOOKUP(B69,'[1]Products by Part Number'!$A:$F,6,0) -> 98.66 | I69: =ROUND(E69*H69,2) -> 98.66
B70: 389-1076 | C70: =VLOOKUP(B70,'[1]Products by Part Number'!$A:$B,2,0) -> CAT 14 (EN4) | D70: =VLOOKUP(B70,'[1]Products by Part Number'!$A:$C,3,0) -> HYDRAULIC FILTER | E70: =VLOOKUP($B70,'[1]Products by Part Number'!$A:$L,10,0) -> 1 | F70: =VLOOKUP(B70,'[1]Products by Part Number'!$A:$D,4,0) -> 103.37 | G70: =E70*F70 -> 103.37 | H70: =VLOOKUP(B70,'[1]Products by Part Number'!$A:$F,6,0) -> 51.69 | I70: =ROUND(E70*H70,2) -> 51.69
B71: 418-60-55151 | C71: =VLOOKUP(B71,'[1]Products by Part Number'!$A:$B,2,0) -> KOM WA320-8 (867) KOM WA320PZ-6 (729) | D71: =VLOOKUP(B71,'[1]Products by Part Number'!$A:$C,3,0) -> HYDRAULIC FILTER | E71: =VLOOKUP($B71,'[1]Products by Part Number'!$A:$L,10,0) -> 2 | F71: =VLOOKUP(B71,'[1]Products by Part Number'!$A:$D,4,0) -> 197.46 | G71: =E71*F71 -> 394.92 | H71: =VLOOKUP(B71,'[1]Products by Part Number'!$A:$F,6,0) -> 98.73 | I71: =ROUND(E71*H71,2) -> 197.46
B72: 421-5479 | C72: =VLOOKUP(B72,'[1]Products by Part Number'!$A:$B,2,0) -> CAT 255 CAT 255 (2) CAT 255 (FL7) | D72: =VLOOKUP(B72,'[1]Products by Part Number'!$A:$C,3,0) -> HYDRAULIC FILTER | E72: =VLOOKUP($B72,'[1]Products by Part Number'!$A:$L,10,0) -> 3 | F72: =VLOOKUP(B72,'[1]Products by Part Number'!$A:$D,4,0) -> 91.89 | G72: =E72*F72 -> 275.67 | H72: =VLOOKUP(B72,'[1]Products by Part Number'!$A:$F,6,0) -> 45.95 | I72: =ROUND(E72*H72,2) -> 137.85
B73: 423-60-45461 | C73: =VLOOKUP(B73,'[1]Products by Part Number'!$A:$B,2,0) -> KOM D71PX-24 (1) KOM D71PX-24 (2) KOM D71PX-24 (3) KOM D71PX-24 (4) KOM D71PX-24 (5) KOM D71PX-24 (6) KOM D71PX-24 (7) KOM WA380-8 (1) KOM WA380-8 (2) | D73: =VLOOKUP(B73,'[1]Products by Part Number'!$A:$C,3,0) -> HYDRAULIC FILTER TANK | E73: =VLOOKUP($B73,'[1]Products by Part Number'!$A:$L,10,0) -> 16 | F73: =VLOOKUP(B73,'[1]Products by Part Number'!$A:$D,4,0) -> 161.1564 | G73: =E73*F73 -> 2578.5024 | H73: =VLOOKUP(B73,'[1]Products by Part Number'!$A:$F,6,0) -> 80.58 | I73: =ROUND(E73*H73,2) -> 1289.28
