Workbook

Sheet MOQ Batteries
E1: MOQ QUOTE | H1: Batteries
B7: COMPANY: | C7: Lincoln County | E7: DATE: | F7: 45870 | H7: PO NUMBER:
B8: CONTACT NAME: | C8: 0 | E8: PHONE NUMBER:
B9: BILLING ADDRESS: | C9: 0 | E9: EMAIL ADDRESS:
C10: 0 | E10: SHIPPING ADDRESS:
C11: 0
C12: 0
F13: CAD $
B14: PART NUMBER | C14: Make & Model | D14: DESCRIPTION | E14: QTY | F14: OEM MSRP | H14: GQP PRICE | I14: TOTAL
B15: 7312553 | C15: =VLOOKUP(B15,'[1]Product by Part Number'!$A:$B,2,0) -> BOBCAT T750 (ANK) BOBCAT T750 (ATF) BOBCAT S650 (A3N) BOBCAT T770 (AT6) BOBCAT T770 (AT6) (2) | D15: =VLOOKUP(B15,'[1]Product by Part Number'!$A:$C,3,0) -> Battery GP | E15: =VLOOKUP(B15,'[1]Product by Part Number'!$A:$K,11,0) -> 5 | F15: =VLOOKUP(B15,'[1]Product by Part Number'!$A:$D,4,0) -> 415.79 | G15: =E15*F15 -> 2078.95 | H15: =VLOOKUP(B15,'[1]Product by Part Number'!$A:$E,5,0) -> 207.9 | I15: =ROUND(E15*H15,2) -> 1039.5
B16: 115-2422 | C16: =VLOOKUP(B16,'[1]Product by Part Number'!$A:$B,2,0) -> CAT 320E L (WBK) CAT 320E L (WBK) (2) CAT 320 (HEX) CAT 320 (MYK) CAT 320 (MYK) (2) CAT 329E L (ZCD) CAT 329F L (ERL) CAT 329F L (ERL) (2) CAT 330F L (MBX) CAT 330F L (HCK) CAT 330F L (HCK) (2) CAT 299D (DX2) | D16: =VLOOKUP(B16,'[1]Product by Part Number'!$A:$C,3,0) -> 12V BATTERY 1000CCA | E16: =VLOOKUP(B16,'[1]Product by Part Number'!$A:$K,11,0) -> 27 | F16: =VLOOKUP(B16,'[1]Product by Part Number'!$A:$D,4,0) -> 523.07 | G16: =E16*F16 -> 14122.89 | H16: =VLOOKUP(B16,'[1]Product by Part Number'!$A:$E,5,0) -> 132.13 | I16: =ROUND(E16*H16,2) -> 3567.51
B17: 153-5656 | C17: =VLOOKUP(B17,'[1]Product by Part Number'!$A:$B,2,0) -> CAT 303.5E | D17: =VLOOKUP(B17,'[1]Product by Part Number'!$A:$C,3,0) -> 12V BATTERY - 650CCA | E17: =VLOOKUP(B17,'[1]Product by Part Number'!$A:$K,11,0) -> 1 | F17: =VLOOKUP(B17,'[1]Product by Part Number'!$A:$D,4,0) -> 356.29 | G17: =E17*F17 -> 356.29 | H17: =VLOOKUP(B17,'[1]Product by Part Number'!$A:$E,5,0) -> 160.67 | I17: =ROUND(E17*H17,2) -> 160.67
B18: 153-5700 | C18: =VLOOKUP(B18,'[1]Product by Part Number'!$A:$B,2,0) -> CAT D3 (1PJ) CAT D7G (92V) CAT D7G (3ZD) CAT D7G (3ZD) (2) CAT 561 (85H) CAT 561 (92J) CAT 561 (92J) (2) | D18: =VLOOKUP(B18,'[1]Product by Part Number'!$A:$C,3,0) -> 12V BATTERY - 1125CCA | E18: =VLOOKUP(B18,'[1]Product by Part Number'!$A:$K,11,0) -> 10 | F18: =VLOOKUP(B18,'[1]Product by Part Number'!$A:$D,4,0) -> 726.37 | G18: =E18*F18 -> 7263.7 | H18: =VLOOKUP(B18,'[1]Product by Part Number'!$A:$E,5,0) -> 292.44 | I18: =ROUND(E18*H18,2) -> 2924.4
B19: 9X-3404 | C19: =VLOOKUP(B19,'[1]Product by Part Number'!$A:$B,2,0) -> CAT 320F L (YBM) CAT 330 (LHW) CAT 330 (LHW) (2) CAT 330 (LHW) (3) CAT 330 (LHW) (4) CAT 330 (WCH) CAT 330 (WCH) (2) CAT 330 (WCH) (3) CAT 330 (WCH) (4) CAT 330 (WCH) (5) CAT 330 (WCH) (6) CAT 561M (1KW) CAT 561N (CPH) CAT 561N (CPH) (2) CAT 561N (CPH) (3) CAT 561N (CPH) (4) CAT 561N (CPH) (5) | D19: =VLOOKUP(B19,'[1]Product by Part Number'!$A:$C,3,0) -> 12V BATTERY - 900CCA | E19: =VLOOKUP(B19,'[1]Product by Part Number'!$A:$K,11,0) -> 54 | F19: =VLOOKUP(B19,'[1]Product by Part Number'!$A:$D,4,0) -> 503.86 | G19: =E19*F19 -> 27208.44 | H19: =VLOOKUP(B19,'[1]Product by Part Number'!$A:$E,5,0) -> 120.88 | I19: =ROUND(E19*H19,2) -> 6527.52
I20: =ROUND(E20*H20,2) -> 0
I21: =ROUND(E21*H21,2) -> 0
I22: =ROUND(E22*H22,2) -> 0
I23: =ROUND(E23*H23,2) -> 0
I24: =ROUND(E24*H24,2) -> 0
I25: =ROUND(E25*H25,2) -> 0
I26: =ROUND(E26*H26,2) -> 0
I27: =ROUND(E27*H27,2) -> 0
I28: =ROUND(E28*H28,2) -> 0
I29: =ROUND(E29*H29,2) -> 0
I30: =ROUND(E30*H30,2) -> 0
I31: =ROUND(E31*H31,2) -> 0
... I57: =ROUND(E57*H57,2) -> 0
H58: Subtotal | I58: =SUM(I15:I57) -> 14219.6
D59: OEM MSRP : | E59: =SUM(G15:G57) -> 51030.27 | H59: Shipping | I59: 0
D60: GQP : | E60: =SUM(I15:I57) -> 14219.6 | H60: Customs/Broker Fee | I60: 0
D61: GQP SAVINGS : | E61: =E59-E60 -> 36810.67 | H61: Total | I61: =SUM(I58:I60) -> 14219.6
H62: GST | I62: =I61*0.05 -> 710.98
H63: PST / QST
B64: Quote valid for 14 days, shipping subject to delays in supply chain. | H64: GRAND TOTAL | I64: =SUM(I61:I63) -> 14930.58

Sheet MOQ Engine
E1: MOQ QUOTE | H1: ENGINE
B7: COMPANY: | C7: Lincoln County | E7: DATE: | F7: 45870 | H7: PO NUMBER:
B8: CONTACT NAME: | C8: 0 | E8: PHONE NUMBER:
B9: BILLING ADDRESS: | C9: 0 | E9: EMAIL ADDRESS:
C10: 0 | E10: SHIPPING ADDRESS:
C11: 0
C12: 0
F13: CAD $
B14: PART NUMBER | C14: Make & Model | D14: DESCRIPTION | E14: QTY | F14: OEM MSRP | H14: GQP PRICE | I14: TOTAL
B15: 6689756 | C15: =VLOOKUP(B15,'[1]Product by Part Number'!$A:$B,2,0) -> BOBCAT T750 (ANK) | D15: =VLOOKUP(B15,'[1]Product by Part Number'!$A:$C,3,0) -> Upper Gasket Kit | E15: =VLOOKUP(B15,'[1]Product by Part Number'!$A:$K,11,0) -> 1 | F15: =VLOOKUP(B15,'[1]Product by Part Number'!$A:$D,4,0) -> 361.99 | G15: =E15*F15 -> 361.99 | H15: =VLOOKUP(B15,'[1]Product by Part Number'!$A:$E,5,0) -> 181 | I15: =ROUND(E15*H15,2) -> 181
B16: 6698579 | C16: =VLOOKUP(B16,'[1]Product by Part Number'!$A:$B,2,0) -> BOBCAT T750 (ANK) | D16: =VLOOKUP(B16,'[1]Product by Part Number'!$A:$C,3,0) -> Lower Gasket Kit | E16: =VLOOKUP(B16,'[1]Product by Part Number'!$A:$K,11,0) -> 1 | F16: =VLOOKUP(B16,'[1]Product by Part Number'!$A:$D,4,0) -> 417.49 | G16: =E16*F16 -> 417.49 | H16: =VLOOKUP(B16,'[1]Product by Part Number'!$A:$E,5,0) -> 208.75 | I16: =ROUND(E16*H16,2) -> 208.75
B17: 7008510 | C17: =VLOOKUP(B17,'[1]Product by Part Number'!$A:$B,2,0) -> BOBCAT S650 (A3N) | D17: =VLOOKUP(B17,'[1]Product by Part Number'!$A:$C,3,0) -> Upper Gasket Kit | E17: =VLOOKUP(B17,'[1]Product by Part Number'!$A:$K,11,0) -> 1 | F17: =VLOOKUP(B17,'[1]Product by Part Number'!$A:$D,4,0) -> 470.49 | G17: =E17*F17 -> 470.49 | H17: =VLOOKUP(B17,'[1]Product by Part Number'!$A:$E,5,0) -> 235.25 | I17: =ROUND(E17*H17,2) -> 235.25
B18: 7008511 | C18: =VLOOKUP(B18,'[1]Product by Part Number'!$A:$B,2,0) -> BOBCAT S650 (A3N) | D18: =VLOOKUP(B18,'[1]Product by Part Number'!$A:$C,3,0) -> Lower Gasket Kit | E18: =VLOOKUP(B18,'[1]Product by Part Number'!$A:$K,11,0) -> 1 | F18: =VLOOKUP(B18,'[1]Product by Part Number'!$A:$D,4,0) -> 482.99 | G18: =E18*F18 -> 482.99 | H18: =VLOOKUP(B18,'[1]Product by Part Number'!$A:$E,5,0) -> 241.5 | I18: =ROUND(E18*H18,2) -> 241.5
B19: 7020950 | C19: =VLOOKUP(B19,'[1]Product by Part Number'!$A:$B,2,0) -> BOBCAT T750 (ANK) | D19: =VLOOKUP(B19,'[1]Product by Part Number'!$A:$C,3,0) -> CYLINDER HEAD | E19: =VLOOKUP(B19,'[1]Product by Part Number'!$A:$K,11,0) -> 1 | F19: =VLOOKUP(B19,'[1]Product by Part Number'!$A:$D,4,0) -> 4359.99 | G19: =E19*F19 -> 4359.99 | H19: =VLOOKUP(B19,'[1]Product by Part Number'!$A:$E,5,0) -> 2180 | I19: =ROUND(E19*H19,2) -> 2180
B20: 7024264 | C20: =VLOOKUP(B20,'[1]Product by Part Number'!$A:$B,2,0) -> BOBCAT T750 (ATF) | D20: =VLOOKUP(B20,'[1]Product by Part Number'!$A:$C,3,0) -> CRANKSHAFT | E20: =VLOOKUP(B20,'[1]Product by Part Number'!$A:$K,11,0) -> 1 | F20: =VLOOKUP(B20,'[1]Product by Part Number'!$A:$D,4,0) -> 6916.49 | G20: =E20*F20 -> 6916.49 | H20: =VLOOKUP(B20,'[1]Product by Part Number'!$A:$E,5,0) -> 3458.25 | I20: =ROUND(E20*H20,2) -> 3458.25
B21: 7024384 | C21: =VLOOKUP(B21,'[1]Product by Part Number'!$A:$B,2,0) -> BOBCAT T750 (ATF) | D21: =VLOOKUP(B21,'[1]Product by Part Number'!$A:$C,3,0) -> CYLINDER HEAD | E21: =VLOOKUP(B21,'[1]Product by Part Number'!$A:$K,11,0) -> 1 | F21: =VLOOKUP(B21,'[1]Product by Part Number'!$A:$D,4,0) -> 2400.49 | G21: =E21*F21 -> 2400.49 | H21: =VLOOKUP(B21,'[1]Product by Part Number'!$A:$E,5,0) -> 1200.25 | I21: =ROUND(E21*H21,2) -> 1200.25
B22: 7024930 | C22: =VLOOKUP(B22,'[1]Product by Part Number'!$A:$B,2,0) -> BOBCAT T750 (ATF) | D22: =VLOOKUP(B22,'[1]Product by Part Number'!$A:$C,3,0) -> Upper Gasket Kit | E22: =VLOOKUP(B22,'[1]Product by Part Number'!$A:$K,11,0) -> 1 | F22: =VLOOKUP(B22,'[1]Product by Part Number'!$A:$D,4,0) -> 587.99 | G22: =E22*F22 -> 587.99 | H22: =VLOOKUP(B22,'[1]Product by Part Number'!$A:$E,5,0) -> 294 | I22: =ROUND(E22*H22,2) -> 294
B23: 7024931 | C23: =VLOOKUP(B23,'[1]Product by Part Number'!$A:$B,2,0) -> BOBCAT T750 (ATF) | D23: =VLOOKUP(B23,'[1]Product by Part Number'!$A:$C,3,0) -> Lower Gasket Kit | E23: =VLOOKUP(B23,'[1]Product by Part Number'!$A:$K,11,0) -> 1 | F23: =VLOOKUP(B23,'[1]Product by Part Number'!$A:$D,4,0) -> 445.99 | G23: =E23*F23 -> 445.99 | H23: =VLOOKUP(B23,'[1]Product by Part Number'!$A:$E,5,0) -> 223 | I23: =ROUND(E23*H23,2) -> 223
B24: 7256752 | C24: =VLOOKUP(B24,'[1]Product by Part Number'!$A:$B,2,0) -> BOBCAT T770 (AT6) BOBCAT T770 (AT6) (2) | D24: =VLOOKUP(B24,'[1]Product by Part Number'!$A:$C,3,0) -> CRANKSHAFT / Gear | E24: =VLOOKUP(B24,'[1]Product by Part Number'!$A:$K,11,0) -> 2 | F24: =VLOOKUP(B24,'[1]Product by Part Number'!$A:$D,4,0) -> 2799.99 | G24: =E24*F24 -> 5599.98 | H24: =VLOOKUP(B24,'[1]Product by Part Number'!$A:$E,5,0) -> 1400 | I24: =ROUND(E24*H24,2) -> 2800
B25: 7298788 | C25: =VLOOKUP(B25,'[1]Product by Part Number'!$A:$B,2,0) -> BOBCAT T770 (AT6) BOBCAT T770 (AT6) (2) | D25: =VLOOKUP(B25,'[1]Product by Part Number'!$A:$C,3,0) -> CYLINDER HEAD | E25: =VLOOKUP(B25,'[1]Product by Part Number'!$A:$K,11,0) -> 2 | F25: =VLOOKUP(B25,'[1]Product by Part Number'!$A:$D,4,0) -> 4052.99 | G25: =E25*F25 -> 8105.98 | H25: =VLOOKUP(B25,'[1]Product by Part Number'!$A:$E,5,0) -> 2026.5 | I25: =ROUND(E25*H25,2) -> 4053
B26: 134-5276 | C26: =VLOOKUP(B26,'[1]Product by Part Number'!$A:$B,2,0) -> CAT D5 (3CR) CAT D5 (3CR) (2) CAT 561M (1KW) | D26: =VLOOKUP(B26,'[1]Product by Part Number'!$A:$C,3,0) -> CAMSHAFT | E26: =VLOOKUP(B26,'[1]Product by Part Number'!$A:$K,11,0) -> 3 | F26: =VLOOKUP(B26,'[1]Product by Part Number'!$A:$D,4,0) -> 4368 | G26: =E26*F26 -> 13104 | H26: =VLOOKUP(B26,'[1]Product by Part Number'!$A:$E,5,0) -> 2184 | I26: =ROUND(E26*H26,2) -> 6552
B27: 216-7921 | C27: =VLOOKUP(B27,'[1]Product by Part Number'!$A:$B,2,0) -> CAT 561N (CPH) CAT 561N (CPH) (2) CAT 561N (CPH) (3) CAT 561N (CPH) (4) CAT 561N (CPH) (5) CAT PL61 (WGS) CAT PL61 (WGS) (2) CAT PL61 (WGS) (3) | D27: =VLOOKUP(B27,'[1]Product by Part Number'!$A:$C,3,0) -> CAMSHAFT | E27: =VLOOKUP(B27,'[1]Product by Part Number'!$A:$K,11,0) -> 8 | F27: =VLOOKUP(B27,'[1]Product by Part Number'!$A:$D,4,0) -> 4686.51 | G27: =E27*F27 -> 37492.08 | H27: =VLOOKUP(B27,'[1]Product by Part Number'!$A:$E,5,0) -> 2343.26 | I27: =ROUND(E27*H27,2) -> 18746.08
B28: 334-8389 | C28: =VLOOKUP(B28,'[1]Product by Part Number'!$A:$B,2,0) -> CAT D7G (92V) CAT D7G (3ZD) CAT D7G (3ZD) (2) | D28: =VLOOKUP(B28,'[1]Product by Part Number'!$A:$C,3,0) -> CRANKSHAFT ASSY | E28: =VLOOKUP(B28,'[1]Product by Part Number'!$A:$K,11,0) -> 3 | F28: =VLOOKUP(B28,'[1]Product by Part Number'!$A:$D,4,0) -> 17640.77 | G28: =E28*F28 -> 52922.31 | H28: =VLOOKUP(B28,'[1]Product by Part Number'!$A:$E,5,0) -> 8820.39 | I28: =ROUND(E28*H28,2) -> 26461.17
B29: 383-0293 | C29: =VLOOKUP(B29,'[1]Product by Part Number'!$A:$B,2,0) -> CAT 303.5E | D29: =VLOOKUP(B29,'[1]Product by Part Number'!$A:$C,3,0) -> OIL PUMP ENGINE | E29: =VLOOKUP(B29,'[1]Product by Part Number'!$A:$K,11,0) -> 1 | F29: =VLOOKUP(B29,'[1]Product by Part Number'!$A:$D,4,0) -> 831.44 | G29: =E29*F29 -> 831.44 | H29: =VLOOKUP(B29,'[1]Product by Part Number'!$A:$E,5,0) -> 415.72 | I29: =ROUND(E29*H29,2) -> 415.72
B30: 383-0433 | C30: =VLOOKUP(B30,'[1]Product by Part Number'!$A:$B,2,0) -> CAT 303.5E | D30: =VLOOKUP(B30,'[1]Product by Part Number'!$A:$C,3,0) -> WATER PUMP | E30: =VLOOKUP(B30,'[1]Product by Part Number'!$A:$K,11,0) -> 1 | F30: =VLOOKUP(B30,'[1]Product by Part Number'!$A:$D,4,0) -> 512.79 | G30: =E30*F30 -> 512.79 | H30: =VLOOKUP(B30,'[1]Product by Part Number'!$A:$E,5,0) -> 256.4 | I30: =ROUND(E30*H30,2) -> 256.4
B31: 386-6920 | C31: =VLOOKUP(B31,'[1]Product by Part Number'!$A:$B,2,0) -> CAT 303.5E | D31: =VLOOKUP(B31,'[1]Product by Part Number'!$A:$C,3,0) -> CYLINDER HEAD | E31: =VLOOKUP(B31,'[1]Product by Part Number'!$A:$K,11,0) -> 1 | F31: =VLOOKUP(B31,'[1]Product by Part Number'!$A:$D,4,0) -> 3744.05 | G31: =E31*F31 -> 3744.05 | H31: =VLOOKUP(B31,'[1]Product by Part Number'!$A:$E,5,0) -> 1872.03 | I31: =ROUND(E31*H31,2) -> 1872.03
B32: 386-6934 | C32: =VLOOKUP(B32,'[1]Product by Part Number'!$A:$B,2,0) -> CAT 303.5E | D32: =VLOOKUP(B32,'[1]Product by Part Number'!$A:$C,3,0) -> CAMSHAFT AS | E32: =VLOOKUP(B32,'[1]Product by Part Number'!$A:$K,11,0) -> 1 | F32: =VLOOKUP(B32,'[1]Product by Part Number'!$A:$D,4,0) -> 515.17 | G32: =E32*F32 -> 515.17 | H32: =VLOOKUP(B32,'[1]Product by Part Number'!$A:$E,5,0) -> 257.59 | I32: =ROUND(E32*H32,2) -> 257.59
B33: 386-6936 | C33: =VLOOKUP(B33,'[1]Product by Part Number'!$A:$B,2,0) -> CAT 303.5E | D33: =VLOOKUP(B33,'[1]Product by Part Number'!$A:$C,3,0) -> CRANKSHAFT ASSY | E33: =VLOOKUP(B33,'[1]Product by Part Number'!$A:$K,11,0) -> 1 | F33: =VLOOKUP(B33,'[1]Product by Part Number'!$A:$D,4,0) -> 4035.36 | G33: =E33*F33 -> 4035.36 | H33: =VLOOKUP(B33,'[1]Product by Part Number'!$A:$E,5,0) -> 2017.68 | I33: =ROUND(E33*H33,2) -> 2017.68
B34: 389-5128 | C34: =VLOOKUP(B34,'[1]Product by Part Number'!$A:$B,2,0) -> CAT 299D (DX2) | D34: =VLOOKUP(B34,'[1]Product by Part Number'!$A:$C,3,0) -> CYLINDER HEAD | E34: =VLOOKUP(B34,'[1]Product by Part Number'!$A:$K,11,0) -> 1 | F34: =VLOOKUP(B34,'[1]Product by Part Number'!$A:$D,4,0) -> 9634.25 | G34: =E34*F34 -> 9634.25 | H34: =VLOOKUP(B34,'[1]Product by Part Number'!$A:$E,5,0) -> 4817.13 | I34: =ROUND(E34*H34,2) -> 4817.13
B35: 389-5185 | C35: =VLOOKUP(B35,'[1]Product by Part Number'!$A:$B,2,0) -> CAT 299D (DX2) | D35: =VLOOKUP(B35,'[1]Product by Part Number'!$A:$C,3,0) -> CRANKSHAFT | E35: =VLOOKUP(B35,'[1]Product by Part Number'!$A:$K,11,0) -> 1 | F35: =VLOOKUP(B35,'[1]Product by Part Number'!$A:$D,4,0) -> 4526.64 | G35: =E35*F35 -> 4526.64 | H35: =VLOOKUP(B35,'[1]Product by Part Number'!$A:$E,5,0) -> 2263.32 | I35: =ROUND(E35*H35,2) -> 2263.32
B36: 389-5200 | C36: =VLOOKUP(B36,'[1]Product by Part Number'!$A:$B,2,0) -> CAT 299D (DX2) | D36: =VLOOKUP(B36,'[1]Product by Part Number'!$A:$C,3,0) -> CAMSHAFT | E36: =VLOOKUP(B36,'[1]Product by Part Number'!$A:$K,11,0) -> 1 | F36: =VLOOKUP(B36,'[1]Product by Part Number'!$A:$D,4,0) -> 1117.59 | G36: =E36*F36 -> 1117.59 | H36: =VLOOKUP(B36,'[1]Product by Part Number'!$A:$E,5,0) -> 558.8 | I36: =ROUND(E36*H36,2) -> 558.8
B37: 489-2731 | C37: =VLOOKUP(B37,'[1]Product by Part Number'!$A:$B,2,0) -> CAT D5 (3CR) CAT D5 (3CR) (2) CAT 561M (1KW) CAT 561N (CPH) CAT 561N (CPH) (2) CAT 561N (CPH) (3) CAT 561N (CPH) (4) CAT 561N (CPH) (5) CAT PL61 (WGS) CAT PL61 (WGS) (2) CAT PL61 (WGS) (3) | D37: =VLOOKUP(B37,'[1]Product by Part Number'!$A:$C,3,0) -> CRANKSHAFT | E37: =VLOOKUP(B37,'[1]Product by Part Number'!$A:$K,11,0) -> 11 | F37: =VLOOKUP(B37,'[1]Product by Part Number'!$A:$D,4,0) -> 14944.09 | G37: =E37*F37 -> 164384.99 | H37: =VLOOKUP(B37,'[1]Product by Part Number'!$A:$E,5,0) -> 7472.05 | I37: =ROUND(E37*H37,2) -> 82192.55
... B52: CUSTOM-GQPD7GSOK | C52: =VLOOKUP(B52,'[1]Product by Part Number'!$A:$B,2,0) -> CAT D7G (92V) CAT D7G (3ZD) CAT D7G (3ZD) (2) | D52: =VLOOKUP(B52,'[1]Product by Part Number'!$A:$C,3,0) -> SILVER ENGINE OVERHAUL KIT | E52: =VLOOKUP(B52,'[1]Product by Part Number'!$A:$K,11,0) -> 3 | F52: =VLOOKUP(B52,'[1]Product by Part Number'!$A:$D,4,0) -> 6725.5 | G52: =E52*F52 -> 20176.5 | H52: =VLOOKUP(B52,'[1]Product by Part Number'!$A:$E,5,0) -> 3362.75 | I52: =ROUND(E52*H52,2) -> 10088.25
I53: =ROUND(E53*H53,2) -> 0
I54: =ROUND(E54*H54,2) -> 0
I55: =ROUND(E55*H55,2) -> 0
I56: =ROUND(E56*H56,2) -> 0
I57: =ROUND(E57*H57,2) -> 0
I58: =ROUND(E58*H58,2) -> 0
I59: =ROUND(E59*H59,2) -> 0
...

Sheet MOQ Filters Q1
E1: MOQ QUOTE | H1: Filters Q1
B7: COMPANY: | C7: Lincoln County | E7: DATE: | F7: 45870 | H7: PO NUMBER:
B8: CONTACT NAME: | C8: 0 | E8: PHONE NUMBER:
B9: BILLING ADDRESS: | C9: 0 | E9: EMAIL ADDRESS:
C10: 0 | E10: SHIPPING ADDRESS:
C11: 0
C12: 0
F13: CAD $
B14: PART NUMBER | C14: Make & Model | D14: DESCRIPTION | E14: QTY | F14: OEM MSRP | H14: GQP PRICE | I14: TOTAL
B15: 7008043 | C15: =VLOOKUP(B15,[1]!Table3[[Part Number]:[Make and Model]],2,0) -> BOBCAT S650 (A3N) | D15: =VLOOKUP(B15,[1]!Table3[[Part Number]:[Part Description]],3,0) -> PRIMARY AIR FILTER ELEMENT (OUTER) | E15: =VLOOKUP(B15,[1]!Table3[[Part Number]:[Q1 QTY]],7,0) -> 1 | F15: =VLOOKUP(B15,[1]!Table3[[Part Number]:[OEM CAD $]],4,0) -> 62.49 | G15: =E15*F15 -> 62.49 | H15: =VLOOKUP(B15,[1]!Table3[[Part Number]:[GQP CAD $]],5,0) -> 23.75 | I15: =ROUND(E15*H15,2) -> 23.75
B16: 7008044 | C16: =VLOOKUP(B16,[1]!Table3[[Part Number]:[Make and Model]],2,0) -> BOBCAT S650 (A3N) | D16: =VLOOKUP(B16,[1]!Table3[[Part Number]:[Part Description]],3,0) -> SECONDARY AIR FILTER ELEMENT | E16: =VLOOKUP(B16,[1]!Table3[[Part Number]:[Q1 QTY]],7,0) -> 1 | F16: =VLOOKUP(B16,[1]!Table3[[Part Number]:[OEM CAD $]],4,0) -> 39.99 | G16: =E16*F16 -> 39.99 | H16: =VLOOKUP(B16,[1]!Table3[[Part Number]:[GQP CAD $]],5,0) -> 15.2 | I16: =ROUND(E16*H16,2) -> 15.2
B17: 7010031 | C17: =VLOOKUP(B17,[1]!Table3[[Part Number]:[Make and Model]],2,0) -> BOBCAT T750 (ANK) BOBCAT T750 (ATF) BOBCAT T770 (AT6) BOBCAT T770 (AT6) (2) | D17: =VLOOKUP(B17,[1]!Table3[[Part Number]:[Part Description]],3,0) -> SECONDARY AIR FILTER ELEMENT | E17: =VLOOKUP(B17,[1]!Table3[[Part Number]:[Q1 QTY]],7,0) -> 4 | F17: =VLOOKUP(B17,[1]!Table3[[Part Number]:[OEM CAD $]],4,0) -> 103.99 | G17: =E17*F17 -> 415.96 | H17: =VLOOKUP(B17,[1]!Table3[[Part Number]:[GQP CAD $]],5,0) -> 39.52 | I17: =ROUND(E17*H17,2) -> 158.08
B18: 7286652 | C18: =VLOOKUP(B18,[1]!Table3[[Part Number]:[Make and Model]],2,0) -> BOBCAT T750 (ANK) BOBCAT T750 (ATF) BOBCAT T770 (AT6) BOBCAT T770 (AT6) (2) | D18: =VLOOKUP(B18,[1]!Table3[[Part Number]:[Part Description]],3,0) -> PRIMARY AIR FILTER ELEMENT (OUTER) | E18: =VLOOKUP(B18,[1]!Table3[[Part Number]:[Q1 QTY]],7,0) -> 4 | F18: =VLOOKUP(B18,[1]!Table3[[Part Number]:[OEM CAD $]],4,0) -> 140.99 | G18: =E18*F18 -> 563.96 | H18: =VLOOKUP(B18,[1]!Table3[[Part Number]:[GQP CAD $]],5,0) -> 53.58 | I18: =ROUND(E18*H18,2) -> 214.32
B19: 110-6326 | C19: =VLOOKUP(B19,[1]!Table3[[Part Number]:[Make and Model]],2,0) -> CAT 299D (DX2) | D19: =VLOOKUP(B19,[1]!Table3[[Part Number]:[Part Description]],3,0) -> PRIMARY AIR FILTER ELEMENT | E19: =VLOOKUP(B19,[1]!Table3[[Part Number]:[Q1 QTY]],7,0) -> 1 | F19: =VLOOKUP(B19,[1]!Table3[[Part Number]:[OEM CAD $]],4,0) -> 76.02 | G19: =E19*F19 -> 76.02 | H19: =VLOOKUP(B19,[1]!Table3[[Part Number]:[GQP CAD $]],5,0) -> 28.89 | I19: =ROUND(E19*H19,2) -> 28.89
B20: 110-6331 | C20: =VLOOKUP(B20,[1]!Table3[[Part Number]:[Make and Model]],2,0) -> CAT 299D (DX2) | D20: =VLOOKUP(B20,[1]!Table3[[Part Number]:[Part Description]],3,0) -> SECONDARY AIR FILTER ELEMENT | E20: =VLOOKUP(B20,[1]!Table3[[Part Number]:[Q1 QTY]],7,0) -> 1 | F20: =VLOOKUP(B20,[1]!Table3[[Part Number]:[OEM CAD $]],4,0) -> 54.17 | G20: =E20*F20 -> 54.17 | H20: =VLOOKUP(B20,[1]!Table3[[Part Number]:[GQP CAD $]],5,0) -> 20.58 | I20: =ROUND(E20*H20,2) -> 20.58
B21: 112-7448 | C21: =VLOOKUP(B21,[1]!Table3[[Part Number]:[Make and Model]],2,0) -> CAT D6T (MH7) | D21: =VLOOKUP(B21,[1]!Table3[[Part Number]:[Part Description]],3,0) -> CABIN AIR FILTER ELEMENT | E21: =VLOOKUP(B21,[1]!Table3[[Part Number]:[Q1 QTY]],7,0) -> 1 | F21: =VLOOKUP(B21,[1]!Table3[[Part Number]:[OEM CAD $]],4,0) -> 43.37 | G21: =E21*F21 -> 43.37 | H21: =VLOOKUP(B21,[1]!Table3[[Part Number]:[GQP CAD $]],5,0) -> 16.48 | I21: =ROUND(E21*H21,2) -> 16.48
B22: 131-8821 | C22: =VLOOKUP(B22,[1]!Table3[[Part Number]:[Make and Model]],2,0) -> CAT 320E L (WBK) CAT 320E L (WBK) (2) CAT 320F L (YBM) | D22: =VLOOKUP(B22,[1]!Table3[[Part Number]:[Part Description]],3,0) -> SECONDARY AIR FILTER ELEMENT | E22: =VLOOKUP(B22,[1]!Table3[[Part Number]:[Q1 QTY]],7,0) -> 3 | F22: =VLOOKUP(B22,[1]!Table3[[Part Number]:[OEM CAD $]],4,0) -> 97.91 | G22: =E22*F22 -> 293.73 | H22: =VLOOKUP(B22,[1]!Table3[[Part Number]:[GQP CAD $]],5,0) -> 37.21 | I22: =ROUND(E22*H22,2) -> 111.63
B23: 131-8822 | C23: =VLOOKUP(B23,[1]!Table3[[Part Number]:[Make and Model]],2,0) -> CAT 320E L (WBK) CAT 320E L (WBK) (2) CAT 320F L (YBM) | D23: =VLOOKUP(B23,[1]!Table3[[Part Number]:[Part Description]],3,0) -> PRIMARY AIR FILTER ELEMENT | E23: =VLOOKUP(B23,[1]!Table3[[Part Number]:[Q1 QTY]],7,0) -> 3 | F23: =VLOOKUP(B23,[1]!Table3[[Part Number]:[OEM CAD $]],4,0) -> 120.35 | G23: =E23*F23 -> 361.05 | H23: =VLOOKUP(B23,[1]!Table3[[Part Number]:[GQP CAD $]],5,0) -> 45.73 | I23: =ROUND(E23*H23,2) -> 137.19
B24: 134-8726 | C24: =VLOOKUP(B24,[1]!Table3[[Part Number]:[Make and Model]],2,0) -> CAT 303.5E | D24: =VLOOKUP(B24,[1]!Table3[[Part Number]:[Part Description]],3,0) -> PRIMARY AIR FILTER ELEMENT | E24: =VLOOKUP(B24,[1]!Table3[[Part Number]:[Q1 QTY]],7,0) -> 1 | F24: =VLOOKUP(B24,[1]!Table3[[Part Number]:[OEM CAD $]],4,0) -> 67.33 | G24: =E24*F24 -> 67.33 | H24: =VLOOKUP(B24,[1]!Table3[[Part Number]:[GQP CAD $]],5,0) -> 25.59 | I24: =ROUND(E24*H24,2) -> 25.59
B25: 140-2334 | C25: =VLOOKUP(B25,[1]!Table3[[Part Number]:[Make and Model]],2,0) -> CAT 303.5E | D25: =VLOOKUP(B25,[1]!Table3[[Part Number]:[Part Description]],3,0) -> SECONDARY AIR FILTER ELEMENT | E25: =VLOOKUP(B25,[1]!Table3[[Part Number]:[Q1 QTY]],7,0) -> 1 | F25: =VLOOKUP(B25,[1]!Table3[[Part Number]:[OEM CAD $]],4,0) -> 61.69 | G25: =E25*F25 -> 61.69 | H25: =VLOOKUP(B25,[1]!Table3[[Part Number]:[GQP CAD $]],5,0) -> 23.44 | I25: =ROUND(E25*H25,2) -> 23.44
B26: 142-1339 | C26: =VLOOKUP(B26,[1]!Table3[[Part Number]:[Make and Model]],2,0) -> CAT 336F L (RKB) | D26: =VLOOKUP(B26,[1]!Table3[[Part Number]:[Part Description]],3,0) -> PRIMARY AIR FILTER ELEMENT | E26: =VLOOKUP(B26,[1]!Table3[[Part Number]:[Q1 QTY]],7,0) -> 1 | F26: =VLOOKUP(B26,[1]!Table3[[Part Number]:[OEM CAD $]],4,0) -> 201.81 | G26: =E26*F26 -> 201.81 | H26: =VLOOKUP(B26,[1]!Table3[[Part Number]:[GQP CAD $]],5,0) -> 76.69 | I26: =ROUND(E26*H26,2) -> 76.69
B27: 142-1404 | C27: =VLOOKUP(B27,[1]!Table3[[Part Number]:[Make and Model]],2,0) -> CAT 336F L (RKB) | D27: =VLOOKUP(B27,[1]!Table3[[Part Number]:[Part Description]],3,0) -> SECONDARY AIR FILTER ELEMENT | E27: =VLOOKUP(B27,[1]!Table3[[Part Number]:[Q1 QTY]],7,0) -> 1 | F27: =VLOOKUP(B27,[1]!Table3[[Part Number]:[OEM CAD $]],4,0) -> 119.45 | G27: =E27*F27 -> 119.45 | H27: =VLOOKUP(B27,[1]!Table3[[Part Number]:[GQP CAD $]],5,0) -> 45.39 | I27: =ROUND(E27*H27,2) -> 45.39
B28: 151-0914 | C28: =VLOOKUP(B28,[1]!Table3[[Part Number]:[Make and Model]],2,0) -> CAT D6N LGP (PBA) CAT D6N LGP (PBA) (2) | D28: =VLOOKUP(B28,[1]!Table3[[Part Number]:[Part Description]],3,0) -> PRIMARY CABIN AIR FILTER ELEMENT | E28: =VLOOKUP(B28,[1]!Table3[[Part Number]:[Q1 QTY]],7,0) -> 2 | F28: =VLOOKUP(B28,[1]!Table3[[Part Number]:[OEM CAD $]],4,0) -> 112.48 | G28: =E28*F28 -> 224.96 | H28: =VLOOKUP(B28,[1]!Table3[[Part Number]:[GQP CAD $]],5,0) -> 42.74 | I28: =ROUND(E28*H28,2) -> 85.48
B29: 209-8217 | C29: =VLOOKUP(B29,[1]!Table3[[Part Number]:[Make and Model]],2,0) -> CAT PL61 (WGS) CAT PL61 (WGS) (2) CAT PL61 (WGS) (3) | D29: =VLOOKUP(B29,[1]!Table3[[Part Number]:[Part Description]],3,0) -> CABIN AIR FILTER ELEMENT | E29: =VLOOKUP(B29,[1]!Table3[[Part Number]:[Q1 QTY]],7,0) -> 3 | F29: =VLOOKUP(B29,[1]!Table3[[Part Number]:[OEM CAD $]],4,0) -> 85.17 | G29: =E29*F29 -> 255.51 | H29: =VLOOKUP(B29,[1]!Table3[[Part Number]:[GQP CAD $]],5,0) -> 32.36 | I29: =ROUND(E29*H29,2) -> 97.08
B30: 252-5001 | C30: =VLOOKUP(B30,[1]!Table3[[Part Number]:[Make and Model]],2,0) -> CAT D6N LGP (GHS) CAT PL61 (WGS) CAT PL61 (WGS) (2) CAT PL61 (WGS) (3) | D30: =VLOOKUP(B30,[1]!Table3[[Part Number]:[Part Description]],3,0) -> PRIMARY AIR FILTER ELEMENT | E30: =VLOOKUP(B30,[1]!Table3[[Part Number]:[Q1 QTY]],7,0) -> 4 | F30: =VLOOKUP(B30,[1]!Table3[[Part Number]:[OEM CAD $]],4,0) -> 221.03 | G30: =E30*F30 -> 884.12 | H30: =VLOOKUP(B30,[1]!Table3[[Part Number]:[GQP CAD $]],5,0) -> 83.99 | I30: =ROUND(E30*H30,2) -> 335.96
... B60: 9S-9972 | C60: =VLOOKUP(B60,[1]!Table3[[Part Number]:[Make and Model]],2,0) -> CAT D7G (92V) CAT D7G (3ZD) CAT D7G (3ZD) (2) | D60: =VLOOKUP(B60,[1]!Table3[[Part Number]:[Part Description]],3,0) -> SECONDARY AIR FILTER ELEMENT | E60: =VLOOKUP(B60,[1]!Table3[[Part Number]:[Q1 QTY]],7,0) -> 3 | F60: =VLOOKUP(B60,[1]!Table3[[Part Number]:[OEM CAD $]],4,0) -> 115.44 | G60: =E60*F60 -> 346.32 | H60: =VLOOKUP(B60,[1]!Table3[[Part Number]:[GQP CAD $]],5,0) -> 43.87 | I60: =ROUND(E60*H60,2) -> 131.61
B61: 6692337 | C61: =VLOOKUP(B61,[1]!Table3[[Part Number]:[Make and Model]],2,0) -> BOBCAT T750 (ATF) BOBCAT S650 (A3N) | D61: =VLOOKUP(B61,[1]!Table3[[Part Number]:[Part Description]],3,0) -> HYDRAULIC OIL FILTER ELEMENT | E61: =VLOOKUP(B61,[1]!Table3[[Part Number]:[Q1 QTY]],7,0) -> 2 | F61: =VLOOKUP(B61,[1]!Table3[[Part Number]:[OEM CAD $]],4,0) -> 93.99 | G61: =E61*F61 -> 187.98 | H61: =VLOOKUP(B61,[1]!Table3[[Part Number]:[GQP CAD $]],5,0) -> 35.72 | I61: =ROUND(E61*H61,2) -> 71.44
B62: 7012314 | C62: =VLOOKUP(B62,[1]!Table3[[Part Number]:[Make and Model]],2,0) -> BOBCAT T750 (ANK) | D62: =VLOOKUP(B62,[1]!Table3[[Part Number]:[Part Description]],3,0) -> HYDRAULIC OIL FILTER ELEMENT | E62: =VLOOKUP(B62,[1]!Table3[[Part Number]:[Q1 QTY]],7,0) -> 1 | F62: =VLOOKUP(B62,[1]!Table3[[Part Number]:[OEM CAD $]],4,0) -> 138.99 | G62: =E62*F62 -> 138.99 | H62: =VLOOKUP(B62,[1]!Table3[[Part Number]:[GQP CAD $]],5,0) -> 52.82 | I62: =ROUND(E62*H62,2) -> 52.82
B63: 7414582 | C63: =VLOOKUP(B63,[1]!Table3[[Part Number]:[Make and Model]],2,0) -> BOBCAT T770 (AT6) BOBCAT T770 (AT6) (2) | D63: =VLOOKUP(B63,[1]!Table3[[Part Number]:[Part Description]],3,0) -> HYDRAULIC OIL FILTER ELEMENT | E63: =VLOOKUP(B63,[1]!Table3[[Part Number]:[Q1 QTY]],7,0) -> 2 | F63: =VLOOKUP(B63,[1]!Table3[[Part Number]:[OEM CAD $]],4,0) -> 117.99 | G63: =E63*F63 -> 235.98 | H63: =VLOOKUP(B63,[1]!Table3[[Part Number]:[GQP CAD $]],5,0) -> 44.84 | I63: =ROUND(E63*H63,2) -> 89.68
B64: 093-7521 | C64: =VLOOKUP(B64,[1]!Table3[[Part Number]:[Make and Model]],2,0) -> CAT 320F L (YBM) CAT 336F L (RKB) | D64: =VLOOKUP(B64,[1]!Table3[[Part Number]:[Part Description]],3,0) -> HYDRAULIC OIL FILTER | E64: =VLOOKUP(B64,[1]!Table3[[Part Number]:[Q1 QTY]],7,0) -> 2 | F64: =VLOOKUP(B64,[1]!Table3[[Part Number]:[OEM CAD $]],4,0) -> 102.09 | G64: =E64*F64 -> 204.18 | H64: =VLOOKUP(B64,[1]!Table3[[Part Number]:[GQP CAD $]],5,0) -> 38.79 | I64: =ROUND(E64*H64,2) -> 77.58
B65: 169-4019 | C65: =VLOOKUP(B65,[1]!Table3[[Part Number]:[Make and Model]],2,0) -> CAT D4 (66J) | D65: =VLOOKUP(B65,[1]!Table3[[Part Number]:[Part Description]],3,0) -> HYDRAULIC OIL FILTER | E65: =VLOOKUP(B65,[1]!Table3[[Part Number]:[Q1 QTY]],7,0) -> 1 | F65: =VLOOKUP(B65,[1]!Table3[[Part Number]:[OEM CAD $]],4,0) -> 703.78 | G65: =E65*F65 -> 703.78 | H65: =VLOOKUP(B65,[1]!Table3[[Part Number]:[GQP CAD $]],5,0) -> 267.44 | I65: =ROUND(E65*H65,2) -> 267.44
B66: 179-9806 | C66: =VLOOKUP(B66,[1]!Table3[[Part Number]:[Make and Model]],2,0) -> CAT 320E L (WBK) CAT 320E L (WBK) (2) CAT 320F L (YBM) CAT 329E L (ZCD) CAT 329F L (ERL) CAT 329F L (ERL) (2) CAT 330F L (MBX) CAT 330F L (HCK) CAT 330F L (HCK) (2) CAT 336F L (RKB) | D66: =VLOOKUP(B66,[1]!Table3[[Part Number]:[Part Description]],3,0) -> HYDRAULIC OIL FILTER ELEMENT | E66: =VLOOKUP(B66,[1]!Table3[[Part Number]:[Q1 QTY]],7,0) -> 12 | F66: =VLOOKUP(B66,[1]!Table3[[Part Number]:[OEM CAD $]],4,0) -> 229 | G66: =E66*F66 -> 2748 | H66: =VLOOKUP(B66,[1]!Table3[[Part Number]:[GQP CAD $]],5,0) -> 87.02 | I66: =ROUND(E66*H66,2) -> 1044.24
B67: 1G-8878 | C67: =VLOOKUP(B67,[1]!Table3[[Part Number]:[Make and Model]],2,0) -> CAT PL61 (WGS) CAT PL61 (WGS) (2) CAT PL61 (WGS) (3) | D67: =VLOOKUP(B67,[1]!Table3[[Part Number]:[Part Description]],3,0) -> HYDRAULIC OIL FILTER ELEMENT | E67: =VLOOKUP(B67,[1]!Table3[[Part Number]:[Q1 QTY]],7,0) -> 3 | F67: =VLOOKUP(B67,[1]!Table3[[Part Number]:[OEM CAD $]],4,0) -> 150.47 | G67: =E67*F67 -> 451.41 | H67: =VLOOKUP(B67,[1]!Table3[[Part Number]:[GQP CAD $]],5,0) -> 57.18 | I67: =ROUND(E67*H67,2) -> 171.54
B68: 1R-0719 | C68: =VLOOKUP(B68,[1]!Table3[[Part Number]:[Make and Model]],2,0) -> CAT D3 (1PJ) CAT D5 (3CR) CAT D5 (3CR) (2) | D68: =VLOOKUP(B68,[1]!Table3[[Part Number]:[Part Description]],3,0) -> HYDRAULIC OIL FILTER | E68: =VLOOKUP(B68,[1]!Table3[[Part Number]:[Q1 QTY]],7,0) -> 3 | F68: =VLOOKUP(B68,[1]!Table3[[Part Number]:[OEM CAD $]],4,0) -> 38.32 | G68: =E68*F68 -> 114.96 | H68: =VLOOKUP(B68,[1]!Table3[[Part Number]:[GQP CAD $]],5,0) -> 14.56 | I68: =ROUND(E68*H68,2) -> 43.68
B69: 1R-0746 | C69: =VLOOKUP(B69,[1]!Table3[[Part Number]:[Make and Model]],2,0) -> CAT D3 (1PJ) | D69: =VLOOKUP(B69,[1]!Table3[[Part Number]:[Part Description]],3,0) -> HYDRAULIC/TRANSMISSION OIL FILTER | E69: =VLOOKUP(B69,[1]!Table3[[Part Number]:[Q1 QTY]],7,0) -> 1 | F69: =VLOOKUP(B69,[1]!Table3[[Part Number]:[OEM CAD $]],4,0) -> 47.44 | G69: =E69*F69 -> 47.44 | H69: =VLOOKUP(B69,[1]!Table3[[Part Number]:[GQP CAD $]],5,0) -> 18.03 | I69: =ROUND(E69*H69,2) -> 18.03
B70: 1R-0777 | C70: =VLOOKUP(B70,[1]!Table3[[Part Number]:[Make and Model]],2,0) -> CAT D4 (66J) | D70: =VLOOKUP(B70,[1]!Table3[[Part Number]:[Part Description]],3,0) -> HYDRAULIC OIL FILTER ELEMENT | E70: =VLOOKUP(B70,[1]!Table3[[Part Number]:[Q1 QTY]],7,0) -> 1 | F70: =VLOOKUP(B70,[1]!Table3[[Part Number]:[OEM CAD $]],4,0) -> 93.49 | G70: =E70*F70 -> 93.49 | H70: =VLOOKUP(B70,[1]!Table3[[Part Number]:[GQP CAD $]],5,0) -> 35.53 | I70: =ROUND(E70*H70,2) -> 35.53
B71: 304-7196 | C71: =VLOOKUP(B71,[1]!Table3[[Part Number]:[Make and Model]],2,0) -> CAT 303.5E | D71: =VLOOKUP(B71,[1]!Table3[[Part Number]:[Part Description]],3,0) -> HYDRAULIC OIL FILTER | E71: =VLOOKUP(B71,[1]!Table3[[Part Number]:[Q1 QTY]],7,0) -> 1 | F71: =VLOOKUP(B71,[1]!Table3[[Part Number]:[OEM CAD $]],4,0) -> 130.47 | G71: =E71*F71 -> 130.47 | H71: =VLOOKUP(B71,[1]!Table3[[Part Number]:[GQP CAD $]],5,0) -> 49.58 | I71: =ROUND(E71*H71,2) -> 49.58
B72: 328-3655 | C72: =VLOOKUP(B72,[1]!Table3[[Part Number]:[Make and Model]],2,0) -> CAT D6N LGP (GHS) | D72: =VLOOKUP(B72,[1]!Table3[[Part Number]:[Part Description]],3,0) -> HYDRAULIC OIL FILTER ELEMENT | E72: =VLOOKUP(B72,[1]!Table3[[Part Number]:[Q1 QTY]],7,0) -> 1 | F72: =VLOOKUP(B72,[1]!Table3[[Part Number]:[OEM CAD $]],4,0) -> 204.36 | G72: =E72*F72 -> 204.36 | H72: =VLOOKUP(B72,[1]!Table3[[Part Number]:[GQP CAD $]],5,0) -> 77.66 | I72: =ROUND(E72*H72,2) -> 77.66
B73: 376-2025 | C73: =VLOOKUP(B73,[1]!Table3[[Part Number]:[Make and Model]],2,0) -> CAT 303.5E | D73: =VLOOKUP(B73,[1]!Table3[[Part Number]:[Part Description]],3,0) -> HYDRAULIC PUMP | E73: =VLOOKUP(B73,[1]!Table3[[Part Number]:[Q1 QTY]],7,0) -> 1 | F73: =VLOOKUP(B73,[1]!Table3[[Part Number]:[OEM CAD $]],4,0) -> 7622.73 | G73: =E73*F73 -> 7622.73 | H73: =VLOOKUP(B73,[1]!Table3[[Part Number]:[GQP CAD $]],5,0) -> 3811.37 | I73: =ROUND(E73*H73,2) -> 3811.37
B74: 421-5479 | C74: =VLOOKUP(B74,[1]!Table3[[Part Number]:[Make and Model]],2,0) -> CAT 299D (DX2) | D74: =VLOOKUP(B74,[1]!Table3[[Part Number]:[Part Description]],3,0) -> HYDRAULIC OIL FILTER ELEMENT | E74: =VLOOKUP(B74,[1]!Table3[[Part Number]:[Q1 QTY]],7,0) -> 1 | F74: =VLOOKUP(B74,[1]!Table3[[Part Number]:[OEM CAD $]],4,0) -> 72.07 | G74: =E74*F74 -> 72.07 | H74: =VLOOKUP(B74,[1]!Table3[[Part Number]:[GQP CAD $]],5,0) -> 27.39 | I74: =ROUND(E74*H74,2) -> 27.39
...

Sheet MOQ Filters Q2
E1: MOQ QUOTE | H1: Filters Q1
B7: COMPANY: | C7: Lincoln County | E7: DATE: | F7: 45870 | H7: PO NUMBER:
B8: CONTACT NAME: | C8: 0 | E8: PHONE NUMBER:
B9: BILLING ADDRESS: | C9: 0 | E9: EMAIL ADDRESS:
C10: 0 | E10: SHIPPING ADDRESS:
C11: 0
C12: 0
F13: CAD $
B14: PART NUMBER | C14: Make & Model | D14: DESCRIPTION | E14: QTY | F14: OEM MSRP | H14: GQP PRICE | I14: TOTAL
B15: 7008043 | C15: =VLOOKUP(B15,[1]!Table3[[Part Number]:[Make and Model]],2,0) -> BOBCAT S650 (A3N) | D15: =VLOOKUP(B15,[1]!Table3[[Part Number]:[Part Description]],3,0) -> PRIMARY AIR FILTER ELEMENT (OUTER) | E15: =VLOOKUP(B15,[1]!Table3[[Part Number]:[Q2 QTY]],8,0) -> 0 | F15: =VLOOKUP(B15,[1]!Table3[[Part Number]:[OEM CAD $]],4,0) -> 62.49 | G15: =E15*F15 -> 0 | H15: =VLOOKUP(B15,[1]!Table3[[Part Number]:[GQP CAD $]],5,0) -> 23.75 | I15: =ROUND(E15*H15,2) -> 0
B16: 7008044 | C16: =VLOOKUP(B16,[1]!Table3[[Part Number]:[Make and Model]],2,0) -> BOBCAT S650 (A3N) | D16: =VLOOKUP(B16,[1]!Table3[[Part Number]:[Part Description]],3,0) -> SECONDARY AIR FILTER ELEMENT | E16: =VLOOKUP(B16,[1]!Table3[[Part Number]:[Q2 QTY]],8,0) -> 0 | F16: =VLOOKUP(B16,[1]!Table3[[Part Number]:[OEM CAD $]],4,0) -> 39.99 | G16: =E16*F16 -> 0 | H16: =VLOOKUP(B16,[1]!Table3[[Part Number]:[GQP CAD $]],5,0) -> 15.2 | I16: =ROUND(E16*H16,2) -> 0
B17: 7010031 | C17: =VLOOKUP(B17,[1]!Table3[[Part Number]:[Make and Model]],2,0) -> BOBCAT T750 (ANK) BOBCAT T750 (ATF) BOBCAT T770 (AT6) BOBCAT T770 (AT6) (2) | D17: =VLOOKUP(B17,[1]!Table3[[Part Number]:[Part Description]],3,0) -> SECONDARY AIR FILTER ELEMENT | E17: =VLOOKUP(B17,[1]!Table3[[Part Number]:[Q2 QTY]],8,0) -> 0 | F17: =VLOOKUP(B17,[1]!Table3[[Part Number]:[OEM CAD $]],4,0) -> 103.99 | G17: =E17*F17 -> 0 | H17: =VLOOKUP(B17,[1]!Table3[[Part Number]:[GQP CAD $]],5,0) -> 39.52 | I17: =ROUND(E17*H17,2) -> 0
B18: 7286652 | C18: =VLOOKUP(B18,[1]!Table3[[Part Number]:[Make and Model]],2,0) -> BOBCAT T750 (ANK) BOBCAT T750 (ATF) BOBCAT T770 (AT6) BOBCAT T770 (AT6) (2) | D18: =VLOOKUP(B18,[1]!Table3[[Part Number]:[Part Description]],3,0) -> PRIMARY AIR FILTER ELEMENT (OUTER) | E18: =VLOOKUP(B18,[1]!Table3[[Part Number]:[Q2 QTY]],8,0) -> 0 | F18: =VLOOKUP(B18,[1]!Table3[[Part Number]:[OEM CAD $]],4,0) -> 140.99 | G18: =E18*F18 -> 0 | H18: =VLOOKUP(B18,[1]!Table3[[Part Number]:[GQP CAD $]],5,0) -> 53.58 | I18: =ROUND(E18*H18,2) -> 0
B19: 110-6326 | C19: =VLOOKUP(B19,[1]!Table3[[Part Number]:[Make and Model]],2,0) -> CAT 299D (DX2) | D19: =VLOOKUP(B19,[1]!Table3[[Part Number]:[Part Description]],3,0) -> PRIMARY AIR FILTER ELEMENT | E19: =VLOOKUP(B19,[1]!Table3[[Part Number]:[Q2 QTY]],8,0) -> 0 | F19: =VLOOKUP(B19,[1]!Table3[[Part Number]:[OEM CAD $]],4,0) -> 76.02 | G19: =E19*F19 -> 0 | H19: =VLOOKUP(B19,[1]!Table3[[Part Number]:[GQP CAD $]],5,0) -> 28.89 | I19: =ROUND(E19*H19,2) -> 0
B20: 110-6331 | C20: =VLOOKUP(B20,[1]!Table3[[Part Number]:[Make and Model]],2,0) -> CAT 299D (DX2) | D20: =VLOOKUP(B20,[1]!Table3[[Part Number]:[Part Description]],3,0) -> SECONDARY AIR FILTER ELEMENT | E20: =VLOOKUP(B20,[1]!Table3[[Part Number]:[Q2 QTY]],8,0) -> 0 | F20: =VLOOKUP(B20,[1]!Table3[[Part Number]:[OEM CAD $]],4,0) -> 54.17 | G20: =E20*F20 -> 0 | H20: =VLOOKUP(B20,[1]!Table3[[Part Number]:[GQP CAD $]],5,0) -> 20.58 | I20: =ROUND(E20*H20,2) -> 0
B21: 112-7448 | C21: =VLOOKUP(B21,[1]!Table3[[Part Number]:[Make and Model]],2,0) -> CAT D6T (MH7) | D21: =VLOOKUP(B21,[1]!Table3[[Part Number]:[Part Description]],3,0) -> CABIN AIR FILTER ELEMENT | E21: =VLOOKUP(B21,[1]!Table3[[Part Number]:[Q2 QTY]],8,0) -> 0 | F21: =VLOOKUP(B21,[1]!Table3[[Part Number]:[OEM CAD $]],4,0) -> 43.37 | G21: =E21*F21 -> 0 | H21: =VLOOKUP(B21,[1]!Table3[[Part Number]:[GQP CAD $]],5,0) -> 16.48 | I21: =ROUND(E21*H21,2) -> 0
B22: 131-8821 | C22: =VLOOKUP(B22,[1]!Table3[[Part Number]:[Make and Model]],2,0) -> CAT 320E L (WBK) CAT 320E L (WBK) (2) CAT 320F L (YBM) | D22: =VLOOKUP(B22,[1]!Table3[[Part Number]:[Part Description]],3,0) -> SECONDARY AIR FILTER ELEMENT | E22: =VLOOKUP(B22,[1]!Table3[[Part Number]:[Q2 QTY]],8,0) -> 0 | F22: =VLOOKUP(B22,[1]!Table3[[Part Number]:[OEM CAD $]],4,0) -> 97.91 | G22: =E22*F22 -> 0 | H22: =VLOOKUP(B22,[1]!Table3[[Part Number]:[GQP CAD $]],5,0) -> 37.21 | I22: =ROUND(E22*H22,2) -> 0
B23: 131-8822 | C23: =VLOOKUP(B23,[1]!Table3[[Part Number]:[Make and Model]],2,0) -> CAT 320E L (WBK) CAT 320E L (WBK) (2) CAT 320F L (YBM) | D23: =VLOOKUP(B23,[1]!Table3[[Part Number]:[Part Description]],3,0) -> PRIMARY AIR FILTER ELEMENT | E23: =VLOOKUP(B23,[1]!Table3[[Part Number]:[Q2 QTY]],8,0) -> 0 | F23: =VLOOKUP(B23,[1]!Table3[[Part Number]:[OEM CAD $]],4,0) -> 120.35 | G23: =E23*F23 -> 0 | H23: =VLOOKUP(B23,[1]!Table3[[Part Number]:[GQP CAD $]],5,0) -> 45.73 | I23: =ROUND(E23*H23,2) -> 0
B24: 134-8726 | C24: =VLOOKUP(B24,[1]!Table3[[Part Number]:[Make and Model]],2,0) -> CAT 303.5E | D24: =VLOOKUP(B24,[1]!Table3[[Part Number]:[Part Description]],3,0) -> PRIMARY AIR FILTER ELEMENT | E24: =VLOOKUP(B24,[1]!Table3[[Part Number]:[Q2 QTY]],8,0) -> 0 | F24: =VLOOKUP(B24,[1]!Table3[[Part Number]:[OEM CAD $]],4,0) -> 67.33 | G24: =E24*F24 -> 0 | H24: =VLOOKUP(B24,[1]!Table3[[Part Number]:[GQP CAD $]],5,0) -> 25.59 | I24: =ROUND(E24*H24,2) -> 0
B25: 140-2334 | C25: =VLOOKUP(B25,[1]!Table3[[Part Number]:[Make and Model]],2,0) -> CAT 303.5E | D25: =VLOOKUP(B25,[1]!Table3[[Part Number]:[Part Description]],3,0) -> SECONDARY AIR FILTER ELEMENT | E25: =VLOOKUP(B25,[1]!Table3[[Part Number]:[Q2 QTY]],8,0) -> 0 | F25: =VLOOKUP(B25,[1]!Table3[[Part Number]:[OEM CAD $]],4,0) -> 61.69 | G25: =E25*F25 -> 0 | H25: =VLOOKUP(B25,[1]!Table3[[Part Number]:[GQP CAD $]],5,0) -> 23.44 | I25: =ROUND(E25*H25,2) -> 0
B26: 142-1339 | C26: =VLOOKUP(B26,[1]!Table3[[Part Number]:[Make and Model]],2,0) -> CAT 336F L (RKB) | D26: =VLOOKUP(B26,[1]!Table3[[Part Number]:[Part Description]],3,0) -> PRIMARY AIR FILTER ELEMENT | E26: =VLOOKUP(B26,[1]!Table3[[Part Number]:[Q2 QTY]],8,0) -> 0 | F26: =VLOOKUP(B26,[1]!Table3[[Part Number]:[OEM CAD $]],4,0) -> 201.81 | G26: =E26*F26 -> 0 | H26: =VLOOKUP(B26,[1]!Table3[[Part Number]:[GQP CAD $]],5,0) -> 76.69 | I26: =ROUND(E26*H26,2) -> 0
B27: 142-1404 | C27: =VLOOKUP(B27,[1]!Table3[[Part Number]:[Make and Model]],2,0) -> CAT 336F L (RKB) | D27: =VLOOKUP(B27,[1]!Table3[[Part Number]:[Part Description]],3,0) -> SECONDARY AIR FILTER ELEMENT | E27: =VLOOKUP(B27,[1]!Table3[[Part Number]:[Q2 QTY]],8,0) -> 0 | F27: =VLOOKUP(B27,[1]!Table3[[Part Number]:[OEM CAD $]],4,0) -> 119.45 | G27: =E27*F27 -> 0 | H27: =VLOOKUP(B27,[1]!Table3[[Part Number]:[GQP CAD $]],5,0) -> 45.39 | I27: =ROUND(E27*H27,2) -> 0
B28: 151-0914 | C28: =VLOOKUP(B28,[1]!Table3[[Part Number]:[Make and Model]],2,0) -> CAT D6N LGP (PBA) CAT D6N LGP (PBA) (2) | D28: =VLOOKUP(B28,[1]!Table3[[Part Number]:[Part Description]],3,0) -> PRIMARY CABIN AIR FILTER ELEMENT | E28: =VLOOKUP(B28,[1]!Table3[[Part Number]:[Q2 QTY]],8,0) -> 0 | F28: =VLOOKUP(B28,[1]!Table3[[Part Number]:[OEM CAD $]],4,0) -> 112.48 | G28: =E28*F28 -> 0 | H28: =VLOOKUP(B28,[1]!Table3[[Part Number]:[GQP CAD $]],5,0) -> 42.74 | I28: =ROUND(E28*H28,2) -> 0
B29: 209-8217 | C29: =VLOOKUP(B29,[1]!Table3[[Part Number]:[Make and Model]],2,0) -> CAT PL61 (WGS) CAT PL61 (WGS) (2) CAT PL61 (WGS) (3) | D29: =VLOOKUP(B29,[1]!Table3[[Part Number]:[Part Description]],3,0) -> CABIN AIR FILTER ELEMENT | E29: =VLOOKUP(B29,[1]!Table3[[Part Number]:[Q2 QTY]],8,0) -> 0 | F29: =VLOOKUP(B29,[1]!Table3[[Part Number]:[OEM CAD $]],4,0) -> 85.17 | G29: =E29*F29 -> 0 | H29: =VLOOKUP(B29,[1]!Table3[[Part Number]:[GQP CAD $]],5,0) -> 32.36 | I29: =ROUND(E29*H29,2) -> 0
B30: 252-5001 | C30: =VLOOKUP(B30,[1]!Table3[[Part Number]:[Make and Model]],2,0) -> CAT D6N LGP (GHS) CAT PL61 (WGS) CAT PL61 (WGS) (2) CAT PL61 (WGS) (3) | D30: =VLOOKUP(B30,[1]!Table3[[Part Number]:[Part Description]],3,0) -> PRIMARY AIR FILTER ELEMENT | E30: =VLOOKUP(B30,[1]!Table3[[Part Number]:[Q2 QTY]],8,0) -> 0 | F30: =VLOOKUP(B30,[1]!Table3[[Part Number]:[OEM CAD $]],4,0) -> 221.03 | G30: =E30*F30 -> 0 | H30: =VLOOKUP(B30,[1]!Table3[[Part Number]:[GQP CAD $]],5,0) -> 83.99 | I30: =ROUND(E30*H30,2) -> 0
... B60: 9S-9972 | C60: =VLOOKUP(B60,[1]!Table3[[Part Number]:[Make and Model]],2,0) -> CAT D7G (92V) CAT D7G (3ZD) CAT D7G (3ZD) (2) | D60: =VLOOKUP(B60,[1]!Table3[[Part Number]:[Part Description]],3,0) -> SECONDARY AIR FILTER ELEMENT | E60: =VLOOKUP(B60,[1]!Table3[[Part Number]:[Q2 QTY]],8,0) -> 0 | F60: =VLOOKUP(B60,[1]!Table3[[Part Number]:[OEM CAD $]],4,0) -> 115.44 | G60: =E60*F60 -> 0 | H60: =VLOOKUP(B60,[1]!Table3[[Part Number]:[GQP CAD $]],5,0) -> 43.87 | I60: =ROUND(E60*H60,2) -> 0
B61: 6692337 | C61: =VLOOKUP(B61,[1]!Table3[[Part Number]:[Make and Model]],2,0) -> BOBCAT T750 (ATF) BOBCAT S650 (A3N) | D61: =VLOOKUP(B61,[1]!Table3[[Part Number]:[Part Description]],3,0) -> HYDRAULIC OIL FILTER ELEMENT | E61: =VLOOKUP(B61,[1]!Table3[[Part Number]:[Q2 QTY]],8,0) -> 2 | F61: =VLOOKUP(B61,[1]!Table3[[Part Number]:[OEM CAD $]],4,0) -> 93.99 | G61: =E61*F61 -> 187.98 | H61: =VLOOKUP(B61,[1]!Table3[[Part Number]:[GQP CAD $]],5,0) -> 35.72 | I61: =ROUND(E61*H61,2) -> 71.44
B62: 7012314 | C62: =VLOOKUP(B62,[1]!Table3[[Part Number]:[Make and Model]],2,0) -> BOBCAT T750 (ANK) | D62: =VLOOKUP(B62,[1]!Table3[[Part Number]:[Part Description]],3,0) -> HYDRAULIC OIL FILTER ELEMENT | E62: =VLOOKUP(B62,[1]!Table3[[Part Number]:[Q2 QTY]],8,0) -> 1 | F62: =VLOOKUP(B62,[1]!Table3[[Part Number]:[OEM CAD $]],4,0) -> 138.99 | G62: =E62*F62 -> 138.99 | H62: =VLOOKUP(B62,[1]!Table3[[Part Number]:[GQP CAD $]],5,0) -> 52.82 | I62: =ROUND(E62*H62,2) -> 52.82
B63: 7414582 | C63: =VLOOKUP(B63,[1]!Table3[[Part Number]:[Make and Model]],2,0) -> BOBCAT T770 (AT6) BOBCAT T770 (AT6) (2) | D63: =VLOOKUP(B63,[1]!Table3[[Part Number]:[Part Description]],3,0) -> HYDRAULIC OIL FILTER ELEMENT | E63: =VLOOKUP(B63,[1]!Table3[[Part Number]:[Q2 QTY]],8,0) -> 2 | F63: =VLOOKUP(B63,[1]!Table3[[Part Number]:[OEM CAD $]],4,0) -> 117.99 | G63: =E63*F63 -> 235.98 | H63: =VLOOKUP(B63,[1]!Table3[[Part Number]:[GQP CAD $]],5,0) -> 44.84 | I63: =ROUND(E63*H63,2) -> 89.68
B64: 093-7521 | C64: =VLOOKUP(B64,[1]!Table3[[Part Number]:[Make and Model]],2,0) -> CAT 320F L (YBM) CAT 336F L (RKB) | D64: =VLOOKUP(B64,[1]!Table3[[Part Number]:[Part Description]],3,0) -> HYDRAULIC OIL FILTER | E64: =VLOOKUP(B64,[1]!Table3[[Part Number]:[Q2 QTY]],8,0) -> 2 | F64: =VLOOKUP(B64,[1]!Table3[[Part Number]:[OEM CAD $]],4,0) -> 102.09 | G64: =E64*F64 -> 204.18 | H64: =VLOOKUP(B64,[1]!Table3[[Part Number]:[GQP CAD $]],5,0) -> 38.79 | I64: =ROUND(E64*H64,2) -> 77.58
B65: 169-4019 | C65: =VLOOKUP(B65,[1]!Table3[[Part Number]:[Make and Model]],2,0) -> CAT D4 (66J) | D65: =VLOOKUP(B65,[1]!Table3[[Part Number]:[Part Description]],3,0) -> HYDRAULIC OIL FILTER | E65: =VLOOKUP(B65,[1]!Table3[[Part Number]:[Q2 QTY]],8,0) -> 1 | F65: =VLOOKUP(B65,[1]!Table3[[Part Number]:[OEM CAD $]],4,0) -> 703.78 | G65: =E65*F65 -> 703.78 | H65: =VLOOKUP(B65,[1]!Table3[[Part Number]:[GQP CAD $]],5,0) -> 267.44 | I65: =ROUND(E65*H65,2) -> 267.44
B66: 179-9806 | C66: =VLOOKUP(B66,[1]!Table3[[Part Number]:[Make and Model]],2,0) -> CAT 320E L (WBK) CAT 320E L (WBK) (2) CAT 320F L (YBM) CAT 329E L (ZCD) CAT 329F L (ERL) CAT 329F L (ERL) (2) CAT 330F L (MBX) CAT 330F L (HCK) CAT 330F L (HCK) (2) CAT 336F L (RKB) | D66: =VLOOKUP(B66,[1]!Table3[[Part Number]:[Part Description]],3,0) -> HYDRAULIC OIL FILTER ELEMENT | E66: =VLOOKUP(B66,[1]!Table3[[Part Number]:[Q2 QTY]],8,0) -> 12 | F66: =VLOOKUP(B66,[1]!Table3[[Part Number]:[OEM CAD $]],4,0) -> 229 | G66: =E66*F66 -> 2748 | H66: =VLOOKUP(B66,[1]!Table3[[Part Number]:[GQP CAD $]],5,0) -> 87.02 | I66: =ROUND(E66*H66,2) -> 1044.24
B67: 1G-8878 | C67: =VLOOKUP(B67,[1]!Table3[[Part Number]:[Make and Model]],2,0) -> CAT PL61 (WGS) CAT PL61 (WGS) (2) CAT PL61 (WGS) (3) | D67: =VLOOKUP(B67,[1]!Table3[[Part Number]:[Part Description]],3,0) -> HYDRAULIC OIL FILTER ELEMENT | E67: =VLOOKUP(B67,[1]!Table3[[Part Number]:[Q2 QTY]],8,0) -> 3 | F67: =VLOOKUP(B67,[1]!Table3[[Part Number]:[OEM CAD $]],4,0) -> 150.47 | G67: =E67*F67 -> 451.41 | H67: =VLOOKUP(B67,[1]!Table3[[Part Number]:[GQP CAD $]],5,0) -> 57.18 | I67: =ROUND(E67*H67,2) -> 171.54
B68: 1R-0719 | C68: =VLOOKUP(B68,[1]!Table3[[Part Number]:[Make and Model]],2,0) -> CAT D3 (1PJ) CAT D5 (3CR) CAT D5 (3CR) (2) | D68: =VLOOKUP(B68,[1]!Table3[[Part Number]:[Part Description]],3,0) -> HYDRAULIC OIL FILTER | E68: =VLOOKUP(B68,[1]!Table3[[Part Number]:[Q2 QTY]],8,0) -> 3 | F68: =VLOOKUP(B68,[1]!Table3[[Part Number]:[OEM CAD $]],4,0) -> 38.32 | G68: =E68*F68 -> 114.96 | H68: =VLOOKUP(B68,[1]!Table3[[Part Number]:[GQP CAD $]],5,0) -> 14.56 | I68: =ROUND(E68*H68,2) -> 43.68
B69: 1R-0746 | C69: =VLOOKUP(B69,[1]!Table3[[Part Number]:[Make and Model]],2,0) -> CAT D3 (1PJ) | D69: =VLOOKUP(B69,[1]!Table3[[Part Number]:[Part Description]],3,0) -> HYDRAULIC/TRANSMISSION OIL FILTER | E69: =VLOOKUP(B69,[1]!Table3[[Part Number]:[Q2 QTY]],8,0) -> 1 | F69: =VLOOKUP(B69,[1]!Table3[[Part Number]:[OEM CAD $]],4,0) -> 47.44 | G69: =E69*F69 -> 47.44 | H69: =VLOOKUP(B69,[1]!Table3[[Part Number]:[GQP CAD $]],5,0) -> 18.03 | I69: =ROUND(E69*H69,2) -> 18.03
B70: 1R-0777 | C70: =VLOOKUP(B70,[1]!Table3[[Part Number]:[Make and Model]],2,0) -> CAT D4 (66J) | D70: =VLOOKUP(B70,[1]!Table3[[Part Number]:[Part Description]],3,0) -> HYDRAULIC OIL FILTER ELEMENT | E70: =VLOOKUP(B70,[1]!Table3[[Part Number]:[Q2 QTY]],8,0) -> 1 | F70: =VLOOKUP(B70,[1]!Table3[[Part Number]:[OEM CAD $]],4,0) -> 93.49 | G70: =E70*F70 -> 93.49 | H70: =VLOOKUP(B70,[1]!Table3[[Part Number]:[GQP CAD $]],5,0) -> 35.53 | I70: =ROUND(E70*H70,2) -> 35.53
B71: 304-7196 | C71: =VLOOKUP(B71,[1]!Table3[[Part Number]:[Make and Model]],2,0) -> CAT 303.5E | D71: =VLOOKUP(B71,[1]!Table3[[Part Number]:[Part Description]],3,0) -> HYDRAULIC OIL FILTER | E71: =VLOOKUP(B71,[1]!Table3[[Part Number]:[Q2 QTY]],8,0) -> 1 | F71: =VLOOKUP(B71,[1]!Table3[[Part Number]:[OEM CAD $]],4,0) -> 130.47 | G71: =E71*F71 -> 130.47 | H71: =VLOOKUP(B71,[1]!Table3[[Part Number]:[GQP CAD $]],5,0) -> 49.58 | I71: =ROUND(E71*H71,2) -> 49.58
B72: 328-3655 | C72: =VLOOKUP(B72,[1]!Table3[[Part Number]:[Make and Model]],2,0) -> CAT D6N LGP (GHS) | D72: =VLOOKUP(B72,[1]!Table3[[Part Number]:[Part Description]],3,0) -> HYDRAULIC OIL FILTER ELEMENT | E72: =VLOOKUP(B72,[1]!Table3[[Part Number]:[Q2 QTY]],8,0) -> 1 | F72: =VLOOKUP(B72,[1]!Table3[[Part Number]:[OEM CAD $]],4,0) -> 204.36 | G72: =E72*F72 -> 204.36 | H72: =VLOOKUP(B72,[1]!Table3[[Part Number]:[GQP CAD $]],5,0) -> 77.66 | I72: =ROUND(E72*H72,2) -> 77.66
B73: 376-2025 | C73: =VLOOKUP(B73,[1]!Table3[[Part Number]:[Make and Model]],2,0) -> CAT 303.5E | D73: =VLOOKUP(B73,[1]!Table3[[Part Number]:[Part Description]],3,0) -> HYDRAULIC PUMP | E73: =VLOOKUP(B73,[1]!Table3[[Part Number]:[Q2 QTY]],8,0) -> 1 | F73: =VLOOKUP(B73,[1]!Table3[[Part Number]:[OEM CAD $]],4,0) -> 7622.73 | G73: =E73*F73 -> 7622.73 | H73: =VLOOKUP(B73,[1]!Table3[[Part Number]:[GQP CAD $]],5,0) -> 3811.37 | I73: =ROUND(E73*H73,2) -> 3811.37
B74: 421-5479 | C74: =VLOOKUP(B74,[1]!Table3[[Part Number]:[Make and Model]],2,0) -> CAT 299D (DX2) | D74: =VLOOKUP(B74,[1]!Table3[[Part Number]:[Part Description]],3,0) -> HYDRAULIC OIL FILTER ELEMENT | E74: =VLOOKUP(B74,[1]!Table3[[Part Number]:[Q2 QTY]],8,0) -> 1 | F74: =VLOOKUP(B74,[1]!Table3[[Part Number]:[OEM CAD $]],4,0) -> 72.07 | G74: =E74*F74 -> 72.07 | H74: =VLOOKUP(B74,[1]!Table3[[Part Number]:[GQP CAD $]],5,0) -> 27.39 | I74: =ROUND(E74*H74,2) -> 27.39
...

Sheet MOQ Filters Q3
E1: MOQ QUOTE | H1: Filters Q1
B7: COMPANY: | C7: Lincoln County | E7: DATE: | F7: 45870 | H7: PO NUMBER:
B8: CONTACT NAME: | C8: 0 | E8: PHONE NUMBER:
B9: BILLING ADDRESS: | C9: 0 | E9: EMAIL ADDRESS:
C10: 0 | E10: SHIPPING ADDRESS:
C11: 0
C12: 0
F13: CAD $
B14: PART NUMBER | C14: Make & Model | D14: DESCRIPTION | E14: QTY | F14: OEM MSRP | H14: GQP PRICE | I14: TOTAL
B15: 7008043 | C15: =VLOOKUP(B15,[1]!Table3[[Part Number]:[Make and Model]],2,0) -> BOBCAT S650 (A3N) | D15: =VLOOKUP(B15,[1]!Table3[[Part Number]:[Part Description]],3,0) -> PRIMARY AIR FILTER ELEMENT (OUTER) | E15: =VLOOKUP(B15,'[1]Product by Part Number'!$A:$I,9,0) -> 0 | F15: =VLOOKUP(B15,[1]!Table3[[Part Number]:[OEM CAD $]],4,0) -> 62.49 | G15: =E15*F15 -> 0 | H15: =VLOOKUP(B15,[1]!Table3[[Part Number]:[GQP CAD $]],5,0) -> 23.75 | I15: =ROUND(E15*H15,2) -> 0
B16: 7008044 | C16: =VLOOKUP(B16,[1]!Table3[[Part Number]:[Make and Model]],2,0) -> BOBCAT S650 (A3N) | D16: =VLOOKUP(B16,[1]!Table3[[Part Number]:[Part Description]],3,0) -> SECONDARY AIR FILTER ELEMENT | E16: =VLOOKUP(B16,'[1]Product by Part Number'!$A:$I,9,0) -> 0 | F16: =VLOOKUP(B16,[1]!Table3[[Part Number]:[OEM CAD $]],4,0) -> 39.99 | G16: =E16*F16 -> 0 | H16: =VLOOKUP(B16,[1]!Table3[[Part Number]:[GQP CAD $]],5,0) -> 15.2 | I16: =ROUND(E16*H16,2) -> 0
B17: 7010031 | C17: =VLOOKUP(B17,[1]!Table3[[Part Number]:[Make and Model]],2,0) -> BOBCAT T750 (ANK) BOBCAT T750 (ATF) BOBCAT T770 (AT6) BOBCAT T770 (AT6) (2) | D17: =VLOOKUP(B17,[1]!Table3[[Part Number]:[Part Description]],3,0) -> SECONDARY AIR FILTER ELEMENT | E17: =VLOOKUP(B17,'[1]Product by Part Number'!$A:$I,9,0) -> 0 | F17: =VLOOKUP(B17,[1]!Table3[[Part Number]:[OEM CAD $]],4,0) -> 103.99 | G17: =E17*F17 -> 0 | H17: =VLOOKUP(B17,[1]!Table3[[Part Number]:[GQP CAD $]],5,0) -> 39.52 | I17: =ROUND(E17*H17,2) -> 0
B18: 7286652 | C18: =VLOOKUP(B18,[1]!Table3[[Part Number]:[Make and Model]],2,0) -> BOBCAT T750 (ANK) BOBCAT T750 (ATF) BOBCAT T770 (AT6) BOBCAT T770 (AT6) (2) | D18: =VLOOKUP(B18,[1]!Table3[[Part Number]:[Part Description]],3,0) -> PRIMARY AIR FILTER ELEMENT (OUTER) | E18: =VLOOKUP(B18,'[1]Product by Part Number'!$A:$I,9,0) -> 0 | F18: =VLOOKUP(B18,[1]!Table3[[Part Number]:[OEM CAD $]],4,0) -> 140.99 | G18: =E18*F18 -> 0 | H18: =VLOOKUP(B18,[1]!Table3[[Part Number]:[GQP CAD $]],5,0) -> 53.58 | I18: =ROUND(E18*H18,2) -> 0
B19: 110-6326 | C19: =VLOOKUP(B19,[1]!Table3[[Part Number]:[Make and Model]],2,0) -> CAT 299D (DX2) | D19: =VLOOKUP(B19,[1]!Table3[[Part Number]:[Part Description]],3,0) -> PRIMARY AIR FILTER ELEMENT | E19: =VLOOKUP(B19,'[1]Product by Part Number'!$A:$I,9,0) -> 0 | F19: =VLOOKUP(B19,[1]!Table3[[Part Number]:[OEM CAD $]],4,0) -> 76.02 | G19: =E19*F19 -> 0 | H19: =VLOOKUP(B19,[1]!Table3[[Part Number]:[GQP CAD $]],5,0) -> 28.89 | I19: =ROUND(E19*H19,2) -> 0
B20: 110-6331 | C20: =VLOOKUP(B20,[1]!Table3[[Part Number]:[Make and Model]],2,0) -> CAT 299D (DX2) | D20: =VLOOKUP(B20,[1]!Table3[[Part Number]:[Part Description]],3,0) -> SECONDARY AIR FILTER ELEMENT | E20: =VLOOKUP(B20,'[1]Product by Part Number'!$A:$I,9,0) -> 0 | F20: =VLOOKUP(B20,[1]!Table3[[Part Number]:[OEM CAD $]],4,0) -> 54.17 | G20: =E20*F20 -> 0 | H20: =VLOOKUP(B20,[1]!Table3[[Part Number]:[GQP CAD $]],5,0) -> 20.58 | I20: =ROUND(E20*H20,2) -> 0
B21: 112-7448 | C21: =VLOOKUP(B21,[1]!Table3[[Part Number]:[Make and Model]],2,0) -> CAT D6T (MH7) | D21: =VLOOKUP(B21,[1]!Table3[[Part Number]:[Part Description]],3,0) -> CABIN AIR FILTER ELEMENT | E21: =VLOOKUP(B21,'[1]Product by Part Number'!$A:$I,9,0) -> 0 | F21: =VLOOKUP(B21,[1]!Table3[[Part Number]:[OEM CAD $]],4,0) -> 43.37 | G21: =E21*F21 -> 0 | H21: =VLOOKUP(B21,[1]!Table3[[Part Number]:[GQP CAD $]],5,0) -> 16.48 | I21: =ROUND(E21*H21,2) -> 0
B22: 131-8821 | C22: =VLOOKUP(B22,[1]!Table3[[Part Number]:[Make and Model]],2,0) -> CAT 320E L (WBK) CAT 320E L (WBK) (2) CAT 320F L (YBM) | D22: =VLOOKUP(B22,[1]!Table3[[Part Number]:[Part Description]],3,0) -> SECONDARY AIR FILTER ELEMENT | E22: =VLOOKUP(B22,'[1]Product by Part Number'!$A:$I,9,0) -> 0 | F22: =VLOOKUP(B22,[1]!Table3[[Part Number]:[OEM CAD $]],4,0) -> 97.91 | G22: =E22*F22 -> 0 | H22: =VLOOKUP(B22,[1]!Table3[[Part Number]:[GQP CAD $]],5,0) -> 37.21 | I22: =ROUND(E22*H22,2) -> 0
B23: 131-8822 | C23: =VLOOKUP(B23,[1]!Table3[[Part Number]:[Make and Model]],2,0) -> CAT 320E L (WBK) CAT 320E L (WBK) (2) CAT 320F L (YBM) | D23: =VLOOKUP(B23,[1]!Table3[[Part Number]:[Part Description]],3,0) -> PRIMARY AIR FILTER ELEMENT | E23: =VLOOKUP(B23,'[1]Product by Part Number'!$A:$I,9,0) -> 0 | F23: =VLOOKUP(B23,[1]!Table3[[Part Number]:[OEM CAD $]],4,0) -> 120.35 | G23: =E23*F23 -> 0 | H23: =VLOOKUP(B23,[1]!Table3[[Part Number]:[GQP CAD $]],5,0) -> 45.73 | I23: =ROUND(E23*H23,2) -> 0
B24: 134-8726 | C24: =VLOOKUP(B24,[1]!Table3[[Part Number]:[Make and Model]],2,0) -> CAT 303.5E | D24: =VLOOKUP(B24,[1]!Table3[[Part Number]:[Part Description]],3,0) -> PRIMARY AIR FILTER ELEMENT | E24: =VLOOKUP(B24,'[1]Product by Part Number'!$A:$I,9,0) -> 0 | F24: =VLOOKUP(B24,[1]!Table3[[Part Number]:[OEM CAD $]],4,0) -> 67.33 | G24: =E24*F24 -> 0 | H24: =VLOOKUP(B24,[1]!Table3[[Part Number]:[GQP CAD $]],5,0) -> 25.59 | I24: =ROUND(E24*H24,2) -> 0
B25: 140-2334 | C25: =VLOOKUP(B25,[1]!Table3[[Part Number]:[Make and Model]],2,0) -> CAT 303.5E | D25: =VLOOKUP(B25,[1]!Table3[[Part Number]:[Part Description]],3,0) -> SECONDARY AIR FILTER ELEMENT | E25: =VLOOKUP(B25,'[1]Product by Part Number'!$A:$I,9,0) -> 0 | F25: =VLOOKUP(B25,[1]!Table3[[Part Number]:[OEM CAD $]],4,0) -> 61.69 | G25: =E25*F25 -> 0 | H25: =VLOOKUP(B25,[1]!Table3[[Part Number]:[GQP CAD $]],5,0) -> 23.44 | I25: =ROUND(E25*H25,2) -> 0
B26: 142-1339 | C26: =VLOOKUP(B26,[1]!Table3[[Part Number]:[Make and Model]],2,0) -> CAT 336F L (RKB) | D26: =VLOOKUP(B26,[1]!Table3[[Part Number]:[Part Description]],3,0) -> PRIMARY AIR FILTER ELEMENT | E26: =VLOOKUP(B26,'[1]Product by Part Number'!$A:$I,9,0) -> 0 | F26: =VLOOKUP(B26,[1]!Table3[[Part Number]:[OEM CAD $]],4,0) -> 201.81 | G26: =E26*F26 -> 0 | H26: =VLOOKUP(B26,[1]!Table3[[Part Number]:[GQP CAD $]],5,0) -> 76.69 | I26: =ROUND(E26*H26,2) -> 0
B27: 142-1404 | C27: =VLOOKUP(B27,[1]!Table3[[Part Number]:[Make and Model]],2,0) -> CAT 336F L (RKB) | D27: =VLOOKUP(B27,[1]!Table3[[Part Number]:[Part Description]],3,0) -> SECONDARY AIR FILTER ELEMENT | E27: =VLOOKUP(B27,'[1]Product by Part Number'!$A:$I,9,0) -> 0 | F27: =VLOOKUP(B27,[1]!Table3[[Part Number]:[OEM CAD $]],4,0) -> 119.45 | G27: =E27*F27 -> 0 | H27: =VLOOKUP(B27,[1]!Table3[[Part Number]:[GQP CAD $]],5,0) -> 45.39 | I27: =ROUND(E27*H27,2) -> 0
B28: 151-0914 | C28: =VLOOKUP(B28,[1]!Table3[[Part Number]:[Make and Model]],2,0) -> CAT D6N LGP (PBA) CAT D6N LGP (PBA) (2) | D28: =VLOOKUP(B28,[1]!Table3[[Part Number]:[Part Description]],3,0) -> PRIMARY CABIN AIR FILTER ELEMENT | E28: =VLOOKUP(B28,'[1]Product by Part Number'!$A:$I,9,0) -> 0 | F28: =VLOOKUP(B28,[1]!Table3[[Part Number]:[OEM CAD $]],4,0) -> 112.48 | G28: =E28*F28 -> 0 | H28: =VLOOKUP(B28,[1]!Table3[[Part Number]:[GQP CAD $]],5,0) -> 42.74 | I28: =ROUND(E28*H28,2) -> 0
B29: 209-8217 | C29: =VLOOKUP(B29,[1]!Table3[[Part Number]:[Make and Model]],2,0) -> CAT PL61 (WGS) CAT PL61 (WGS) (2) CAT PL61 (WGS) (3) | D29: =VLOOKUP(B29,[1]!Table3[[Part Number]:[Part Description]],3,0) -> CABIN AIR FILTER ELEMENT | E29: =VLOOKUP(B29,'[1]Product by Part Number'!$A:$I,9,0) -> 0 | F29: =VLOOKUP(B29,[1]!Table3[[Part Number]:[OEM CAD $]],4,0) -> 85.17 | G29: =E29*F29 -> 0 | H29: =VLOOKUP(B29,[1]!Table3[[Part Number]:[GQP CAD $]],5,0) -> 32.36 | I29: =ROUND(E29*H29,2) -> 0
B30: 252-5001 | C30: =VLOOKUP(B30,[1]!Table3[[Part Number]:[Make and Model]],2,0) -> CAT D6N LGP (GHS) CAT PL61 (WGS) CAT PL61 (WGS) (2) CAT PL61 (WGS) (3) | D30: =VLOOKUP(B30,[1]!Table3[[Part Number]:[Part Description]],3,0) -> PRIMARY AIR FILTER ELEMENT | E30: =VLOOKUP(B30,'[1]Product by Part Number'!$A:$I,9,0) -> 0 | F30: =VLOOKUP(B30,[1]!Table3[[Part Number]:[OEM CAD $]],4,0) -> 221.03 | G30: =E30*F30 -> 0 | H30: =VLOOKUP(B30,[1]!Table3[[Part Number]:[GQP CAD $]],5,0) -> 83.99 | I30: =ROUND(E30*H30,2) -> 0
... B60: 9S-9972 | C60: =VLOOKUP(B60,[1]!Table3[[Part Number]:[Make and Model]],2,0) -> CAT D7G (92V) CAT D7G (3ZD) CAT D7G (3ZD) (2) | D60: =VLOOKUP(B60,[1]!Table3[[Part Number]:[Part Description]],3,0) -> SECONDARY AIR FILTER ELEMENT | E60: =VLOOKUP(B60,'[1]Product by Part Number'!$A:$I,9,0) -> 0 | F60: =VLOOKUP(B60,[1]!Table3[[Part Number]:[OEM CAD $]],4,0) -> 115.44 | G60: =E60*F60 -> 0 | H60: =VLOOKUP(B60,[1]!Table3[[Part Number]:[GQP CAD $]],5,0) -> 43.87 | I60: =ROUND(E60*H60,2) -> 0
B61: 6692337 | C61: =VLOOKUP(B61,[1]!Table3[[Part Number]:[Make and Model]],2,0) -> BOBCAT T750 (ATF) BOBCAT S650 (A3N) | D61: =VLOOKUP(B61,[1]!Table3[[Part Number]:[Part Description]],3,0) -> HYDRAULIC OIL FILTER ELEMENT | E61: =VLOOKUP(B61,'[1]Product by Part Number'!$A:$I,9,0) -> 0 | F61: =VLOOKUP(B61,[1]!Table3[[Part Number]:[OEM CAD $]],4,0) -> 93.99 | G61: =E61*F61 -> 0 | H61: =VLOOKUP(B61,[1]!Table3[[Part Number]:[GQP CAD $]],5,0) -> 35.72 | I61: =ROUND(E61*H61,2) -> 0
B62: 7012314 | C62: =VLOOKUP(B62,[1]!Table3[[Part Number]:[Make and Model]],2,0) -> BOBCAT T750 (ANK) | D62: =VLOOKUP(B62,[1]!Table3[[Part Number]:[Part Description]],3,0) -> HYDRAULIC OIL FILTER ELEMENT | E62: =VLOOKUP(B62,'[1]Product by Part Number'!$A:$I,9,0) -> 0 | F62: =VLOOKUP(B62,[1]!Table3[[Part Number]:[OEM CAD $]],4,0) -> 138.99 | G62: =E62*F62 -> 0 | H62: =VLOOKUP(B62,[1]!Table3[[Part Number]:[GQP CAD $]],5,0) -> 52.82 | I62: =ROUND(E62*H62,2) -> 0
B63: 7414582 | C63: =VLOOKUP(B63,[1]!Table3[[Part Number]:[Make and Model]],2,0) -> BOBCAT T770 (AT6) BOBCAT T770 (AT6) (2) | D63: =VLOOKUP(B63,[1]!Table3[[Part Number]:[Part Description]],3,0) -> HYDRAULIC OIL FILTER ELEMENT | E63: =VLOOKUP(B63,'[1]Product by Part Number'!$A:$I,9,0) -> 0 | F63: =VLOOKUP(B63,[1]!Table3[[Part Number]:[OEM CAD $]],4,0) -> 117.99 | G63: =E63*F63 -> 0 | H63: =VLOOKUP(B63,[1]!Table3[[Part Number]:[GQP CAD $]],5,0) -> 44.84 | I63: =ROUND(E63*H63,2) -> 0
B64: 093-7521 | C64: =VLOOKUP(B64,[1]!Table3[[Part Number]:[Make and Model]],2,0) -> CAT 320F L (YBM) CAT 336F L (RKB) | D64: =VLOOKUP(B64,[1]!Table3[[Part Number]:[Part Description]],3,0) -> HYDRAULIC OIL FILTER | E64: =VLOOKUP(B64,'[1]Product by Part Number'!$A:$I,9,0) -> 0 | F64: =VLOOKUP(B64,[1]!Table3[[Part Number]:[OEM CAD $]],4,0) -> 102.09 | G64: =E64*F64 -> 0 | H64: =VLOOKUP(B64,[1]!Table3[[Part Number]:[GQP CAD $]],5,0) -> 38.79 | I64: =ROUND(E64*H64,2) -> 0
B65: 169-4019 | C65: =VLOOKUP(B65,[1]!Table3[[Part Number]:[Make and Model]],2,0) -> CAT D4 (66J) | D65: =VLOOKUP(B65,[1]!Table3[[Part Number]:[Part Description]],3,0) -> HYDRAULIC OIL FILTER | E65: =VLOOKUP(B65,'[1]Product by Part Number'!$A:$I,9,0) -> 0 | F65: =VLOOKUP(B65,[1]!Table3[[Part Number]:[OEM CAD $]],4,0) -> 703.78 | G65: =E65*F65 -> 0 | H65: =VLOOKUP(B65,[1]!Table3[[Part Number]:[GQP CAD $]],5,0) -> 267.44 | I65: =ROUND(E65*H65,2) -> 0
B66: 179-9806 | C66: =VLOOKUP(B66,[1]!Table3[[Part Number]:[Make and Model]],2,0) -> CAT 320E L (WBK) CAT 320E L (WBK) (2) CAT 320F L (YBM) CAT 329E L (ZCD) CAT 329F L (ERL) CAT 329F L (ERL) (2) CAT 330F L (MBX) CAT 330F L (HCK) CAT 330F L (HCK) (2) CAT 336F L (RKB) | D66: =VLOOKUP(B66,[1]!Table3[[Part Number]:[Part Description]],3,0) -> HYDRAULIC OIL FILTER ELEMENT | E66: =VLOOKUP(B66,'[1]Product by Part Number'!$A:$I,9,0) -> 0 | F66: =VLOOKUP(B66,[1]!Table3[[Part Number]:[OEM CAD $]],4,0) -> 229 | G66: =E66*F66 -> 0 | H66: =VLOOKUP(B66,[1]!Table3[[Part Number]:[GQP CAD $]],5,0) -> 87.02 | I66: =ROUND(E66*H66,2) -> 0
B67: 1G-8878 | C67: =VLOOKUP(B67,[1]!Table3[[Part Number]:[Make and Model]],2,0) -> CAT PL61 (WGS) CAT PL61 (WGS) (2) CAT PL61 (WGS) (3) | D67: =VLOOKUP(B67,[1]!Table3[[Part Number]:[Part Description]],3,0) -> HYDRAULIC OIL FILTER ELEMENT | E67: =VLOOKUP(B67,'[1]Product by Part Number'!$A:$I,9,0) -> 0 | F67: =VLOOKUP(B67,[1]!Table3[[Part Number]:[OEM CAD $]],4,0) -> 150.47 | G67: =E67*F67 -> 0 | H67: =VLOOKUP(B67,[1]!Table3[[Part Number]:[GQP CAD $]],5,0) -> 57.18 | I67: =ROUND(E67*H67,2) -> 0
B68: 1R-0719 | C68: =VLOOKUP(B68,[1]!Table3[[Part Number]:[Make and Model]],2,0) -> CAT D3 (1PJ) CAT D5 (3CR) CAT D5 (3CR) (2) | D68: =VLOOKUP(B68,[1]!Table3[[Part Number]:[Part Description]],3,0) -> HYDRAULIC OIL FILTER | E68: =VLOOKUP(B68,'[1]Product by Part Number'!$A:$I,9,0) -> 0 | F68: =VLOOKUP(B68,[1]!Table3[[Part Number]:[OEM CAD $]],4,0) -> 38.32 | G68: =E68*F68 -> 0 | H68: =VLOOKUP(B68,[1]!Table3[[Part Number]:[GQP CAD $]],5,0) -> 14.56 | I68: =ROUND(E68*H68,2) -> 0
B69: 1R-0746 | C69: =VLOOKUP(B69,[1]!Table3[[Part Number]:[Make and Model]],2,0) -> CAT D3 (1PJ) | D69: =VLOOKUP(B69,[1]!Table3[[Part Number]:[Part Description]],3,0) -> HYDRAULIC/TRANSMISSION OIL FILTER | E69: =VLOOKUP(B69,'[1]Product by Part Number'!$A:$I,9,0) -> 0 | F69: =VLOOKUP(B69,[1]!Table3[[Part Number]:[OEM CAD $]],4,0) -> 47.44 | G69: =E69*F69 -> 0 | H69: =VLOOKUP(B69,[1]!Table3[[Part Number]:[GQP CAD $]],5,0) -> 18.03 | I69: =ROUND(E69*H69,2) -> 0
