Workbook

Sheet MOQ Batteries
E1: MOQ QUOTE | H1: Batteries
B7: COMPANY: | C7: MPI OILFIELD | E7: DATE: | F7: ='MOQ Grand Total'!F7 -> 45839 | H7: PO NUMBER: | I7: ='MOQ Grand Total'!I7
B8: CONTACT NAME: | E8: PHONE NUMBER: | H8: ='MOQ Grand Total'!H8 -> (780) 385-8652
B9: BILLING ADDRESS: | C9: ='MOQ Grand Total'!C9 -> 0 | E9: EMAIL ADDRESS:
E10: SHIPPING ADDRESS: | H10: ='MOQ Grand Total'!H10 -> 0
C11: ='MOQ Grand Total'!C11 -> 0 | H11: ='MOQ Grand Total'!H11 -> 0
C12: ='MOQ Grand Total'!C12 -> Based on 200 machine hours per month | H12: ='MOQ Grand Total'!H12
F13: CAD $
B14: PART NUMBER | C14: Make & Model | D14: DESCRIPTION | E14: QTY | F14: OEM MSRP | H14: GQP PRICE | I14: TOTAL
B15: 153-5710 | C15: =VLOOKUP(B15,[1]!Table3[[Part Number]:[Annual]],2,0) -> CAT D7G (DSC) CAT D7G (DSC) (2) CAT D7G (DSC) (3) CAT D7G (SUB) CAT D7G (3ZD) CAT 572R (DSC) CAT 572R (DSC) (2) | D15: =VLOOKUP(B15,[1]!Table3[[Part Number]:[Annual]],3,0) -> 12V BATTERY | E15: =VLOOKUP(B15,[1]!Table3[[Part Number]:[Annual]],11,0) -> 14 | F15: =VLOOKUP(B15,[1]!Table3[[Part Number]:[Annual]],4,0) -> 783.62 | G15: =E15*F15 -> 10970.68 | H15: =VLOOKUP(B15,[1]!Table3[[Part Number]:[Annual]],5,0) -> 391.81 | I15: =ROUND(E15*H15,2) -> 5485.34
B16: 153-5720 | C16: =VLOOKUP(B16,[1]!Table3[[Part Number]:[Annual]],2,0) -> CAT 583T (CMX) CAT 589 (31Z) CAT 594 (96V) CAT 594H (96V) CAT DK8 (893) CAT DK8 (950) | D16: =VLOOKUP(B16,[1]!Table3[[Part Number]:[Annual]],3,0) -> Battery | E16: =VLOOKUP(B16,[1]!Table3[[Part Number]:[Annual]],11,0) -> 12 | F16: =VLOOKUP(B16,[1]!Table3[[Part Number]:[Annual]],4,0) -> 822.89 | G16: =E16*F16 -> 9874.68 | H16: =VLOOKUP(B16,[1]!Table3[[Part Number]:[Annual]],5,0) -> 411.45 | I16: =ROUND(E16*H16,2) -> 4937.4
B17: 9X-3404 | C17: =VLOOKUP(B17,[1]!Table3[[Part Number]:[Annual]],2,0) -> CAT PL61 (DHA) CAT PL61 (WGS) CAT D6D (06X) | D17: =VLOOKUP(B17,[1]!Table3[[Part Number]:[Annual]],3,0) -> 12V BATTERY | E17: =VLOOKUP(B17,[1]!Table3[[Part Number]:[Annual]],11,0) -> 6 | F17: =VLOOKUP(B17,[1]!Table3[[Part Number]:[Annual]],4,0) -> 486.48 | G17: =E17*F17 -> 2918.88 | H17: =VLOOKUP(B17,[1]!Table3[[Part Number]:[Annual]],5,0) -> 243.24 | I17: =ROUND(E17*H17,2) -> 1459.44
B18: TY23020 | C18: =VLOOKUP(B18,[1]!Table3[[Part Number]:[Annual]],2,0) -> HITACHI ZX290LC-5 (1FF) HITACHI ZX290LC-5 (1FF) (2) HITACHI ZX290LC-5 (1FF) (3) | D18: =VLOOKUP(B18,[1]!Table3[[Part Number]:[Annual]],3,0) -> BATTERY 12V 1400 CCA | E18: =VLOOKUP(B18,[1]!Table3[[Part Number]:[Annual]],11,0) -> 6 | F18: =VLOOKUP(B18,[1]!Table3[[Part Number]:[Annual]],4,0) -> 575.4186 | G18: =E18*F18 -> 3452.5116 | H18: =VLOOKUP(B18,[1]!Table3[[Part Number]:[Annual]],5,0) -> 287.71 | I18: =ROUND(E18*H18,2) -> 1726.26
B19: TY23020B | C19: =VLOOKUP(B19,[1]!Table3[[Part Number]:[Annual]],2,0) -> JD 470GLC (1FF) HITACHI 470GLC (HCM) | D19: =VLOOKUP(B19,[1]!Table3[[Part Number]:[Annual]],3,0) -> BATTERY 12V 1400 CCA | E19: =VLOOKUP(B19,[1]!Table3[[Part Number]:[Annual]],11,0) -> 4 | F19: =VLOOKUP(B19,[1]!Table3[[Part Number]:[Annual]],4,0) -> 474.8718 | G19: =E19*F19 -> 1899.4872 | H19: =VLOOKUP(B19,[1]!Table3[[Part Number]:[Annual]],5,0) -> 237.44 | I19: =ROUND(E19*H19,2) -> 949.76
G20: =E20*F20 -> 0 | I20: =ROUND(E20*H20,2) -> 0
G21: =E21*F21 -> 0 | I21: =ROUND(E21*H21,2) -> 0
G22: =E22*F22 -> 0 | I22: =ROUND(E22*H22,2) -> 0
G23: =E23*F23 -> 0 | I23: =ROUND(E23*H23,2) -> 0
I24: =ROUND(E24*H24,2) -> 0
I25: =ROUND(E25*H25,2) -> 0
I26: =ROUND(E26*H26,2) -> 0
I27: =ROUND(E27*H27,2) -> 0
I28: =ROUND(E28*H28,2) -> 0
I29: =ROUND(E29*H29,2) -> 0
I30: =ROUND(E30*H30,2) -> 0
I31: =ROUND(E31*H31,2) -> 0
I32: =ROUND(E32*H32,2) -> 0
I33: =ROUND(E33*H33,2) -> 0
I34: =ROUND(E34*H34,2) -> 0
I35: =ROUND(E35*H35,2) -> 0
... I55: =ROUND(E55*H55,2) -> 0
H56: Subtotal | I56: =SUM(I15:I55) -> 14558.2
D57: OEM MSRP : | E57: =SUM(G15:G55) -> 29116.239 | H57: Shipping | I57: 0
D58: GQP : | E58: =SUM(I15:I55) -> 14558.2 | H58: Customs/Broker Fee | I58: 0
D59: GQP SAVINGS : | E59: =E57-E58 -> 14558.039 | H59: Total | I59: =SUM(I56:I58) -> 14558.2
H60: GST | I60: =I59*0.05 -> 727.91
H61: PST / QST
B62: Quote valid for 14 days, shipping subject to delays in supply chain. | H62: GRAND TOTAL | I62: =SUM(I59:I61) -> 15286.11

Sheet MOQ Engines
E1: MOQ QUOTE | H1: Engines
B7: COMPANY: | C7: MPI OILFIELD | E7: DATE: | F7: ='MOQ Grand Total'!F7 -> 45839 | H7: PO NUMBER: | I7: ='MOQ Grand Total'!I7
B8: CONTACT NAME: | E8: PHONE NUMBER: | H8: ='MOQ Grand Total'!H8 -> (780) 385-8652
B9: BILLING ADDRESS: | C9: ='MOQ Grand Total'!C9 -> 0 | E9: EMAIL ADDRESS:
E10: SHIPPING ADDRESS: | H10: ='MOQ Grand Total'!H10 -> 0
C11: ='MOQ Grand Total'!C11 -> 0 | H11: ='MOQ Grand Total'!H11 -> 0
C12: ='MOQ Grand Total'!C12 -> Based on 200 machine hours per month | H12: ='MOQ Grand Total'!H12
F13: CAD $
B14: PART NUMBER | C14: Make & Model | D14: DESCRIPTION | E14: QTY | F14: OEM MSRP | H14: GQP PRICE | I14: TOTAL
B15: 8976030500 | C15: =VLOOKUP(B15,[1]!Table3[[Part Number]:[Annual]],2,0) -> JD 470GLC (1FF) HITACHI 470GLC (HCM) | D15: =VLOOKUP(B15,[1]!Table3[[Part Number]:[Annual]],3,0) -> CAMSHAFT | E15: =VLOOKUP(B15,[1]!Table3[[Part Number]:[Annual]],11,0) -> 2 | F15: =VLOOKUP(B15,[1]!Table3[[Part Number]:[Annual]],4,0) -> 2918.9898 | G15: =E15*F15 -> 5837.9796 | H15: =VLOOKUP(B15,[1]!Table3[[Part Number]:[Annual]],5,0) -> 1459.49 | I15: =ROUND(E15*H15,2) -> 2918.98
B16: 8984814630 | C16: =VLOOKUP(B16,[1]!Table3[[Part Number]:[Annual]],2,0) -> JD 470GLC (1FF) HITACHI 470GLC (HCM) | D16: =VLOOKUP(B16,[1]!Table3[[Part Number]:[Annual]],3,0) -> CRANKSHAFT | E16: =VLOOKUP(B16,[1]!Table3[[Part Number]:[Annual]],11,0) -> 2 | F16: =VLOOKUP(B16,[1]!Table3[[Part Number]:[Annual]],4,0) -> 12606.245 | G16: =E16*F16 -> 25212.49 | H16: =VLOOKUP(B16,[1]!Table3[[Part Number]:[Annual]],5,0) -> 6303.12 | I16: =ROUND(E16*H16,2) -> 12606.24
B17: 171-3063 | C17: =VLOOKUP(B17,[1]!Table3[[Part Number]:[Annual]],2,0) -> CAT D7G (DSC) CAT D7G (DSC) (2) CAT D7G (DSC) (3) CAT D7G (SUB) CAT D7G (3ZD) CAT 572R (DSC) CAT 572R (DSC) (2) | D17: =VLOOKUP(B17,[1]!Table3[[Part Number]:[Annual]],3,0) -> CAMSHAFT | E17: =VLOOKUP(B17,[1]!Table3[[Part Number]:[Annual]],11,0) -> 7 | F17: =VLOOKUP(B17,[1]!Table3[[Part Number]:[Annual]],4,0) -> 6723.47 | G17: =E17*F17 -> 47064.29 | H17: =VLOOKUP(B17,[1]!Table3[[Part Number]:[Annual]],5,0) -> 3361.74 | I17: =ROUND(E17*H17,2) -> 23532.18
B18: 2P-2800 | C18: =VLOOKUP(B18,[1]!Table3[[Part Number]:[Annual]],2,0) -> CAT 594 (96V) CAT 594H (96V) | D18: =VLOOKUP(B18,[1]!Table3[[Part Number]:[Annual]],3,0) -> CRANKSHAFT | E18: =VLOOKUP(B18,[1]!Table3[[Part Number]:[Annual]],11,0) -> 2 | F18: =VLOOKUP(B18,[1]!Table3[[Part Number]:[Annual]],4,0) -> 57259.02 | G18: =E18*F18 -> 114518.04 | H18: =VLOOKUP(B18,[1]!Table3[[Part Number]:[Annual]],5,0) -> 28629.51 | I18: =ROUND(E18*H18,2) -> 57259.02
B19: 326-4278 | C19: =VLOOKUP(B19,[1]!Table3[[Part Number]:[Annual]],2,0) -> CAT D7G (DSC) CAT D7G (DSC) (2) CAT D7G (DSC) (3) CAT D7G (SUB) CAT D7G (3ZD) CAT 572R (DSC) CAT 572R (DSC) (2) | D19: =VLOOKUP(B19,[1]!Table3[[Part Number]:[Annual]],3,0) -> CRANKSHAFT | E19: =VLOOKUP(B19,[1]!Table3[[Part Number]:[Annual]],11,0) -> 7 | F19: =VLOOKUP(B19,[1]!Table3[[Part Number]:[Annual]],4,0) -> 20109.56 | G19: =E19*F19 -> 140766.92 | H19: =VLOOKUP(B19,[1]!Table3[[Part Number]:[Annual]],5,0) -> 10054.78 | I19: =ROUND(E19*H19,2) -> 70383.46
B20: 347-1132 | C20: =VLOOKUP(B20,[1]!Table3[[Part Number]:[Annual]],2,0) -> CAT PL61 (DHA) CAT PL61 (WGS) CAT D6D (06X) | D20: =VLOOKUP(B20,[1]!Table3[[Part Number]:[Annual]],3,0) -> CAMSHAFT | E20: =VLOOKUP(B20,[1]!Table3[[Part Number]:[Annual]],11,0) -> 3 | F20: =VLOOKUP(B20,[1]!Table3[[Part Number]:[Annual]],4,0) -> 744.17 | G20: =E20*F20 -> 2232.51 | H20: =VLOOKUP(B20,[1]!Table3[[Part Number]:[Annual]],5,0) -> 372.09 | I20: =ROUND(E20*H20,2) -> 1116.27
B21: 376-4075 | C21: =VLOOKUP(B21,[1]!Table3[[Part Number]:[Annual]],2,0) -> CAT PL61 (DHA) CAT PL61 (WGS) CAT D6D (06X) | D21: =VLOOKUP(B21,[1]!Table3[[Part Number]:[Annual]],3,0) -> CRANKSHAFT | E21: =VLOOKUP(B21,[1]!Table3[[Part Number]:[Annual]],11,0) -> 3 | F21: =VLOOKUP(B21,[1]!Table3[[Part Number]:[Annual]],4,0) -> 6363.17 | G21: =E21*F21 -> 19089.51 | H21: =VLOOKUP(B21,[1]!Table3[[Part Number]:[Annual]],5,0) -> 3181.59 | I21: =ROUND(E21*H21,2) -> 9544.77
B22: 4H-9983 | C22: =VLOOKUP(B22,[1]!Table3[[Part Number]:[Annual]],2,0) -> CAT 594 (96V) CAT 594H (96V) | D22: =VLOOKUP(B22,[1]!Table3[[Part Number]:[Annual]],3,0) -> CAMSHAFT | E22: =VLOOKUP(B22,[1]!Table3[[Part Number]:[Annual]],11,0) -> 2 | F22: =VLOOKUP(B22,[1]!Table3[[Part Number]:[Annual]],4,0) -> 6442.44 | G22: =E22*F22 -> 12884.88 | H22: =VLOOKUP(B22,[1]!Table3[[Part Number]:[Annual]],5,0) -> 3221.22 | I22: =ROUND(E22*H22,2) -> 6442.44
B23: RE507149 | C23: =VLOOKUP(B23,[1]!Table3[[Part Number]:[Annual]],2,0) -> HITACHI ZX290LC-5 (1FF) HITACHI ZX290LC-5 (1FF) (2) HITACHI ZX290LC-5 (1FF) (3) | D23: =VLOOKUP(B23,[1]!Table3[[Part Number]:[Annual]],3,0) -> CAMSHAFT | E23: =VLOOKUP(B23,[1]!Table3[[Part Number]:[Annual]],11,0) -> 3 | F23: =VLOOKUP(B23,[1]!Table3[[Part Number]:[Annual]],4,0) -> 798.0402 | G23: =E23*F23 -> 2394.1206 | H23: =VLOOKUP(B23,[1]!Table3[[Part Number]:[Annual]],5,0) -> 399.02 | I23: =ROUND(E23*H23,2) -> 1197.06
B24: RE515785 | C24: =VLOOKUP(B24,[1]!Table3[[Part Number]:[Annual]],2,0) -> HITACHI ZX290LC-5 (1FF) HITACHI ZX290LC-5 (1FF) (2) HITACHI ZX290LC-5 (1FF) (3) | D24: =VLOOKUP(B24,[1]!Table3[[Part Number]:[Annual]],3,0) -> CRANKSHAFT | E24: =VLOOKUP(B24,[1]!Table3[[Part Number]:[Annual]],11,0) -> 3 | F24: =VLOOKUP(B24,[1]!Table3[[Part Number]:[Annual]],4,0) -> 5593.071 | G24: =E24*F24 -> 16779.213 | H24: =VLOOKUP(B24,[1]!Table3[[Part Number]:[Annual]],5,0) -> 2796.54 | I24: =ROUND(E24*H24,2) -> 8389.62
I25: =ROUND(E25*H25,2) -> 0
I26: =ROUND(E26*H26,2) -> 0
I27: =ROUND(E27*H27,2) -> 0
I28: =ROUND(E28*H28,2) -> 0
I29: =ROUND(E29*H29,2) -> 0
I30: =ROUND(E30*H30,2) -> 0
I31: =ROUND(E31*H31,2) -> 0
I32: =ROUND(E32*H32,2) -> 0
I33: =ROUND(E33*H33,2) -> 0
I34: =ROUND(E34*H34,2) -> 0
I35: =ROUND(E35*H35,2) -> 0
I36: =ROUND(E36*H36,2) -> 0
... I55: =ROUND(E55*H55,2) -> 0
H56: Subtotal | I56: =SUM(I15:I55) -> 193390.04
D57: OEM MSRP : | E57: =SUM(G15:G55) -> 386779.95 | H57: Shipping | I57: 0
D58: GQP : | E58: =SUM(I15:I55) -> 193390.04 | H58: Customs/Broker Fee | I58: 0
D59: GQP SAVINGS : | E59: =E57-E58 -> 193389.91 | H59: Total | I59: =SUM(I56:I58) -> 193390.04
H60: GST | I60: =I59*0.05 -> 9669.502
H61: PST / QST
B62: Quote valid for 14 days, shipping subject to delays in supply chain. | H62: GRAND TOTAL | I62: =SUM(I59:I61) -> 203059.54

Sheet MOQ Filters Q1
E1: MOQ QUOTE | H1: Filters Q1
B7: COMPANY: | C7: MPI OILFIELD | E7: DATE: | F7: ='MOQ Grand Total'!F7 -> 45839 | H7: PO NUMBER: | I7: ='MOQ Grand Total'!I7
B8: CONTACT NAME: | E8: PHONE NUMBER: | H8: ='MOQ Grand Total'!H8 -> (780) 385-8652
B9: BILLING ADDRESS: | C9: ='MOQ Grand Total'!C9 -> 0 | E9: EMAIL ADDRESS:
E10: SHIPPING ADDRESS: | H10: ='MOQ Grand Total'!H10 -> 0
C11: ='MOQ Grand Total'!C11 -> 0 | H11: ='MOQ Grand Total'!H11 -> 0
C12: ='MOQ Grand Total'!C12 -> Based on 200 machine hours per month | H12: ='MOQ Grand Total'!H12
F13: CAD $
B14: PART NUMBER | C14: Make & Model | D14: DESCRIPTION | E14: QTY | F14: OEM MSRP | H14: GQP PRICE | I14: TOTAL
B15: 4630525 | C15: =VLOOKUP(B15,[1]!Table3[[Part Number]:[Annual]],2,0) -> JD 470GLC (1FF) HITACHI 470GLC (HCM) | D15: =VLOOKUP(B15,[1]!Table3[[Part Number]:[Annual]],3,0) -> HYDRAULIC FILTER | E15: =VLOOKUP(B15,[1]!Table3[[Part Number]:[Annual]],7,0) -> 2 | F15: =VLOOKUP(B15,[1]!Table3[[Part Number]:[Annual]],4,0) -> 96.1446 | G15: =E15*F15 -> 192.2892 | H15: =VLOOKUP(B15,[1]!Table3[[Part Number]:[Annual]],5,0) -> 48.07 | I15: =ROUND(E15*H15,2) -> 96.14
B16: 8981527381 | C16: =VLOOKUP(B16,[1]!Table3[[Part Number]:[Annual]],2,0) -> JD 470GLC (1FF) HITACHI 470GLC (HCM) | D16: =VLOOKUP(B16,[1]!Table3[[Part Number]:[Annual]],3,0) -> FINAL FUEL FILTER | E16: =VLOOKUP(B16,[1]!Table3[[Part Number]:[Annual]],7,0) -> 8 | F16: =VLOOKUP(B16,[1]!Table3[[Part Number]:[Annual]],4,0) -> 80.868 | G16: =E16*F16 -> 646.944 | H16: =VLOOKUP(B16,[1]!Table3[[Part Number]:[Annual]],5,0) -> 40.43 | I16: =ROUND(E16*H16,2) -> 323.44
B17: 8983020750 | C17: =VLOOKUP(B17,[1]!Table3[[Part Number]:[Annual]],2,0) -> JD 470GLC (1FF) HITACHI 470GLC (HCM) | D17: =VLOOKUP(B17,[1]!Table3[[Part Number]:[Annual]],3,0) -> ENGINE OIL FILTER | E17: =VLOOKUP(B17,[1]!Table3[[Part Number]:[Annual]],7,0) -> 8 | F17: =VLOOKUP(B17,[1]!Table3[[Part Number]:[Annual]],4,0) -> 107.0742 | G17: =E17*F17 -> 856.5936 | H17: =VLOOKUP(B17,[1]!Table3[[Part Number]:[Annual]],5,0) -> 53.54 | I17: =ROUND(E17*H17,2) -> 428.32
B18: 1G-8878 | C18: =VLOOKUP(B18,[1]!Table3[[Part Number]:[Annual]],2,0) -> CAT PL61 (DHA) CAT PL61 (WGS) CAT D6D (06X) | D18: =VLOOKUP(B18,[1]!Table3[[Part Number]:[Annual]],3,0) -> HYDRAULIC OIL FILTER (POWER TRAIN) | E18: =VLOOKUP(B18,[1]!Table3[[Part Number]:[Annual]],7,0) -> 3 | F18: =VLOOKUP(B18,[1]!Table3[[Part Number]:[Annual]],4,0) -> 145.28 | G18: =E18*F18 -> 435.84 | H18: =VLOOKUP(B18,[1]!Table3[[Part Number]:[Annual]],5,0) -> 72.64 | I18: =ROUND(E18*H18,2) -> 217.92
B19: 1P-7360 | C19: =VLOOKUP(B19,[1]!Table3[[Part Number]:[Annual]],2,0) -> CAT 583T (CMX) CAT 589 (31Z) CAT DK8 (893) CAT DK8 (950) | D19: =VLOOKUP(B19,[1]!Table3[[Part Number]:[Annual]],3,0) -> Air Filter - Secondary | E19: =VLOOKUP(B19,[1]!Table3[[Part Number]:[Annual]],7,0) -> 8 | F19: =VLOOKUP(B19,[1]!Table3[[Part Number]:[Annual]],4,0) -> 167.36 | G19: =E19*F19 -> 1338.88 | H19: =VLOOKUP(B19,[1]!Table3[[Part Number]:[Annual]],5,0) -> 108.78 | I19: =ROUND(E19*H19,2) -> 870.24
B20: 1P-8482 | C20: =VLOOKUP(B20,[1]!Table3[[Part Number]:[Annual]],2,0) -> CAT 594 (96V) CAT 594H (96V) | D20: =VLOOKUP(B20,[1]!Table3[[Part Number]:[Annual]],3,0) -> SECONDARY AIR FILTER ELEMENT | E20: =VLOOKUP(B20,[1]!Table3[[Part Number]:[Annual]],7,0) -> 6 | F20: =VLOOKUP(B20,[1]!Table3[[Part Number]:[Annual]],4,0) -> 222 | G20: =E20*F20 -> 1332 | H20: =VLOOKUP(B20,[1]!Table3[[Part Number]:[Annual]],5,0) -> 144.3 | I20: =ROUND(E20*H20,2) -> 865.8
B21: 1P-8483 | C21: =VLOOKUP(B21,[1]!Table3[[Part Number]:[Annual]],2,0) -> CAT 594 (96V) CAT 594H (96V) | D21: =VLOOKUP(B21,[1]!Table3[[Part Number]:[Annual]],3,0) -> PRIMARY AIR FILTER ELEMENT | E21: =VLOOKUP(B21,[1]!Table3[[Part Number]:[Annual]],7,0) -> 6 | F21: =VLOOKUP(B21,[1]!Table3[[Part Number]:[Annual]],4,0) -> 121.8 | G21: =E21*F21 -> 730.8 | H21: =VLOOKUP(B21,[1]!Table3[[Part Number]:[Annual]],5,0) -> 79.17 | I21: =ROUND(E21*H21,2) -> 475.02
B22: 1R-0716 | C22: =VLOOKUP(B22,[1]!Table3[[Part Number]:[Annual]],2,0) -> CAT D7G (DSC) CAT D7G (DSC) (2) CAT D7G (DSC) (3) CAT D7G (SUB) CAT D7G (3ZD) CAT 572R (DSC) CAT 572R (DSC) (2) | D22: =VLOOKUP(B22,[1]!Table3[[Part Number]:[Annual]],3,0) -> ENGINE OIL FILTER | E22: =VLOOKUP(B22,[1]!Table3[[Part Number]:[Annual]],7,0) -> 21 | F22: =VLOOKUP(B22,[1]!Table3[[Part Number]:[Annual]],4,0) -> 59.49 | G22: =E22*F22 -> 1249.29 | H22: =VLOOKUP(B22,[1]!Table3[[Part Number]:[Annual]],5,0) -> 29.75 | I22: =ROUND(E22*H22,2) -> 624.75
B23: 1R-0728 | C23: =VLOOKUP(B23,[1]!Table3[[Part Number]:[Annual]],2,0) -> CAT 594 (96V) CAT 594H (96V) | D23: =VLOOKUP(B23,[1]!Table3[[Part Number]:[Annual]],3,0) -> HYDRAULIC FILTER | E23: =VLOOKUP(B23,[1]!Table3[[Part Number]:[Annual]],7,0) -> 4 | F23: =VLOOKUP(B23,[1]!Table3[[Part Number]:[Annual]],4,0) -> 47.98 | G23: =E23*F23 -> 191.92 | H23: =VLOOKUP(B23,[1]!Table3[[Part Number]:[Annual]],5,0) -> 23.99 | I23: =ROUND(E23*H23,2) -> 95.96
B24: 1R-0741 | C24: =VLOOKUP(B24,[1]!Table3[[Part Number]:[Annual]],2,0) -> CAT 583T (CMX) CAT 589 (31Z) CAT 594 (96V) CAT 594H (96V) CAT DK8 (893) CAT DK8 (950) | D24: =VLOOKUP(B24,[1]!Table3[[Part Number]:[Annual]],3,0) -> Hydraulic Filter | E24: =VLOOKUP(B24,[1]!Table3[[Part Number]:[Annual]],7,0) -> 16 | F24: =VLOOKUP(B24,[1]!Table3[[Part Number]:[Annual]],4,0) -> 38.31 | G24: =E24*F24 -> 612.96 | H24: =VLOOKUP(B24,[1]!Table3[[Part Number]:[Annual]],5,0) -> 19.16 | I24: =ROUND(E24*H24,2) -> 306.56
B25: 1R-0749 | C25: =VLOOKUP(B25,[1]!Table3[[Part Number]:[Annual]],2,0) -> CAT D7G (DSC) CAT D7G (DSC) (2) CAT D7G (DSC) (3) CAT D7G (SUB) CAT D7G (3ZD) CAT 572R (DSC) CAT 572R (DSC) (2) | D25: =VLOOKUP(B25,[1]!Table3[[Part Number]:[Annual]],3,0) -> FUEL FILTER | E25: =VLOOKUP(B25,[1]!Table3[[Part Number]:[Annual]],7,0) -> 21 | F25: =VLOOKUP(B25,[1]!Table3[[Part Number]:[Annual]],4,0) -> 49.75 | G25: =E25*F25 -> 1044.75 | H25: =VLOOKUP(B25,[1]!Table3[[Part Number]:[Annual]],5,0) -> 24.88 | I25: =ROUND(E25*H25,2) -> 522.48
B26: 1R-0750 | C26: =VLOOKUP(B26,[1]!Table3[[Part Number]:[Annual]],2,0) -> CAT 583T (CMX) CAT 589 (31Z) CAT 594 (96V) CAT 594H (96V) CAT DK8 (893) CAT DK8 (950) | D26: =VLOOKUP(B26,[1]!Table3[[Part Number]:[Annual]],3,0) -> Fuel Filter - Secondary | E26: =VLOOKUP(B26,[1]!Table3[[Part Number]:[Annual]],7,0) -> 28 | F26: =VLOOKUP(B26,[1]!Table3[[Part Number]:[Annual]],4,0) -> 41.22 | G26: =E26*F26 -> 1154.16 | H26: =VLOOKUP(B26,[1]!Table3[[Part Number]:[Annual]],5,0) -> 20.61 | I26: =ROUND(E26*H26,2) -> 577.08
B27: 209-8217 | C27: =VLOOKUP(B27,[1]!Table3[[Part Number]:[Annual]],2,0) -> CAT PL61 (DHA) CAT PL61 (WGS) CAT D6D (06X) | D27: =VLOOKUP(B27,[1]!Table3[[Part Number]:[Annual]],3,0) -> CABIN AIR FILTER ELEMENT | E27: =VLOOKUP(B27,[1]!Table3[[Part Number]:[Annual]],7,0) -> 3 | F27: =VLOOKUP(B27,[1]!Table3[[Part Number]:[Annual]],4,0) -> 82.23 | G27: =E27*F27 -> 246.69 | H27: =VLOOKUP(B27,[1]!Table3[[Part Number]:[Annual]],5,0) -> 53.45 | I27: =ROUND(E27*H27,2) -> 160.35
B28: 252-5001 | C28: =VLOOKUP(B28,[1]!Table3[[Part Number]:[Annual]],2,0) -> CAT PL61 (DHA) CAT PL61 (WGS) CAT D6D (06X) | D28: =VLOOKUP(B28,[1]!Table3[[Part Number]:[Annual]],3,0) -> PRIMARY AIR FILTER ELEMENT | E28: =VLOOKUP(B28,[1]!Table3[[Part Number]:[Annual]],7,0) -> 6 | F28: =VLOOKUP(B28,[1]!Table3[[Part Number]:[Annual]],4,0) -> 214.1 | G28: =E28*F28 -> 1284.6 | H28: =VLOOKUP(B28,[1]!Table3[[Part Number]:[Annual]],5,0) -> 139.17 | I28: =ROUND(E28*H28,2) -> 835.02
B29: 252-5002 | C29: =VLOOKUP(B29,[1]!Table3[[Part Number]:[Annual]],2,0) -> CAT PL61 (DHA) CAT PL61 (WGS) CAT D6D (06X) | D29: =VLOOKUP(B29,[1]!Table3[[Part Number]:[Annual]],3,0) -> SECONDARY AIR FILTER ELEMENT | E29: =VLOOKUP(B29,[1]!Table3[[Part Number]:[Annual]],7,0) -> 6 | F29: =VLOOKUP(B29,[1]!Table3[[Part Number]:[Annual]],4,0) -> 147.41 | G29: =E29*F29 -> 884.46 | H29: =VLOOKUP(B29,[1]!Table3[[Part Number]:[Annual]],5,0) -> 95.82 | I29: =ROUND(E29*H29,2) -> 574.92
... B58: TT220747 | C58: =VLOOKUP(B58,[1]!Table3[[Part Number]:[Annual]],2,0) -> JD 470GLC (1FF) HITACHI 470GLC (HCM) | D58: =VLOOKUP(B58,[1]!Table3[[Part Number]:[Annual]],3,0) -> SECONDARY AIR FILTER | E58: =VLOOKUP(B58,[1]!Table3[[Part Number]:[Annual]],7,0) -> 2 | F58: =VLOOKUP(B58,[1]!Table3[[Part Number]:[Annual]],4,0) -> 119.3286 | G58: =E58*F58 -> 238.6572 | H58: =VLOOKUP(B58,[1]!Table3[[Part Number]:[Annual]],5,0) -> 77.56 | I58: =ROUND(E58*H58,2) -> 155.12
I59: =ROUND(E59*H59,2) -> 0
I60: =ROUND(E60*H60,2) -> 0
I61: =ROUND(E61*H61,2) -> 0
I62: =ROUND(E62*H62,2) -> 0
I63: =ROUND(E63*H63,2) -> 0
I64: =ROUND(E64*H64,2) -> 0
I65: =ROUND(E65*H65,2) -> 0
I66: =ROUND(E66*H66,2) -> 0
I67: =ROUND(E67*H67,2) -> 0
I68: =ROUND(E68*H68,2) -> 0
I69: =ROUND(E69*H69,2) -> 0
I70: =ROUND(E70*H70,2) -> 0
... I164: =ROUND(E164*H164,2) -> 0
H165: Subtotal | I165: =SUM(I15:I164) -> 19027.73
D166: OEM MSRP : | E166: =SUM(G15:G164) -> 33177.961 | H166: Shipping | I166: 0
...

Sheet MOQ Filters Q2
E1: MOQ QUOTE | H1: Filters Q2
B7: COMPANY: | C7: MPI OILFIELD | E7: DATE: | F7: ='MOQ Grand Total'!F7 -> 45839 | H7: PO NUMBER: | I7: ='MOQ Grand Total'!I7
B8: CONTACT NAME: | E8: PHONE NUMBER: | H8: ='MOQ Grand Total'!H8 -> (780) 385-8652
B9: BILLING ADDRESS: | C9: ='MOQ Grand Total'!C9 -> 0 | E9: EMAIL ADDRESS:
E10: SHIPPING ADDRESS: | H10: ='MOQ Grand Total'!H10 -> 0
C11: ='MOQ Grand Total'!C11 -> 0 | H11: ='MOQ Grand Total'!H11 -> 0
C12: ='MOQ Grand Total'!C12 -> Based on 200 machine hours per month | H12: ='MOQ Grand Total'!H12
F13: CAD $
B14: PART NUMBER | C14: Make & Model | D14: DESCRIPTION | E14: QTY | F14: OEM MSRP | H14: GQP PRICE | I14: TOTAL
B15: 4630525 | C15: =VLOOKUP(B15,[1]!Table3[[Part Number]:[Annual]],2,0) -> JD 470GLC (1FF) HITACHI 470GLC (HCM) | D15: =VLOOKUP(B15,[1]!Table3[[Part Number]:[Annual]],3,0) -> HYDRAULIC FILTER | E15: =VLOOKUP(B15,[1]!Table3[[Part Number]:[Annual]],8,0) -> 2 | F15: =VLOOKUP(B15,[1]!Table3[[Part Number]:[Annual]],4,0) -> 96.1446 | G15: =E15*F15 -> 192.2892 | H15: =VLOOKUP(B15,[1]!Table3[[Part Number]:[Annual]],5,0) -> 48.07 | I15: =ROUND(E15*H15,2) -> 96.14
B16: 8981527381 | C16: =VLOOKUP(B16,[1]!Table3[[Part Number]:[Annual]],2,0) -> JD 470GLC (1FF) HITACHI 470GLC (HCM) | D16: =VLOOKUP(B16,[1]!Table3[[Part Number]:[Annual]],3,0) -> FINAL FUEL FILTER | E16: =VLOOKUP(B16,[1]!Table3[[Part Number]:[Annual]],8,0) -> 4 | F16: =VLOOKUP(B16,[1]!Table3[[Part Number]:[Annual]],4,0) -> 80.868 | G16: =E16*F16 -> 323.472 | H16: =VLOOKUP(B16,[1]!Table3[[Part Number]:[Annual]],5,0) -> 40.43 | I16: =ROUND(E16*H16,2) -> 161.72
B17: 8983020750 | C17: =VLOOKUP(B17,[1]!Table3[[Part Number]:[Annual]],2,0) -> JD 470GLC (1FF) HITACHI 470GLC (HCM) | D17: =VLOOKUP(B17,[1]!Table3[[Part Number]:[Annual]],3,0) -> ENGINE OIL FILTER | E17: =VLOOKUP(B17,[1]!Table3[[Part Number]:[Annual]],8,0) -> 4 | F17: =VLOOKUP(B17,[1]!Table3[[Part Number]:[Annual]],4,0) -> 107.0742 | G17: =E17*F17 -> 428.2968 | H17: =VLOOKUP(B17,[1]!Table3[[Part Number]:[Annual]],5,0) -> 53.54 | I17: =ROUND(E17*H17,2) -> 214.16
B18: 1G-8878 | C18: =VLOOKUP(B18,[1]!Table3[[Part Number]:[Annual]],2,0) -> CAT PL61 (DHA) CAT PL61 (WGS) CAT D6D (06X) | D18: =VLOOKUP(B18,[1]!Table3[[Part Number]:[Annual]],3,0) -> HYDRAULIC OIL FILTER (POWER TRAIN) | E18: =VLOOKUP(B18,[1]!Table3[[Part Number]:[Annual]],8,0) -> 3 | F18: =VLOOKUP(B18,[1]!Table3[[Part Number]:[Annual]],4,0) -> 145.28 | G18: =E18*F18 -> 435.84 | H18: =VLOOKUP(B18,[1]!Table3[[Part Number]:[Annual]],5,0) -> 72.64 | I18: =ROUND(E18*H18,2) -> 217.92
B19: 1P-7360 | C19: =VLOOKUP(B19,[1]!Table3[[Part Number]:[Annual]],2,0) -> CAT 583T (CMX) CAT 589 (31Z) CAT DK8 (893) CAT DK8 (950) | D19: =VLOOKUP(B19,[1]!Table3[[Part Number]:[Annual]],3,0) -> Air Filter - Secondary | E19: =VLOOKUP(B19,[1]!Table3[[Part Number]:[Annual]],8,0) -> 4 | F19: =VLOOKUP(B19,[1]!Table3[[Part Number]:[Annual]],4,0) -> 167.36 | G19: =E19*F19 -> 669.44 | H19: =VLOOKUP(B19,[1]!Table3[[Part Number]:[Annual]],5,0) -> 108.78 | I19: =ROUND(E19*H19,2) -> 435.12
B20: 1P-8482 | C20: =VLOOKUP(B20,[1]!Table3[[Part Number]:[Annual]],2,0) -> CAT 594 (96V) CAT 594H (96V) | D20: =VLOOKUP(B20,[1]!Table3[[Part Number]:[Annual]],3,0) -> SECONDARY AIR FILTER ELEMENT | E20: =VLOOKUP(B20,[1]!Table3[[Part Number]:[Annual]],8,0) -> 4 | F20: =VLOOKUP(B20,[1]!Table3[[Part Number]:[Annual]],4,0) -> 222 | G20: =E20*F20 -> 888 | H20: =VLOOKUP(B20,[1]!Table3[[Part Number]:[Annual]],5,0) -> 144.3 | I20: =ROUND(E20*H20,2) -> 577.2
B21: 1P-8483 | C21: =VLOOKUP(B21,[1]!Table3[[Part Number]:[Annual]],2,0) -> CAT 594 (96V) CAT 594H (96V) | D21: =VLOOKUP(B21,[1]!Table3[[Part Number]:[Annual]],3,0) -> PRIMARY AIR FILTER ELEMENT | E21: =VLOOKUP(B21,[1]!Table3[[Part Number]:[Annual]],8,0) -> 4 | F21: =VLOOKUP(B21,[1]!Table3[[Part Number]:[Annual]],4,0) -> 121.8 | G21: =E21*F21 -> 487.2 | H21: =VLOOKUP(B21,[1]!Table3[[Part Number]:[Annual]],5,0) -> 79.17 | I21: =ROUND(E21*H21,2) -> 316.68
B22: 1R-0716 | C22: =VLOOKUP(B22,[1]!Table3[[Part Number]:[Annual]],2,0) -> CAT D7G (DSC) CAT D7G (DSC) (2) CAT D7G (DSC) (3) CAT D7G (SUB) CAT D7G (3ZD) CAT 572R (DSC) CAT 572R (DSC) (2) | D22: =VLOOKUP(B22,[1]!Table3[[Part Number]:[Annual]],3,0) -> ENGINE OIL FILTER | E22: =VLOOKUP(B22,[1]!Table3[[Part Number]:[Annual]],8,0) -> 14 | F22: =VLOOKUP(B22,[1]!Table3[[Part Number]:[Annual]],4,0) -> 59.49 | G22: =E22*F22 -> 832.86 | H22: =VLOOKUP(B22,[1]!Table3[[Part Number]:[Annual]],5,0) -> 29.75 | I22: =ROUND(E22*H22,2) -> 416.5
B23: 1R-0728 | C23: =VLOOKUP(B23,[1]!Table3[[Part Number]:[Annual]],2,0) -> CAT 594 (96V) CAT 594H (96V) | D23: =VLOOKUP(B23,[1]!Table3[[Part Number]:[Annual]],3,0) -> HYDRAULIC FILTER | E23: =VLOOKUP(B23,[1]!Table3[[Part Number]:[Annual]],8,0) -> 2 | F23: =VLOOKUP(B23,[1]!Table3[[Part Number]:[Annual]],4,0) -> 47.98 | G23: =E23*F23 -> 95.96 | H23: =VLOOKUP(B23,[1]!Table3[[Part Number]:[Annual]],5,0) -> 23.99 | I23: =ROUND(E23*H23,2) -> 47.98
B24: 1R-0741 | C24: =VLOOKUP(B24,[1]!Table3[[Part Number]:[Annual]],2,0) -> CAT 583T (CMX) CAT 589 (31Z) CAT 594 (96V) CAT 594H (96V) CAT DK8 (893) CAT DK8 (950) | D24: =VLOOKUP(B24,[1]!Table3[[Part Number]:[Annual]],3,0) -> Hydraulic Filter | E24: =VLOOKUP(B24,[1]!Table3[[Part Number]:[Annual]],8,0) -> 8 | F24: =VLOOKUP(B24,[1]!Table3[[Part Number]:[Annual]],4,0) -> 38.31 | G24: =E24*F24 -> 306.48 | H24: =VLOOKUP(B24,[1]!Table3[[Part Number]:[Annual]],5,0) -> 19.16 | I24: =ROUND(E24*H24,2) -> 153.28
B25: 1R-0749 | C25: =VLOOKUP(B25,[1]!Table3[[Part Number]:[Annual]],2,0) -> CAT D7G (DSC) CAT D7G (DSC) (2) CAT D7G (DSC) (3) CAT D7G (SUB) CAT D7G (3ZD) CAT 572R (DSC) CAT 572R (DSC) (2) | D25: =VLOOKUP(B25,[1]!Table3[[Part Number]:[Annual]],3,0) -> FUEL FILTER | E25: =VLOOKUP(B25,[1]!Table3[[Part Number]:[Annual]],8,0) -> 14 | F25: =VLOOKUP(B25,[1]!Table3[[Part Number]:[Annual]],4,0) -> 49.75 | G25: =E25*F25 -> 696.5 | H25: =VLOOKUP(B25,[1]!Table3[[Part Number]:[Annual]],5,0) -> 24.88 | I25: =ROUND(E25*H25,2) -> 348.32
B26: 1R-0750 | C26: =VLOOKUP(B26,[1]!Table3[[Part Number]:[Annual]],2,0) -> CAT 583T (CMX) CAT 589 (31Z) CAT 594 (96V) CAT 594H (96V) CAT DK8 (893) CAT DK8 (950) | D26: =VLOOKUP(B26,[1]!Table3[[Part Number]:[Annual]],3,0) -> Fuel Filter - Secondary | E26: =VLOOKUP(B26,[1]!Table3[[Part Number]:[Annual]],8,0) -> 16 | F26: =VLOOKUP(B26,[1]!Table3[[Part Number]:[Annual]],4,0) -> 41.22 | G26: =E26*F26 -> 659.52 | H26: =VLOOKUP(B26,[1]!Table3[[Part Number]:[Annual]],5,0) -> 20.61 | I26: =ROUND(E26*H26,2) -> 329.76
B27: 209-8217 | C27: =VLOOKUP(B27,[1]!Table3[[Part Number]:[Annual]],2,0) -> CAT PL61 (DHA) CAT PL61 (WGS) CAT D6D (06X) | D27: =VLOOKUP(B27,[1]!Table3[[Part Number]:[Annual]],3,0) -> CABIN AIR FILTER ELEMENT | E27: =VLOOKUP(B27,[1]!Table3[[Part Number]:[Annual]],8,0) -> 0 | F27: =VLOOKUP(B27,[1]!Table3[[Part Number]:[Annual]],4,0) -> 82.23 | G27: =E27*F27 -> 0 | H27: =VLOOKUP(B27,[1]!Table3[[Part Number]:[Annual]],5,0) -> 53.45 | I27: =ROUND(E27*H27,2) -> 0
B28: 252-5001 | C28: =VLOOKUP(B28,[1]!Table3[[Part Number]:[Annual]],2,0) -> CAT PL61 (DHA) CAT PL61 (WGS) CAT D6D (06X) | D28: =VLOOKUP(B28,[1]!Table3[[Part Number]:[Annual]],3,0) -> PRIMARY AIR FILTER ELEMENT | E28: =VLOOKUP(B28,[1]!Table3[[Part Number]:[Annual]],8,0) -> 3 | F28: =VLOOKUP(B28,[1]!Table3[[Part Number]:[Annual]],4,0) -> 214.1 | G28: =E28*F28 -> 642.3 | H28: =VLOOKUP(B28,[1]!Table3[[Part Number]:[Annual]],5,0) -> 139.17 | I28: =ROUND(E28*H28,2) -> 417.51
B29: 252-5002 | C29: =VLOOKUP(B29,[1]!Table3[[Part Number]:[Annual]],2,0) -> CAT PL61 (DHA) CAT PL61 (WGS) CAT D6D (06X) | D29: =VLOOKUP(B29,[1]!Table3[[Part Number]:[Annual]],3,0) -> SECONDARY AIR FILTER ELEMENT | E29: =VLOOKUP(B29,[1]!Table3[[Part Number]:[Annual]],8,0) -> 3 | F29: =VLOOKUP(B29,[1]!Table3[[Part Number]:[Annual]],4,0) -> 147.41 | G29: =E29*F29 -> 442.23 | H29: =VLOOKUP(B29,[1]!Table3[[Part Number]:[Annual]],5,0) -> 95.82 | I29: =ROUND(E29*H29,2) -> 287.46
... B58: TT220747 | C58: =VLOOKUP(B58,[1]!Table3[[Part Number]:[Annual]],2,0) -> JD 470GLC (1FF) HITACHI 470GLC (HCM) | D58: =VLOOKUP(B58,[1]!Table3[[Part Number]:[Annual]],3,0) -> SECONDARY AIR FILTER | E58: =VLOOKUP(B58,[1]!Table3[[Part Number]:[Annual]],8,0) -> 2 | F58: =VLOOKUP(B58,[1]!Table3[[Part Number]:[Annual]],4,0) -> 119.3286 | G58: =E58*F58 -> 238.6572 | H58: =VLOOKUP(B58,[1]!Table3[[Part Number]:[Annual]],5,0) -> 77.56 | I58: =ROUND(E58*H58,2) -> 155.12
I59: =ROUND(E59*H59,2) -> 0
I60: =ROUND(E60*H60,2) -> 0
I61: =ROUND(E61*H61,2) -> 0
I62: =ROUND(E62*H62,2) -> 0
I63: =ROUND(E63*H63,2) -> 0
I64: =ROUND(E64*H64,2) -> 0
I65: =ROUND(E65*H65,2) -> 0
I66: =ROUND(E66*H66,2) -> 0
I67: =ROUND(E67*H67,2) -> 0
I68: =ROUND(E68*H68,2) -> 0
I69: =ROUND(E69*H69,2) -> 0
I70: =ROUND(E70*H70,2) -> 0
... I164: =ROUND(E164*H164,2) -> 0
H165: Subtotal | I165: =SUM(I15:I164) -> 11417.39
D166: OEM MSRP : | E166: =SUM(G15:G164) -> 19811.282 | H166: Shipping | I166: 0
...

Sheet MOQ Filters Q3
E1: MOQ QUOTE | H1: Filters Q3
B7: COMPANY: | C7: MPI OILFIELD | E7: DATE: | F7: ='MOQ Grand Total'!F7 -> 45839 | H7: PO NUMBER: | I7: ='MOQ Grand Total'!I7
B8: CONTACT NAME: | E8: PHONE NUMBER: | H8: ='MOQ Grand Total'!H8 -> (780) 385-8652
B9: BILLING ADDRESS: | C9: ='MOQ Grand Total'!C9 -> 0 | E9: EMAIL ADDRESS:
E10: SHIPPING ADDRESS: | H10: ='MOQ Grand Total'!H10 -> 0
C11: ='MOQ Grand Total'!C11 -> 0 | H11: ='MOQ Grand Total'!H11 -> 0
C12: ='MOQ Grand Total'!C12 -> Based on 200 machine hours per month | H12: ='MOQ Grand Total'!H12
F13: CAD $
B14: PART NUMBER | C14: Make & Model | D14: DESCRIPTION | E14: QTY | F14: OEM MSRP | H14: GQP PRICE | I14: TOTAL
B15: 4630525 | C15: =VLOOKUP(B15,[1]!Table3[[Part Number]:[Annual]],2,0) -> JD 470GLC (1FF) HITACHI 470GLC (HCM) | D15: =VLOOKUP(B15,[1]!Table3[[Part Number]:[Annual]],3,0) -> HYDRAULIC FILTER | E15: =VLOOKUP(B15,[1]!Table3[[Part Number]:[Annual]],9,0) -> 0 | F15: =VLOOKUP(B15,[1]!Table3[[Part Number]:[Annual]],4,0) -> 96.1446 | G15: =E15*F15 -> 0 | H15: =VLOOKUP(B15,[1]!Table3[[Part Number]:[Annual]],5,0) -> 48.07 | I15: =ROUND(E15*H15,2) -> 0
B16: 8981527381 | C16: =VLOOKUP(B16,[1]!Table3[[Part Number]:[Annual]],2,0) -> JD 470GLC (1FF) HITACHI 470GLC (HCM) | D16: =VLOOKUP(B16,[1]!Table3[[Part Number]:[Annual]],3,0) -> FINAL FUEL FILTER | E16: =VLOOKUP(B16,[1]!Table3[[Part Number]:[Annual]],9,0) -> 4 | F16: =VLOOKUP(B16,[1]!Table3[[Part Number]:[Annual]],4,0) -> 80.868 | G16: =E16*F16 -> 323.472 | H16: =VLOOKUP(B16,[1]!Table3[[Part Number]:[Annual]],5,0) -> 40.43 | I16: =ROUND(E16*H16,2) -> 161.72
B17: 8983020750 | C17: =VLOOKUP(B17,[1]!Table3[[Part Number]:[Annual]],2,0) -> JD 470GLC (1FF) HITACHI 470GLC (HCM) | D17: =VLOOKUP(B17,[1]!Table3[[Part Number]:[Annual]],3,0) -> ENGINE OIL FILTER | E17: =VLOOKUP(B17,[1]!Table3[[Part Number]:[Annual]],9,0) -> 4 | F17: =VLOOKUP(B17,[1]!Table3[[Part Number]:[Annual]],4,0) -> 107.0742 | G17: =E17*F17 -> 428.2968 | H17: =VLOOKUP(B17,[1]!Table3[[Part Number]:[Annual]],5,0) -> 53.54 | I17: =ROUND(E17*H17,2) -> 214.16
B18: 1G-8878 | C18: =VLOOKUP(B18,[1]!Table3[[Part Number]:[Annual]],2,0) -> CAT PL61 (DHA) CAT PL61 (WGS) CAT D6D (06X) | D18: =VLOOKUP(B18,[1]!Table3[[Part Number]:[Annual]],3,0) -> HYDRAULIC OIL FILTER (POWER TRAIN) | E18: =VLOOKUP(B18,[1]!Table3[[Part Number]:[Annual]],9,0) -> 0 | F18: =VLOOKUP(B18,[1]!Table3[[Part Number]:[Annual]],4,0) -> 145.28 | G18: =E18*F18 -> 0 | H18: =VLOOKUP(B18,[1]!Table3[[Part Number]:[Annual]],5,0) -> 72.64 | I18: =ROUND(E18*H18,2) -> 0
B19: 1P-7360 | C19: =VLOOKUP(B19,[1]!Table3[[Part Number]:[Annual]],2,0) -> CAT 583T (CMX) CAT 589 (31Z) CAT DK8 (893) CAT DK8 (950) | D19: =VLOOKUP(B19,[1]!Table3[[Part Number]:[Annual]],3,0) -> Air Filter - Secondary | E19: =VLOOKUP(B19,[1]!Table3[[Part Number]:[Annual]],9,0) -> 4 | F19: =VLOOKUP(B19,[1]!Table3[[Part Number]:[Annual]],4,0) -> 167.36 | G19: =E19*F19 -> 669.44 | H19: =VLOOKUP(B19,[1]!Table3[[Part Number]:[Annual]],5,0) -> 108.78 | I19: =ROUND(E19*H19,2) -> 435.12
B20: 1P-8482 | C20: =VLOOKUP(B20,[1]!Table3[[Part Number]:[Annual]],2,0) -> CAT 594 (96V) CAT 594H (96V) | D20: =VLOOKUP(B20,[1]!Table3[[Part Number]:[Annual]],3,0) -> SECONDARY AIR FILTER ELEMENT | E20: =VLOOKUP(B20,[1]!Table3[[Part Number]:[Annual]],9,0) -> 6 | F20: =VLOOKUP(B20,[1]!Table3[[Part Number]:[Annual]],4,0) -> 222 | G20: =E20*F20 -> 1332 | H20: =VLOOKUP(B20,[1]!Table3[[Part Number]:[Annual]],5,0) -> 144.3 | I20: =ROUND(E20*H20,2) -> 865.8
B21: 1P-8483 | C21: =VLOOKUP(B21,[1]!Table3[[Part Number]:[Annual]],2,0) -> CAT 594 (96V) CAT 594H (96V) | D21: =VLOOKUP(B21,[1]!Table3[[Part Number]:[Annual]],3,0) -> PRIMARY AIR FILTER ELEMENT | E21: =VLOOKUP(B21,[1]!Table3[[Part Number]:[Annual]],9,0) -> 6 | F21: =VLOOKUP(B21,[1]!Table3[[Part Number]:[Annual]],4,0) -> 121.8 | G21: =E21*F21 -> 730.8 | H21: =VLOOKUP(B21,[1]!Table3[[Part Number]:[Annual]],5,0) -> 79.17 | I21: =ROUND(E21*H21,2) -> 475.02
B22: 1R-0716 | C22: =VLOOKUP(B22,[1]!Table3[[Part Number]:[Annual]],2,0) -> CAT D7G (DSC) CAT D7G (DSC) (2) CAT D7G (DSC) (3) CAT D7G (SUB) CAT D7G (3ZD) CAT 572R (DSC) CAT 572R (DSC) (2) | D22: =VLOOKUP(B22,[1]!Table3[[Part Number]:[Annual]],3,0) -> ENGINE OIL FILTER | E22: =VLOOKUP(B22,[1]!Table3[[Part Number]:[Annual]],9,0) -> 21 | F22: =VLOOKUP(B22,[1]!Table3[[Part Number]:[Annual]],4,0) -> 59.49 | G22: =E22*F22 -> 1249.29 | H22: =VLOOKUP(B22,[1]!Table3[[Part Number]:[Annual]],5,0) -> 29.75 | I22: =ROUND(E22*H22,2) -> 624.75
B23: 1R-0728 | C23: =VLOOKUP(B23,[1]!Table3[[Part Number]:[Annual]],2,0) -> CAT 594 (96V) CAT 594H (96V) | D23: =VLOOKUP(B23,[1]!Table3[[Part Number]:[Annual]],3,0) -> HYDRAULIC FILTER | E23: =VLOOKUP(B23,[1]!Table3[[Part Number]:[Annual]],9,0) -> 2 | F23: =VLOOKUP(B23,[1]!Table3[[Part Number]:[Annual]],4,0) -> 47.98 | G23: =E23*F23 -> 95.96 | H23: =VLOOKUP(B23,[1]!Table3[[Part Number]:[Annual]],5,0) -> 23.99 | I23: =ROUND(E23*H23,2) -> 47.98
B24: 1R-0741 | C24: =VLOOKUP(B24,[1]!Table3[[Part Number]:[Annual]],2,0) -> CAT 583T (CMX) CAT 589 (31Z) CAT 594 (96V) CAT 594H (96V) CAT DK8 (893) CAT DK8 (950) | D24: =VLOOKUP(B24,[1]!Table3[[Part Number]:[Annual]],3,0) -> Hydraulic Filter | E24: =VLOOKUP(B24,[1]!Table3[[Part Number]:[Annual]],9,0) -> 8 | F24: =VLOOKUP(B24,[1]!Table3[[Part Number]:[Annual]],4,0) -> 38.31 | G24: =E24*F24 -> 306.48 | H24: =VLOOKUP(B24,[1]!Table3[[Part Number]:[Annual]],5,0) -> 19.16 | I24: =ROUND(E24*H24,2) -> 153.28
B25: 1R-0749 | C25: =VLOOKUP(B25,[1]!Table3[[Part Number]:[Annual]],2,0) -> CAT D7G (DSC) CAT D7G (DSC) (2) CAT D7G (DSC) (3) CAT D7G (SUB) CAT D7G (3ZD) CAT 572R (DSC) CAT 572R (DSC) (2) | D25: =VLOOKUP(B25,[1]!Table3[[Part Number]:[Annual]],3,0) -> FUEL FILTER | E25: =VLOOKUP(B25,[1]!Table3[[Part Number]:[Annual]],9,0) -> 21 | F25: =VLOOKUP(B25,[1]!Table3[[Part Number]:[Annual]],4,0) -> 49.75 | G25: =E25*F25 -> 1044.75 | H25: =VLOOKUP(B25,[1]!Table3[[Part Number]:[Annual]],5,0) -> 24.88 | I25: =ROUND(E25*H25,2) -> 522.48
B26: 1R-0750 | C26: =VLOOKUP(B26,[1]!Table3[[Part Number]:[Annual]],2,0) -> CAT 583T (CMX) CAT 589 (31Z) CAT 594 (96V) CAT 594H (96V) CAT DK8 (893) CAT DK8 (950) | D26: =VLOOKUP(B26,[1]!Table3[[Part Number]:[Annual]],3,0) -> Fuel Filter - Secondary | E26: =VLOOKUP(B26,[1]!Table3[[Part Number]:[Annual]],9,0) -> 20 | F26: =VLOOKUP(B26,[1]!Table3[[Part Number]:[Annual]],4,0) -> 41.22 | G26: =E26*F26 -> 824.4 | H26: =VLOOKUP(B26,[1]!Table3[[Part Number]:[Annual]],5,0) -> 20.61 | I26: =ROUND(E26*H26,2) -> 412.2
B27: 209-8217 | C27: =VLOOKUP(B27,[1]!Table3[[Part Number]:[Annual]],2,0) -> CAT PL61 (DHA) CAT PL61 (WGS) CAT D6D (06X) | D27: =VLOOKUP(B27,[1]!Table3[[Part Number]:[Annual]],3,0) -> CABIN AIR FILTER ELEMENT | E27: =VLOOKUP(B27,[1]!Table3[[Part Number]:[Annual]],9,0) -> 0 | F27: =VLOOKUP(B27,[1]!Table3[[Part Number]:[Annual]],4,0) -> 82.23 | G27: =E27*F27 -> 0 | H27: =VLOOKUP(B27,[1]!Table3[[Part Number]:[Annual]],5,0) -> 53.45 | I27: =ROUND(E27*H27,2) -> 0
B28: 252-5001 | C28: =VLOOKUP(B28,[1]!Table3[[Part Number]:[Annual]],2,0) -> CAT PL61 (DHA) CAT PL61 (WGS) CAT D6D (06X) | D28: =VLOOKUP(B28,[1]!Table3[[Part Number]:[Annual]],3,0) -> PRIMARY AIR FILTER ELEMENT | E28: =VLOOKUP(B28,[1]!Table3[[Part Number]:[Annual]],9,0) -> 3 | F28: =VLOOKUP(B28,[1]!Table3[[Part Number]:[Annual]],4,0) -> 214.1 | G28: =E28*F28 -> 642.3 | H28: =VLOOKUP(B28,[1]!Table3[[Part Number]:[Annual]],5,0) -> 139.17 | I28: =ROUND(E28*H28,2) -> 417.51
B29: 252-5002 | C29: =VLOOKUP(B29,[1]!Table3[[Part Number]:[Annual]],2,0) -> CAT PL61 (DHA) CAT PL61 (WGS) CAT D6D (06X) | D29: =VLOOKUP(B29,[1]!Table3[[Part Number]:[Annual]],3,0) -> SECONDARY AIR FILTER ELEMENT | E29: =VLOOKUP(B29,[1]!Table3[[Part Number]:[Annual]],9,0) -> 3 | F29: =VLOOKUP(B29,[1]!Table3[[Part Number]:[Annual]],4,0) -> 147.41 | G29: =E29*F29 -> 442.23 | H29: =VLOOKUP(B29,[1]!Table3[[Part Number]:[Annual]],5,0) -> 95.82 | I29: =ROUND(E29*H29,2) -> 287.46
... B58: TT220747 | C58: =VLOOKUP(B58,[1]!Table3[[Part Number]:[Annual]],2,0) -> JD 470GLC (1FF) HITACHI 470GLC (HCM) | D58: =VLOOKUP(B58,[1]!Table3[[Part Number]:[Annual]],3,0) -> SECONDARY AIR FILTER | E58: =VLOOKUP(B58,[1]!Table3[[Part Number]:[Annual]],9,0) -> 0 | F58: =VLOOKUP(B58,[1]!Table3[[Part Number]:[Annual]],4,0) -> 119.3286 | G58: =E58*F58 -> 0 | H58: =VLOOKUP(B58,[1]!Table3[[Part Number]:[Annual]],5,0) -> 77.56 | I58: =ROUND(E58*H58,2) -> 0
I59: =ROUND(E59*H59,2) -> 0
I60: =ROUND(E60*H60,2) -> 0
I61: =ROUND(E61*H61,2) -> 0
I62: =ROUND(E62*H62,2) -> 0
I63: =ROUND(E63*H63,2) -> 0
I64: =ROUND(E64*H64,2) -> 0
I65: =ROUND(E65*H65,2) -> 0
I66: =ROUND(E66*H66,2) -> 0
I67: =ROUND(E67*H67,2) -> 0
I68: =ROUND(E68*H68,2) -> 0
I69: =ROUND(E69*H69,2) -> 0
I70: =ROUND(E70*H70,2) -> 0
... I164: =ROUND(E164*H164,2) -> 0
H165: Subtotal | I165: =SUM(I15:I164) -> 11672.92
D166: OEM MSRP : | E166: =SUM(G15:G164) -> 20404.057 | H166: Shipping | I166: 0
...

Sheet MOQ Filters Q4
E1: MOQ QUOTE | H1: Filters Q4
B7: COMPANY: | C7: MPI OILFIELD | E7: DATE: | F7: ='MOQ Grand Total'!F7 -> 45839 | H7: PO NUMBER: | I7: ='MOQ Grand Total'!I7
B8: CONTACT NAME: | E8: PHONE NUMBER: | H8: ='MOQ Grand Total'!H8 -> (780) 385-8652
B9: BILLING ADDRESS: | C9: ='MOQ Grand Total'!C9 -> 0 | E9: EMAIL ADDRESS:
E10: SHIPPING ADDRESS: | H10: ='MOQ Grand Total'!H10 -> 0
C11: ='MOQ Grand Total'!C11 -> 0 | H11: ='MOQ Grand Total'!H11 -> 0
C12: ='MOQ Grand Total'!C12 -> Based on 200 machine hours per month | H12: ='MOQ Grand Total'!H12
F13: CAD $
B14: PART NUMBER | C14: Make & Model | D14: DESCRIPTION | E14: QTY | F14: OEM MSRP | H14: GQP PRICE | I14: TOTAL
B15: 4630525 | C15: =VLOOKUP(B15,[1]!Table3[[Part Number]:[Annual]],2,0) -> JD 470GLC (1FF) HITACHI 470GLC (HCM) | D15: =VLOOKUP(B15,[1]!Table3[[Part Number]:[Annual]],3,0) -> HYDRAULIC FILTER | E15: =VLOOKUP(B15,[1]!Table3[[Part Number]:[Annual]],10,0) -> 2 | F15: =VLOOKUP(B15,[1]!Table3[[Part Number]:[Annual]],4,0) -> 96.1446 | G15: =E15*F15 -> 192.2892 | H15: =VLOOKUP(B15,[1]!Table3[[Part Number]:[Annual]],5,0) -> 48.07 | I15: =ROUND(E15*H15,2) -> 96.14
B16: 8981527381 | C16: =VLOOKUP(B16,[1]!Table3[[Part Number]:[Annual]],2,0) -> JD 470GLC (1FF) HITACHI 470GLC (HCM) | D16: =VLOOKUP(B16,[1]!Table3[[Part Number]:[Annual]],3,0) -> FINAL FUEL FILTER | E16: =VLOOKUP(B16,[1]!Table3[[Part Number]:[Annual]],10,0) -> 4 | F16: =VLOOKUP(B16,[1]!Table3[[Part Number]:[Annual]],4,0) -> 80.868 | G16: =E16*F16 -> 323.472 | H16: =VLOOKUP(B16,[1]!Table3[[Part Number]:[Annual]],5,0) -> 40.43 | I16: =ROUND(E16*H16,2) -> 161.72
B17: 8983020750 | C17: =VLOOKUP(B17,[1]!Table3[[Part Number]:[Annual]],2,0) -> JD 470GLC (1FF) HITACHI 470GLC (HCM) | D17: =VLOOKUP(B17,[1]!Table3[[Part Number]:[Annual]],3,0) -> ENGINE OIL FILTER | E17: =VLOOKUP(B17,[1]!Table3[[Part Number]:[Annual]],10,0) -> 4 | F17: =VLOOKUP(B17,[1]!Table3[[Part Number]:[Annual]],4,0) -> 107.0742 | G17: =E17*F17 -> 428.2968 | H17: =VLOOKUP(B17,[1]!Table3[[Part Number]:[Annual]],5,0) -> 53.54 | I17: =ROUND(E17*H17,2) -> 214.16
B18: 1G-8878 | C18: =VLOOKUP(B18,[1]!Table3[[Part Number]:[Annual]],2,0) -> CAT PL61 (DHA) CAT PL61 (WGS) CAT D6D (06X) | D18: =VLOOKUP(B18,[1]!Table3[[Part Number]:[Annual]],3,0) -> HYDRAULIC OIL FILTER (POWER TRAIN) | E18: =VLOOKUP(B18,[1]!Table3[[Part Number]:[Annual]],10,0) -> 3 | F18: =VLOOKUP(B18,[1]!Table3[[Part Number]:[Annual]],4,0) -> 145.28 | G18: =E18*F18 -> 435.84 | H18: =VLOOKUP(B18,[1]!Table3[[Part Number]:[Annual]],5,0) -> 72.64 | I18: =ROUND(E18*H18,2) -> 217.92
B19: 1P-7360 | C19: =VLOOKUP(B19,[1]!Table3[[Part Number]:[Annual]],2,0) -> CAT 583T (CMX) CAT 589 (31Z) CAT DK8 (893) CAT DK8 (950) | D19: =VLOOKUP(B19,[1]!Table3[[Part Number]:[Annual]],3,0) -> Air Filter - Secondary | E19: =VLOOKUP(B19,[1]!Table3[[Part Number]:[Annual]],10,0) -> 4 | F19: =VLOOKUP(B19,[1]!Table3[[Part Number]:[Annual]],4,0) -> 167.36 | G19: =E19*F19 -> 669.44 | H19: =VLOOKUP(B19,[1]!Table3[[Part Number]:[Annual]],5,0) -> 108.78 | I19: =ROUND(E19*H19,2) -> 435.12
B20: 1P-8482 | C20: =VLOOKUP(B20,[1]!Table3[[Part Number]:[Annual]],2,0) -> CAT 594 (96V) CAT 594H (96V) | D20: =VLOOKUP(B20,[1]!Table3[[Part Number]:[Annual]],3,0) -> SECONDARY AIR FILTER ELEMENT | E20: =VLOOKUP(B20,[1]!Table3[[Part Number]:[Annual]],10,0) -> 4 | F20: =VLOOKUP(B20,[1]!Table3[[Part Number]:[Annual]],4,0) -> 222 | G20: =E20*F20 -> 888 | H20: =VLOOKUP(B20,[1]!Table3[[Part Number]:[Annual]],5,0) -> 144.3 | I20: =ROUND(E20*H20,2) -> 577.2
B21: 1P-8483 | C21: =VLOOKUP(B21,[1]!Table3[[Part Number]:[Annual]],2,0) -> CAT 594 (96V) CAT 594H (96V) | D21: =VLOOKUP(B21,[1]!Table3[[Part Number]:[Annual]],3,0) -> PRIMARY AIR FILTER ELEMENT | E21: =VLOOKUP(B21,[1]!Table3[[Part Number]:[Annual]],10,0) -> 4 | F21: =VLOOKUP(B21,[1]!Table3[[Part Number]:[Annual]],4,0) -> 121.8 | G21: =E21*F21 -> 487.2 | H21: =VLOOKUP(B21,[1]!Table3[[Part Number]:[Annual]],5,0) -> 79.17 | I21: =ROUND(E21*H21,2) -> 316.68
B22: 1R-0716 | C22: =VLOOKUP(B22,[1]!Table3[[Part Number]:[Annual]],2,0) -> CAT D7G (DSC) CAT D7G (DSC) (2) CAT D7G (DSC) (3) CAT D7G (SUB) CAT D7G (3ZD) CAT 572R (DSC) CAT 572R (DSC) (2) | D22: =VLOOKUP(B22,[1]!Table3[[Part Number]:[Annual]],3,0) -> ENGINE OIL FILTER | E22: =VLOOKUP(B22,[1]!Table3[[Part Number]:[Annual]],10,0) -> 14 | F22: =VLOOKUP(B22,[1]!Table3[[Part Number]:[Annual]],4,0) -> 59.49 | G22: =E22*F22 -> 832.86 | H22: =VLOOKUP(B22,[1]!Table3[[Part Number]:[Annual]],5,0) -> 29.75 | I22: =ROUND(E22*H22,2) -> 416.5
B23: 1R-0728 | C23: =VLOOKUP(B23,[1]!Table3[[Part Number]:[Annual]],2,0) -> CAT 594 (96V) CAT 594H (96V) | D23: =VLOOKUP(B23,[1]!Table3[[Part Number]:[Annual]],3,0) -> HYDRAULIC FILTER | E23: =VLOOKUP(B23,[1]!Table3[[Part Number]:[Annual]],10,0) -> 2 | F23: =VLOOKUP(B23,[1]!Table3[[Part Number]:[Annual]],4,0) -> 47.98 | G23: =E23*F23 -> 95.96 | H23: =VLOOKUP(B23,[1]!Table3[[Part Number]:[Annual]],5,0) -> 23.99 | I23: =ROUND(E23*H23,2) -> 47.98
B24: 1R-0741 | C24: =VLOOKUP(B24,[1]!Table3[[Part Number]:[Annual]],2,0) -> CAT 583T (CMX) CAT 589 (31Z) CAT 594 (96V) CAT 594H (96V) CAT DK8 (893) CAT DK8 (950) | D24: =VLOOKUP(B24,[1]!Table3[[Part Number]:[Annual]],3,0) -> Hydraulic Filter | E24: =VLOOKUP(B24,[1]!Table3[[Part Number]:[Annual]],10,0) -> 8 | F24: =VLOOKUP(B24,[1]!Table3[[Part Number]:[Annual]],4,0) -> 38.31 | G24: =E24*F24 -> 306.48 | H24: =VLOOKUP(B24,[1]!Table3[[Part Number]:[Annual]],5,0) -> 19.16 | I24: =ROUND(E24*H24,2) -> 153.28
B25: 1R-0749 | C25: =VLOOKUP(B25,[1]!Table3[[Part Number]:[Annual]],2,0) -> CAT D7G (DSC) CAT D7G (DSC) (2) CAT D7G (DSC) (3) CAT D7G (SUB) CAT D7G (3ZD) CAT 572R (DSC) CAT 572R (DSC) (2) | D25: =VLOOKUP(B25,[1]!Table3[[Part Number]:[Annual]],3,0) -> FUEL FILTER | E25: =VLOOKUP(B25,[1]!Table3[[Part Number]:[Annual]],10,0) -> 14 | F25: =VLOOKUP(B25,[1]!Table3[[Part Number]:[Annual]],4,0) -> 49.75 | G25: =E25*F25 -> 696.5 | H25: =VLOOKUP(B25,[1]!Table3[[Part Number]:[Annual]],5,0) -> 24.88 | I25: =ROUND(E25*H25,2) -> 348.32
B26: 1R-0750 | C26: =VLOOKUP(B26,[1]!Table3[[Part Number]:[Annual]],2,0) -> CAT 583T (CMX) CAT 589 (31Z) CAT 594 (96V) CAT 594H (96V) CAT DK8 (893) CAT DK8 (950) | D26: =VLOOKUP(B26,[1]!Table3[[Part Number]:[Annual]],3,0) -> Fuel Filter - Secondary | E26: =VLOOKUP(B26,[1]!Table3[[Part Number]:[Annual]],10,0) -> 16 | F26: =VLOOKUP(B26,[1]!Table3[[Part Number]:[Annual]],4,0) -> 41.22 | G26: =E26*F26 -> 659.52 | H26: =VLOOKUP(B26,[1]!Table3[[Part Number]:[Annual]],5,0) -> 20.61 | I26: =ROUND(E26*H26,2) -> 329.76
B27: 209-8217 | C27: =VLOOKUP(B27,[1]!Table3[[Part Number]:[Annual]],2,0) -> CAT PL61 (DHA) CAT PL61 (WGS) CAT D6D (06X) | D27: =VLOOKUP(B27,[1]!Table3[[Part Number]:[Annual]],3,0) -> CABIN AIR FILTER ELEMENT | E27: =VLOOKUP(B27,[1]!Table3[[Part Number]:[Annual]],10,0) -> 0 | F27: =VLOOKUP(B27,[1]!Table3[[Part Number]:[Annual]],4,0) -> 82.23 | G27: =E27*F27 -> 0 | H27: =VLOOKUP(B27,[1]!Table3[[Part Number]:[Annual]],5,0) -> 53.45 | I27: =ROUND(E27*H27,2) -> 0
B28: 252-5001 | C28: =VLOOKUP(B28,[1]!Table3[[Part Number]:[Annual]],2,0) -> CAT PL61 (DHA) CAT PL61 (WGS) CAT D6D (06X) | D28: =VLOOKUP(B28,[1]!Table3[[Part Number]:[Annual]],3,0) -> PRIMARY AIR FILTER ELEMENT | E28: =VLOOKUP(B28,[1]!Table3[[Part Number]:[Annual]],10,0) -> 3 | F28: =VLOOKUP(B28,[1]!Table3[[Part Number]:[Annual]],4,0) -> 214.1 | G28: =E28*F28 -> 642.3 | H28: =VLOOKUP(B28,[1]!Table3[[Part Number]:[Annual]],5,0) -> 139.17 | I28: =ROUND(E28*H28,2) -> 417.51
B29: 252-5002 | C29: =VLOOKUP(B29,[1]!Table3[[Part Number]:[Annual]],2,0) -> CAT PL61 (DHA) CAT PL61 (WGS) CAT D6D (06X) | D29: =VLOOKUP(B29,[1]!Table3[[Part Number]:[Annual]],3,0) -> SECONDARY AIR FILTER ELEMENT | E29: =VLOOKUP(B29,[1]!Table3[[Part Number]:[Annual]],10,0) -> 3 | F29: =VLOOKUP(B29,[1]!Table3[[Part Number]:[Annual]],4,0) -> 147.41 | G29: =E29*F29 -> 442.23 | H29: =VLOOKUP(B29,[1]!Table3[[Part Number]:[Annual]],5,0) -> 95.82 | I29: =ROUND(E29*H29,2) -> 287.46
... B58: TT220747 | C58: =VLOOKUP(B58,[1]!Table3[[Part Number]:[Annual]],2,0) -> JD 470GLC (1FF) HITACHI 470GLC (HCM) | D58: =VLOOKUP(B58,[1]!Table3[[Part Number]:[Annual]],3,0) -> SECONDARY AIR FILTER | E58: =VLOOKUP(B58,[1]!Table3[[Part Number]:[Annual]],10,0) -> 2 | F58: =VLOOKUP(B58,[1]!Table3[[Part Number]:[Annual]],4,0) -> 119.3286 | G58: =E58*F58 -> 238.6572 | H58: =VLOOKUP(B58,[1]!Table3[[Part Number]:[Annual]],5,0) -> 77.56 | I58: =ROUND(E58*H58,2) -> 155.12
I59: =ROUND(E59*H59,2) -> 0
I60: =ROUND(E60*H60,2) -> 0
I61: =ROUND(E61*H61,2) -> 0
I62: =ROUND(E62*H62,2) -> 0
I63: =ROUND(E63*H63,2) -> 0
I64: =ROUND(E64*H64,2) -> 0
I65: =ROUND(E65*H65,2) -> 0
I66: =ROUND(E66*H66,2) -> 0
I67: =ROUND(E67*H67,2) -> 0
I68: =ROUND(E68*H68,2) -> 0
I69: =ROUND(E69*H69,2) -> 0
I70: =ROUND(E70*H70,2) -> 0
... I164: =ROUND(E164*H164,2) -> 0
H165: Subtotal | I165: =SUM(I15:I164) -> 11417.39
D166: OEM MSRP : | E166: =SUM(G15:G164) -> 19811.282 | H166: Shipping | I166: 0
...

Sheet MOQ GET
E1: MOQ QUOTE | H1: G.E.T.
B7: COMPANY: | C7: MPI OILFIELD | E7: DATE: | F7: ='MOQ Grand Total'!F7 -> 45839 | H7: PO NUMBER: | I7: ='MOQ Grand Total'!I7
B8: CONTACT NAME: | E8: PHONE NUMBER: | H8: ='MOQ Grand Total'!H8 -> (780) 385-8652
B9: BILLING ADDRESS: | C9: ='MOQ Grand Total'!C9 -> 0 | E9: EMAIL ADDRESS:
E10: SHIPPING ADDRESS: | H10: ='MOQ Grand Total'!H10 -> 0
C11: ='MOQ Grand Total'!C11 -> 0 | H11: ='MOQ Grand Total'!H11 -> 0
C12: ='MOQ Grand Total'!C12 -> Based on 200 machine hours per month | H12: ='MOQ Grand Total'!H12
F13: CAD $
B14: PART NUMBER | C14: Make & Model | D14: DESCRIPTION | E14: QTY | F14: OEM MSRP | H14: GQP PRICE | I14: TOTAL
B15: AT131090 | C15: =VLOOKUP(B15,[1]!Table3[[Part Number]:[Annual]],2,0) -> HITACHI ZX290LC-5 (1FF) HITACHI ZX290LC-5 (1FF) (2) HITACHI ZX290LC-5 (1FF) (3) | D15: =VLOOKUP(B15,[1]!Table3[[Part Number]:[Annual]],3,0) -> CUTTING EDGE | E15: =VLOOKUP(B15,[1]!Table3[[Part Number]:[Annual]],11,0) -> 3 | F15: =VLOOKUP(B15,[1]!Table3[[Part Number]:[Annual]],4,0) -> 1340.9736 | G15: =E15*F15 -> 4022.9208 | H15: =VLOOKUP(B15,[1]!Table3[[Part Number]:[Annual]],5,0) -> 670.49 | I15: =ROUND(E15*H15,2) -> 2011.47
I16: =ROUND(E16*H16,2) -> 0
I17: =ROUND(E17*H17,2) -> 0
I18: =ROUND(E18*H18,2) -> 0
I19: =ROUND(E19*H19,2) -> 0
I20: =ROUND(E20*H20,2) -> 0
I21: =ROUND(E21*H21,2) -> 0
I22: =ROUND(E22*H22,2) -> 0
I23: =ROUND(E23*H23,2) -> 0
I24: =ROUND(E24*H24,2) -> 0
I25: =ROUND(E25*H25,2) -> 0
I26: =ROUND(E26*H26,2) -> 0
I27: =ROUND(E27*H27,2) -> 0
... I73: =ROUND(E73*H73,2) -> 0
H74: Subtotal | I74: =SUM(I15:I73) -> 2011.47
D75: OEM MSRP : | E75: =SUM(G15:G73) -> 4022.9208 | H75: Shipping | I75: 0
D76: GQP : | E76: =SUM(I15:I73) -> 2011.47 | H76: Customs/Broker Fee | I76: 0
D77: GQP SAVINGS : | E77: =E75-E76 -> 2011.4508 | H77: Total | I77: =SUM(I74:I76) -> 2011.47
H78: GST | I78: =I77*0.05 -> 100.5735
H79: PST / QST
B80: Quote valid for 14 days, shipping subject to delays in supply chain. | H80: GRAND TOTAL | I80: =SUM(I77:I79) -> 2112.0435

Sheet MOQ Injector
E1: MOQ QUOTE | H1: INJECTOR
B7: COMPANY: | C7: MPI OILFIELD | E7: DATE: | F7: ='MOQ Grand Total'!F7 -> 45839 | H7: PO NUMBER: | I7: ='MOQ Grand Total'!I7
B8: CONTACT NAME: | E8: PHONE NUMBER: | H8: ='MOQ Grand Total'!H8 -> (780) 385-8652
B9: BILLING ADDRESS: | C9: ='MOQ Grand Total'!C9 -> 0 | E9: EMAIL ADDRESS:
E10: SHIPPING ADDRESS: | H10: ='MOQ Grand Total'!H10 -> 0
C11: ='MOQ Grand Total'!C11 -> 0 | H11: ='MOQ Grand Total'!H11 -> 0
C12: ='MOQ Grand Total'!C12 -> Based on 200 machine hours per month | H12: ='MOQ Grand Total'!H12
F13: CAD $
B14: PART NUMBER | C14: Make & Model | D14: DESCRIPTION | E14: QTY | F14: OEM MSRP | H14: GQP PRICE | I14: TOTAL
B15: 8976227194 | C15: =VLOOKUP(B15,[1]!Table3[[Part Number]:[Annual]],2,0) -> JD 470GLC (1FF) HITACHI 470GLC (HCM) | D15: =VLOOKUP(B15,[1]!Table3[[Part Number]:[Annual]],3,0) -> INJECTOR | E15: =VLOOKUP(B15,[1]!Table3[[Part Number]:[Annual]],11,0) -> 12 | F15: =VLOOKUP(B15,[1]!Table3[[Part Number]:[Annual]],4,0) -> 1263.7488 | G15: =E15*F15 -> 15164.986 | H15: =VLOOKUP(B15,[1]!Table3[[Part Number]:[Annual]],5,0) -> 884.62 | I15: =ROUND(E15*H15,2) -> 10615.44
B16: 317-5278 | C16: =VLOOKUP(B16,[1]!Table3[[Part Number]:[Annual]],2,0) -> CAT D7G (DSC) CAT D7G (DSC) (2) CAT D7G (DSC) (3) CAT D7G (SUB) CAT D7G (3ZD) CAT 572R (DSC) CAT 572R (DSC) (2) | D16: =VLOOKUP(B16,[1]!Table3[[Part Number]:[Annual]],3,0) -> FUEL INJECTOR NOZZLE | E16: =VLOOKUP(B16,[1]!Table3[[Part Number]:[Annual]],11,0) -> 42 | F16: =VLOOKUP(B16,[1]!Table3[[Part Number]:[Annual]],4,0) -> 1882.24 | G16: =E16*F16 -> 79054.08 | H16: =VLOOKUP(B16,[1]!Table3[[Part Number]:[Annual]],5,0) -> 1317.57 | I16: =ROUND(E16*H16,2) -> 55337.94
B17: 320-9380 | C17: =VLOOKUP(B17,[1]!Table3[[Part Number]:[Annual]],2,0) -> CAT PL61 (DHA) CAT PL61 (WGS) CAT D6D (06X) | D17: =VLOOKUP(B17,[1]!Table3[[Part Number]:[Annual]],3,0) -> FUEL INJECTOR NOZZLE | E17: =VLOOKUP(B17,[1]!Table3[[Part Number]:[Annual]],11,0) -> 18 | F17: =VLOOKUP(B17,[1]!Table3[[Part Number]:[Annual]],4,0) -> 1234.93 | G17: =E17*F17 -> 22228.74 | H17: =VLOOKUP(B17,[1]!Table3[[Part Number]:[Annual]],5,0) -> 864.45 | I17: =ROUND(E17*H17,2) -> 15560.1
B18: 8N-1831 | C18: =VLOOKUP(B18,[1]!Table3[[Part Number]:[Annual]],2,0) -> CAT 594 (96V) CAT 594H (96V) | D18: =VLOOKUP(B18,[1]!Table3[[Part Number]:[Annual]],3,0) -> FUEL INJECTOR NOZZLE | E18: =VLOOKUP(B18,[1]!Table3[[Part Number]:[Annual]],11,0) -> 12 | F18: =VLOOKUP(B18,[1]!Table3[[Part Number]:[Annual]],4,0) -> 154.75 | G18: =E18*F18 -> 1857 | H18: =VLOOKUP(B18,[1]!Table3[[Part Number]:[Annual]],5,0) -> 108.33 | I18: =ROUND(E18*H18,2) -> 1299.96
B19: RE507948 | C19: =VLOOKUP(B19,[1]!Table3[[Part Number]:[Annual]],2,0) -> HITACHI ZX290LC-5 (1FF) HITACHI ZX290LC-5 (1FF) (2) HITACHI ZX290LC-5 (1FF) (3) | D19: =VLOOKUP(B19,[1]!Table3[[Part Number]:[Annual]],3,0) -> INJECTOR | E19: =VLOOKUP(B19,[1]!Table3[[Part Number]:[Annual]],11,0) -> 18 | F19: =VLOOKUP(B19,[1]!Table3[[Part Number]:[Annual]],4,0) -> 228.5418 | G19: =E19*F19 -> 4113.7524 | H19: =VLOOKUP(B19,[1]!Table3[[Part Number]:[Annual]],5,0) -> 159.98 | I19: =ROUND(E19*H19,2) -> 2879.64
I20: =ROUND(E20*H20,2) -> 0
I21: =ROUND(E21*H21,2) -> 0
I22: =ROUND(E22*H22,2) -> 0
I23: =ROUND(E23*H23,2) -> 0
I24: =ROUND(E24*H24,2) -> 0
I25: =ROUND(E25*H25,2) -> 0
I26: =ROUND(E26*H26,2) -> 0
I27: =ROUND(E27*H27,2) -> 0
I28: =ROUND(E28*H28,2) -> 0
I29: =ROUND(E29*H29,2) -> 0
I30: =ROUND(E30*H30,2) -> 0
I31: =ROUND(E31*H31,2) -> 0
... I79: =ROUND(E79*H79,2) -> 0
H80: Subtotal | I80: =SUM(I15:I79) -> 85693.08
D81: OEM MSRP : | E81: =SUM(G15:G79) -> 122418.56 | H81: Shipping | I81: 0
D82: GQP : | E82: =SUM(I15:I79) -> 85693.08 | H82: Customs/Broker Fee | I82: 0
D83: GQP SAVINGS : | E83: =E81-E82 -> 36725.478 | H83: Total | I83: =SUM(I80:I82) -> 85693.08
H84: GST | I84: =I83*0.05 -> 4284.654
H85: PST / QST
B86: Quote valid for 14 days, shipping subject to delays in supply chain. | H86: GRAND TOTAL | I86: =SUM(I83:I85) -> 89977.734

Sheet MOQ Turbos
E1: MOQ QUOTE | H1: Turbos
B7: COMPANY: | C7: MPI OILFIELD | E7: DATE: | F7: ='MOQ Grand Total'!F7 -> 45839 | H7: PO NUMBER: | I7: ='MOQ Grand Total'!I7
B8: CONTACT NAME: | E8: PHONE NUMBER: | H8: ='MOQ Grand Total'!H8 -> (780) 385-8652
B9: BILLING ADDRESS: | C9: ='MOQ Grand Total'!C9 -> 0 | E9: EMAIL ADDRESS:
E10: SHIPPING ADDRESS: | H10: ='MOQ Grand Total'!H10 -> 0
C11: ='MOQ Grand Total'!C11 -> 0 | H11: ='MOQ Grand Total'!H11 -> 0
C12: ='MOQ Grand Total'!C12 -> Based on 200 machine hours per month | H12: ='MOQ Grand Total'!H12
F13: CAD $
B14: PART NUMBER | C14: Make & Model | D14: DESCRIPTION | E14: QTY | F14: OEM MSRP | H14: GQP PRICE | I14: TOTAL
B15: 8983698700 | C15: =VLOOKUP(B15,[1]!Table3[[Part Number]:[Annual]],2,0) -> JD 470GLC (1FF) HITACHI 470GLC (HCM) | D15: =VLOOKUP(B15,[1]!Table3[[Part Number]:[Annual]],3,0) -> TURBOCHARGER | E15: =VLOOKUP(B15,[1]!Table3[[Part Number]:[Annual]],11,0) -> 2 | F15: =VLOOKUP(B15,[1]!Table3[[Part Number]:[Annual]],4,0) -> 4709.664 | G15: =E15*F15 -> 9419.328 | H15: =VLOOKUP(B15,[1]!Table3[[Part Number]:[Annual]],5,0) -> 2354.83 | I15: =ROUND(E15*H15,2) -> 4709.66
B16: 167-9666 | C16: =VLOOKUP(B16,[1]!Table3[[Part Number]:[Annual]],2,0) -> CAT D7G (DSC) CAT D7G (DSC) (2) CAT D7G (DSC) (3) CAT D7G (SUB) CAT D7G (3ZD) CAT 572R (DSC) CAT 572R (DSC) (2) | D16: =VLOOKUP(B16,[1]!Table3[[Part Number]:[Annual]],3,0) -> TURBOCHARGER | E16: =VLOOKUP(B16,[1]!Table3[[Part Number]:[Annual]],11,0) -> 7 | F16: =VLOOKUP(B16,[1]!Table3[[Part Number]:[Annual]],4,0) -> 6780.97 | G16: =E16*F16 -> 47466.79 | H16: =VLOOKUP(B16,[1]!Table3[[Part Number]:[Annual]],5,0) -> 3390.49 | I16: =ROUND(E16*H16,2) -> 23733.43
B17: 315-9810 | C17: =VLOOKUP(B17,[1]!Table3[[Part Number]:[Annual]],2,0) -> CAT PL61 (DHA) CAT PL61 (WGS) CAT D6D (06X) | D17: =VLOOKUP(B17,[1]!Table3[[Part Number]:[Annual]],3,0) -> TURBOCHARGER | E17: =VLOOKUP(B17,[1]!Table3[[Part Number]:[Annual]],11,0) -> 3 | F17: =VLOOKUP(B17,[1]!Table3[[Part Number]:[Annual]],4,0) -> 6681.88 | G17: =E17*F17 -> 20045.64 | H17: =VLOOKUP(B17,[1]!Table3[[Part Number]:[Annual]],5,0) -> 3340.94 | I17: =ROUND(E17*H17,2) -> 10022.82
B18: 7N-2495 | C18: =VLOOKUP(B18,[1]!Table3[[Part Number]:[Annual]],2,0) -> CAT 594 (96V) CAT 594H (96V) | D18: =VLOOKUP(B18,[1]!Table3[[Part Number]:[Annual]],3,0) -> TURBOCHARGER | E18: =VLOOKUP(B18,[1]!Table3[[Part Number]:[Annual]],11,0) -> 2 | F18: =VLOOKUP(B18,[1]!Table3[[Part Number]:[Annual]],4,0) -> 9221.34 | G18: =E18*F18 -> 18442.68 | H18: =VLOOKUP(B18,[1]!Table3[[Part Number]:[Annual]],5,0) -> 4610.67 | I18: =ROUND(E18*H18,2) -> 9221.34
B19: 8N-5510 | C19: =VLOOKUP(B19,[1]!Table3[[Part Number]:[Annual]],2,0) -> CAT 583T (CMX) CAT 589 (31Z) CAT DK8 (893) CAT DK8 (950) | D19: =VLOOKUP(B19,[1]!Table3[[Part Number]:[Annual]],3,0) -> Turbocharger | E19: =VLOOKUP(B19,[1]!Table3[[Part Number]:[Annual]],11,0) -> 4 | F19: =VLOOKUP(B19,[1]!Table3[[Part Number]:[Annual]],4,0) -> 9607.81 | G19: =E19*F19 -> 38431.24 | H19: =VLOOKUP(B19,[1]!Table3[[Part Number]:[Annual]],5,0) -> 4803.91 | I19: =ROUND(E19*H19,2) -> 19215.64
B20: SE501669 | C20: =VLOOKUP(B20,[1]!Table3[[Part Number]:[Annual]],2,0) -> HITACHI ZX290LC-5 (1FF) HITACHI ZX290LC-5 (1FF) (2) HITACHI ZX290LC-5 (1FF) (3) | D20: =VLOOKUP(B20,[1]!Table3[[Part Number]:[Annual]],3,0) -> TURBOCHARGER | E20: =VLOOKUP(B20,[1]!Table3[[Part Number]:[Annual]],11,0) -> 3 | F20: =VLOOKUP(B20,[1]!Table3[[Part Number]:[Annual]],4,0) -> 2168.3802 | G20: =E20*F20 -> 6505.1406 | H20: =VLOOKUP(B20,[1]!Table3[[Part Number]:[Annual]],5,0) -> 1084.19 | I20: =ROUND(E20*H20,2) -> 3252.57
I21: =ROUND(E21*H21,2) -> 0
G22: =E22*F22 -> 0 | I22: =ROUND(E22*H22,2) -> 0
G23: =E23*F23 -> 0 | I23: =ROUND(E23*H23,2) -> 0
G24: =E24*F24 -> 0 | I24: =ROUND(E24*H24,2) -> 0
G25: =E25*F25 -> 0 | I25: =ROUND(E25*H25,2) -> 0
G26: =E26*F26 -> 0 | I26: =ROUND(E26*H26,2) -> 0
G27: =E27*F27 -> 0 | I27: =ROUND(E27*H27,2) -> 0
G28: =E28*F28 -> 0 | I28: =ROUND(E28*H28,2) -> 0
G29: =E29*F29 -> 0 | I29: =ROUND(E29*H29,2) -> 0
G30: =E30*F30 -> 0 | I30: =ROUND(E30*H30,2) -> 0
G31: =E31*F31 -> 0 | I31: =ROUND(E31*H31,2) -> 0
G32: =E32*F32 -> 0 | I32: =ROUND(E32*H32,2) -> 0
G33: =E33*F33 -> 0 | I33: =ROUND(E33*H33,2) -> 0
... G38: =E38*F38 -> 0 | I38: =ROUND(E38*H38,2) -> 0
I39: =ROUND(E39*H39,2) -> 0
I40: =ROUND(E40*H40,2) -> 0
I41: =ROUND(E41*H41,2) -> 0
I42: =ROUND(E42*H42,2) -> 0
I43: =ROUND(E43*H43,2) -> 0
I44: =ROUND(E44*H44,2) -> 0
I45: =ROUND(E45*H45,2) -> 0
I46: =ROUND(E46*H46,2) -> 0
I47: =ROUND(E47*H47,2) -> 0
I48: =ROUND(E48*H48,2) -> 0
I49: =ROUND(E49*H49,2) -> 0
...

Sheet UC
E1: MOQ QUOTE | H1: UC
B7: COMPANY: | C7: MPI OILFIELD | E7: DATE: | F7: ='MOQ Grand Total'!F7 -> 45839 | H7: PO NUMBER: | I7: ='MOQ Grand Total'!I7
B8: CONTACT NAME: | E8: PHONE NUMBER: | H8: ='MOQ Grand Total'!H8 -> (780) 385-8652
B9: BILLING ADDRESS: | C9: ='MOQ Grand Total'!C9 -> 0 | E9: EMAIL ADDRESS:
E10: SHIPPING ADDRESS: | H10: ='MOQ Grand Total'!H10 -> 0
C11: ='MOQ Grand Total'!C11 -> 0 | H11: ='MOQ Grand Total'!H11 -> 0
C12: ='MOQ Grand Total'!C12 -> Based on 200 machine hours per month | H12: ='MOQ Grand Total'!H12
F13: CAD $
B14: PART NUMBER | C14: Make & Model | D14: DESCRIPTION | E14: QTY | F14: OEM MSRP | H14: GQP PRICE | I14: TOTAL
B15: 470GLC_MTO_35.4"_53LINK | C15: =VLOOKUP(B15,[1]!Table3[[Part Number]:[Annual]],2,0) -> JD 470GLC (1FF) HITACHI 470GLC (HCM) | D15: =VLOOKUP(B15,[1]!Table3[[Part Number]:[Annual]],3,0) -> GQP 470GLC Complete UC KIT | E15: =VLOOKUP(B15,[1]!Table3[[Part Number]:[Annual]],11,0) -> 2 | F15: =VLOOKUP(B15,[1]!Table3[[Part Number]:[Annual]],4,0) -> 106637.54 | G15: =E15*F15 -> 213275.08 | H15: =VLOOKUP(B15,[1]!Table3[[Part Number]:[Annual]],5,0) -> 42655.02 | I15: =ROUND(E15*H15,2) -> 85310.04
B16: 572R_MS_MTO_26"_43LINK | C16: =VLOOKUP(B16,[1]!Table3[[Part Number]:[Annual]],2,0) -> CAT D7G (DSC) CAT D7G (DSC) (2) CAT D7G (DSC) (3) CAT D7G (SUB) CAT D7G (3ZD) CAT 572R (DSC) CAT 572R (DSC) (2) | D16: =VLOOKUP(B16,[1]!Table3[[Part Number]:[Annual]],3,0) -> GQP 572R Complete UC KIT | E16: =VLOOKUP(B16,[1]!Table3[[Part Number]:[Annual]],11,0) -> 7 | F16: =VLOOKUP(B16,[1]!Table3[[Part Number]:[Annual]],4,0) -> 98900.34 | G16: =E16*F16 -> 692302.38 | H16: =VLOOKUP(B16,[1]!Table3[[Part Number]:[Annual]],5,0) -> 54395.19 | I16: =ROUND(E16*H16,2) -> 380766.33
B17: 583_GD_MTO_22"_41LINK | C17: =VLOOKUP(B17,[1]!Table3[[Part Number]:[Annual]],2,0) -> CAT 583T (CMX) CAT 589 (31Z) CAT DK8 (893) CAT DK8 (950) | D17: =VLOOKUP(B17,[1]!Table3[[Part Number]:[Annual]],3,0) -> GQP 583T Complete UC KIT | E17: =VLOOKUP(B17,[1]!Table3[[Part Number]:[Annual]],11,0) -> 4 | F17: =VLOOKUP(B17,[1]!Table3[[Part Number]:[Annual]],4,0) -> 89509.32 | G17: =E17*F17 -> 358037.28 | H17: =VLOOKUP(B17,[1]!Table3[[Part Number]:[Annual]],5,0) -> 49230.13 | I17: =ROUND(E17*H17,2) -> 196920.52
B18: D9G/H_MS_MTO_40"_42LINK | C18: =VLOOKUP(B18,[1]!Table3[[Part Number]:[Annual]],2,0) -> CAT 594 (96V) CAT 594H (96V) | D18: =VLOOKUP(B18,[1]!Table3[[Part Number]:[Annual]],3,0) -> GQP D9G/H Complete UC KIT | E18: =VLOOKUP(B18,[1]!Table3[[Part Number]:[Annual]],11,0) -> 2 | F18: =VLOOKUP(B18,[1]!Table3[[Part Number]:[Annual]],4,0) -> 265728.26 | G18: =E18*F18 -> 531456.52 | H18: =VLOOKUP(B18,[1]!Table3[[Part Number]:[Annual]],5,0) -> 146150.54 | I18: =ROUND(E18*H18,2) -> 292301.08
B19: PL61_MS_MTO_22"_40LINK | C19: =VLOOKUP(B19,[1]!Table3[[Part Number]:[Annual]],2,0) -> CAT PL61 (DHA) CAT PL61 (WGS) CAT D6D (06X) | D19: =VLOOKUP(B19,[1]!Table3[[Part Number]:[Annual]],3,0) -> GQP PL61 Complete UC KIT | E19: =VLOOKUP(B19,[1]!Table3[[Part Number]:[Annual]],11,0) -> 3 | F19: =VLOOKUP(B19,[1]!Table3[[Part Number]:[Annual]],4,0) -> 54495.98 | G19: =E19*F19 -> 163487.94 | H19: =VLOOKUP(B19,[1]!Table3[[Part Number]:[Annual]],5,0) -> 29972.79 | I19: =ROUND(E19*H19,2) -> 89918.37
