Workbook

Sheet Instructions
A1: Global Wholesale Machinery Inc.
A2: OEM Compareson Spreadsheet Instructions
A4: NET MARKUP% for each quote must be over 100% otherwise need approval from Quinten.
A5: NET MARGIN% for each quote must be over 50% otherwise need approval from Quinten.
A7: Customer Information Section
B8: Must be fully completed in OEM COMPARISON TAB.
B9: Information entered will be automatically transferred to QUOTE, and SERVICE QUOTE tab.
B10: Customer Information will not be transferred to RFQ tab as we do not give out customer information to vendors.
A12: Machine Information Section
B13: Optional - depends on customer request.
B14: Information entered will be automatically transferred to RFQ, QUOTE, and SERVICE QUOTE tab.
A16: Machine Service Interval Section
B17: Optional - depends on customer request.
B18: For internal use only. Information entered will not be transferred to RFQ, QUOTE, and SERVICE QUOTE tab.
A20: Parts Pricing and Cost Section
B21: Part Number - OEM Part Number (with exception to UC and Tires)
B22: Description - Description of Part
B23: Vendor - Name of the Vendor where we acquire parts from
B24: OEM Name - Name of OEM Manufacturer used for MSRP comparison
B25: Freight Cost - Vendor shipping cost.
A27: Customizable Features
A28: 1) Show or Hide OEM Comparison in Quote or Service Quote to cusomter.
B29: Select from drop down option at cell J13
A34: 2) Enter OEM pricing in USD or CAD.
B35: Select from drop down option at cell G17
A41: 3) Provide customer quotes in USD or CAD.
B42: Select from drop down option at cell L17
A51: 4) Enter Vendor pricing in USD or CAD.
B52: Select from drop down option at cell Q17

Sheet CAT 740
B1: CUSTOMER INFORMATION | D1: MACHINE INFORMATION | H1: MACHINE SERVICE HR INTERVALS | L1: SUMMARY | P1: =K17 -> CAD $ | S1: COMPLETED DEAL INFORMATION
B2: DATE: | D2: UNIT # | F2: AT-08 | H2: ENGINE AIR | L2: OEM MSRP | P2: =H49 -> 77837.91 | S2: SALES REP
B3: COMPANY: | D3: YEAR | F3: 2009 | H3: ENGINE OIL | L3: GQP LIST | P3: =L49 -> 42810.89 | S3: ORDER PO #
B4: CUSTOMER: | D4: MAKE | F4: CAT | H4: FUEL FILTERS | L4: $ SAVINGS | P4: =P2-P3 -> 35027.02 | S4: PROJECT #
B5: PHONE: | D5: MODEL | F5: 740 | H5: HYDRAULIC FILTERS | L5: % SAVINGS | P5: =IFERROR((P2-P3)/P2,"") -> 0.44999949 | S5: CUST INVOICE #
B6: EMAIL: | D6: SERIAL NUMBER | F6: B1P04757 | H6: TRANSMISSION FILTERS | L6: TOTAL ORDER MARGIN | P6: =T49 -> 42810.89 | S6: PAYMENT TYPE
B7: SALES REP: | D7: ENGINE SER NUMBER | F7: LHX21840 | H7: CAB FILTERS | L7: TOTAL ITEM COST | P7: =R49 -> 0 | S7: DATE DELIVERED
D8: CURRENT HOURS | H8: UNDERCARRIAGE / TIRES | L8: TOTAL ORDER FREIGHT | P8: =IF(P1=Q14,R14,IF(Q14="CAD $",R14*D15,IF(Q14="USD $",R14*E15,0))) -> 0 | S8: TOTAL COST | T8: NET MARGIN | U8: NET MARKUP % | V8: NET MARGIN %
D9: USAGE/MONTH | F9: Articulated Dump Truck | L9: TOTAL CUSTOMS/BROKERAGE | P9: =V14 -> 0 | S9: =P7+P8+P9 -> 0 | T9: =P3-S9 -> 42810.89 | U9: =IFERROR(((P3-S9)/S9),0) -> 0 | V9: =IFERROR(T9/P3,0) -> 1
L10: TOTAL NUMBER PIECES | P10: =E49 -> 24
D11: ENTER EXCHANGE RATES $ | F11: OEM MSRP | J11: CUSTOMER SELL PRICE | P11: COST ANALYSIS | Y11: CAD $
Y12: USD $
F13: SHOW OEM MSRP ON QUOTE: | H13: YES | Y13: YES
D14: CAD-USD | E14: USD-CAD | F14: OEM NAME | J14: CUSTOMER TYPE/TIER | L14: IE: VIP - Gold | P14: FREIGHT TOTAL ORDER | Q14: USD $ | S14: CUSTOMS AND BROKERAGE % | T14: 0.025 | U14: BROKERAGE FEES | V14: =ROUND(R49*T14,2) -> 0 | Y14: NO
D15: =1/E15 -> 0.70422535 | E15: 1.42 | P15: MARKUP LESS THAN 100% REQUIRES MANAGER APPROVAL
B16: PART NUMBER | C16: DESCRIPTION | D16: SERVICE INTERVAL | E16: QTY | F16: UNIT PRICE | H16: EXT AMOUNT | J16: QTY | K16: UNIT PRICE | L16: EXTENDED AMOUNT | M16: PRCING METHOD %OEM / MARKUP | N16: OEM DISC % / MARKUP % | P16: VENDOR | Q16: COST EACH | R16: EXTENDED COST | S16: MARGIN EACH | T16: EXTENDED MARGIN | U16: MARKUP % | V16: MARGIN %
F17: USD $ | G17: =IF(F17="USD $", "CAD $", "USD $") -> CAD $ | H17: =K17 -> CAD $ | K17: CAD $ | Q17: USD $ | R17: =K17 -> CAD $
B18: 1R-0716 | C18: ENGINE OIL FILTER | D18: 250 | E18: 1 | F18: 33.88 | G18: =ROUND(IF($F$17="USD $", F18*$E$15,F18*$D$15),2) -> 48.11 | H18: =ROUND(IF($H$17=$G$17,E18*G18,E18*F18),2) -> 48.11 | J18: =E18 -> 1 | K18: =IFERROR(IF(M18="OEM DISC %",ROUND(IF($K$17=$F$17,F18*(1-N18),G18*(1-N18)),2),IF(M18="MARKUP %",ROUND(R18/J18*(1+N18),2))),0) -> 26.46 | L18: =ROUND((J18*K18),2) -> 26.46 | M18: OEM DISC % | N18: 0.45 | R18: =ROUND(IF($R$17=$Q$17,Q18,IF($R$17="USD $",Q18*$D$15,Q18*$E$15))*E18,2) -> 0 | S18: =IFERROR(ROUND(T18/E18,2),0) -> 26.46 | T18: =ROUND(L18-R18,2) -> 26.46 | U18: =IFERROR(((K18-(R18/J18))/(R18/J18)),0) -> 0 | V18: =IFERROR(((K18-(R18/J18))/K18),0) -> 1 | Z18: 250
B19: 1R-0762 | C19: FUEL FILTER | D19: 250 | E19: 1 | F19: 45.86 | G19: =ROUND(IF($F$17="USD $", F19*$E$15,F19*$D$15),2) -> 65.12 | H19: =ROUND(IF($H$17=$G$17,E19*G19,E19*F19),2) -> 65.12 | J19: =E19 -> 1 | K19: =IFERROR(IF(M19="OEM DISC %",ROUND(IF($K$17=$F$17,F19*(1-N19),G19*(1-N19)),2),IF(M19="MARKUP %",ROUND(R19/J19*(1+N19),2))),0) -> 35.82 | L19: =ROUND((J19*K19),2) -> 35.82 | M19: OEM DISC % | N19: 0.45 | R19: =ROUND(IF($R$17=$Q$17,Q19,IF($R$17="USD $",Q19*$D$15,Q19*$E$15))*E19,2) -> 0 | S19: =IFERROR(ROUND(T19/E19,2),0) -> 35.82 | T19: =ROUND(L19-R19,2) -> 35.82 | U19: =IFERROR(((K19-(R19/J19))/(R19/J19)),0) -> 0 | V19: =IFERROR(((K19-(R19/J19))/K19),0) -> 1 | Y19: GQP | Z19: 500
B20: 326-1644 | C20: FUEL WATER SEPARATOR FILTER | D20: 500 | E20: 1 | F20: 58.2 | G20: =ROUND(IF($F$17="USD $", F20*$E$15,F20*$D$15),2) -> 82.64 | H20: =ROUND(IF($H$17=$G$17,E20*G20,E20*F20),2) -> 82.64 | J20: =E20 -> 1 | K20: =IFERROR(IF(M20="OEM DISC %",ROUND(IF($K$17=$F$17,F20*(1-N20),G20*(1-N20)),2),IF(M20="MARKUP %",ROUND(R20/J20*(1+N20),2))),0) -> 45.45 | L20: =ROUND((J20*K20),2) -> 45.45 | M20: OEM DISC % | N20: 0.45 | R20: =ROUND(IF($R$17=$Q$17,Q20,IF($R$17="USD $",Q20*$D$15,Q20*$E$15))*E20,2) -> 0 | S20: =IFERROR(ROUND(T20/E20,2),0) -> 45.45 | T20: =ROUND(L20-R20,2) -> 45.45 | U20: =IFERROR(((K20-(R20/J20))/(R20/J20)),0) -> 0 | V20: =IFERROR(((K20-(R20/J20))/K20),0) -> 1 | Y20: CTP | Z20: 750
B21: 1R-0719 | C21: TRANSMISSION FILTER | D21: 500 | E21: 1 | F21: 26.06 | G21: =ROUND(IF($F$17="USD $", F21*$E$15,F21*$D$15),2) -> 37.01 | H21: =ROUND(IF($H$17=$G$17,E21*G21,E21*F21),2) -> 37.01 | J21: =E21 -> 1 | K21: =IFERROR(IF(M21="OEM DISC %",ROUND(IF($K$17=$F$17,F21*(1-N21),G21*(1-N21)),2),IF(M21="MARKUP %",ROUND(R21/J21*(1+N21),2))),0) -> 20.36 | L21: =ROUND((J21*K21),2) -> 20.36 | M21: OEM DISC % | N21: 0.45 | R21: =ROUND(IF($R$17=$Q$17,Q21,IF($R$17="USD $",Q21*$D$15,Q21*$E$15))*E21,2) -> 0 | S21: =IFERROR(ROUND(T21/E21,2),0) -> 20.36 | T21: =ROUND(L21-R21,2) -> 20.36 | U21: =IFERROR(((K21-(R21/J21))/(R21/J21)),0) -> 0 | V21: =IFERROR(((K21-(R21/J21))/K21),0) -> 1 | Y21: BLMQ | Z21: 1000
B22: 1G-8878 | C22: HYDRAULIC FILTER | D22: 500 | E22: 1 | F22: 102.31 | G22: =ROUND(IF($F$17="USD $", F22*$E$15,F22*$D$15),2) -> 145.28 | H22: =ROUND(IF($H$17=$G$17,E22*G22,E22*F22),2) -> 145.28 | J22: =E22 -> 1 | K22: =IFERROR(IF(M22="OEM DISC %",ROUND(IF($K$17=$F$17,F22*(1-N22),G22*(1-N22)),2),IF(M22="MARKUP %",ROUND(R22/J22*(1+N22),2))),0) -> 79.9 | L22: =ROUND((J22*K22),2) -> 79.9 | M22: OEM DISC % | N22: 0.45 | R22: =ROUND(IF($R$17=$Q$17,Q22,IF($R$17="USD $",Q22*$D$15,Q22*$E$15))*E22,2) -> 0 | S22: =IFERROR(ROUND(T22/E22,2),0) -> 79.9 | T22: =ROUND(L22-R22,2) -> 79.9 | U22: =IFERROR(((K22-(R22/J22))/(R22/J22)),0) -> 0 | V22: =IFERROR(((K22-(R22/J22))/K22),0) -> 1 | Y22: CAT | Z22: 1200
B23: 142-1340 | C23: PRIMARY AIR FILTER | D23: 500 | E23: 1 | F23: 178.61 | G23: =ROUND(IF($F$17="USD $", F23*$E$15,F23*$D$15),2) -> 253.63 | H23: =ROUND(IF($H$17=$G$17,E23*G23,E23*F23),2) -> 253.63 | J23: =E23 -> 1 | K23: =IFERROR(IF(M23="OEM DISC %",ROUND(IF($K$17=$F$17,F23*(1-N23),G23*(1-N23)),2),IF(M23="MARKUP %",ROUND(R23/J23*(1+N23),2))),0) -> 139.5 | L23: =ROUND((J23*K23),2) -> 139.5 | M23: OEM DISC % | N23: 0.45 | R23: =ROUND(IF($R$17=$Q$17,Q23,IF($R$17="USD $",Q23*$D$15,Q23*$E$15))*E23,2) -> 0 | S23: =IFERROR(ROUND(T23/E23,2),0) -> 139.5 | T23: =ROUND(L23-R23,2) -> 139.5 | U23: =IFERROR(((K23-(R23/J23))/(R23/J23)),0) -> 0 | V23: =IFERROR(((K23-(R23/J23))/K23),0) -> 1 | Y23: FINNING | Z23: 2000
B24: 142-1403 | C24: SECONDARY AIR FILTER | D24: 250 | E24: 1 | F24: 99.07 | G24: =ROUND(IF($F$17="USD $", F24*$E$15,F24*$D$15),2) -> 140.68 | H24: =ROUND(IF($H$17=$G$17,E24*G24,E24*F24),2) -> 140.68 | J24: =E24 -> 1 | K24: =IFERROR(IF(M24="OEM DISC %",ROUND(IF($K$17=$F$17,F24*(1-N24),G24*(1-N24)),2),IF(M24="MARKUP %",ROUND(R24/J24*(1+N24),2))),0) -> 77.37 | L24: =ROUND((J24*K24),2) -> 77.37 | M24: OEM DISC % | N24: 0.45 | R24: =ROUND(IF($R$17=$Q$17,Q24,IF($R$17="USD $",Q24*$D$15,Q24*$E$15))*E24,2) -> 0 | S24: =IFERROR(ROUND(T24/E24,2),0) -> 77.37 | T24: =ROUND(L24-R24,2) -> 77.37 | U24: =IFERROR(((K24-(R24/J24))/(R24/J24)),0) -> 0 | V24: =IFERROR(((K24-(R24/J24))/K24),0) -> 1 | Y24: JD | Z24: 4000
B25: 268-6704 | C25: CABIN AIR FILTER | D25: 250 | E25: 1 | F25: 86.44 | G25: =ROUND(IF($F$17="USD $", F25*$E$15,F25*$D$15),2) -> 122.74 | H25: =ROUND(IF($H$17=$G$17,E25*G25,E25*F25),2) -> 122.74 | J25: =E25 -> 1 | K25: =IFERROR(IF(M25="OEM DISC %",ROUND(IF($K$17=$F$17,F25*(1-N25),G25*(1-N25)),2),IF(M25="MARKUP %",ROUND(R25/J25*(1+N25),2))),0) -> 67.51 | L25: =ROUND((J25*K25),2) -> 67.51 | M25: OEM DISC % | N25: 0.45 | R25: =ROUND(IF($R$17=$Q$17,Q25,IF($R$17="USD $",Q25*$D$15,Q25*$E$15))*E25,2) -> 0 | S25: =IFERROR(ROUND(T25/E25,2),0) -> 67.51 | T25: =ROUND(L25-R25,2) -> 67.51 | U25: =IFERROR(((K25-(R25/J25))/(R25/J25)),0) -> 0 | V25: =IFERROR(((K25-(R25/J25))/K25),0) -> 1 | Y25: BRANDT | Z25: 6000
G26: =ROUND(IF($F$17="USD $", F26*$E$15,F26*$D$15),2) -> 0 | H26: =ROUND(IF($H$17=$G$17,E26*G26,E26*F26),2) -> 0 | J26: =E26 -> 0 | K26: =IFERROR(IF(M26="OEM DISC %",ROUND(IF($K$17=$F$17,F26*(1-N26),G26*(1-N26)),2),IF(M26="MARKUP %",ROUND(R26/J26*(1+N26),2))),0) -> 0 | L26: =ROUND((J26*K26),2) -> 0 | M26: OEM DISC % | N26: 0.45 | R26: =ROUND(IF($R$17=$Q$17,Q26,IF($R$17="USD $",Q26*$D$15,Q26*$E$15))*E26,2) -> 0 | S26: =IFERROR(ROUND(T26/E26,2),0) -> 0 | T26: =ROUND(L26-R26,2) -> 0 | U26: =IFERROR(((K26-(R26/J26))/(R26/J26)),0) -> 0 | V26: =IFERROR(((K26-(R26/J26))/K26),0) -> 0 | Y26: PTI | Z26: 8000
B27: 447-1525 | C27: ENGINE OVERHAUL KIT SILVER | D27: 10000 | E27: 1 | G27: =ROUND(IF($F$17="USD $", F27*$E$15,F27*$D$15),2) -> 0 | H27: =ROUND(IF($H$17=$G$17,E27*G27,E27*F27),2) -> 0 | J27: =E27 -> 1 | K27: =IFERROR(IF(M27="OEM DISC %",ROUND(IF($K$17=$F$17,F27*(1-N27),G27*(1-N27)),2),IF(M27="MARKUP %",ROUND(R27/J27*(1+N27),2))),0) -> 0 | L27: =ROUND((J27*K27),2) -> 0 | M27: OEM DISC % | N27: 0.45 | R27: =ROUND(IF($R$17=$Q$17,Q27,IF($R$17="USD $",Q27*$D$15,Q27*$E$15))*E27,2) -> 0 | S27: =IFERROR(ROUND(T27/E27,2),0) -> 0 | T27: =ROUND(L27-R27,2) -> 0 | U27: =IFERROR(((K27-(R27/J27))/(R27/J27)),0) -> 0 | V27: =IFERROR(((K27-(R27/J27))/K27),0) -> 0 | Y27: CONEQUIP | Z27: 10000
C28: SEAT GP-SUSPENSION | G28: =ROUND(IF($F$17="USD $", F28*$E$15,F28*$D$15),2) -> 0 | H28: =ROUND(IF($H$17=$G$17,E28*G28,E28*F28),2) -> 0 | J28: =E28 -> 0 | K28: =IFERROR(IF(M28="OEM DISC %",ROUND(IF($K$17=$F$17,F28*(1-N28),G28*(1-N28)),2),IF(M28="MARKUP %",ROUND(R28/J28*(1+N28),2))),0) -> 0 | L28: =ROUND((J28*K28),2) -> 0 | M28: OEM DISC % | N28: 0.45 | R28: =ROUND(IF($R$17=$Q$17,Q28,IF($R$17="USD $",Q28*$D$15,Q28*$E$15))*E28,2) -> 0 | S28: =IFERROR(ROUND(T28/E28,2),0) -> 0 | T28: =ROUND(L28-R28,2) -> 0 | U28: =IFERROR(((K28-(R28/J28))/(R28/J28)),0) -> 0 | V28: =IFERROR(((K28-(R28/J28))/K28),0) -> 0 | Y28: CANDY | Z28: AS REQ'D
B29: 153-5700 | C29: BATTERY | D29: AS REQ'D | E29: 2 | F29: 493.89 | G29: =ROUND(IF($F$17="USD $", F29*$E$15,F29*$D$15),2) -> 701.32 | H29: =ROUND(IF($H$17=$G$17,E29*G29,E29*F29),2) -> 1402.64 | J29: =E29 -> 2 | K29: =IFERROR(IF(M29="OEM DISC %",ROUND(IF($K$17=$F$17,F29*(1-N29),G29*(1-N29)),2),IF(M29="MARKUP %",ROUND(R29/J29*(1+N29),2))),0) -> 385.73 | L29: =ROUND((J29*K29),2) -> 771.46 | M29: OEM DISC % | N29: 0.45 | R29: =ROUND(IF($R$17=$Q$17,Q29,IF($R$17="USD $",Q29*$D$15,Q29*$E$15))*E29,2) -> 0 | S29: =IFERROR(ROUND(T29/E29,2),0) -> 385.73 | T29: =ROUND(L29-R29,2) -> 771.46 | U29: =IFERROR(((K29-(R29/J29))/(R29/J29)),0) -> 0 | V29: =IFERROR(((K29-(R29/J29))/K29),0) -> 1 | Y29: U/C
B30: 230-3542 | C30: TURBOCHARGER | D30: 6000 | E30: 1 | F30: 4583.66 | G30: =ROUND(IF($F$17="USD $", F30*$E$15,F30*$D$15),2) -> 6508.8 | H30: =ROUND(IF($H$17=$G$17,E30*G30,E30*F30),2) -> 6508.8 | J30: =E30 -> 1 | K30: =IFERROR(IF(M30="OEM DISC %",ROUND(IF($K$17=$F$17,F30*(1-N30),G30*(1-N30)),2),IF(M30="MARKUP %",ROUND(R30/J30*(1+N30),2))),0) -> 3579.84 | L30: =ROUND((J30*K30),2) -> 3579.84 | M30: OEM DISC % | N30: 0.45 | R30: =ROUND(IF($R$17=$Q$17,Q30,IF($R$17="USD $",Q30*$D$15,Q30*$E$15))*E30,2) -> 0 | S30: =IFERROR(ROUND(T30/E30,2),0) -> 3579.84 | T30: =ROUND(L30-R30,2) -> 3579.84 | U30: =IFERROR(((K30-(R30/J30))/(R30/J30)),0) -> 0 | V30: =IFERROR(((K30-(R30/J30))/K30),0) -> 1
B31: 647-0750 | C31: INJECTOR | D31: 6000 | E31: 6 | F31: 1430.29 | G31: =ROUND(IF($F$17="USD $", F31*$E$15,F31*$D$15),2) -> 2031.01 | H31: =ROUND(IF($H$17=$G$17,E31*G31,E31*F31),2) -> 12186.06 | J31: =E31 -> 6 | K31: =IFERROR(IF(M31="OEM DISC %",ROUND(IF($K$17=$F$17,F31*(1-N31),G31*(1-N31)),2),IF(M31="MARKUP %",ROUND(R31/J31*(1+N31),2))),0) -> 1117.06 | L31: =ROUND((J31*K31),2) -> 6702.36 | M31: OEM DISC % | N31: 0.45 | R31: =ROUND(IF($R$17=$Q$17,Q31,IF($R$17="USD $",Q31*$D$15,Q31*$E$15))*E31,2) -> 0 | S31: =IFERROR(ROUND(T31/E31,2),0) -> 1117.06 | T31: =ROUND(L31-R31,2) -> 6702.36 | U31: =IFERROR(((K31-(R31/J31))/(R31/J31)),0) -> 0 | V31: =IFERROR(((K31-(R31/J31))/K31),0) -> 1 | Y31: OEM DISC %
G32: =ROUND(IF($F$17="USD $", F32*$E$15,F32*$D$15),2) -> 0 | H32: =ROUND(IF($H$17=$G$17,E32*G32,E32*F32),2) -> 0 | J32: =E32 -> 0 | K32: =IFERROR(IF(M32="OEM DISC %",ROUND(IF($K$17=$F$17,F32*(1-N32),G32*(1-N32)),2),IF(M32="MARKUP %",ROUND(R32/J32*(1+N32),2))),0) -> 0 | L32: =ROUND((J32*K32),2) -> 0 | M32: OEM DISC % | N32: 0.45 | R32: =ROUND(IF($R$17=$Q$17,Q32,IF($R$17="USD $",Q32*$D$15,Q32*$E$15))*E32,2) -> 0 | S32: =IFERROR(ROUND(T32/E32,2),0) -> 0 | T32: =ROUND(L32-R32,2) -> 0 | U32: =IFERROR(((K32-(R32/J32))/(R32/J32)),0) -> 0 | V32: =IFERROR(((K32-(R32/J32))/K32),0) -> 0 | Y32: MARKUP %
C33: TIRES 29.5r25 | D33: 5000 | E33: 6 | F33: 6671.97 | G33: =ROUND(IF($F$17="USD $", F33*$E$15,F33*$D$15),2) -> 9474.2 | H33: =ROUND(IF($H$17=$G$17,E33*G33,E33*F33),2) -> 56845.2 | J33: =E33 -> 6 | K33: =IFERROR(IF(M33="OEM DISC %",ROUND(IF($K$17=$F$17,F33*(1-N33),G33*(1-N33)),2),IF(M33="MARKUP %",ROUND(R33/J33*(1+N33),2))),0) -> 5210.81 | L33: =ROUND((J33*K33),2) -> 31264.86 | M33: OEM DISC % | N33: 0.45 | R33: =ROUND(IF($R$17=$Q$17,Q33,IF($R$17="USD $",Q33*$D$15,Q33*$E$15))*E33,2) -> 0 | S33: =IFERROR(ROUND(T33/E33,2),0) -> 5210.81 | T33: =ROUND(L33-R33,2) -> 31264.86 | U33: =IFERROR(((K33-(R33/J33))/(R33/J33)),0) -> 0 | V33: =IFERROR(((K33-(R33/J33))/K33),0) -> 1
G34: =ROUND(IF($F$17="USD $", F34*$E$15,F34*$D$15),2) -> 0 | H34: =ROUND(IF($H$17=$G$17,E34*G34,E34*F34),2) -> 0 | J34: =E34 -> 0 | K34: =IFERROR(IF(M34="OEM DISC %",ROUND(IF($K$17=$F$17,F34*(1-N34),G34*(1-N34)),2),IF(M34="MARKUP %",ROUND(R34/J34*(1+N34),2))),0) -> 0 | L34: =ROUND((J34*K34),2) -> 0 | M34: OEM DISC % | N34: 0.45 | R34: =ROUND(IF($R$17=$Q$17,Q34,IF($R$17="USD $",Q34*$D$15,Q34*$E$15))*E34,2) -> 0 | S34: =IFERROR(ROUND(T34/E34,2),0) -> 0 | T34: =ROUND(L34-R34,2) -> 0 | U34: =IFERROR(((K34-(R34/J34))/(R34/J34)),0) -> 0 | V34: =IFERROR(((K34-(R34/J34))/K34),0) -> 0
G35: =ROUND(IF($F$17="USD $", F35*$E$15,F35*$D$15),2) -> 0 | H35: =ROUND(IF($H$17=$G$17,E35*G35,E35*F35),2) -> 0 | J35: =E35 -> 0 | K35: =IFERROR(IF(M35="OEM DISC %",ROUND(IF($K$17=$F$17,F35*(1-N35),G35*(1-N35)),2),IF(M35="MARKUP %",ROUND(R35/J35*(1+N35),2))),0) -> 0 | L35: =ROUND((J35*K35),2) -> 0 | M35: OEM DISC % | N35: 0.45 | R35: =ROUND(IF($R$17=$Q$17,Q35,IF($R$17="USD $",Q35*$D$15,Q35*$E$15))*E35,2) -> 0 | S35: =IFERROR(ROUND(T35/E35,2),0) -> 0 | T35: =ROUND(L35-R35,2) -> 0 | U35: =IFERROR(((K35-(R35/J35))/(R35/J35)),0) -> 0 | V35: =IFERROR(((K35-(R35/J35))/K35),0) -> 0
G36: =ROUND(IF($F$17="USD $", F36*$E$15,F36*$D$15),2) -> 0 | H36: =ROUND(IF($H$17=$G$17,E36*G36,E36*F36),2) -> 0 | J36: =E36 -> 0 | K36: =IFERROR(IF(M36="OEM DISC %",ROUND(IF($K$17=$F$17,F36*(1-N36),G36*(1-N36)),2),IF(M36="MARKUP %",ROUND(R36/J36*(1+N36),2))),0) -> 0 | L36: =ROUND((J36*K36),2) -> 0 | M36: OEM DISC % | N36: 0.45 | R36: =ROUND(IF($R$17=$Q$17,Q36,IF($R$17="USD $",Q36*$D$15,Q36*$E$15))*E36,2) -> 0 | S36: =IFERROR(ROUND(T36/E36,2),0) -> 0 | T36: =ROUND(L36-R36,2) -> 0 | U36: =IFERROR(((K36-(R36/J36))/(R36/J36)),0) -> 0 | V36: =IFERROR(((K36-(R36/J36))/K36),0) -> 0
G37: =ROUND(IF($F$17="USD $", F37*$E$15,F37*$D$15),2) -> 0 | H37: =ROUND(IF($H$17=$G$17,E37*G37,E37*F37),2) -> 0 | J37: =E37 -> 0 | K37: =IFERROR(IF(M37="OEM DISC %",ROUND(IF($K$17=$F$17,F37*(1-N37),G37*(1-N37)),2),IF(M37="MARKUP %",ROUND(R37/J37*(1+N37),2))),0) -> 0 | L37: =ROUND((J37*K37),2) -> 0 | M37: OEM DISC % | N37: 0.45 | R37: =ROUND(IF($R$17=$Q$17,Q37,IF($R$17="USD $",Q37*$D$15,Q37*$E$15))*E37,2) -> 0 | S37: =IFERROR(ROUND(T37/E37,2),0) -> 0 | T37: =ROUND(L37-R37,2) -> 0 | U37: =IFERROR(((K37-(R37/J37))/(R37/J37)),0) -> 0 | V37: =IFERROR(((K37-(R37/J37))/K37),0) -> 0
G38: =ROUND(IF($F$17="USD $", F38*$E$15,F38*$D$15),2) -> 0 | H38: =ROUND(IF($H$17=$G$17,E38*G38,E38*F38),2) -> 0 | J38: =E38 -> 0 | K38: =IFERROR(IF(M38="OEM DISC %",ROUND(IF($K$17=$F$17,F38*(1-N38),G38*(1-N38)),2),IF(M38="MARKUP %",ROUND(R38/J38*(1+N38),2))),0) -> 0 | L38: =ROUND((J38*K38),2) -> 0 | M38: OEM DISC % | N38: 0.45 | R38: =ROUND(IF($R$17=$Q$17,Q38,IF($R$17="USD $",Q38*$D$15,Q38*$E$15))*E38,2) -> 0 | S38: =IFERROR(ROUND(T38/E38,2),0) -> 0 | T38: =ROUND(L38-R38,2) -> 0 | U38: =IFERROR(((K38-(R38/J38))/(R38/J38)),0) -> 0 | V38: =IFERROR(((K38-(R38/J38))/K38),0) -> 0
G39: =ROUND(IF($F$17="USD $", F39*$E$15,F39*$D$15),2) -> 0 | H39: =ROUND(IF($H$17=$G$17,E39*G39,E39*F39),2) -> 0 | J39: =E39 -> 0 | K39: =IFERROR(IF(M39="OEM DISC %",ROUND(IF($K$17=$F$17,F39*(1-N39),G39*(1-N39)),2),IF(M39="MARKUP %",ROUND(R39/J39*(1+N39),2))),0) -> 0 | L39: =ROUND((J39*K39),2) -> 0 | M39: OEM DISC % | N39: 0.45 | R39: =ROUND(IF($R$17=$Q$17,Q39,IF($R$17="USD $",Q39*$D$15,Q39*$E$15))*E39,2) -> 0 | S39: =IFERROR(ROUND(T39/E39,2),0) -> 0 | T39: =ROUND(L39-R39,2) -> 0 | U39: =IFERROR(((K39-(R39/J39))/(R39/J39)),0) -> 0 | V39: =IFERROR(((K39-(R39/J39))/K39),0) -> 0
G40: =ROUND(IF($F$17="USD $", F40*$E$15,F40*$D$15),2) -> 0 | H40: =ROUND(IF($H$17=$G$17,E40*G40,E40*F40),2) -> 0 | J40: =E40 -> 0 | K40: =IFERROR(IF(M40="OEM DISC %",ROUND(IF($K$17=$F$17,F40*(1-N40),G40*(1-N40)),2),IF(M40="MARKUP %",ROUND(R40/J40*(1+N40),2))),0) -> 0 | L40: =ROUND((J40*K40),2) -> 0 | M40: OEM DISC % | N40: 0.45 | R40: =ROUND(IF($R$17=$Q$17,Q40,IF($R$17="USD $",Q40*$D$15,Q40*$E$15))*E40,2) -> 0 | S40: =IFERROR(ROUND(T40/E40,2),0) -> 0 | T40: =ROUND(L40-R40,2) -> 0 | U40: =IFERROR(((K40-(R40/J40))/(R40/J40)),0) -> 0 | V40: =IFERROR(((K40-(R40/J40))/K40),0) -> 0
...

Sheet CAT 740 (2)
B1: CUSTOMER INFORMATION | D1: MACHINE INFORMATION | H1: MACHINE SERVICE HR INTERVALS | L1: SUMMARY | P1: =K17 -> CAD $ | S1: COMPLETED DEAL INFORMATION
B2: DATE: | D2: UNIT # | F2: AT-07 | H2: ENGINE AIR | L2: OEM MSRP | P2: =H49 -> 77837.91 | S2: SALES REP
B3: COMPANY: | D3: YEAR | F3: 2009 | H3: ENGINE OIL | L3: GQP LIST | P3: =L49 -> 42810.89 | S3: ORDER PO #
B4: CUSTOMER: | D4: MAKE | F4: CAT | H4: FUEL FILTERS | L4: $ SAVINGS | P4: =P2-P3 -> 35027.02 | S4: PROJECT #
B5: PHONE: | D5: MODEL | F5: 740 | H5: HYDRAULIC FILTERS | L5: % SAVINGS | P5: =IFERROR((P2-P3)/P2,"") -> 0.44999949 | S5: CUST INVOICE #
B6: EMAIL: | D6: SERIAL NUMBER | F6: B1P05108 | H6: TRANSMISSION FILTERS | L6: TOTAL ORDER MARGIN | P6: =T49 -> 42810.89 | S6: PAYMENT TYPE
B7: SALES REP: | D7: ENGINE SER NUMBER | F7: LHX23321 | H7: CAB FILTERS | L7: TOTAL ITEM COST | P7: =R49 -> 0 | S7: DATE DELIVERED
D8: CURRENT HOURS | H8: UNDERCARRIAGE / TIRES | L8: TOTAL ORDER FREIGHT | P8: =IF(P1=Q14,R14,IF(Q14="CAD $",R14*D15,IF(Q14="USD $",R14*E15,0))) -> 0 | S8: TOTAL COST | T8: NET MARGIN | U8: NET MARKUP % | V8: NET MARGIN %
D9: USAGE/MONTH | F9: Articulated Dump Truck | L9: TOTAL CUSTOMS/BROKERAGE | P9: =V14 -> 0 | S9: =P7+P8+P9 -> 0 | T9: =P3-S9 -> 42810.89 | U9: =IFERROR(((P3-S9)/S9),0) -> 0 | V9: =IFERROR(T9/P3,0) -> 1
L10: TOTAL NUMBER PIECES | P10: =E49 -> 24
D11: ENTER EXCHANGE RATES $ | F11: OEM MSRP | J11: CUSTOMER SELL PRICE | P11: COST ANALYSIS | Y11: CAD $
Y12: USD $
F13: SHOW OEM MSRP ON QUOTE: | H13: YES | Y13: YES
D14: CAD-USD | E14: USD-CAD | F14: OEM NAME | J14: CUSTOMER TYPE/TIER | L14: IE: VIP - Gold | P14: FREIGHT TOTAL ORDER | Q14: USD $ | S14: CUSTOMS AND BROKERAGE % | T14: 0.025 | U14: BROKERAGE FEES | V14: =ROUND(R49*T14,2) -> 0 | Y14: NO
D15: =1/E15 -> 0.70422535 | E15: 1.42 | P15: MARKUP LESS THAN 100% REQUIRES MANAGER APPROVAL
B16: PART NUMBER | C16: DESCRIPTION | D16: SERVICE INTERVAL | E16: QTY | F16: UNIT PRICE | H16: EXT AMOUNT | J16: QTY | K16: UNIT PRICE | L16: EXTENDED AMOUNT | M16: PRCING METHOD %OEM / MARKUP | N16: OEM DISC % / MARKUP % | P16: VENDOR | Q16: COST EACH | R16: EXTENDED COST | S16: MARGIN EACH | T16: EXTENDED MARGIN | U16: MARKUP % | V16: MARGIN %
F17: USD $ | G17: =IF(F17="USD $", "CAD $", "USD $") -> CAD $ | H17: =K17 -> CAD $ | K17: CAD $ | Q17: USD $ | R17: =K17 -> CAD $
B18: 1R-0716 | C18: ENGINE OIL FILTER | D18: 250 | E18: 1 | F18: 33.88 | G18: =ROUND(IF($F$17="USD $", F18*$E$15,F18*$D$15),2) -> 48.11 | H18: =ROUND(IF($H$17=$G$17,E18*G18,E18*F18),2) -> 48.11 | J18: =E18 -> 1 | K18: =IFERROR(IF(M18="OEM DISC %",ROUND(IF($K$17=$F$17,F18*(1-N18),G18*(1-N18)),2),IF(M18="MARKUP %",ROUND(R18/J18*(1+N18),2))),0) -> 26.46 | L18: =ROUND((J18*K18),2) -> 26.46 | M18: OEM DISC % | N18: 0.45 | R18: =ROUND(IF($R$17=$Q$17,Q18,IF($R$17="USD $",Q18*$D$15,Q18*$E$15))*E18,2) -> 0 | S18: =IFERROR(ROUND(T18/E18,2),0) -> 26.46 | T18: =ROUND(L18-R18,2) -> 26.46 | U18: =IFERROR(((K18-(R18/J18))/(R18/J18)),0) -> 0 | V18: =IFERROR(((K18-(R18/J18))/K18),0) -> 1 | Z18: 250
B19: 1R-0762 | C19: FUEL FILTER | D19: 250 | E19: 1 | F19: 45.86 | G19: =ROUND(IF($F$17="USD $", F19*$E$15,F19*$D$15),2) -> 65.12 | H19: =ROUND(IF($H$17=$G$17,E19*G19,E19*F19),2) -> 65.12 | J19: =E19 -> 1 | K19: =IFERROR(IF(M19="OEM DISC %",ROUND(IF($K$17=$F$17,F19*(1-N19),G19*(1-N19)),2),IF(M19="MARKUP %",ROUND(R19/J19*(1+N19),2))),0) -> 35.82 | L19: =ROUND((J19*K19),2) -> 35.82 | M19: OEM DISC % | N19: 0.45 | R19: =ROUND(IF($R$17=$Q$17,Q19,IF($R$17="USD $",Q19*$D$15,Q19*$E$15))*E19,2) -> 0 | S19: =IFERROR(ROUND(T19/E19,2),0) -> 35.82 | T19: =ROUND(L19-R19,2) -> 35.82 | U19: =IFERROR(((K19-(R19/J19))/(R19/J19)),0) -> 0 | V19: =IFERROR(((K19-(R19/J19))/K19),0) -> 1 | Y19: GQP | Z19: 500
B20: 326-1644 | C20: FUEL WATER SEPARATOR FILTER | D20: 500 | E20: 1 | F20: 58.2 | G20: =ROUND(IF($F$17="USD $", F20*$E$15,F20*$D$15),2) -> 82.64 | H20: =ROUND(IF($H$17=$G$17,E20*G20,E20*F20),2) -> 82.64 | J20: =E20 -> 1 | K20: =IFERROR(IF(M20="OEM DISC %",ROUND(IF($K$17=$F$17,F20*(1-N20),G20*(1-N20)),2),IF(M20="MARKUP %",ROUND(R20/J20*(1+N20),2))),0) -> 45.45 | L20: =ROUND((J20*K20),2) -> 45.45 | M20: OEM DISC % | N20: 0.45 | R20: =ROUND(IF($R$17=$Q$17,Q20,IF($R$17="USD $",Q20*$D$15,Q20*$E$15))*E20,2) -> 0 | S20: =IFERROR(ROUND(T20/E20,2),0) -> 45.45 | T20: =ROUND(L20-R20,2) -> 45.45 | U20: =IFERROR(((K20-(R20/J20))/(R20/J20)),0) -> 0 | V20: =IFERROR(((K20-(R20/J20))/K20),0) -> 1 | Y20: CTP | Z20: 750
B21: 1R-0719 | C21: TRANSMISSION FILTER | D21: 500 | E21: 1 | F21: 26.06 | G21: =ROUND(IF($F$17="USD $", F21*$E$15,F21*$D$15),2) -> 37.01 | H21: =ROUND(IF($H$17=$G$17,E21*G21,E21*F21),2) -> 37.01 | J21: =E21 -> 1 | K21: =IFERROR(IF(M21="OEM DISC %",ROUND(IF($K$17=$F$17,F21*(1-N21),G21*(1-N21)),2),IF(M21="MARKUP %",ROUND(R21/J21*(1+N21),2))),0) -> 20.36 | L21: =ROUND((J21*K21),2) -> 20.36 | M21: OEM DISC % | N21: 0.45 | R21: =ROUND(IF($R$17=$Q$17,Q21,IF($R$17="USD $",Q21*$D$15,Q21*$E$15))*E21,2) -> 0 | S21: =IFERROR(ROUND(T21/E21,2),0) -> 20.36 | T21: =ROUND(L21-R21,2) -> 20.36 | U21: =IFERROR(((K21-(R21/J21))/(R21/J21)),0) -> 0 | V21: =IFERROR(((K21-(R21/J21))/K21),0) -> 1 | Y21: BLMQ | Z21: 1000
B22: 1G-8878 | C22: HYDRAULIC FILTER | D22: 500 | E22: 1 | F22: 102.31 | G22: =ROUND(IF($F$17="USD $", F22*$E$15,F22*$D$15),2) -> 145.28 | H22: =ROUND(IF($H$17=$G$17,E22*G22,E22*F22),2) -> 145.28 | J22: =E22 -> 1 | K22: =IFERROR(IF(M22="OEM DISC %",ROUND(IF($K$17=$F$17,F22*(1-N22),G22*(1-N22)),2),IF(M22="MARKUP %",ROUND(R22/J22*(1+N22),2))),0) -> 79.9 | L22: =ROUND((J22*K22),2) -> 79.9 | M22: OEM DISC % | N22: 0.45 | R22: =ROUND(IF($R$17=$Q$17,Q22,IF($R$17="USD $",Q22*$D$15,Q22*$E$15))*E22,2) -> 0 | S22: =IFERROR(ROUND(T22/E22,2),0) -> 79.9 | T22: =ROUND(L22-R22,2) -> 79.9 | U22: =IFERROR(((K22-(R22/J22))/(R22/J22)),0) -> 0 | V22: =IFERROR(((K22-(R22/J22))/K22),0) -> 1 | Y22: CAT | Z22: 1200
B23: 142-1340 | C23: PRIMARY AIR FILTER | D23: 500 | E23: 1 | F23: 178.61 | G23: =ROUND(IF($F$17="USD $", F23*$E$15,F23*$D$15),2) -> 253.63 | H23: =ROUND(IF($H$17=$G$17,E23*G23,E23*F23),2) -> 253.63 | J23: =E23 -> 1 | K23: =IFERROR(IF(M23="OEM DISC %",ROUND(IF($K$17=$F$17,F23*(1-N23),G23*(1-N23)),2),IF(M23="MARKUP %",ROUND(R23/J23*(1+N23),2))),0) -> 139.5 | L23: =ROUND((J23*K23),2) -> 139.5 | M23: OEM DISC % | N23: 0.45 | R23: =ROUND(IF($R$17=$Q$17,Q23,IF($R$17="USD $",Q23*$D$15,Q23*$E$15))*E23,2) -> 0 | S23: =IFERROR(ROUND(T23/E23,2),0) -> 139.5 | T23: =ROUND(L23-R23,2) -> 139.5 | U23: =IFERROR(((K23-(R23/J23))/(R23/J23)),0) -> 0 | V23: =IFERROR(((K23-(R23/J23))/K23),0) -> 1 | Y23: FINNING | Z23: 2000
B24: 142-1403 | C24: SECONDARY AIR FILTER | D24: 250 | E24: 1 | F24: 99.07 | G24: =ROUND(IF($F$17="USD $", F24*$E$15,F24*$D$15),2) -> 140.68 | H24: =ROUND(IF($H$17=$G$17,E24*G24,E24*F24),2) -> 140.68 | J24: =E24 -> 1 | K24: =IFERROR(IF(M24="OEM DISC %",ROUND(IF($K$17=$F$17,F24*(1-N24),G24*(1-N24)),2),IF(M24="MARKUP %",ROUND(R24/J24*(1+N24),2))),0) -> 77.37 | L24: =ROUND((J24*K24),2) -> 77.37 | M24: OEM DISC % | N24: 0.45 | R24: =ROUND(IF($R$17=$Q$17,Q24,IF($R$17="USD $",Q24*$D$15,Q24*$E$15))*E24,2) -> 0 | S24: =IFERROR(ROUND(T24/E24,2),0) -> 77.37 | T24: =ROUND(L24-R24,2) -> 77.37 | U24: =IFERROR(((K24-(R24/J24))/(R24/J24)),0) -> 0 | V24: =IFERROR(((K24-(R24/J24))/K24),0) -> 1 | Y24: JD | Z24: 4000
B25: 268-6704 | C25: CABIN AIR FILTER | D25: 250 | E25: 1 | F25: 86.44 | G25: =ROUND(IF($F$17="USD $", F25*$E$15,F25*$D$15),2) -> 122.74 | H25: =ROUND(IF($H$17=$G$17,E25*G25,E25*F25),2) -> 122.74 | J25: =E25 -> 1 | K25: =IFERROR(IF(M25="OEM DISC %",ROUND(IF($K$17=$F$17,F25*(1-N25),G25*(1-N25)),2),IF(M25="MARKUP %",ROUND(R25/J25*(1+N25),2))),0) -> 67.51 | L25: =ROUND((J25*K25),2) -> 67.51 | M25: OEM DISC % | N25: 0.45 | R25: =ROUND(IF($R$17=$Q$17,Q25,IF($R$17="USD $",Q25*$D$15,Q25*$E$15))*E25,2) -> 0 | S25: =IFERROR(ROUND(T25/E25,2),0) -> 67.51 | T25: =ROUND(L25-R25,2) -> 67.51 | U25: =IFERROR(((K25-(R25/J25))/(R25/J25)),0) -> 0 | V25: =IFERROR(((K25-(R25/J25))/K25),0) -> 1 | Y25: BRANDT | Z25: 6000
G26: =ROUND(IF($F$17="USD $", F26*$E$15,F26*$D$15),2) -> 0 | H26: =ROUND(IF($H$17=$G$17,E26*G26,E26*F26),2) -> 0 | J26: =E26 -> 0 | K26: =IFERROR(IF(M26="OEM DISC %",ROUND(IF($K$17=$F$17,F26*(1-N26),G26*(1-N26)),2),IF(M26="MARKUP %",ROUND(R26/J26*(1+N26),2))),0) -> 0 | L26: =ROUND((J26*K26),2) -> 0 | M26: OEM DISC % | N26: 0.45 | R26: =ROUND(IF($R$17=$Q$17,Q26,IF($R$17="USD $",Q26*$D$15,Q26*$E$15))*E26,2) -> 0 | S26: =IFERROR(ROUND(T26/E26,2),0) -> 0 | T26: =ROUND(L26-R26,2) -> 0 | U26: =IFERROR(((K26-(R26/J26))/(R26/J26)),0) -> 0 | V26: =IFERROR(((K26-(R26/J26))/K26),0) -> 0 | Y26: PTI | Z26: 8000
B27: 447-1525 | C27: ENGINE OVERHAUL KIT SILVER | D27: 10000 | E27: 1 | G27: =ROUND(IF($F$17="USD $", F27*$E$15,F27*$D$15),2) -> 0 | H27: =ROUND(IF($H$17=$G$17,E27*G27,E27*F27),2) -> 0 | J27: =E27 -> 1 | K27: =IFERROR(IF(M27="OEM DISC %",ROUND(IF($K$17=$F$17,F27*(1-N27),G27*(1-N27)),2),IF(M27="MARKUP %",ROUND(R27/J27*(1+N27),2))),0) -> 0 | L27: =ROUND((J27*K27),2) -> 0 | M27: OEM DISC % | N27: 0.45 | R27: =ROUND(IF($R$17=$Q$17,Q27,IF($R$17="USD $",Q27*$D$15,Q27*$E$15))*E27,2) -> 0 | S27: =IFERROR(ROUND(T27/E27,2),0) -> 0 | T27: =ROUND(L27-R27,2) -> 0 | U27: =IFERROR(((K27-(R27/J27))/(R27/J27)),0) -> 0 | V27: =IFERROR(((K27-(R27/J27))/K27),0) -> 0 | Y27: CONEQUIP | Z27: 10000
C28: SEAT GP-SUSPENSION | G28: =ROUND(IF($F$17="USD $", F28*$E$15,F28*$D$15),2) -> 0 | H28: =ROUND(IF($H$17=$G$17,E28*G28,E28*F28),2) -> 0 | J28: =E28 -> 0 | K28: =IFERROR(IF(M28="OEM DISC %",ROUND(IF($K$17=$F$17,F28*(1-N28),G28*(1-N28)),2),IF(M28="MARKUP %",ROUND(R28/J28*(1+N28),2))),0) -> 0 | L28: =ROUND((J28*K28),2) -> 0 | M28: OEM DISC % | N28: 0.45 | R28: =ROUND(IF($R$17=$Q$17,Q28,IF($R$17="USD $",Q28*$D$15,Q28*$E$15))*E28,2) -> 0 | S28: =IFERROR(ROUND(T28/E28,2),0) -> 0 | T28: =ROUND(L28-R28,2) -> 0 | U28: =IFERROR(((K28-(R28/J28))/(R28/J28)),0) -> 0 | V28: =IFERROR(((K28-(R28/J28))/K28),0) -> 0 | Y28: CANDY | Z28: AS REQ'D
B29: 153-5700 | C29: BATTERY | D29: AS REQ'D | E29: 2 | F29: 493.89 | G29: =ROUND(IF($F$17="USD $", F29*$E$15,F29*$D$15),2) -> 701.32 | H29: =ROUND(IF($H$17=$G$17,E29*G29,E29*F29),2) -> 1402.64 | J29: =E29 -> 2 | K29: =IFERROR(IF(M29="OEM DISC %",ROUND(IF($K$17=$F$17,F29*(1-N29),G29*(1-N29)),2),IF(M29="MARKUP %",ROUND(R29/J29*(1+N29),2))),0) -> 385.73 | L29: =ROUND((J29*K29),2) -> 771.46 | M29: OEM DISC % | N29: 0.45 | R29: =ROUND(IF($R$17=$Q$17,Q29,IF($R$17="USD $",Q29*$D$15,Q29*$E$15))*E29,2) -> 0 | S29: =IFERROR(ROUND(T29/E29,2),0) -> 385.73 | T29: =ROUND(L29-R29,2) -> 771.46 | U29: =IFERROR(((K29-(R29/J29))/(R29/J29)),0) -> 0 | V29: =IFERROR(((K29-(R29/J29))/K29),0) -> 1 | Y29: U/C
B30: 230-3542 | C30: TURBOCHARGER | D30: 6000 | E30: 1 | F30: 4583.66 | G30: =ROUND(IF($F$17="USD $", F30*$E$15,F30*$D$15),2) -> 6508.8 | H30: =ROUND(IF($H$17=$G$17,E30*G30,E30*F30),2) -> 6508.8 | J30: =E30 -> 1 | K30: =IFERROR(IF(M30="OEM DISC %",ROUND(IF($K$17=$F$17,F30*(1-N30),G30*(1-N30)),2),IF(M30="MARKUP %",ROUND(R30/J30*(1+N30),2))),0) -> 3579.84 | L30: =ROUND((J30*K30),2) -> 3579.84 | M30: OEM DISC % | N30: 0.45 | R30: =ROUND(IF($R$17=$Q$17,Q30,IF($R$17="USD $",Q30*$D$15,Q30*$E$15))*E30,2) -> 0 | S30: =IFERROR(ROUND(T30/E30,2),0) -> 3579.84 | T30: =ROUND(L30-R30,2) -> 3579.84 | U30: =IFERROR(((K30-(R30/J30))/(R30/J30)),0) -> 0 | V30: =IFERROR(((K30-(R30/J30))/K30),0) -> 1
B31: 647-0750 | C31: INJECTOR | D31: 6000 | E31: 6 | F31: 1430.29 | G31: =ROUND(IF($F$17="USD $", F31*$E$15,F31*$D$15),2) -> 2031.01 | H31: =ROUND(IF($H$17=$G$17,E31*G31,E31*F31),2) -> 12186.06 | J31: =E31 -> 6 | K31: =IFERROR(IF(M31="OEM DISC %",ROUND(IF($K$17=$F$17,F31*(1-N31),G31*(1-N31)),2),IF(M31="MARKUP %",ROUND(R31/J31*(1+N31),2))),0) -> 1117.06 | L31: =ROUND((J31*K31),2) -> 6702.36 | M31: OEM DISC % | N31: 0.45 | R31: =ROUND(IF($R$17=$Q$17,Q31,IF($R$17="USD $",Q31*$D$15,Q31*$E$15))*E31,2) -> 0 | S31: =IFERROR(ROUND(T31/E31,2),0) -> 1117.06 | T31: =ROUND(L31-R31,2) -> 6702.36 | U31: =IFERROR(((K31-(R31/J31))/(R31/J31)),0) -> 0 | V31: =IFERROR(((K31-(R31/J31))/K31),0) -> 1 | Y31: OEM DISC %
G32: =ROUND(IF($F$17="USD $", F32*$E$15,F32*$D$15),2) -> 0 | H32: =ROUND(IF($H$17=$G$17,E32*G32,E32*F32),2) -> 0 | J32: =E32 -> 0 | K32: =IFERROR(IF(M32="OEM DISC %",ROUND(IF($K$17=$F$17,F32*(1-N32),G32*(1-N32)),2),IF(M32="MARKUP %",ROUND(R32/J32*(1+N32),2))),0) -> 0 | L32: =ROUND((J32*K32),2) -> 0 | M32: OEM DISC % | N32: 0.45 | R32: =ROUND(IF($R$17=$Q$17,Q32,IF($R$17="USD $",Q32*$D$15,Q32*$E$15))*E32,2) -> 0 | S32: =IFERROR(ROUND(T32/E32,2),0) -> 0 | T32: =ROUND(L32-R32,2) -> 0 | U32: =IFERROR(((K32-(R32/J32))/(R32/J32)),0) -> 0 | V32: =IFERROR(((K32-(R32/J32))/K32),0) -> 0 | Y32: MARKUP %
C33: TIRES 29.5r25 | D33: 5000 | E33: 6 | F33: 6671.97 | G33: =ROUND(IF($F$17="USD $", F33*$E$15,F33*$D$15),2) -> 9474.2 | H33: =ROUND(IF($H$17=$G$17,E33*G33,E33*F33),2) -> 56845.2 | J33: =E33 -> 6 | K33: =IFERROR(IF(M33="OEM DISC %",ROUND(IF($K$17=$F$17,F33*(1-N33),G33*(1-N33)),2),IF(M33="MARKUP %",ROUND(R33/J33*(1+N33),2))),0) -> 5210.81 | L33: =ROUND((J33*K33),2) -> 31264.86 | M33: OEM DISC % | N33: 0.45 | R33: =ROUND(IF($R$17=$Q$17,Q33,IF($R$17="USD $",Q33*$D$15,Q33*$E$15))*E33,2) -> 0 | S33: =IFERROR(ROUND(T33/E33,2),0) -> 5210.81 | T33: =ROUND(L33-R33,2) -> 31264.86 | U33: =IFERROR(((K33-(R33/J33))/(R33/J33)),0) -> 0 | V33: =IFERROR(((K33-(R33/J33))/K33),0) -> 1
G34: =ROUND(IF($F$17="USD $", F34*$E$15,F34*$D$15),2) -> 0 | H34: =ROUND(IF($H$17=$G$17,E34*G34,E34*F34),2) -> 0 | J34: =E34 -> 0 | K34: =IFERROR(IF(M34="OEM DISC %",ROUND(IF($K$17=$F$17,F34*(1-N34),G34*(1-N34)),2),IF(M34="MARKUP %",ROUND(R34/J34*(1+N34),2))),0) -> 0 | L34: =ROUND((J34*K34),2) -> 0 | M34: OEM DISC % | N34: 0.45 | R34: =ROUND(IF($R$17=$Q$17,Q34,IF($R$17="USD $",Q34*$D$15,Q34*$E$15))*E34,2) -> 0 | S34: =IFERROR(ROUND(T34/E34,2),0) -> 0 | T34: =ROUND(L34-R34,2) -> 0 | U34: =IFERROR(((K34-(R34/J34))/(R34/J34)),0) -> 0 | V34: =IFERROR(((K34-(R34/J34))/K34),0) -> 0
G35: =ROUND(IF($F$17="USD $", F35*$E$15,F35*$D$15),2) -> 0 | H35: =ROUND(IF($H$17=$G$17,E35*G35,E35*F35),2) -> 0 | J35: =E35 -> 0 | K35: =IFERROR(IF(M35="OEM DISC %",ROUND(IF($K$17=$F$17,F35*(1-N35),G35*(1-N35)),2),IF(M35="MARKUP %",ROUND(R35/J35*(1+N35),2))),0) -> 0 | L35: =ROUND((J35*K35),2) -> 0 | M35: OEM DISC % | N35: 0.45 | R35: =ROUND(IF($R$17=$Q$17,Q35,IF($R$17="USD $",Q35*$D$15,Q35*$E$15))*E35,2) -> 0 | S35: =IFERROR(ROUND(T35/E35,2),0) -> 0 | T35: =ROUND(L35-R35,2) -> 0 | U35: =IFERROR(((K35-(R35/J35))/(R35/J35)),0) -> 0 | V35: =IFERROR(((K35-(R35/J35))/K35),0) -> 0
G36: =ROUND(IF($F$17="USD $", F36*$E$15,F36*$D$15),2) -> 0 | H36: =ROUND(IF($H$17=$G$17,E36*G36,E36*F36),2) -> 0 | J36: =E36 -> 0 | K36: =IFERROR(IF(M36="OEM DISC %",ROUND(IF($K$17=$F$17,F36*(1-N36),G36*(1-N36)),2),IF(M36="MARKUP %",ROUND(R36/J36*(1+N36),2))),0) -> 0 | L36: =ROUND((J36*K36),2) -> 0 | M36: OEM DISC % | N36: 0.45 | R36: =ROUND(IF($R$17=$Q$17,Q36,IF($R$17="USD $",Q36*$D$15,Q36*$E$15))*E36,2) -> 0 | S36: =IFERROR(ROUND(T36/E36,2),0) -> 0 | T36: =ROUND(L36-R36,2) -> 0 | U36: =IFERROR(((K36-(R36/J36))/(R36/J36)),0) -> 0 | V36: =IFERROR(((K36-(R36/J36))/K36),0) -> 0
G37: =ROUND(IF($F$17="USD $", F37*$E$15,F37*$D$15),2) -> 0 | H37: =ROUND(IF($H$17=$G$17,E37*G37,E37*F37),2) -> 0 | J37: =E37 -> 0 | K37: =IFERROR(IF(M37="OEM DISC %",ROUND(IF($K$17=$F$17,F37*(1-N37),G37*(1-N37)),2),IF(M37="MARKUP %",ROUND(R37/J37*(1+N37),2))),0) -> 0 | L37: =ROUND((J37*K37),2) -> 0 | M37: OEM DISC % | N37: 0.45 | R37: =ROUND(IF($R$17=$Q$17,Q37,IF($R$17="USD $",Q37*$D$15,Q37*$E$15))*E37,2) -> 0 | S37: =IFERROR(ROUND(T37/E37,2),0) -> 0 | T37: =ROUND(L37-R37,2) -> 0 | U37: =IFERROR(((K37-(R37/J37))/(R37/J37)),0) -> 0 | V37: =IFERROR(((K37-(R37/J37))/K37),0) -> 0
G38: =ROUND(IF($F$17="USD $", F38*$E$15,F38*$D$15),2) -> 0 | H38: =ROUND(IF($H$17=$G$17,E38*G38,E38*F38),2) -> 0 | J38: =E38 -> 0 | K38: =IFERROR(IF(M38="OEM DISC %",ROUND(IF($K$17=$F$17,F38*(1-N38),G38*(1-N38)),2),IF(M38="MARKUP %",ROUND(R38/J38*(1+N38),2))),0) -> 0 | L38: =ROUND((J38*K38),2) -> 0 | M38: OEM DISC % | N38: 0.45 | R38: =ROUND(IF($R$17=$Q$17,Q38,IF($R$17="USD $",Q38*$D$15,Q38*$E$15))*E38,2) -> 0 | S38: =IFERROR(ROUND(T38/E38,2),0) -> 0 | T38: =ROUND(L38-R38,2) -> 0 | U38: =IFERROR(((K38-(R38/J38))/(R38/J38)),0) -> 0 | V38: =IFERROR(((K38-(R38/J38))/K38),0) -> 0
G39: =ROUND(IF($F$17="USD $", F39*$E$15,F39*$D$15),2) -> 0 | H39: =ROUND(IF($H$17=$G$17,E39*G39,E39*F39),2) -> 0 | J39: =E39 -> 0 | K39: =IFERROR(IF(M39="OEM DISC %",ROUND(IF($K$17=$F$17,F39*(1-N39),G39*(1-N39)),2),IF(M39="MARKUP %",ROUND(R39/J39*(1+N39),2))),0) -> 0 | L39: =ROUND((J39*K39),2) -> 0 | M39: OEM DISC % | N39: 0.45 | R39: =ROUND(IF($R$17=$Q$17,Q39,IF($R$17="USD $",Q39*$D$15,Q39*$E$15))*E39,2) -> 0 | S39: =IFERROR(ROUND(T39/E39,2),0) -> 0 | T39: =ROUND(L39-R39,2) -> 0 | U39: =IFERROR(((K39-(R39/J39))/(R39/J39)),0) -> 0 | V39: =IFERROR(((K39-(R39/J39))/K39),0) -> 0
G40: =ROUND(IF($F$17="USD $", F40*$E$15,F40*$D$15),2) -> 0 | H40: =ROUND(IF($H$17=$G$17,E40*G40,E40*F40),2) -> 0 | J40: =E40 -> 0 | K40: =IFERROR(IF(M40="OEM DISC %",ROUND(IF($K$17=$F$17,F40*(1-N40),G40*(1-N40)),2),IF(M40="MARKUP %",ROUND(R40/J40*(1+N40),2))),0) -> 0 | L40: =ROUND((J40*K40),2) -> 0 | M40: OEM DISC % | N40: 0.45 | R40: =ROUND(IF($R$17=$Q$17,Q40,IF($R$17="USD $",Q40*$D$15,Q40*$E$15))*E40,2) -> 0 | S40: =IFERROR(ROUND(T40/E40,2),0) -> 0 | T40: =ROUND(L40-R40,2) -> 0 | U40: =IFERROR(((K40-(R40/J40))/(R40/J40)),0) -> 0 | V40: =IFERROR(((K40-(R40/J40))/K40),0) -> 0
...

Sheet CAT 740 (3)
B1: CUSTOMER INFORMATION | D1: MACHINE INFORMATION | H1: MACHINE SERVICE HR INTERVALS | L1: SUMMARY | P1: =K17 -> CAD $ | S1: COMPLETED DEAL INFORMATION
B2: DATE: | D2: UNIT # | F2: AT-09 | H2: ENGINE AIR | L2: OEM MSRP | P2: =H49 -> 77837.91 | S2: SALES REP
B3: COMPANY: | D3: YEAR | F3: 2009 | H3: ENGINE OIL | L3: GQP LIST | P3: =L49 -> 42810.89 | S3: ORDER PO #
B4: CUSTOMER: | D4: MAKE | F4: CAT | H4: FUEL FILTERS | L4: $ SAVINGS | P4: =P2-P3 -> 35027.02 | S4: PROJECT #
B5: PHONE: | D5: MODEL | F5: 740 | H5: HYDRAULIC FILTERS | L5: % SAVINGS | P5: =IFERROR((P2-P3)/P2,"") -> 0.44999949 | S5: CUST INVOICE #
B6: EMAIL: | D6: SERIAL NUMBER | F6: B1P04865 | H6: TRANSMISSION FILTERS | L6: TOTAL ORDER MARGIN | P6: =T49 -> 42810.89 | S6: PAYMENT TYPE
B7: SALES REP: | D7: ENGINE SER NUMBER | F7: LHX22515 | H7: CAB FILTERS | L7: TOTAL ITEM COST | P7: =R49 -> 0 | S7: DATE DELIVERED
D8: CURRENT HOURS | H8: UNDERCARRIAGE / TIRES | L8: TOTAL ORDER FREIGHT | P8: =IF(P1=Q14,R14,IF(Q14="CAD $",R14*D15,IF(Q14="USD $",R14*E15,0))) -> 0 | S8: TOTAL COST | T8: NET MARGIN | U8: NET MARKUP % | V8: NET MARGIN %
D9: USAGE/MONTH | F9: Articulated Dump Truck | L9: TOTAL CUSTOMS/BROKERAGE | P9: =V14 -> 0 | S9: =P7+P8+P9 -> 0 | T9: =P3-S9 -> 42810.89 | U9: =IFERROR(((P3-S9)/S9),0) -> 0 | V9: =IFERROR(T9/P3,0) -> 1
L10: TOTAL NUMBER PIECES | P10: =E49 -> 24
D11: ENTER EXCHANGE RATES $ | F11: OEM MSRP | J11: CUSTOMER SELL PRICE | P11: COST ANALYSIS | Y11: CAD $
Y12: USD $
F13: SHOW OEM MSRP ON QUOTE: | H13: YES | Y13: YES
D14: CAD-USD | E14: USD-CAD | F14: OEM NAME | J14: CUSTOMER TYPE/TIER | L14: IE: VIP - Gold | P14: FREIGHT TOTAL ORDER | Q14: USD $ | S14: CUSTOMS AND BROKERAGE % | T14: 0.025 | U14: BROKERAGE FEES | V14: =ROUND(R49*T14,2) -> 0 | Y14: NO
D15: =1/E15 -> 0.70422535 | E15: 1.42 | P15: MARKUP LESS THAN 100% REQUIRES MANAGER APPROVAL
B16: PART NUMBER | C16: DESCRIPTION | D16: SERVICE INTERVAL | E16: QTY | F16: UNIT PRICE | H16: EXT AMOUNT | J16: QTY | K16: UNIT PRICE | L16: EXTENDED AMOUNT | M16: PRCING METHOD %OEM / MARKUP | N16: OEM DISC % / MARKUP % | P16: VENDOR | Q16: COST EACH | R16: EXTENDED COST | S16: MARGIN EACH | T16: EXTENDED MARGIN | U16: MARKUP % | V16: MARGIN %
F17: USD $ | G17: =IF(F17="USD $", "CAD $", "USD $") -> CAD $ | H17: =K17 -> CAD $ | K17: CAD $ | Q17: USD $ | R17: =K17 -> CAD $
B18: 1R-0716 | C18: ENGINE OIL FILTER | D18: 250 | E18: 1 | F18: 33.88 | G18: =ROUND(IF($F$17="USD $", F18*$E$15,F18*$D$15),2) -> 48.11 | H18: =ROUND(IF($H$17=$G$17,E18*G18,E18*F18),2) -> 48.11 | J18: =E18 -> 1 | K18: =IFERROR(IF(M18="OEM DISC %",ROUND(IF($K$17=$F$17,F18*(1-N18),G18*(1-N18)),2),IF(M18="MARKUP %",ROUND(R18/J18*(1+N18),2))),0) -> 26.46 | L18: =ROUND((J18*K18),2) -> 26.46 | M18: OEM DISC % | N18: 0.45 | R18: =ROUND(IF($R$17=$Q$17,Q18,IF($R$17="USD $",Q18*$D$15,Q18*$E$15))*E18,2) -> 0 | S18: =IFERROR(ROUND(T18/E18,2),0) -> 26.46 | T18: =ROUND(L18-R18,2) -> 26.46 | U18: =IFERROR(((K18-(R18/J18))/(R18/J18)),0) -> 0 | V18: =IFERROR(((K18-(R18/J18))/K18),0) -> 1 | Z18: 250
B19: 1R-0762 | C19: FUEL FILTER | D19: 250 | E19: 1 | F19: 45.86 | G19: =ROUND(IF($F$17="USD $", F19*$E$15,F19*$D$15),2) -> 65.12 | H19: =ROUND(IF($H$17=$G$17,E19*G19,E19*F19),2) -> 65.12 | J19: =E19 -> 1 | K19: =IFERROR(IF(M19="OEM DISC %",ROUND(IF($K$17=$F$17,F19*(1-N19),G19*(1-N19)),2),IF(M19="MARKUP %",ROUND(R19/J19*(1+N19),2))),0) -> 35.82 | L19: =ROUND((J19*K19),2) -> 35.82 | M19: OEM DISC % | N19: 0.45 | R19: =ROUND(IF($R$17=$Q$17,Q19,IF($R$17="USD $",Q19*$D$15,Q19*$E$15))*E19,2) -> 0 | S19: =IFERROR(ROUND(T19/E19,2),0) -> 35.82 | T19: =ROUND(L19-R19,2) -> 35.82 | U19: =IFERROR(((K19-(R19/J19))/(R19/J19)),0) -> 0 | V19: =IFERROR(((K19-(R19/J19))/K19),0) -> 1 | Y19: GQP | Z19: 500
B20: 326-1644 | C20: FUEL WATER SEPARATOR FILTER | D20: 500 | E20: 1 | F20: 58.2 | G20: =ROUND(IF($F$17="USD $", F20*$E$15,F20*$D$15),2) -> 82.64 | H20: =ROUND(IF($H$17=$G$17,E20*G20,E20*F20),2) -> 82.64 | J20: =E20 -> 1 | K20: =IFERROR(IF(M20="OEM DISC %",ROUND(IF($K$17=$F$17,F20*(1-N20),G20*(1-N20)),2),IF(M20="MARKUP %",ROUND(R20/J20*(1+N20),2))),0) -> 45.45 | L20: =ROUND((J20*K20),2) -> 45.45 | M20: OEM DISC % | N20: 0.45 | R20: =ROUND(IF($R$17=$Q$17,Q20,IF($R$17="USD $",Q20*$D$15,Q20*$E$15))*E20,2) -> 0 | S20: =IFERROR(ROUND(T20/E20,2),0) -> 45.45 | T20: =ROUND(L20-R20,2) -> 45.45 | U20: =IFERROR(((K20-(R20/J20))/(R20/J20)),0) -> 0 | V20: =IFERROR(((K20-(R20/J20))/K20),0) -> 1 | Y20: CTP | Z20: 750
B21: 1R-0719 | C21: TRANSMISSION FILTER | D21: 500 | E21: 1 | F21: 26.06 | G21: =ROUND(IF($F$17="USD $", F21*$E$15,F21*$D$15),2) -> 37.01 | H21: =ROUND(IF($H$17=$G$17,E21*G21,E21*F21),2) -> 37.01 | J21: =E21 -> 1 | K21: =IFERROR(IF(M21="OEM DISC %",ROUND(IF($K$17=$F$17,F21*(1-N21),G21*(1-N21)),2),IF(M21="MARKUP %",ROUND(R21/J21*(1+N21),2))),0) -> 20.36 | L21: =ROUND((J21*K21),2) -> 20.36 | M21: OEM DISC % | N21: 0.45 | R21: =ROUND(IF($R$17=$Q$17,Q21,IF($R$17="USD $",Q21*$D$15,Q21*$E$15))*E21,2) -> 0 | S21: =IFERROR(ROUND(T21/E21,2),0) -> 20.36 | T21: =ROUND(L21-R21,2) -> 20.36 | U21: =IFERROR(((K21-(R21/J21))/(R21/J21)),0) -> 0 | V21: =IFERROR(((K21-(R21/J21))/K21),0) -> 1 | Y21: BLMQ | Z21: 1000
B22: 1G-8878 | C22: HYDRAULIC FILTER | D22: 500 | E22: 1 | F22: 102.31 | G22: =ROUND(IF($F$17="USD $", F22*$E$15,F22*$D$15),2) -> 145.28 | H22: =ROUND(IF($H$17=$G$17,E22*G22,E22*F22),2) -> 145.28 | J22: =E22 -> 1 | K22: =IFERROR(IF(M22="OEM DISC %",ROUND(IF($K$17=$F$17,F22*(1-N22),G22*(1-N22)),2),IF(M22="MARKUP %",ROUND(R22/J22*(1+N22),2))),0) -> 79.9 | L22: =ROUND((J22*K22),2) -> 79.9 | M22: OEM DISC % | N22: 0.45 | R22: =ROUND(IF($R$17=$Q$17,Q22,IF($R$17="USD $",Q22*$D$15,Q22*$E$15))*E22,2) -> 0 | S22: =IFERROR(ROUND(T22/E22,2),0) -> 79.9 | T22: =ROUND(L22-R22,2) -> 79.9 | U22: =IFERROR(((K22-(R22/J22))/(R22/J22)),0) -> 0 | V22: =IFERROR(((K22-(R22/J22))/K22),0) -> 1 | Y22: CAT | Z22: 1200
B23: 142-1340 | C23: PRIMARY AIR FILTER | D23: 500 | E23: 1 | F23: 178.61 | G23: =ROUND(IF($F$17="USD $", F23*$E$15,F23*$D$15),2) -> 253.63 | H23: =ROUND(IF($H$17=$G$17,E23*G23,E23*F23),2) -> 253.63 | J23: =E23 -> 1 | K23: =IFERROR(IF(M23="OEM DISC %",ROUND(IF($K$17=$F$17,F23*(1-N23),G23*(1-N23)),2),IF(M23="MARKUP %",ROUND(R23/J23*(1+N23),2))),0) -> 139.5 | L23: =ROUND((J23*K23),2) -> 139.5 | M23: OEM DISC % | N23: 0.45 | R23: =ROUND(IF($R$17=$Q$17,Q23,IF($R$17="USD $",Q23*$D$15,Q23*$E$15))*E23,2) -> 0 | S23: =IFERROR(ROUND(T23/E23,2),0) -> 139.5 | T23: =ROUND(L23-R23,2) -> 139.5 | U23: =IFERROR(((K23-(R23/J23))/(R23/J23)),0) -> 0 | V23: =IFERROR(((K23-(R23/J23))/K23),0) -> 1 | Y23: FINNING | Z23: 2000
B24: 142-1403 | C24: SECONDARY AIR FILTER | D24: 250 | E24: 1 | F24: 99.07 | G24: =ROUND(IF($F$17="USD $", F24*$E$15,F24*$D$15),2) -> 140.68 | H24: =ROUND(IF($H$17=$G$17,E24*G24,E24*F24),2) -> 140.68 | J24: =E24 -> 1 | K24: =IFERROR(IF(M24="OEM DISC %",ROUND(IF($K$17=$F$17,F24*(1-N24),G24*(1-N24)),2),IF(M24="MARKUP %",ROUND(R24/J24*(1+N24),2))),0) -> 77.37 | L24: =ROUND((J24*K24),2) -> 77.37 | M24: OEM DISC % | N24: 0.45 | R24: =ROUND(IF($R$17=$Q$17,Q24,IF($R$17="USD $",Q24*$D$15,Q24*$E$15))*E24,2) -> 0 | S24: =IFERROR(ROUND(T24/E24,2),0) -> 77.37 | T24: =ROUND(L24-R24,2) -> 77.37 | U24: =IFERROR(((K24-(R24/J24))/(R24/J24)),0) -> 0 | V24: =IFERROR(((K24-(R24/J24))/K24),0) -> 1 | Y24: JD | Z24: 4000
B25: 268-6704 | C25: CABIN AIR FILTER | D25: 250 | E25: 1 | F25: 86.44 | G25: =ROUND(IF($F$17="USD $", F25*$E$15,F25*$D$15),2) -> 122.74 | H25: =ROUND(IF($H$17=$G$17,E25*G25,E25*F25),2) -> 122.74 | J25: =E25 -> 1 | K25: =IFERROR(IF(M25="OEM DISC %",ROUND(IF($K$17=$F$17,F25*(1-N25),G25*(1-N25)),2),IF(M25="MARKUP %",ROUND(R25/J25*(1+N25),2))),0) -> 67.51 | L25: =ROUND((J25*K25),2) -> 67.51 | M25: OEM DISC % | N25: 0.45 | R25: =ROUND(IF($R$17=$Q$17,Q25,IF($R$17="USD $",Q25*$D$15,Q25*$E$15))*E25,2) -> 0 | S25: =IFERROR(ROUND(T25/E25,2),0) -> 67.51 | T25: =ROUND(L25-R25,2) -> 67.51 | U25: =IFERROR(((K25-(R25/J25))/(R25/J25)),0) -> 0 | V25: =IFERROR(((K25-(R25/J25))/K25),0) -> 1 | Y25: BRANDT | Z25: 6000
G26: =ROUND(IF($F$17="USD $", F26*$E$15,F26*$D$15),2) -> 0 | H26: =ROUND(IF($H$17=$G$17,E26*G26,E26*F26),2) -> 0 | J26: =E26 -> 0 | K26: =IFERROR(IF(M26="OEM DISC %",ROUND(IF($K$17=$F$17,F26*(1-N26),G26*(1-N26)),2),IF(M26="MARKUP %",ROUND(R26/J26*(1+N26),2))),0) -> 0 | L26: =ROUND((J26*K26),2) -> 0 | M26: OEM DISC % | N26: 0.45 | R26: =ROUND(IF($R$17=$Q$17,Q26,IF($R$17="USD $",Q26*$D$15,Q26*$E$15))*E26,2) -> 0 | S26: =IFERROR(ROUND(T26/E26,2),0) -> 0 | T26: =ROUND(L26-R26,2) -> 0 | U26: =IFERROR(((K26-(R26/J26))/(R26/J26)),0) -> 0 | V26: =IFERROR(((K26-(R26/J26))/K26),0) -> 0 | Y26: PTI | Z26: 8000
B27: 447-1525 | C27: ENGINE OVERHAUL KIT SILVER | D27: 10000 | E27: 1 | G27: =ROUND(IF($F$17="USD $", F27*$E$15,F27*$D$15),2) -> 0 | H27: =ROUND(IF($H$17=$G$17,E27*G27,E27*F27),2) -> 0 | J27: =E27 -> 1 | K27: =IFERROR(IF(M27="OEM DISC %",ROUND(IF($K$17=$F$17,F27*(1-N27),G27*(1-N27)),2),IF(M27="MARKUP %",ROUND(R27/J27*(1+N27),2))),0) -> 0 | L27: =ROUND((J27*K27),2) -> 0 | M27: OEM DISC % | N27: 0.45 | R27: =ROUND(IF($R$17=$Q$17,Q27,IF($R$17="USD $",Q27*$D$15,Q27*$E$15))*E27,2) -> 0 | S27: =IFERROR(ROUND(T27/E27,2),0) -> 0 | T27: =ROUND(L27-R27,2) -> 0 | U27: =IFERROR(((K27-(R27/J27))/(R27/J27)),0) -> 0 | V27: =IFERROR(((K27-(R27/J27))/K27),0) -> 0 | Y27: CONEQUIP | Z27: 10000
C28: SEAT GP-SUSPENSION | G28: =ROUND(IF($F$17="USD $", F28*$E$15,F28*$D$15),2) -> 0 | H28: =ROUND(IF($H$17=$G$17,E28*G28,E28*F28),2) -> 0 | J28: =E28 -> 0 | K28: =IFERROR(IF(M28="OEM DISC %",ROUND(IF($K$17=$F$17,F28*(1-N28),G28*(1-N28)),2),IF(M28="MARKUP %",ROUND(R28/J28*(1+N28),2))),0) -> 0 | L28: =ROUND((J28*K28),2) -> 0 | M28: OEM DISC % | N28: 0.45 | R28: =ROUND(IF($R$17=$Q$17,Q28,IF($R$17="USD $",Q28*$D$15,Q28*$E$15))*E28,2) -> 0 | S28: =IFERROR(ROUND(T28/E28,2),0) -> 0 | T28: =ROUND(L28-R28,2) -> 0 | U28: =IFERROR(((K28-(R28/J28))/(R28/J28)),0) -> 0 | V28: =IFERROR(((K28-(R28/J28))/K28),0) -> 0 | Y28: CANDY | Z28: AS REQ'D
B29: 153-5700 | C29: BATTERY | D29: AS REQ'D | E29: 2 | F29: 493.89 | G29: =ROUND(IF($F$17="USD $", F29*$E$15,F29*$D$15),2) -> 701.32 | H29: =ROUND(IF($H$17=$G$17,E29*G29,E29*F29),2) -> 1402.64 | J29: =E29 -> 2 | K29: =IFERROR(IF(M29="OEM DISC %",ROUND(IF($K$17=$F$17,F29*(1-N29),G29*(1-N29)),2),IF(M29="MARKUP %",ROUND(R29/J29*(1+N29),2))),0) -> 385.73 | L29: =ROUND((J29*K29),2) -> 771.46 | M29: OEM DISC % | N29: 0.45 | R29: =ROUND(IF($R$17=$Q$17,Q29,IF($R$17="USD $",Q29*$D$15,Q29*$E$15))*E29,2) -> 0 | S29: =IFERROR(ROUND(T29/E29,2),0) -> 385.73 | T29: =ROUND(L29-R29,2) -> 771.46 | U29: =IFERROR(((K29-(R29/J29))/(R29/J29)),0) -> 0 | V29: =IFERROR(((K29-(R29/J29))/K29),0) -> 1 | Y29: U/C
B30: 230-3542 | C30: TURBOCHARGER | D30: 6000 | E30: 1 | F30: 4583.66 | G30: =ROUND(IF($F$17="USD $", F30*$E$15,F30*$D$15),2) -> 6508.8 | H30: =ROUND(IF($H$17=$G$17,E30*G30,E30*F30),2) -> 6508.8 | J30: =E30 -> 1 | K30: =IFERROR(IF(M30="OEM DISC %",ROUND(IF($K$17=$F$17,F30*(1-N30),G30*(1-N30)),2),IF(M30="MARKUP %",ROUND(R30/J30*(1+N30),2))),0) -> 3579.84 | L30: =ROUND((J30*K30),2) -> 3579.84 | M30: OEM DISC % | N30: 0.45 | R30: =ROUND(IF($R$17=$Q$17,Q30,IF($R$17="USD $",Q30*$D$15,Q30*$E$15))*E30,2) -> 0 | S30: =IFERROR(ROUND(T30/E30,2),0) -> 3579.84 | T30: =ROUND(L30-R30,2) -> 3579.84 | U30: =IFERROR(((K30-(R30/J30))/(R30/J30)),0) -> 0 | V30: =IFERROR(((K30-(R30/J30))/K30),0) -> 1
B31: 647-0750 | C31: INJECTOR | D31: 6000 | E31: 6 | F31: 1430.29 | G31: =ROUND(IF($F$17="USD $", F31*$E$15,F31*$D$15),2) -> 2031.01 | H31: =ROUND(IF($H$17=$G$17,E31*G31,E31*F31),2) -> 12186.06 | J31: =E31 -> 6 | K31: =IFERROR(IF(M31="OEM DISC %",ROUND(IF($K$17=$F$17,F31*(1-N31),G31*(1-N31)),2),IF(M31="MARKUP %",ROUND(R31/J31*(1+N31),2))),0) -> 1117.06 | L31: =ROUND((J31*K31),2) -> 6702.36 | M31: OEM DISC % | N31: 0.45 | R31: =ROUND(IF($R$17=$Q$17,Q31,IF($R$17="USD $",Q31*$D$15,Q31*$E$15))*E31,2) -> 0 | S31: =IFERROR(ROUND(T31/E31,2),0) -> 1117.06 | T31: =ROUND(L31-R31,2) -> 6702.36 | U31: =IFERROR(((K31-(R31/J31))/(R31/J31)),0) -> 0 | V31: =IFERROR(((K31-(R31/J31))/K31),0) -> 1 | Y31: OEM DISC %
G32: =ROUND(IF($F$17="USD $", F32*$E$15,F32*$D$15),2) -> 0 | H32: =ROUND(IF($H$17=$G$17,E32*G32,E32*F32),2) -> 0 | J32: =E32 -> 0 | K32: =IFERROR(IF(M32="OEM DISC %",ROUND(IF($K$17=$F$17,F32*(1-N32),G32*(1-N32)),2),IF(M32="MARKUP %",ROUND(R32/J32*(1+N32),2))),0) -> 0 | L32: =ROUND((J32*K32),2) -> 0 | M32: OEM DISC % | N32: 0.45 | R32: =ROUND(IF($R$17=$Q$17,Q32,IF($R$17="USD $",Q32*$D$15,Q32*$E$15))*E32,2) -> 0 | S32: =IFERROR(ROUND(T32/E32,2),0) -> 0 | T32: =ROUND(L32-R32,2) -> 0 | U32: =IFERROR(((K32-(R32/J32))/(R32/J32)),0) -> 0 | V32: =IFERROR(((K32-(R32/J32))/K32),0) -> 0 | Y32: MARKUP %
C33: TIRES 29.5r25 | D33: 5000 | E33: 6 | F33: 6671.97 | G33: =ROUND(IF($F$17="USD $", F33*$E$15,F33*$D$15),2) -> 9474.2 | H33: =ROUND(IF($H$17=$G$17,E33*G33,E33*F33),2) -> 56845.2 | J33: =E33 -> 6 | K33: =IFERROR(IF(M33="OEM DISC %",ROUND(IF($K$17=$F$17,F33*(1-N33),G33*(1-N33)),2),IF(M33="MARKUP %",ROUND(R33/J33*(1+N33),2))),0) -> 5210.81 | L33: =ROUND((J33*K33),2) -> 31264.86 | M33: OEM DISC % | N33: 0.45 | R33: =ROUND(IF($R$17=$Q$17,Q33,IF($R$17="USD $",Q33*$D$15,Q33*$E$15))*E33,2) -> 0 | S33: =IFERROR(ROUND(T33/E33,2),0) -> 5210.81 | T33: =ROUND(L33-R33,2) -> 31264.86 | U33: =IFERROR(((K33-(R33/J33))/(R33/J33)),0) -> 0 | V33: =IFERROR(((K33-(R33/J33))/K33),0) -> 1
G34: =ROUND(IF($F$17="USD $", F34*$E$15,F34*$D$15),2) -> 0 | H34: =ROUND(IF($H$17=$G$17,E34*G34,E34*F34),2) -> 0 | J34: =E34 -> 0 | K34: =IFERROR(IF(M34="OEM DISC %",ROUND(IF($K$17=$F$17,F34*(1-N34),G34*(1-N34)),2),IF(M34="MARKUP %",ROUND(R34/J34*(1+N34),2))),0) -> 0 | L34: =ROUND((J34*K34),2) -> 0 | M34: OEM DISC % | N34: 0.45 | R34: =ROUND(IF($R$17=$Q$17,Q34,IF($R$17="USD $",Q34*$D$15,Q34*$E$15))*E34,2) -> 0 | S34: =IFERROR(ROUND(T34/E34,2),0) -> 0 | T34: =ROUND(L34-R34,2) -> 0 | U34: =IFERROR(((K34-(R34/J34))/(R34/J34)),0) -> 0 | V34: =IFERROR(((K34-(R34/J34))/K34),0) -> 0
G35: =ROUND(IF($F$17="USD $", F35*$E$15,F35*$D$15),2) -> 0 | H35: =ROUND(IF($H$17=$G$17,E35*G35,E35*F35),2) -> 0 | J35: =E35 -> 0 | K35: =IFERROR(IF(M35="OEM DISC %",ROUND(IF($K$17=$F$17,F35*(1-N35),G35*(1-N35)),2),IF(M35="MARKUP %",ROUND(R35/J35*(1+N35),2))),0) -> 0 | L35: =ROUND((J35*K35),2) -> 0 | M35: OEM DISC % | N35: 0.45 | R35: =ROUND(IF($R$17=$Q$17,Q35,IF($R$17="USD $",Q35*$D$15,Q35*$E$15))*E35,2) -> 0 | S35: =IFERROR(ROUND(T35/E35,2),0) -> 0 | T35: =ROUND(L35-R35,2) -> 0 | U35: =IFERROR(((K35-(R35/J35))/(R35/J35)),0) -> 0 | V35: =IFERROR(((K35-(R35/J35))/K35),0) -> 0
G36: =ROUND(IF($F$17="USD $", F36*$E$15,F36*$D$15),2) -> 0 | H36: =ROUND(IF($H$17=$G$17,E36*G36,E36*F36),2) -> 0 | J36: =E36 -> 0 | K36: =IFERROR(IF(M36="OEM DISC %",ROUND(IF($K$17=$F$17,F36*(1-N36),G36*(1-N36)),2),IF(M36="MARKUP %",ROUND(R36/J36*(1+N36),2))),0) -> 0 | L36: =ROUND((J36*K36),2) -> 0 | M36: OEM DISC % | N36: 0.45 | R36: =ROUND(IF($R$17=$Q$17,Q36,IF($R$17="USD $",Q36*$D$15,Q36*$E$15))*E36,2) -> 0 | S36: =IFERROR(ROUND(T36/E36,2),0) -> 0 | T36: =ROUND(L36-R36,2) -> 0 | U36: =IFERROR(((K36-(R36/J36))/(R36/J36)),0) -> 0 | V36: =IFERROR(((K36-(R36/J36))/K36),0) -> 0
G37: =ROUND(IF($F$17="USD $", F37*$E$15,F37*$D$15),2) -> 0 | H37: =ROUND(IF($H$17=$G$17,E37*G37,E37*F37),2) -> 0 | J37: =E37 -> 0 | K37: =IFERROR(IF(M37="OEM DISC %",ROUND(IF($K$17=$F$17,F37*(1-N37),G37*(1-N37)),2),IF(M37="MARKUP %",ROUND(R37/J37*(1+N37),2))),0) -> 0 | L37: =ROUND((J37*K37),2) -> 0 | M37: OEM DISC % | N37: 0.45 | R37: =ROUND(IF($R$17=$Q$17,Q37,IF($R$17="USD $",Q37*$D$15,Q37*$E$15))*E37,2) -> 0 | S37: =IFERROR(ROUND(T37/E37,2),0) -> 0 | T37: =ROUND(L37-R37,2) -> 0 | U37: =IFERROR(((K37-(R37/J37))/(R37/J37)),0) -> 0 | V37: =IFERROR(((K37-(R37/J37))/K37),0) -> 0
G38: =ROUND(IF($F$17="USD $", F38*$E$15,F38*$D$15),2) -> 0 | H38: =ROUND(IF($H$17=$G$17,E38*G38,E38*F38),2) -> 0 | J38: =E38 -> 0 | K38: =IFERROR(IF(M38="OEM DISC %",ROUND(IF($K$17=$F$17,F38*(1-N38),G38*(1-N38)),2),IF(M38="MARKUP %",ROUND(R38/J38*(1+N38),2))),0) -> 0 | L38: =ROUND((J38*K38),2) -> 0 | M38: OEM DISC % | N38: 0.45 | R38: =ROUND(IF($R$17=$Q$17,Q38,IF($R$17="USD $",Q38*$D$15,Q38*$E$15))*E38,2) -> 0 | S38: =IFERROR(ROUND(T38/E38,2),0) -> 0 | T38: =ROUND(L38-R38,2) -> 0 | U38: =IFERROR(((K38-(R38/J38))/(R38/J38)),0) -> 0 | V38: =IFERROR(((K38-(R38/J38))/K38),0) -> 0
G39: =ROUND(IF($F$17="USD $", F39*$E$15,F39*$D$15),2) -> 0 | H39: =ROUND(IF($H$17=$G$17,E39*G39,E39*F39),2) -> 0 | J39: =E39 -> 0 | K39: =IFERROR(IF(M39="OEM DISC %",ROUND(IF($K$17=$F$17,F39*(1-N39),G39*(1-N39)),2),IF(M39="MARKUP %",ROUND(R39/J39*(1+N39),2))),0) -> 0 | L39: =ROUND((J39*K39),2) -> 0 | M39: OEM DISC % | N39: 0.45 | R39: =ROUND(IF($R$17=$Q$17,Q39,IF($R$17="USD $",Q39*$D$15,Q39*$E$15))*E39,2) -> 0 | S39: =IFERROR(ROUND(T39/E39,2),0) -> 0 | T39: =ROUND(L39-R39,2) -> 0 | U39: =IFERROR(((K39-(R39/J39))/(R39/J39)),0) -> 0 | V39: =IFERROR(((K39-(R39/J39))/K39),0) -> 0
G40: =ROUND(IF($F$17="USD $", F40*$E$15,F40*$D$15),2) -> 0 | H40: =ROUND(IF($H$17=$G$17,E40*G40,E40*F40),2) -> 0 | J40: =E40 -> 0 | K40: =IFERROR(IF(M40="OEM DISC %",ROUND(IF($K$17=$F$17,F40*(1-N40),G40*(1-N40)),2),IF(M40="MARKUP %",ROUND(R40/J40*(1+N40),2))),0) -> 0 | L40: =ROUND((J40*K40),2) -> 0 | M40: OEM DISC % | N40: 0.45 | R40: =ROUND(IF($R$17=$Q$17,Q40,IF($R$17="USD $",Q40*$D$15,Q40*$E$15))*E40,2) -> 0 | S40: =IFERROR(ROUND(T40/E40,2),0) -> 0 | T40: =ROUND(L40-R40,2) -> 0 | U40: =IFERROR(((K40-(R40/J40))/(R40/J40)),0) -> 0 | V40: =IFERROR(((K40-(R40/J40))/K40),0) -> 0
...

Sheet CAT 422E
B1: CUSTOMER INFORMATION | D1: MACHINE INFORMATION | H1: MACHINE SERVICE HR INTERVALS | L1: SUMMARY | P1: =K17 -> CAD $ | S1: COMPLETED DEAL INFORMATION
B2: DATE: | D2: UNIT # | F2: BH-07 | H2: ENGINE AIR | L2: OEM MSRP | P2: =H49 -> #REF! | S2: SALES REP
B3: COMPANY: | D3: YEAR | F3: 2012 | H3: ENGINE OIL | L3: GQP LIST | P3: =L49 -> #REF! | S3: ORDER PO #
B4: CUSTOMER: | D4: MAKE | F4: CAT | H4: FUEL FILTERS | L4: $ SAVINGS | P4: =P2-P3 -> #REF! | S4: PROJECT #
B5: PHONE: | D5: MODEL | F5: 422E | H5: HYDRAULIC FILTERS | L5: % SAVINGS | P5: =IFERROR((P2-P3)/P2,"") | S5: CUST INVOICE #
B6: EMAIL: | D6: SERIAL NUMBER | F6: MAW01556 | H6: TRANSMISSION FILTERS | L6: TOTAL ORDER MARGIN | P6: =T49 -> #REF! | S6: PAYMENT TYPE
B7: SALES REP: | D7: ENGINE SER NUMBER | F7: CRS67419 | H7: CAB FILTERS | L7: TOTAL ITEM COST | P7: =R49 -> #REF! | S7: DATE DELIVERED
D8: CURRENT HOURS | H8: UNDERCARRIAGE / TIRES | L8: TOTAL ORDER FREIGHT | P8: =IF(P1=Q14,R14,IF(Q14="CAD $",R14*D15,IF(Q14="USD $",R14*E15,0))) -> 0 | S8: TOTAL COST | T8: NET MARGIN | U8: NET MARKUP % | V8: NET MARGIN %
D9: USAGE/MONTH | F9: Backhoe Loader | L9: TOTAL CUSTOMS/BROKERAGE | P9: =V14 -> #REF! | S9: =P7+P8+P9 -> #REF! | T9: =P3-S9 -> #REF! | U9: =IFERROR(((P3-S9)/S9),0) -> 0 | V9: =IFERROR(T9/P3,0) -> 0
L10: TOTAL NUMBER PIECES | P10: =E49 -> 86
D11: ENTER EXCHANGE RATES $ | F11: OEM MSRP | J11: CUSTOMER SELL PRICE | P11: COST ANALYSIS | Y11: CAD $
Y12: USD $
F13: SHOW OEM MSRP ON QUOTE: | H13: YES | Y13: YES
D14: CAD-USD | E14: USD-CAD | F14: OEM NAME | J14: CUSTOMER TYPE/TIER | L14: IE: VIP - Gold | P14: FREIGHT TOTAL ORDER | Q14: USD $ | S14: CUSTOMS AND BROKERAGE % | T14: 0.025 | U14: BROKERAGE FEES | V14: =ROUND(R49*T14,2) -> #REF! | Y14: NO
D15: =1/E15 -> 0.70422535 | E15: 1.42 | P15: MARKUP LESS THAN 100% REQUIRES MANAGER APPROVAL
B16: PART NUMBER | C16: DESCRIPTION | D16: SERVICE INTERVAL | E16: QTY | F16: UNIT PRICE | H16: EXT AMOUNT | J16: QTY | K16: UNIT PRICE | L16: EXTENDED AMOUNT | M16: PRCING METHOD %OEM / MARKUP | N16: OEM DISC % / MARKUP % | P16: VENDOR | Q16: COST EACH | R16: EXTENDED COST | S16: MARGIN EACH | T16: EXTENDED MARGIN | U16: MARKUP % | V16: MARGIN %
F17: USD $ | G17: =IF(F17="USD $", "CAD $", "USD $") -> CAD $ | H17: =K17 -> CAD $ | K17: CAD $ | Q17: USD $ | R17: =K17 -> CAD $
B18: 7W-2326 | C18: ENGINE OIL FILTER | D18: 250 | E18: 1 | F18: 20.98 | G18: =ROUND(IF($F$17="USD $", F18*$E$15,F18*$D$15),2) -> 29.79 | H18: =ROUND(IF($H$17=$G$17,E18*G18,E18*F18),2) -> 29.79 | J18: =E18 -> 1 | K18: =IFERROR(IF(M18="OEM DISC %",ROUND(IF($K$17=$F$17,F18*(1-N18),G18*(1-N18)),2),IF(M18="MARKUP %",ROUND(R18/J18*(1+N18),2))),0) -> 16.38 | L18: =ROUND((J18*K18),2) -> 16.38 | M18: OEM DISC % | N18: 0.45 | R18: =ROUND(IF($R$17=$Q$17,Q18,IF($R$17="USD $",Q18*$D$15,Q18*$E$15))*E18,2) -> 0 | S18: =IFERROR(ROUND(T18/E18,2),0) -> 16.38 | T18: =ROUND(L18-R18,2) -> 16.38 | U18: =IFERROR(((K18-(R18/J18))/(R18/J18)),0) -> 0 | V18: =IFERROR(((K18-(R18/J18))/K18),0) -> 1 | Z18: 250
C19: FUEL FILTER | G19: =ROUND(IF($F$17="USD $", F19*$E$15,F19*$D$15),2) -> 0 | H19: =ROUND(IF($H$17=$G$17,E19*G19,E19*F19),2) -> 0 | J19: =E19 -> 0 | K19: =IFERROR(IF(M19="OEM DISC %",ROUND(IF($K$17=$F$17,F19*(1-N19),G19*(1-N19)),2),IF(M19="MARKUP %",ROUND(R19/J19*(1+N19),2))),0) -> 0 | L19: =ROUND((J19*K19),2) -> 0 | M19: OEM DISC % | N19: 0.45 | R19: =ROUND(IF($R$17=$Q$17,Q19,IF($R$17="USD $",Q19*$D$15,Q19*$E$15))*E19,2) -> 0 | S19: =IFERROR(ROUND(T19/E19,2),0) -> 0 | T19: =ROUND(L19-R19,2) -> 0 | U19: =IFERROR(((K19-(R19/J19))/(R19/J19)),0) -> 0 | V19: =IFERROR(((K19-(R19/J19))/K19),0) -> 0 | Y19: GQP | Z19: 500
B20: 228-9130 | C20: FUEL WATER SEPARATOR FILTER | D20: 250 | E20: 1 | F20: 46.86 | G20: =ROUND(IF($F$17="USD $", F20*$E$15,F20*$D$15),2) -> 66.54 | H20: =ROUND(IF($H$17=$G$17,E20*G20,E20*F20),2) -> 66.54 | J20: =E20 -> 1 | K20: =IFERROR(IF(M20="OEM DISC %",ROUND(IF($K$17=$F$17,F20*(1-N20),G20*(1-N20)),2),IF(M20="MARKUP %",ROUND(R20/J20*(1+N20),2))),0) -> 36.6 | L20: =ROUND((J20*K20),2) -> 36.6 | M20: OEM DISC % | N20: 0.45 | R20: =ROUND(IF($R$17=$Q$17,Q20,IF($R$17="USD $",Q20*$D$15,Q20*$E$15))*E20,2) -> 0 | S20: =IFERROR(ROUND(T20/E20,2),0) -> 36.6 | T20: =ROUND(L20-R20,2) -> 36.6 | U20: =IFERROR(((K20-(R20/J20))/(R20/J20)),0) -> 0 | V20: =IFERROR(((K20-(R20/J20))/K20),0) -> 1 | Y20: CTP | Z20: 750
C21: TRANSMISSION FILTER | G21: =ROUND(IF($F$17="USD $", F21*$E$15,F21*$D$15),2) -> 0 | H21: =ROUND(IF($H$17=$G$17,E21*G21,E21*F21),2) -> 0 | J21: =E21 -> 0 | K21: =IFERROR(IF(M21="OEM DISC %",ROUND(IF($K$17=$F$17,F21*(1-N21),G21*(1-N21)),2),IF(M21="MARKUP %",ROUND(R21/J21*(1+N21),2))),0) -> 0 | L21: =ROUND((J21*K21),2) -> 0 | M21: OEM DISC % | N21: 0.45 | R21: =ROUND(IF($R$17=$Q$17,Q21,IF($R$17="USD $",Q21*$D$15,Q21*$E$15))*E21,2) -> 0 | S21: =IFERROR(ROUND(T21/E21,2),0) -> 0 | T21: =ROUND(L21-R21,2) -> 0 | U21: =IFERROR(((K21-(R21/J21))/(R21/J21)),0) -> 0 | V21: =IFERROR(((K21-(R21/J21))/K21),0) -> 0 | Y21: BLMQ | Z21: 1000
B22: 119-4740 | C22: HYDRAULIC FILTER | D22: 500 | E22: 1 | G22: =ROUND(IF($F$17="USD $", F22*$E$15,F22*$D$15),2) -> 0 | H22: =ROUND(IF($H$17=$G$17,E22*G22,E22*F22),2) -> 0 | J22: =E22 -> 1 | K22: =IFERROR(IF(M22="OEM DISC %",ROUND(IF($K$17=$F$17,F22*(1-N22),G22*(1-N22)),2),IF(M22="MARKUP %",ROUND(R22/J22*(1+N22),2))),0) -> 0 | L22: =ROUND((J22*K22),2) -> 0 | M22: OEM DISC % | N22: 0.45 | R22: =ROUND(IF($R$17=$Q$17,Q22,IF($R$17="USD $",Q22*$D$15,Q22*$E$15))*E22,2) -> 0 | S22: =IFERROR(ROUND(T22/E22,2),0) -> 0 | T22: =ROUND(L22-R22,2) -> 0 | U22: =IFERROR(((K22-(R22/J22))/(R22/J22)),0) -> 0 | V22: =IFERROR(((K22-(R22/J22))/K22),0) -> 0 | Y22: CAT | Z22: 1200
